Workbook
Name _DLX1: [1]Rates!#REF!
Name _DLX1.INC: '[2]Car Air'!#REF!
Name _DLX10.INC: '[3]US&Europe'!#REF!
Name _DLX10_INC: #REF!
Name _DLX100.INC: '[3]Bonds Data BIS'!#REF!
Name _DLX14.INC: #REF!
Name _DLX15.INC: '[3]Bonds Data BIS'!#REF!
Name _DLX16.INC: '[3]Bonds Data BIS'!#REF!
Name _DLX2.INC: #REF!
Name _DLX20.INC: #REF!
Name _DLX3.INC: #REF!
Name _DLX4.INC: #REF!
Name _DLX5.INC: #REF!
Name _DLX5_INC: #REF!
Name _DLX50.INC: '[3]US&Europe'!#REF!
Name _DLX52.INC: #REF!
Name _DLX53.INC: '[3]US&Europe'!#REF!
Name _DLX54.INC: '[3]US&Europe'!#REF!
Name _DLX56.INC: '[3]US&Europe'!#REF!
Name _DLX6.INC: #REF!
Name _DLX60.INC: #REF!
Name _DLX7.INC: '[3]US&Europe'!#REF!
Name _DLX8.INC: '[3]US&Europe'!#REF!
Name _DLX80.INC: '[3]Bonds Data BIS'!#REF!
Name _DLX9.INC: '[3]US&Europe'!#REF!
Name AUD_Nom: #REF!
Name AUD_Tenor: #REF!
Name AUD_yr: #REF!
Name CAD_Nom: #REF!
Name CAD_Tenor: #REF!
Name CAD_yr: #REF!
Name CHF_Nom: #REF!
Name CHF_Tenor: #REF!
Name CHF_yr: #REF!
Name cn_asia: [4]Weights!$J$5
Name code: [5]CONSTANT!#REF!
Name Currency_cusip: '[6]Currency bucketing mapping'!$B$35:$B$160
Name Currency_name: '[6]Currency bucketing mapping'!$B$35:$BF$35
Name Currency_table: '[6]Currency bucketing mapping'!$B$35:$BF$160
Name D_0: #REF!
Name D_0_DE: #REF!
Name D_0_FR: #REF!
Name D_0_IT: #REF!
Name D_0_JP: #REF!
Name D_0_UK: #REF!
Name DaysInYear: [7]C!$B$29
Name DE_gwth: #REF!
Name DE_S: #REF!
Name ERP: [8]CF20!$C$18
Name EUR_Nom: #REF!
Name EUR_Tenor: #REF!
Name EUR_yr: #REF!
Name FR_gwth: #REF!
Name FR_S: #REF!
Name GBP_Nom: #REF!
Name GBP_Tenor: #REF!
Name GBP_yr: #REF!
Name gGDP: [8]CF20!$C$14
Name hk_asia: [4]Weights!$J$6
Name hk_nie: [4]Weights!$K$6

Sheet Index
B3: Sheet Colors
B4: Calculation
B5: Raw Report | C5: <-- If we download a report from a source, ex: Djøf, we will store it here and will not directly edit it
B6: Raw Report with Key | C6: <-- Raw Report but a column has been added for lookups
B8: Table Colors
B9: Uploaded to Python
B10: Not Uploaded to Python

Sheet Goals_P1
A1: Goal Info | B1: GOAL A | C1: GOAL B | D1: GOAL C | E1: GOAL D
A2: Value Ratio | B2: 1 | C2: 0.45 | D2: 0.5 | E2: 0.58
A3: Funding Requirement | B3: 5157000 | C3: 5000000 | D3: 713500 | E3: 8812000
A4: Time Horizon | B4: 10 | C4: 30 | D4: 4 | E4: 18

Sheet Goals_P2
A1: Goal Info | B1: GOAL A | C1: GOAL B | D1: GOAL C | E1: GOAL D
A2: Value Ratio | B2: 1 | C2: 0.45 | D2: 0.5 | E2: 0.58
A3: Funding Requirement | B3: 5157000 | C3: 5000000 | D3: 713500 | E3: 8812000
A4: Time Horizon | B4: 10 | C4: 30 | D4: 4 | E4: 18

Sheet Loop
A1: N | B1: Year | C1: AgeP1 | D1: AgeP2 | E1: LoopStatus
A2: 1 | B2: 2025 | C2: 25 | D2: 40 | E2: N
A3: 2 | B3: 2026 | C3: =C2+1 -> 26 | D3: =D2+1 -> 41 | E3: N
A4: 3 | B4: 2027 | C4: =C3+1 -> 27 | D4: =D3+1 -> 42 | E4: N
A5: 4 | B5: 2028 | C5: =C4+1 -> 28 | D5: =D4+1 -> 43 | E5: N
A6: 5 | B6: 2029 | C6: =C5+1 -> 29 | D6: =D5+1 -> 44 | E6: N
A7: 6 | B7: 2030 | C7: =C6+1 -> 30 | D7: =D6+1 -> 45 | E7: N
A8: 7 | B8: 2031 | C8: =C7+1 -> 31 | D8: =D7+1 -> 46 | E8: N
A9: 8 | B9: 2032 | C9: =C8+1 -> 32 | D9: =D8+1 -> 47 | E9: N
A10: 9 | B10: 2033 | C10: =C9+1 -> 33 | D10: =D9+1 -> 48 | E10: N
A11: 10 | B11: 2034 | C11: =C10+1 -> 34 | D11: =D10+1 -> 49 | E11: N
A12: 11 | B12: 2035 | C12: =C11+1 -> 35 | D12: =D11+1 -> 50 | E12: N
A13: 12 | B13: 2036 | C13: =C12+1 -> 36 | D13: =D12+1 -> 51 | E13: N
A14: 13 | B14: 2037 | C14: =C13+1 -> 37 | D14: =D13+1 -> 52 | E14: N
... A52: 51 | B52: 2075 | C52: =C51+1 -> 75 | D52: =D51+1 -> 90 | E52: N

Sheet Income
A1: Year | B1: SalaryP1 | C1: SalaryP2 | E1: Inflation | F1: 0.04 | J1: GrossMonthlySalaryP1 | K1: GrossMonthlySalaryP2 | L1: SwitchP1 | M1: SwitchP2
A2: 2025 | B2: =(TableIncomeCalculations[[#This Row],[GrossMonthlySalaryP1]]*12) -> 526452 | C2: =(TableIncomeCalculations[[#This Row],[GrossMonthlySalaryP2]]*12) -> 768012 | E2: Salary Raise | F2: 0.05 | J2: 43871 | K2: 64001 | L2: =_xlfn.XLOOKUP(_xlfn.XLOOKUP(TableIncome[[#This Row],[Year]],Loop!B:B,Loop!C:C),'Job Hopping'!A:A,'Job Hopping'!E:E) -> N | M2: =_xlfn.XLOOKUP(_xlfn.XLOOKUP(TableIncome[[#This Row],[Year]],Loop!B:B,Loop!D:D),'Job Hopping'!A:A,'Job Hopping'!F:F) -> N
A3: 2026 | B3: =(TableIncomeCalculations[[#This Row],[GrossMonthlySalaryP1]]*12) -> 531716.52 | C3: =(TableIncomeCalculations[[#This Row],[GrossMonthlySalaryP2]]*12) -> 775692.12 | E3: Real Salary Raise | F3: =F2-F1 -> 0.01 | J3: =IF(_xlfn.XLOOKUP(TableIncome[[#This Row],[Year]],Loop!B:B,Loop!C:C)<70,(J2*(1+$F$3))+IF(TableIncomeCalculations[[#This Row],[SwitchP1]]="Y",J2*$F$4,0),0) -> 44309.71 | K3: =IF(_xlfn.XLOOKUP(TableIncome[[#This Row],[Year]],Loop!B:B,Loop!D:D)<70,(K2*(1+$F$3))+IF(TableIncomeCalculations[[#This Row],[SwitchP2]]="Y",K2*$F$4,0),0) -> 64641.01 | L3: =_xlfn.XLOOKUP(_xlfn.XLOOKUP(TableIncome[[#This Row],[Year]],Loop!B:B,Loop!C:C),'Job Hopping'!A:A,'Job Hopping'!E:E) -> N | M3: =_xlfn.XLOOKUP(_xlfn.XLOOKUP(TableIncome[[#This Row],[Year]],Loop!B:B,Loop!D:D),'Job Hopping'!A:A,'Job Hopping'!F:F) -> N
A4: 2027 | B4: =(TableIncomeCalculations[[#This Row],[GrossMonthlySalaryP1]]*12) -> 590205.34 | C4: =(TableIncomeCalculations[[#This Row],[GrossMonthlySalaryP2]]*12) -> 783449.04 | E4: Job Hopping "Bonus" | F4: 0.1 | J4: =IF(_xlfn.XLOOKUP(TableIncome[[#This Row],[Year]],Loop!B:B,Loop!C:C)<70,(J3*(1+$F$3))+IF(TableIncomeCalculations[[#This Row],[SwitchP1]]="Y",J3*$F$4,0),0) -> 49183.778 | K4: =IF(_xlfn.XLOOKUP(TableIncome[[#This Row],[Year]],Loop!B:B,Loop!D:D)<70,(K3*(1+$F$3))+IF(TableIncomeCalculations[[#This Row],[SwitchP2]]="Y",K3*$F$4,0),0) -> 65287.42 | L4: =_xlfn.XLOOKUP(_xlfn.XLOOKUP(TableIncome[[#This Row],[Year]],Loop!B:B,Loop!C:C),'Job Hopping'!A:A,'Job Hopping'!E:E) -> Y | M4: =_xlfn.XLOOKUP(_xlfn.XLOOKUP(TableIncome[[#This Row],[Year]],Loop!B:B,Loop!D:D),'Job Hopping'!A:A,'Job Hopping'!F:F) -> N
A5: 2028 | B5: =(TableIncomeCalculations[[#This Row],[GrossMonthlySalaryP1]]*12) -> 596107.39 | C5: =(TableIncomeCalculations[[#This Row],[GrossMonthlySalaryP2]]*12) -> 869628.44 | J5: =IF(_xlfn.XLOOKUP(TableIncome[[#This Row],[Year]],Loop!B:B,Loop!C:C)<70,(J4*(1+$F$3))+IF(TableIncomeCalculations[[#This Row],[SwitchP1]]="Y",J4*$F$4,0),0) -> 49675.616 | K5: =IF(_xlfn.XLOOKUP(TableIncome[[#This Row],[Year]],Loop!B:B,Loop!D:D)<70,(K4*(1+$F$3))+IF(TableIncomeCalculations[[#This Row],[SwitchP2]]="Y",K4*$F$4,0),0) -> 72469.036 | L5: =_xlfn.XLOOKUP(_xlfn.XLOOKUP(TableIncome[[#This Row],[Year]],Loop!B:B,Loop!C:C),'Job Hopping'!A:A,'Job Hopping'!E:E) -> N | M5: =_xlfn.XLOOKUP(_xlfn.XLOOKUP(TableIncome[[#This Row],[Year]],Loop!B:B,Loop!D:D),'Job Hopping'!A:A,'Job Hopping'!F:F) -> Y
A6: 2029 | B6: =(TableIncomeCalculations[[#This Row],[GrossMonthlySalaryP1]]*12) -> 602068.46 | C6: =(TableIncomeCalculations[[#This Row],[GrossMonthlySalaryP2]]*12) -> 878324.72 | J6: =IF(_xlfn.XLOOKUP(TableIncome[[#This Row],[Year]],Loop!B:B,Loop!C:C)<70,(J5*(1+$F$3))+IF(TableIncomeCalculations[[#This Row],[SwitchP1]]="Y",J5*$F$4,0),0) -> 50172.372 | K6: =IF(_xlfn.XLOOKUP(TableIncome[[#This Row],[Year]],Loop!B:B,Loop!D:D)<70,(K5*(1+$F$3))+IF(TableIncomeCalculations[[#This Row],[SwitchP2]]="Y",K5*$F$4,0),0) -> 73193.727 | L6: =_xlfn.XLOOKUP(_xlfn.XLOOKUP(TableIncome[[#This Row],[Year]],Loop!B:B,Loop!C:C),'Job Hopping'!A:A,'Job Hopping'!E:E) -> N | M6: =_xlfn.XLOOKUP(_xlfn.XLOOKUP(TableIncome[[#This Row],[Year]],Loop!B:B,Loop!D:D),'Job Hopping'!A:A,'Job Hopping'!F:F) -> N
A7: 2030 | B7: =(TableIncomeCalculations[[#This Row],[GrossMonthlySalaryP1]]*12) -> 608089.15 | C7: =(TableIncomeCalculations[[#This Row],[GrossMonthlySalaryP2]]*12) -> 887107.97 | J7: =IF(_xlfn.XLOOKUP(TableIncome[[#This Row],[Year]],Loop!B:B,Loop!C:C)<70,(J6*(1+$F$3))+IF(TableIncomeCalculations[[#This Row],[SwitchP1]]="Y",J6*$F$4,0),0) -> 50674.096 | K7: =IF(_xlfn.XLOOKUP(TableIncome[[#This Row],[Year]],Loop!B:B,Loop!D:D)<70,(K6*(1+$F$3))+IF(TableIncomeCalculations[[#This Row],[SwitchP2]]="Y",K6*$F$4,0),0) -> 73925.664 | L7: =_xlfn.XLOOKUP(_xlfn.XLOOKUP(TableIncome[[#This Row],[Year]],Loop!B:B,Loop!C:C),'Job Hopping'!A:A,'Job Hopping'!E:E) -> N | M7: =_xlfn.XLOOKUP(_xlfn.XLOOKUP(TableIncome[[#This Row],[Year]],Loop!B:B,Loop!D:D),'Job Hopping'!A:A,'Job Hopping'!F:F) -> N
A8: 2031 | B8: =(TableIncomeCalculations[[#This Row],[GrossMonthlySalaryP1]]*12) -> 674978.96 | C8: =(TableIncomeCalculations[[#This Row],[GrossMonthlySalaryP2]]*12) -> 895979.05 | J8: =IF(_xlfn.XLOOKUP(TableIncome[[#This Row],[Year]],Loop!B:B,Loop!C:C)<70,(J7*(1+$F$3))+IF(TableIncomeCalculations[[#This Row],[SwitchP1]]="Y",J7*$F$4,0),0) -> 56248.246 | K8: =IF(_xlfn.XLOOKUP(TableIncome[[#This Row],[Year]],Loop!B:B,Loop!D:D)<70,(K7*(1+$F$3))+IF(TableIncomeCalculations[[#This Row],[SwitchP2]]="Y",K7*$F$4,0),0) -> 74664.921 | L8: =_xlfn.XLOOKUP(_xlfn.XLOOKUP(TableIncome[[#This Row],[Year]],Loop!B:B,Loop!C:C),'Job Hopping'!A:A,'Job Hopping'!E:E) -> Y | M8: =_xlfn.XLOOKUP(_xlfn.XLOOKUP(TableIncome[[#This Row],[Year]],Loop!B:B,Loop!D:D),'Job Hopping'!A:A,'Job Hopping'!F:F) -> N
A9: 2032 | B9: =(TableIncomeCalculations[[#This Row],[GrossMonthlySalaryP1]]*12) -> 681728.75 | C9: =(TableIncomeCalculations[[#This Row],[GrossMonthlySalaryP2]]*12) -> 994536.74 | J9: =IF(_xlfn.XLOOKUP(TableIncome[[#This Row],[Year]],Loop!B:B,Loop!C:C)<70,(J8*(1+$F$3))+IF(TableIncomeCalculations[[#This Row],[SwitchP1]]="Y",J8*$F$4,0),0) -> 56810.729 | K9: =IF(_xlfn.XLOOKUP(TableIncome[[#This Row],[Year]],Loop!B:B,Loop!D:D)<70,(K8*(1+$F$3))+IF(TableIncomeCalculations[[#This Row],[SwitchP2]]="Y",K8*$F$4,0),0) -> 82878.062 | L9: =_xlfn.XLOOKUP(_xlfn.XLOOKUP(TableIncome[[#This Row],[Year]],Loop!B:B,Loop!C:C),'Job Hopping'!A:A,'Job Hopping'!E:E) -> N | M9: =_xlfn.XLOOKUP(_xlfn.XLOOKUP(TableIncome[[#This Row],[Year]],Loop!B:B,Loop!D:D),'Job Hopping'!A:A,'Job Hopping'!F:F) -> Y
A10: 2033 | B10: =(TableIncomeCalculations[[#This Row],[GrossMonthlySalaryP1]]*12) -> 688546.03 | C10: =(TableIncomeCalculations[[#This Row],[GrossMonthlySalaryP2]]*12) -> 1004482.1 | J10: =IF(_xlfn.XLOOKUP(TableIncome[[#This Row],[Year]],Loop!B:B,Loop!C:C)<70,(J9*(1+$F$3))+IF(TableIncomeCalculations[[#This Row],[SwitchP1]]="Y",J9*$F$4,0),0) -> 57378.836 | K10: =IF(_xlfn.XLOOKUP(TableIncome[[#This Row],[Year]],Loop!B:B,Loop!D:D)<70,(K9*(1+$F$3))+IF(TableIncomeCalculations[[#This Row],[SwitchP2]]="Y",K9*$F$4,0),0) -> 83706.842 | L10: =_xlfn.XLOOKUP(_xlfn.XLOOKUP(TableIncome[[#This Row],[Year]],Loop!B:B,Loop!C:C),'Job Hopping'!A:A,'Job Hopping'!E:E) -> N | M10: =_xlfn.XLOOKUP(_xlfn.XLOOKUP(TableIncome[[#This Row],[Year]],Loop!B:B,Loop!D:D),'Job Hopping'!A:A,'Job Hopping'!F:F) -> N
A11: 2034 | B11: =(TableIncomeCalculations[[#This Row],[GrossMonthlySalaryP1]]*12) -> 695431.49 | C11: =(TableIncomeCalculations[[#This Row],[GrossMonthlySalaryP2]]*12) -> 1014526.9 | J11: =IF(_xlfn.XLOOKUP(TableIncome[[#This Row],[Year]],Loop!B:B,Loop!C:C)<70,(J10*(1+$F$3))+IF(TableIncomeCalculations[[#This Row],[SwitchP1]]="Y",J10*$F$4,0),0) -> 57952.624 | K11: =IF(_xlfn.XLOOKUP(TableIncome[[#This Row],[Year]],Loop!B:B,Loop!D:D)<70,(K10*(1+$F$3))+IF(TableIncomeCalculations[[#This Row],[SwitchP2]]="Y",K10*$F$4,0),0) -> 84543.911 | L11: =_xlfn.XLOOKUP(_xlfn.XLOOKUP(TableIncome[[#This Row],[Year]],Loop!B:B,Loop!C:C),'Job Hopping'!A:A,'Job Hopping'!E:E) -> N | M11: =_xlfn.XLOOKUP(_xlfn.XLOOKUP(TableIncome[[#This Row],[Year]],Loop!B:B,Loop!D:D),'Job Hopping'!A:A,'Job Hopping'!F:F) -> N
A12: 2035 | B12: =(TableIncomeCalculations[[#This Row],[GrossMonthlySalaryP1]]*12) -> 771928.96 | C12: =(TableIncomeCalculations[[#This Row],[GrossMonthlySalaryP2]]*12) -> 1024672.2 | J12: =IF(_xlfn.XLOOKUP(TableIncome[[#This Row],[Year]],Loop!B:B,Loop!C:C)<70,(J11*(1+$F$3))+IF(TableIncomeCalculations[[#This Row],[SwitchP1]]="Y",J11*$F$4,0),0) -> 64327.413 | K12: =IF(_xlfn.XLOOKUP(TableIncome[[#This Row],[Year]],Loop!B:B,Loop!D:D)<70,(K11*(1+$F$3))+IF(TableIncomeCalculations[[#This Row],[SwitchP2]]="Y",K11*$F$4,0),0) -> 85389.35 | L12: =_xlfn.XLOOKUP(_xlfn.XLOOKUP(TableIncome[[#This Row],[Year]],Loop!B:B,Loop!C:C),'Job Hopping'!A:A,'Job Hopping'!E:E) -> Y | M12: =_xlfn.XLOOKUP(_xlfn.XLOOKUP(TableIncome[[#This Row],[Year]],Loop!B:B,Loop!D:D),'Job Hopping'!A:A,'Job Hopping'!F:F) -> N
A13: 2036 | B13: =(TableIncomeCalculations[[#This Row],[GrossMonthlySalaryP1]]*12) -> 779648.25 | C13: =(TableIncomeCalculations[[#This Row],[GrossMonthlySalaryP2]]*12) -> 1034918.9 | J13: =IF(_xlfn.XLOOKUP(TableIncome[[#This Row],[Year]],Loop!B:B,Loop!C:C)<70,(J12*(1+$F$3))+IF(TableIncomeCalculations[[#This Row],[SwitchP1]]="Y",J12*$F$4,0),0) -> 64970.687 | K13: =IF(_xlfn.XLOOKUP(TableIncome[[#This Row],[Year]],Loop!B:B,Loop!D:D)<70,(K12*(1+$F$3))+IF(TableIncomeCalculations[[#This Row],[SwitchP2]]="Y",K12*$F$4,0),0) -> 86243.243 | L13: =_xlfn.XLOOKUP(_xlfn.XLOOKUP(TableIncome[[#This Row],[Year]],Loop!B:B,Loop!C:C),'Job Hopping'!A:A,'Job Hopping'!E:E) -> N | M13: =_xlfn.XLOOKUP(_xlfn.XLOOKUP(TableIncome[[#This Row],[Year]],Loop!B:B,Loop!D:D),'Job Hopping'!A:A,'Job Hopping'!F:F) -> N
A14: 2037 | B14: =(TableIncomeCalculations[[#This Row],[GrossMonthlySalaryP1]]*12) -> 787444.73 | C14: =(TableIncomeCalculations[[#This Row],[GrossMonthlySalaryP2]]*12) -> 1045268.1 | J14: =IF(_xlfn.XLOOKUP(TableIncome[[#This Row],[Year]],Loop!B:B,Loop!C:C)<70,(J13*(1+$F$3))+IF(TableIncomeCalculations[[#This Row],[SwitchP1]]="Y",J13*$F$4,0),0) -> 65620.394 | K14: =IF(_xlfn.XLOOKUP(TableIncome[[#This Row],[Year]],Loop!B:B,Loop!D:D)<70,(K13*(1+$F$3))+IF(TableIncomeCalculations[[#This Row],[SwitchP2]]="Y",K13*$F$4,0),0) -> 87105.676 | L14: =_xlfn.XLOOKUP(_xlfn.XLOOKUP(TableIncome[[#This Row],[Year]],Loop!B:B,Loop!C:C),'Job Hopping'!A:A,'Job Hopping'!E:E) -> N | M14: =_xlfn.XLOOKUP(_xlfn.XLOOKUP(TableIncome[[#This Row],[Year]],Loop!B:B,Loop!D:D),'Job Hopping'!A:A,'Job Hopping'!F:F) -> N
A15: 2038 | B15: =(TableIncomeCalculations[[#This Row],[GrossMonthlySalaryP1]]*12) -> 795319.18 | C15: =(TableIncomeCalculations[[#This Row],[GrossMonthlySalaryP2]]*12) -> 1055720.8 | J15: =IF(_xlfn.XLOOKUP(TableIncome[[#This Row],[Year]],Loop!B:B,Loop!C:C)<70,(J14*(1+$F$3))+IF(TableIncomeCalculations[[#This Row],[SwitchP1]]="Y",J14*$F$4,0),0) -> 66276.598 | K15: =IF(_xlfn.XLOOKUP(TableIncome[[#This Row],[Year]],Loop!B:B,Loop!D:D)<70,(K14*(1+$F$3))+IF(TableIncomeCalculations[[#This Row],[SwitchP2]]="Y",K14*$F$4,0),0) -> 87976.733 | L15: =_xlfn.XLOOKUP(_xlfn.XLOOKUP(TableIncome[[#This Row],[Year]],Loop!B:B,Loop!C:C),'Job Hopping'!A:A,'Job Hopping'!E:E) -> N | M15: =_xlfn.XLOOKUP(_xlfn.XLOOKUP(TableIncome[[#This Row],[Year]],Loop!B:B,Loop!D:D),'Job Hopping'!A:A,'Job Hopping'!F:F) -> N
A16: 2039 | B16: =(TableIncomeCalculations[[#This Row],[GrossMonthlySalaryP1]]*12) -> 882804.29 | C16: =(TableIncomeCalculations[[#This Row],[GrossMonthlySalaryP2]]*12) -> 1066278 | J16: =IF(_xlfn.XLOOKUP(TableIncome[[#This Row],[Year]],Loop!B:B,Loop!C:C)<70,(J15*(1+$F$3))+IF(TableIncomeCalculations[[#This Row],[SwitchP1]]="Y",J15*$F$4,0),0) -> 73567.024 | K16: =IF(_xlfn.XLOOKUP(TableIncome[[#This Row],[Year]],Loop!B:B,Loop!D:D)<70,(K15*(1+$F$3))+IF(TableIncomeCalculations[[#This Row],[SwitchP2]]="Y",K15*$F$4,0),0) -> 88856.5 | L16: =_xlfn.XLOOKUP(_xlfn.XLOOKUP(TableIncome[[#This Row],[Year]],Loop!B:B,Loop!C:C),'Job Hopping'!A:A,'Job Hopping'!E:E) -> Y | M16: =_xlfn.XLOOKUP(_xlfn.XLOOKUP(TableIncome[[#This Row],[Year]],Loop!B:B,Loop!D:D),'Job Hopping'!A:A,'Job Hopping'!F:F) -> N
... A47: 2070 | B47: =(TableIncomeCalculations[[#This Row],[GrossMonthlySalaryP1]]*12) -> 0 | C47: =(TableIncomeCalculations[[#This Row],[GrossMonthlySalaryP2]]*12) -> 0 | J47: =IF(_xlfn.XLOOKUP(TableIncome[[#This Row],[Year]],Loop!B:B,Loop!C:C)<70,(J46*(1+$F$3))+IF(TableIncomeCalculations[[#This Row],[SwitchP1]]="Y",J46*$F$4,0),0) -> 0 | K47: =IF(_xlfn.XLOOKUP(TableIncome[[#This Row],[Year]],Loop!B:B,Loop!D:D)<70,(K46*(1+$F$3))+IF(TableIncomeCalculations[[#This Row],[SwitchP2]]="Y",K46*$F$4,0),0) -> 0 | L47: =_xlfn.XLOOKUP(_xlfn.XLOOKUP(TableIncome[[#This Row],[Year]],Loop!B:B,Loop!C:C),'Job Hopping'!A:A,'Job Hopping'!E:E) -> N | M47: =_xlfn.XLOOKUP(_xlfn.XLOOKUP(TableIncome[[#This Row],[Year]],Loop!B:B,Loop!D:D),'Job Hopping'!A:A,'Job Hopping'!F:F) -> N

Sheet Job Hopping
A1: Age | B1: Age Group | C1: FH/FW | D1: Switch | E1: SwitchP1Static | F1: SwitchP2Static | L1: Year | M1: Age Group | N1: Finance Workers | O1: Finance Hoppers | P1: FH/FW | R1: Age Group | S1: FH/FV
A2: 25 | B2: =IF(A2<30, "25-29 år", IF(A2<35, "30-34 år", IF(A2<40, "35-39 år", IF(A2<45, "40-44 år", IF(A2<50, "45-49 år", IF(A2<55, "50-54 år", IF(A2<60, "55-59 år", IF(A2<65, "60-64 år", "65+ år")))))))) -> 25-29 år | C2: =_xlfn.XLOOKUP(B2,R:R,S:S) -> 0.51651948 | D2: =IF(OR(JobHopping[[#This Row],[Age]]=25,JobHopping[[#This Row],[Age]]>69),"N",IF(AND(#REF!="N",D1="N", RAND()<=C2), "Y", "N")) -> N | E2: N | F2: =IF(JobHopping[[#This Row],[Age]]<40,"",JobHopping[[#This Row],[SwitchP1Static]]) | L2: 2013 | M2: 25-29 år | N2: =_xlfn.XLOOKUP(L2&"-"&M2,'Djøf Finance Workers'!D:D,'Djøf Finance Workers'!C:C,0,1) -> 6202 | O2: =_xlfn.XLOOKUP(L2&"-"&M2,'Djøf Finance Hoppers'!D:D,'Djøf Finance Hoppers'!C:C,0,1) -> 2524 | P2: =IF(N2>0, O2/N2, 0) -> 0.4069655 | R2: 25-29 år | S2: =SUMIFS(P:P,M:M,R2)/(MAX($L$2:$L$100)-MIN($L$2:$L$100)) -> 0.51651948
A3: 26 | B3: =IF(A3<30, "25-29 år", IF(A3<35, "30-34 år", IF(A3<40, "35-39 år", IF(A3<45, "40-44 år", IF(A3<50, "45-49 år", IF(A3<55, "50-54 år", IF(A3<60, "55-59 år", IF(A3<65, "60-64 år", "65+ år")))))))) -> 25-29 år | C3: =_xlfn.XLOOKUP(B3,R:R,S:S) -> 0.51651948 | D3: =IF(OR(JobHopping[[#This Row],[Age]]=25,JobHopping[[#This Row],[Age]]>69),"N",IF(AND(D1="N",D2="N", RAND()<=C3), "Y", "N")) -> N | E3: N | F3: =IF(JobHopping[[#This Row],[Age]]<40,"",JobHopping[[#This Row],[SwitchP1Static]]) | L3: 2013 | M3: 30-34 år | N3: =_xlfn.XLOOKUP(L3&"-"&M3,'Djøf Finance Workers'!D:D,'Djøf Finance Workers'!C:C,0,1) -> 8560 | O3: =_xlfn.XLOOKUP(L3&"-"&M3,'Djøf Finance Hoppers'!D:D,'Djøf Finance Hoppers'!C:C,0,1) -> 2176 | P3: =IF(N3>0, O3/N3, 0) -> 0.25420561 | R3: 30-34 år | S3: =SUMIFS(P:P,M:M,R3)/(MAX($L$2:$L$100)-MIN($L$2:$L$100)) -> 0.3390802
A4: 27 | B4: =IF(A4<30, "25-29 år", IF(A4<35, "30-34 år", IF(A4<40, "35-39 år", IF(A4<45, "40-44 år", IF(A4<50, "45-49 år", IF(A4<55, "50-54 år", IF(A4<60, "55-59 år", IF(A4<65, "60-64 år", "65+ år")))))))) -> 25-29 år | C4: =_xlfn.XLOOKUP(B4,R:R,S:S) -> 0.51651948 | D4: =IF(OR(JobHopping[[#This Row],[Age]]=25,JobHopping[[#This Row],[Age]]>69),"N",IF(AND(D2="N",D3="N", RAND()<=C4), "Y", "N")) -> Y | E4: Y | F4: =IF(JobHopping[[#This Row],[Age]]<40,"",JobHopping[[#This Row],[SwitchP1Static]]) | L4: 2013 | M4: 35-39 år | N4: =_xlfn.XLOOKUP(L4&"-"&M4,'Djøf Finance Workers'!D:D,'Djøf Finance Workers'!C:C,0,1) -> 9790 | O4: =_xlfn.XLOOKUP(L4&"-"&M4,'Djøf Finance Hoppers'!D:D,'Djøf Finance Hoppers'!C:C,0,1) -> 1896 | P4: =IF(N4>0, O4/N4, 0) -> 0.19366701 | R4: 35-39 år | S4: =SUMIFS(P:P,M:M,R4)/(MAX($L$2:$L$100)-MIN($L$2:$L$100)) -> 0.26240269
A5: 28 | B5: =IF(A5<30, "25-29 år", IF(A5<35, "30-34 år", IF(A5<40, "35-39 år", IF(A5<45, "40-44 år", IF(A5<50, "45-49 år", IF(A5<55, "50-54 år", IF(A5<60, "55-59 år", IF(A5<65, "60-64 år", "65+ år")))))))) -> 25-29 år | C5: =_xlfn.XLOOKUP(B5,R:R,S:S) -> 0.51651948 | D5: =IF(OR(JobHopping[[#This Row],[Age]]=25,JobHopping[[#This Row],[Age]]>69),"N",IF(AND(D3="N",D4="N", RAND()<=C5), "Y", "N")) -> N | E5: N | F5: =IF(JobHopping[[#This Row],[Age]]<40,"",JobHopping[[#This Row],[SwitchP1Static]]) | L5: 2013 | M5: 40-44 år | N5: =_xlfn.XLOOKUP(L5&"-"&M5,'Djøf Finance Workers'!D:D,'Djøf Finance Workers'!C:C,0,1) -> 9383 | O5: =_xlfn.XLOOKUP(L5&"-"&M5,'Djøf Finance Hoppers'!D:D,'Djøf Finance Hoppers'!C:C,0,1) -> 1579 | P5: =IF(N5>0, O5/N5, 0) -> 0.16828307 | R5: 40-44 år | S5: =SUMIFS(P:P,M:M,R5)/(MAX($L$2:$L$100)-MIN($L$2:$L$100)) -> 0.22131873
A6: 29 | B6: =IF(A6<30, "25-29 år", IF(A6<35, "30-34 år", IF(A6<40, "35-39 år", IF(A6<45, "40-44 år", IF(A6<50, "45-49 år", IF(A6<55, "50-54 år", IF(A6<60, "55-59 år", IF(A6<65, "60-64 år", "65+ år")))))))) -> 25-29 år | C6: =_xlfn.XLOOKUP(B6,R:R,S:S) -> 0.51651948 | D6: =IF(OR(JobHopping[[#This Row],[Age]]=25,JobHopping[[#This Row],[Age]]>69),"N",IF(AND(D4="N",D5="N", RAND()<=C6), "Y", "N")) -> N | E6: N | F6: =IF(JobHopping[[#This Row],[Age]]<40,"",JobHopping[[#This Row],[SwitchP1Static]]) | L6: 2013 | M6: 45-49 år | N6: =_xlfn.XLOOKUP(L6&"-"&M6,'Djøf Finance Workers'!D:D,'Djøf Finance Workers'!C:C,0,1) -> 12762 | O6: =_xlfn.XLOOKUP(L6&"-"&M6,'Djøf Finance Hoppers'!D:D,'Djøf Finance Hoppers'!C:C,0,1) -> 1915 | P6: =IF(N6>0, O6/N6, 0) -> 0.15005485 | R6: 45-49 år | S6: =SUMIFS(P:P,M:M,R6)/(MAX($L$2:$L$100)-MIN($L$2:$L$100)) -> 0.1992948
A7: 30 | B7: =IF(A7<30, "25-29 år", IF(A7<35, "30-34 år", IF(A7<40, "35-39 år", IF(A7<45, "40-44 år", IF(A7<50, "45-49 år", IF(A7<55, "50-54 år", IF(A7<60, "55-59 år", IF(A7<65, "60-64 år", "65+ år")))))))) -> 30-34 år | C7: =_xlfn.XLOOKUP(B7,R:R,S:S) -> 0.3390802 | D7: =IF(OR(JobHopping[[#This Row],[Age]]=25,JobHopping[[#This Row],[Age]]>69),"N",IF(AND(D5="N",D6="N", RAND()<=C7), "Y", "N")) -> Y | E7: N | F7: =IF(JobHopping[[#This Row],[Age]]<40,"",JobHopping[[#This Row],[SwitchP1Static]]) | L7: 2013 | M7: 50-54 år | N7: =_xlfn.XLOOKUP(L7&"-"&M7,'Djøf Finance Workers'!D:D,'Djøf Finance Workers'!C:C,0,1) -> 10587 | O7: =_xlfn.XLOOKUP(L7&"-"&M7,'Djøf Finance Hoppers'!D:D,'Djøf Finance Hoppers'!C:C,0,1) -> 1462 | P7: =IF(N7>0, O7/N7, 0) -> 0.13809389 | R7: 50-54 år | S7: =SUMIFS(P:P,M:M,R7)/(MAX($L$2:$L$100)-MIN($L$2:$L$100)) -> 0.17668929
A8: 31 | B8: =IF(A8<30, "25-29 år", IF(A8<35, "30-34 år", IF(A8<40, "35-39 år", IF(A8<45, "40-44 år", IF(A8<50, "45-49 år", IF(A8<55, "50-54 år", IF(A8<60, "55-59 år", IF(A8<65, "60-64 år", "65+ år")))))))) -> 30-34 år | C8: =_xlfn.XLOOKUP(B8,R:R,S:S) -> 0.3390802 | D8: =IF(OR(JobHopping[[#This Row],[Age]]=25,JobHopping[[#This Row],[Age]]>69),"N",IF(AND(D6="N",D7="N", RAND()<=C8), "Y", "N")) -> N | E8: Y | F8: =IF(JobHopping[[#This Row],[Age]]<40,"",JobHopping[[#This Row],[SwitchP1Static]]) | L8: 2013 | M8: 55-59 år | N8: =_xlfn.XLOOKUP(L8&"-"&M8,'Djøf Finance Workers'!D:D,'Djøf Finance Workers'!C:C,0,1) -> 8811 | O8: =_xlfn.XLOOKUP(L8&"-"&M8,'Djøf Finance Hoppers'!D:D,'Djøf Finance Hoppers'!C:C,0,1) -> 1227 | P8: =IF(N8>0, O8/N8, 0) -> 0.13925775 | R8: 55-59 år | S8: =SUMIFS(P:P,M:M,R8)/(MAX($L$2:$L$100)-MIN($L$2:$L$100)) -> 0.15515675
A9: 32 | B9: =IF(A9<30, "25-29 år", IF(A9<35, "30-34 år", IF(A9<40, "35-39 år", IF(A9<45, "40-44 år", IF(A9<50, "45-49 år", IF(A9<55, "50-54 år", IF(A9<60, "55-59 år", IF(A9<65, "60-64 år", "65+ år")))))))) -> 30-34 år | C9: =_xlfn.XLOOKUP(B9,R:R,S:S) -> 0.3390802 | D9: =IF(OR(JobHopping[[#This Row],[Age]]=25,JobHopping[[#This Row],[Age]]>69),"N",IF(AND(D7="N",D8="N", RAND()<=C9), "Y", "N")) -> N | E9: N | F9: =IF(JobHopping[[#This Row],[Age]]<40,"",JobHopping[[#This Row],[SwitchP1Static]]) | L9: 2013 | M9: 60-64 år | N9: =_xlfn.XLOOKUP(L9&"-"&M9,'Djøf Finance Workers'!D:D,'Djøf Finance Workers'!C:C,0,1) -> 5072 | O9: =_xlfn.XLOOKUP(L9&"-"&M9,'Djøf Finance Hoppers'!D:D,'Djøf Finance Hoppers'!C:C,0,1) -> 667 | P9: =IF(N9>0, O9/N9, 0) -> 0.13150631 | R9: 60-64 år | S9: =SUMIFS(P:P,M:M,R9)/(MAX($L$2:$L$100)-MIN($L$2:$L$100)) -> 0.13997312
A10: 33 | B10: =IF(A10<30, "25-29 år", IF(A10<35, "30-34 år", IF(A10<40, "35-39 år", IF(A10<45, "40-44 år", IF(A10<50, "45-49 år", IF(A10<55, "50-54 år", IF(A10<60, "55-59 år", IF(A10<65, "60-64 år", "65+ år")))))))) -> 30-34 år | C10: =_xlfn.XLOOKUP(B10,R:R,S:S) -> 0.3390802 | D10: =IF(OR(JobHopping[[#This Row],[Age]]=25,JobHopping[[#This Row],[Age]]>69),"N",IF(AND(D8="N",D9="N", RAND()<=C10), "Y", "N")) -> N | E10: N | F10: =IF(JobHopping[[#This Row],[Age]]<40,"",JobHopping[[#This Row],[SwitchP1Static]]) | L10: 2013 | M10: 65+ år | N10: =_xlfn.XLOOKUP(L10&"-"&M10,'Djøf Finance Workers'!D:D,'Djøf Finance Workers'!C:C,0,1) -> 1539 | O10: =_xlfn.XLOOKUP(L10&"-"&M10,'Djøf Finance Hoppers'!D:D,'Djøf Finance Hoppers'!C:C,0,1) -> 224 | P10: =IF(N10>0, O10/N10, 0) -> 0.14554906 | R10: 65+ år | S10: =SUMIFS(P:P,M:M,R10)/(MAX($L$2:$L$100)-MIN($L$2:$L$100)) -> 0.11691873
A11: 34 | B11: =IF(A11<30, "25-29 år", IF(A11<35, "30-34 år", IF(A11<40, "35-39 år", IF(A11<45, "40-44 år", IF(A11<50, "45-49 år", IF(A11<55, "50-54 år", IF(A11<60, "55-59 år", IF(A11<65, "60-64 år", "65+ år")))))))) -> 30-34 år | C11: =_xlfn.XLOOKUP(B11,R:R,S:S) -> 0.3390802 | D11: =IF(OR(JobHopping[[#This Row],[Age]]=25,JobHopping[[#This Row],[Age]]>69),"N",IF(AND(D9="N",D10="N", RAND()<=C11), "Y", "N")) -> Y | E11: N | F11: =IF(JobHopping[[#This Row],[Age]]<40,"",JobHopping[[#This Row],[SwitchP1Static]]) | L11: 2014 | M11: 25-29 år | N11: =_xlfn.XLOOKUP(L11&"-"&M11,'Djøf Finance Workers'!D:D,'Djøf Finance Workers'!C:C,0,1) -> 6041 | O11: =_xlfn.XLOOKUP(L11&"-"&M11,'Djøf Finance Hoppers'!D:D,'Djøf Finance Hoppers'!C:C,0,1) -> 2521 | P11: =IF(N11>0, O11/N11, 0) -> 0.41731501
A12: 35 | B12: =IF(A12<30, "25-29 år", IF(A12<35, "30-34 år", IF(A12<40, "35-39 år", IF(A12<45, "40-44 år", IF(A12<50, "45-49 år", IF(A12<55, "50-54 år", IF(A12<60, "55-59 år", IF(A12<65, "60-64 år", "65+ år")))))))) -> 35-39 år | C12: =_xlfn.XLOOKUP(B12,R:R,S:S) -> 0.26240269 | D12: =IF(OR(JobHopping[[#This Row],[Age]]=25,JobHopping[[#This Row],[Age]]>69),"N",IF(AND(D10="N",D11="N", RAND()<=C12), "Y", "N")) -> N | E12: Y | F12: =IF(JobHopping[[#This Row],[Age]]<40,"",JobHopping[[#This Row],[SwitchP1Static]]) | L12: 2014 | M12: 30-34 år | N12: =_xlfn.XLOOKUP(L12&"-"&M12,'Djøf Finance Workers'!D:D,'Djøf Finance Workers'!C:C,0,1) -> 8203 | O12: =_xlfn.XLOOKUP(L12&"-"&M12,'Djøf Finance Hoppers'!D:D,'Djøf Finance Hoppers'!C:C,0,1) -> 2178 | P12: =IF(N12>0, O12/N12, 0) -> 0.26551262
A13: 36 | B13: =IF(A13<30, "25-29 år", IF(A13<35, "30-34 år", IF(A13<40, "35-39 år", IF(A13<45, "40-44 år", IF(A13<50, "45-49 år", IF(A13<55, "50-54 år", IF(A13<60, "55-59 år", IF(A13<65, "60-64 år", "65+ år")))))))) -> 35-39 år | C13: =_xlfn.XLOOKUP(B13,R:R,S:S) -> 0.26240269 | D13: =IF(OR(JobHopping[[#This Row],[Age]]=25,JobHopping[[#This Row],[Age]]>69),"N",IF(AND(D11="N",D12="N", RAND()<=C13), "Y", "N")) -> N | E13: N | F13: =IF(JobHopping[[#This Row],[Age]]<40,"",JobHopping[[#This Row],[SwitchP1Static]]) | L13: 2014 | M13: 35-39 år | N13: =_xlfn.XLOOKUP(L13&"-"&M13,'Djøf Finance Workers'!D:D,'Djøf Finance Workers'!C:C,0,1) -> 9972 | O13: =_xlfn.XLOOKUP(L13&"-"&M13,'Djøf Finance Hoppers'!D:D,'Djøf Finance Hoppers'!C:C,0,1) -> 2066 | P13: =IF(N13>0, O13/N13, 0) -> 0.2071801
A14: 37 | B14: =IF(A14<30, "25-29 år", IF(A14<35, "30-34 år", IF(A14<40, "35-39 år", IF(A14<45, "40-44 år", IF(A14<50, "45-49 år", IF(A14<55, "50-54 år", IF(A14<60, "55-59 år", IF(A14<65, "60-64 år", "65+ år")))))))) -> 35-39 år | C14: =_xlfn.XLOOKUP(B14,R:R,S:S) -> 0.26240269 | D14: =IF(OR(JobHopping[[#This Row],[Age]]=25,JobHopping[[#This Row],[Age]]>69),"N",IF(AND(D12="N",D13="N", RAND()<=C14), "Y", "N")) -> N | E14: N | F14: =IF(JobHopping[[#This Row],[Age]]<40,"",JobHopping[[#This Row],[SwitchP1Static]]) | L14: 2014 | M14: 40-44 år | N14: =_xlfn.XLOOKUP(L14&"-"&M14,'Djøf Finance Workers'!D:D,'Djøf Finance Workers'!C:C,0,1) -> 9409 | O14: =_xlfn.XLOOKUP(L14&"-"&M14,'Djøf Finance Hoppers'!D:D,'Djøf Finance Hoppers'!C:C,0,1) -> 1647 | P14: =IF(N14>0, O14/N14, 0) -> 0.17504517
A15: 38 | B15: =IF(A15<30, "25-29 år", IF(A15<35, "30-34 år", IF(A15<40, "35-39 år", IF(A15<45, "40-44 år", IF(A15<50, "45-49 år", IF(A15<55, "50-54 år", IF(A15<60, "55-59 år", IF(A15<65, "60-64 år", "65+ år")))))))) -> 35-39 år | C15: =_xlfn.XLOOKUP(B15,R:R,S:S) -> 0.26240269 | D15: =IF(OR(JobHopping[[#This Row],[Age]]=25,JobHopping[[#This Row],[Age]]>69),"N",IF(AND(D13="N",D14="N", RAND()<=C15), "Y", "N")) -> Y | E15: N | F15: =IF(JobHopping[[#This Row],[Age]]<40,"",JobHopping[[#This Row],[SwitchP1Static]]) | L15: 2014 | M15: 45-49 år | N15: =_xlfn.XLOOKUP(L15&"-"&M15,'Djøf Finance Workers'!D:D,'Djøf Finance Workers'!C:C,0,1) -> 12377 | O15: =_xlfn.XLOOKUP(L15&"-"&M15,'Djøf Finance Hoppers'!D:D,'Djøf Finance Hoppers'!C:C,0,1) -> 1953 | P15: =IF(N15>0, O15/N15, 0) -> 0.15779268
A16: 39 | B16: =IF(A16<30, "25-29 år", IF(A16<35, "30-34 år", IF(A16<40, "35-39 år", IF(A16<45, "40-44 år", IF(A16<50, "45-49 år", IF(A16<55, "50-54 år", IF(A16<60, "55-59 år", IF(A16<65, "60-64 år", "65+ år")))))))) -> 35-39 år | C16: =_xlfn.XLOOKUP(B16,R:R,S:S) -> 0.26240269 | D16: =IF(OR(JobHopping[[#This Row],[Age]]=25,JobHopping[[#This Row],[Age]]>69),"N",IF(AND(D14="N",D15="N", RAND()<=C16), "Y", "N")) -> N | E16: Y | F16: =IF(JobHopping[[#This Row],[Age]]<40,"",JobHopping[[#This Row],[SwitchP1Static]]) | L16: 2014 | M16: 50-54 år | N16: =_xlfn.XLOOKUP(L16&"-"&M16,'Djøf Finance Workers'!D:D,'Djøf Finance Workers'!C:C,0,1) -> 10828 | O16: =_xlfn.XLOOKUP(L16&"-"&M16,'Djøf Finance Hoppers'!D:D,'Djøf Finance Hoppers'!C:C,0,1) -> 1636 | P16: =IF(N16>0, O16/N16, 0) -> 0.15108977
A17: 40 | B17: =IF(A17<30, "25-29 år", IF(A17<35, "30-34 år", IF(A17<40, "35-39 år", IF(A17<45, "40-44 år", IF(A17<50, "45-49 år", IF(A17<55, "50-54 år", IF(A17<60, "55-59 år", IF(A17<65, "60-64 år", "65+ år")))))))) -> 40-44 år | C17: =_xlfn.XLOOKUP(B17,R:R,S:S) -> 0.22131873 | D17: =IF(OR(JobHopping[[#This Row],[Age]]=25,JobHopping[[#This Row],[Age]]>69),"N",IF(AND(D15="N",D16="N", RAND()<=C17), "Y", "N")) -> N | E17: N | F17: =IF(JobHopping[[#This Row],[Age]]<40,"",JobHopping[[#This Row],[SwitchP1Static]]) -> N | L17: 2014 | M17: 55-59 år | N17: =_xlfn.XLOOKUP(L17&"-"&M17,'Djøf Finance Workers'!D:D,'Djøf Finance Workers'!C:C,0,1) -> 8888 | O17: =_xlfn.XLOOKUP(L17&"-"&M17,'Djøf Finance Hoppers'!D:D,'Djøf Finance Hoppers'!C:C,0,1) -> 1231 | P17: =IF(N17>0, O17/N17, 0) -> 0.13850135
A18: 41 | B18: =IF(A18<30, "25-29 år", IF(A18<35, "30-34 år", IF(A18<40, "35-39 år", IF(A18<45, "40-44 år", IF(A18<50, "45-49 år", IF(A18<55, "50-54 år", IF(A18<60, "55-59 år", IF(A18<65, "60-64 år", "65+ år")))))))) -> 40-44 år | C18: =_xlfn.XLOOKUP(B18,R:R,S:S) -> 0.22131873 | D18: =IF(OR(JobHopping[[#This Row],[Age]]=25,JobHopping[[#This Row],[Age]]>69),"N",IF(AND(D16="N",D17="N", RAND()<=C18), "Y", "N")) -> N | E18: N | F18: =IF(JobHopping[[#This Row],[Age]]<40,"",JobHopping[[#This Row],[SwitchP1Static]]) -> N | L18: 2014 | M18: 60-64 år | N18: =_xlfn.XLOOKUP(L18&"-"&M18,'Djøf Finance Workers'!D:D,'Djøf Finance Workers'!C:C,0,1) -> 5141 | O18: =_xlfn.XLOOKUP(L18&"-"&M18,'Djøf Finance Hoppers'!D:D,'Djøf Finance Hoppers'!C:C,0,1) -> 706 | P18: =IF(N18>0, O18/N18, 0) -> 0.13732737
A19: 42 | B19: =IF(A19<30, "25-29 år", IF(A19<35, "30-34 år", IF(A19<40, "35-39 år", IF(A19<45, "40-44 år", IF(A19<50, "45-49 år", IF(A19<55, "50-54 år", IF(A19<60, "55-59 år", IF(A19<65, "60-64 år", "65+ år")))))))) -> 40-44 år | C19: =_xlfn.XLOOKUP(B19,R:R,S:S) -> 0.22131873 | D19: =IF(OR(JobHopping[[#This Row],[Age]]=25,JobHopping[[#This Row],[Age]]>69),"N",IF(AND(D17="N",D18="N", RAND()<=C19), "Y", "N")) -> N | E19: N | F19: =IF(JobHopping[[#This Row],[Age]]<40,"",JobHopping[[#This Row],[SwitchP1Static]]) -> N | L19: 2014 | M19: 65+ år | N19: =_xlfn.XLOOKUP(L19&"-"&M19,'Djøf Finance Workers'!D:D,'Djøf Finance Workers'!C:C,0,1) -> 1600 | O19: =_xlfn.XLOOKUP(L19&"-"&M19,'Djøf Finance Hoppers'!D:D,'Djøf Finance Hoppers'!C:C,0,1) -> 204 | P19: =IF(N19>0, O19/N19, 0) -> 0.1275
A20: 43 | B20: =IF(A20<30, "25-29 år", IF(A20<35, "30-34 år", IF(A20<40, "35-39 år", IF(A20<45, "40-44 år", IF(A20<50, "45-49 år", IF(A20<55, "50-54 år", IF(A20<60, "55-59 år", IF(A20<65, "60-64 år", "65+ år")))))))) -> 40-44 år | C20: =_xlfn.XLOOKUP(B20,R:R,S:S) -> 0.22131873 | D20: =IF(OR(JobHopping[[#This Row],[Age]]=25,JobHopping[[#This Row],[Age]]>69),"N",IF(AND(D18="N",D19="N", RAND()<=C20), "Y", "N")) -> N | E20: Y | F20: =IF(JobHopping[[#This Row],[Age]]<40,"",JobHopping[[#This Row],[SwitchP1Static]]) -> Y | L20: 2015 | M20: 25-29 år | N20: =_xlfn.XLOOKUP(L20&"-"&M20,'Djøf Finance Workers'!D:D,'Djøf Finance Workers'!C:C,0,1) -> 5834 | O20: =_xlfn.XLOOKUP(L20&"-"&M20,'Djøf Finance Hoppers'!D:D,'Djøf Finance Hoppers'!C:C,0,1) -> 2715 | P20: =IF(N20>0, O20/N20, 0) -> 0.46537539
A21: 44 | B21: =IF(A21<30, "25-29 år", IF(A21<35, "30-34 år", IF(A21<40, "35-39 år", IF(A21<45, "40-44 år", IF(A21<50, "45-49 år", IF(A21<55, "50-54 år", IF(A21<60, "55-59 år", IF(A21<65, "60-64 år", "65+ år")))))))) -> 40-44 år | C21: =_xlfn.XLOOKUP(B21,R:R,S:S) -> 0.22131873 | D21: =IF(OR(JobHopping[[#This Row],[Age]]=25,JobHopping[[#This Row],[Age]]>69),"N",IF(AND(D19="N",D20="N", RAND()<=C21), "Y", "N")) -> N | E21: N | F21: =IF(JobHopping[[#This Row],[Age]]<40,"",JobHopping[[#This Row],[SwitchP1Static]]) -> N | L21: 2015 | M21: 30-34 år | N21: =_xlfn.XLOOKUP(L21&"-"&M21,'Djøf Finance Workers'!D:D,'Djøf Finance Workers'!C:C,0,1) -> 7834 | O21: =_xlfn.XLOOKUP(L21&"-"&M21,'Djøf Finance Hoppers'!D:D,'Djøf Finance Hoppers'!C:C,0,1) -> 2473 | P21: =IF(N21>0, O21/N21, 0) -> 0.31567526
A22: 45 | B22: =IF(A22<30, "25-29 år", IF(A22<35, "30-34 år", IF(A22<40, "35-39 år", IF(A22<45, "40-44 år", IF(A22<50, "45-49 år", IF(A22<55, "50-54 år", IF(A22<60, "55-59 år", IF(A22<65, "60-64 år", "65+ år")))))))) -> 45-49 år | C22: =_xlfn.XLOOKUP(B22,R:R,S:S) -> 0.1992948 | D22: =IF(OR(JobHopping[[#This Row],[Age]]=25,JobHopping[[#This Row],[Age]]>69),"N",IF(AND(D20="N",D21="N", RAND()<=C22), "Y", "N")) -> N | E22: N | F22: =IF(JobHopping[[#This Row],[Age]]<40,"",JobHopping[[#This Row],[SwitchP1Static]]) -> N | L22: 2015 | M22: 35-39 år | N22: =_xlfn.XLOOKUP(L22&"-"&M22,'Djøf Finance Workers'!D:D,'Djøf Finance Workers'!C:C,0,1) -> 9897 | O22: =_xlfn.XLOOKUP(L22&"-"&M22,'Djøf Finance Hoppers'!D:D,'Djøf Finance Hoppers'!C:C,0,1) -> 2378 | P22: =IF(N22>0, O22/N22, 0) -> 0.24027483
... A77: 100 | B77: =IF(A77<30, "25-29 år", IF(A77<35, "30-34 år", IF(A77<40, "35-39 år", IF(A77<45, "40-44 år", IF(A77<50, "45-49 år", IF(A77<55, "50-54 år", IF(A77<60, "55-59 år", IF(A77<65, "60-64 år", "65+ år")))))))) -> 65+ år | C77: =_xlfn.XLOOKUP(B77,R:R,S:S) -> 0.11691873 | D77: =IF(OR(JobHopping[[#This Row],[Age]]=25,JobHopping[[#This Row],[Age]]>69),"N",IF(AND(D75="N",D76="N", RAND()<=C77), "Y", "N")) -> N | E77: N | F77: =IF(JobHopping[[#This Row],[Age]]<40,"",JobHopping[[#This Row],[SwitchP1Static]]) -> N | L77: 2021 | M77: 40-44 år | N77: =_xlfn.XLOOKUP(L77&"-"&M77,'Djøf Finance Workers'!D:D,'Djøf Finance Workers'!C:C,0,1) -> 10002 | O77: =_xlfn.XLOOKUP(L77&"-"&M77,'Djøf Finance Hoppers'!D:D,'Djøf Finance Hoppers'!C:C,0,1) -> 2220 | P77: =IF(N77>0, O77/N77, 0) -> 0.22195561
L78: 2021 | M78: 45-49 år | N78: =_xlfn.XLOOKUP(L78&"-"&M78,'Djøf Finance Workers'!D:D,'Djøf Finance Workers'!C:C,0,1) -> 10036 | O78: =_xlfn.XLOOKUP(L78&"-"&M78,'Djøf Finance Hoppers'!D:D,'Djøf Finance Hoppers'!C:C,0,1) -> 1980 | P78: =IF(N78>0, O78/N78, 0) -> 0.19728976
L79: 2021 | M79: 50-54 år | N79: =_xlfn.XLOOKUP(L79&"-"&M79,'Djøf Finance Workers'!D:D,'Djøf Finance Workers'!C:C,0,1) -> 10467 | O79: =_xlfn.XLOOKUP(L79&"-"&M79,'Djøf Finance Hoppers'!D:D,'Djøf Finance Hoppers'!C:C,0,1) -> 1810 | P79: =IF(N79>0, O79/N79, 0) -> 0.17292443
L80: 2021 | M80: 55-59 år | N80: =_xlfn.XLOOKUP(L80&"-"&M80,'Djøf Finance Workers'!D:D,'Djøf Finance Workers'!C:C,0,1) -> 10749 | O80: =_xlfn.XLOOKUP(L80&"-"&M80,'Djøf Finance Hoppers'!D:D,'Djøf Finance Hoppers'!C:C,0,1) -> 1631 | P80: =IF(N80>0, O80/N80, 0) -> 0.15173505
L81: 2021 | M81: 60-64 år | N81: =_xlfn.XLOOKUP(L81&"-"&M81,'Djøf Finance Workers'!D:D,'Djøf Finance Workers'!C:C,0,1) -> 6688 | O81: =_xlfn.XLOOKUP(L81&"-"&M81,'Djøf Finance Hoppers'!D:D,'Djøf Finance Hoppers'!C:C,0,1) -> 962 | P81: =IF(N81>0, O81/N81, 0) -> 0.14383971
L82: 2021 | M82: 65+ år | N82: =_xlfn.XLOOKUP(L82&"-"&M82,'Djøf Finance Workers'!D:D,'Djøf Finance Workers'!C:C,0,1) -> 2522 | O82: =_xlfn.XLOOKUP(L82&"-"&M82,'Djøf Finance Hoppers'!D:D,'Djøf Finance Hoppers'!C:C,0,1) -> 216 | P82: =IF(N82>0, O82/N82, 0) -> 0.085646312
L83: 2022 | M83: 25-29 år | N83: =_xlfn.XLOOKUP(L83&"-"&M83,'Djøf Finance Workers'!D:D,'Djøf Finance Workers'!C:C,0,1) -> 8107 | O83: =_xlfn.XLOOKUP(L83&"-"&M83,'Djøf Finance Hoppers'!D:D,'Djøf Finance Hoppers'!C:C,0,1) -> 3870 | P83: =IF(N83>0, O83/N83, 0) -> 0.47736524
L84: 2022 | M84: 30-34 år | N84: =_xlfn.XLOOKUP(L84&"-"&M84,'Djøf Finance Workers'!D:D,'Djøf Finance Workers'!C:C,0,1) -> 9307 | O84: =_xlfn.XLOOKUP(L84&"-"&M84,'Djøf Finance Hoppers'!D:D,'Djøf Finance Hoppers'!C:C,0,1) -> 3004 | P84: =IF(N84>0, O84/N84, 0) -> 0.32276781
L85: 2022 | M85: 35-39 år | N85: =_xlfn.XLOOKUP(L85&"-"&M85,'Djøf Finance Workers'!D:D,'Djøf Finance Workers'!C:C,0,1) -> 9287 | O85: =_xlfn.XLOOKUP(L85&"-"&M85,'Djøf Finance Hoppers'!D:D,'Djøf Finance Hoppers'!C:C,0,1) -> 2511 | P85: =IF(N85>0, O85/N85, 0) -> 0.27037795
L86: 2022 | M86: 40-44 år | N86: =_xlfn.XLOOKUP(L86&"-"&M86,'Djøf Finance Workers'!D:D,'Djøf Finance Workers'!C:C,0,1) -> 9808 | O86: =_xlfn.XLOOKUP(L86&"-"&M86,'Djøf Finance Hoppers'!D:D,'Djøf Finance Hoppers'!C:C,0,1) -> 2191 | P86: =IF(N86>0, O86/N86, 0) -> 0.22338907
L87: 2022 | M87: 45-49 år | N87: =_xlfn.XLOOKUP(L87&"-"&M87,'Djøf Finance Workers'!D:D,'Djøf Finance Workers'!C:C,0,1) -> 10063 | O87: =_xlfn.XLOOKUP(L87&"-"&M87,'Djøf Finance Hoppers'!D:D,'Djøf Finance Hoppers'!C:C,0,1) -> 2044 | P87: =IF(N87>0, O87/N87, 0) -> 0.20312034
L88: 2022 | M88: 50-54 år | N88: =_xlfn.XLOOKUP(L88&"-"&M88,'Djøf Finance Workers'!D:D,'Djøf Finance Workers'!C:C,0,1) -> 9799 | O88: =_xlfn.XLOOKUP(L88&"-"&M88,'Djøf Finance Hoppers'!D:D,'Djøf Finance Hoppers'!C:C,0,1) -> 1683 | P88: =IF(N88>0, O88/N88, 0) -> 0.17175222
L89: 2022 | M89: 55-59 år | N89: =_xlfn.XLOOKUP(L89&"-"&M89,'Djøf Finance Workers'!D:D,'Djøf Finance Workers'!C:C,0,1) -> 11340 | O89: =_xlfn.XLOOKUP(L89&"-"&M89,'Djøf Finance Hoppers'!D:D,'Djøf Finance Hoppers'!C:C,0,1) -> 1578 | P89: =IF(N89>0, O89/N89, 0) -> 0.13915344
... L100: 2023 | M100: 65+ år | N100: =_xlfn.XLOOKUP(L100&"-"&M100,'Djøf Finance Workers'!D:D,'Djøf Finance Workers'!C:C,0,1) -> 3139 | O100: =_xlfn.XLOOKUP(L100&"-"&M100,'Djøf Finance Hoppers'!D:D,'Djøf Finance Hoppers'!C:C,0,1) -> 295 | P100: =IF(N100>0, O100/N100, 0) -> 0.093978974

Sheet Djøf Finance Workers
A1: Status på arbejdsmarkedet/ Beskæftigelse og jobskifte/ Antal lønmodtagere efter bopæl
C2: Hele landet
C3: Herkomst i alt
C4: Køn i alt
C5: Finansiering og forsikring
C6: Antal fuldtidsbeskæftigede lønmodtagere efter bopæl
A7: 2008 | B7: 25-29 år | C7: 6876 | D7: =A7&"-"&B7 -> 2008-25-29 år
A8: 2008 | B8: 30-34 år | C8: 8541 | D8: =A8&"-"&B8 -> 2008-30-34 år
A9: 2008 | B9: 35-39 år | C9: 8222 | D9: =A9&"-"&B9 -> 2008-35-39 år
A10: 2008 | B10: 40-44 år | C10: 11172 | D10: =A10&"-"&B10 -> 2008-40-44 år
A11: 2008 | B11: 45-49 år | C11: 9399 | D11: =A11&"-"&B11 -> 2008-45-49 år
A12: 2008 | B12: 50-54 år | C12: 8459 | D12: =A12&"-"&B12 -> 2008-50-54 år
A13: 2008 | B13: 55-59 år | C13: 7916 | D13: =A13&"-"&B13 -> 2008-55-59 år
A14: 2008 | B14: 60-64 år | C14: 4371 | D14: =A14&"-"&B14 -> 2008-60-64 år
A15: 2008 | B15: 65+ år | C15: 857 | D15: =A15&"-"&B15 -> 2008-65+ år
A16: 2009 | B16: 25-29 år | C16: 7284 | D16: =A16&"-"&B16 -> 2009-25-29 år
A17: 2009 | B17: 30-34 år | C17: 9750 | D17: =A17&"-"&B17 -> 2009-30-34 år
A18: 2009 | B18: 35-39 år | C18: 9328 | D18: =A18&"-"&B18 -> 2009-35-39 år
... A159: 2024 | B159: 65+ år | C159: 3573 | D159: =A159&"-"&B159 -> 2024-65+ år
A162: Kilde: CPR-registeret, CVR-registeret og DetailCOR
A163: Anm.: Pga. efterregistreringer kan tallene for især den seneste periode stige ved næste opdatering.

Sheet Djøf Finance Hoppers
A1: Status på arbejdsmarkedet/ Beskæftigelse og jobskifte/ Antal personer der har skiftet eller startet i nyt job (jobomsætning)
C2: Hele landet
C3: Privat sektor
C4: Herkomst i alt
C5: Køn i alt
C6: Finansiering og forsikring
C7: Jobomsætning
A8: 2009 | B8: 25-29 år | C8: 3410 | D8: =A8&"-"&B8 -> 2009-25-29 år
A9: 2009 | B9: 30-34 år | C9: 3525 | D9: =A9&"-"&B9 -> 2009-30-34 år
A10: 2009 | B10: 35-39 år | C10: 3090 | D10: =A10&"-"&B10 -> 2009-35-39 år
A11: 2009 | B11: 40-44 år | C11: 4180 | D11: =A11&"-"&B11 -> 2009-40-44 år
A12: 2009 | B12: 45-49 år | C12: 3533 | D12: =A12&"-"&B12 -> 2009-45-49 år
A13: 2009 | B13: 50-54 år | C13: 2940 | D13: =A13&"-"&B13 -> 2009-50-54 år
A14: 2009 | B14: 55-59 år | C14: 2419 | D14: =A14&"-"&B14 -> 2009-55-59 år
A15: 2009 | B15: 60-64 år | C15: 1263 | D15: =A15&"-"&B15 -> 2009-60-64 år
A16: 2009 | B16: 65-69 år | C16: 196 | D16: =A16&"-"&B16 -> 2009-65-69 år
A17: 2010 | B17: 25-29 år | C17: 2457 | D17: =A17&"-"&B17 -> 2010-25-29 år
A18: 2010 | B18: 30-34 år | C18: 2382 | D18: =A18&"-"&B18 -> 2010-30-34 år
A19: 2010 | B19: 35-39 år | C19: 1880 | D19: =A19&"-"&B19 -> 2010-35-39 år
... A142: 2023 | B142: 65-69 år | C142: 295 | D142: =A142&"-"&B142 -> 2023-65-69 år
A145: Kilde: CPR-registeret, CVR-registeret og DetailCOR
A146: Anm.: Pga. efterregistreringer kan tallene for især den seneste periode stige ved næste opdatering.

Sheet returns_short_low
A1: Year | B1: EUNK | C1: SXR8 | D1: IUSN | E1: JGHY | F1: LYXF | G1: SXR4 | H1: SYBA | I1: SYBB | J1: SYBC
A2: 2025
A3: 2026
A4: 2027
A5: 2028
A6: 2029
A7: 2030
A8: 2031
A9: 2032
A10: 2033
A11: 2034

Sheet returns_short_medium
A1: Year | B1: EUNK | C1: SXR8 | D1: IUSN | E1: JGHY | F1: LYXF | G1: SXR4 | H1: SYBA | I1: SYBB | J1: SYBC
A2: 2025
A3: 2026
A4: 2027
A5: 2028
A6: 2029
A7: 2030
A8: 2031
A9: 2032
A10: 2033
A11: 2034

Sheet returns_short_high
A1: Year | B1: EUNK | C1: SXR8 | D1: IUSN | E1: JGHY | F1: LYXF | G1: SXR4 | H1: SYBA | I1: SYBB | J1: SYBC
A2: 2025
A3: 2026
A4: 2027
A5: 2028
A6: 2029
A7: 2030
A8: 2031
A9: 2032
A10: 2033
A11: 2034

Sheet returns_long_low
A1: Year | B1: EUNK | C1: SXR8 | D1: IUSN | E1: JGHY | F1: LYXF | G1: SXR4 | H1: SYBA | I1: SYBB | J1: SYBC
A2: 2035 | B2: {=_xlfn.XLOOKUP(_xlfn.XLOOKUP(returns_long_low[[#This Row],[Year]],helper_ya[[#All],[Year]],helper_ya[[#All],[Category]]),br_er_low[[#All],[Ticker]],br_er_low[[#All],[EUNK]])} -> 0.026488237 | D2: {=_xlfn.XLOOKUP(_xlfn.XLOOKUP(returns_long_low[[#This Row],[Year]],helper_ya[[#All],[Year]],helper_ya[[#All],[Category]]),br_er_low[[#All],[Ticker]],br_er_low[[#All],[IUSN]])} -> -0.0024346665 | E2: {=_xlfn.XLOOKUP(_xlfn.XLOOKUP(returns_long_low[[#This Row],[Year]],helper_ya[[#All],[Year]],helper_ya[[#All],[Category]]),br_er_low[[#All],[Ticker]],br_er_low[[#All],[JGHY]])} -> 0.020640534 | F2: {=_xlfn.XLOOKUP(_xlfn.XLOOKUP(returns_long_low[[#This Row],[Year]],helper_ya[[#All],[Year]],helper_ya[[#All],[Category]]),br_er_low[[#All],[Ticker]],br_er_low[[#All],[LYXF]])} -> -0.025698614 | G2: {=_xlfn.XLOOKUP(_xlfn.XLOOKUP(returns_long_low[[#This Row],[Year]],helper_ya[[#All],[Year]],helper_ya[[#All],[Category]]),br_er_low[[#All],[Ticker]],br_er_low[[#All],[SXR4]])} -> -0.0069260345 | I2: {=_xlfn.XLOOKUP(_xlfn.XLOOKUP(returns_long_low[[#This Row],[Year]],helper_ya[[#All],[Year]],helper_ya[[#All],[Category]]),br_er_low[[#All],[Ticker]],br_er_low[[#All],[SYBB]])} -> 0.0069259975 | J2: {=_xlfn.XLOOKUP(_xlfn.XLOOKUP(returns_long_low[[#This Row],[Year]],helper_ya[[#All],[Year]],helper_ya[[#All],[Category]]),br_er_low[[#All],[Ticker]],br_er_low[[#All],[SYBC]])} -> 0.014807433
A3: 2036 | B3: {=_xlfn.XLOOKUP(_xlfn.XLOOKUP(returns_long_low[[#This Row],[Year]],helper_ya[[#All],[Year]],helper_ya[[#All],[Category]]),br_er_low[[#All],[Ticker]],br_er_low[[#All],[EUNK]])} -> 0.022961634 | D3: {=_xlfn.XLOOKUP(_xlfn.XLOOKUP(returns_long_low[[#This Row],[Year]],helper_ya[[#All],[Year]],helper_ya[[#All],[Category]]),br_er_low[[#All],[Ticker]],br_er_low[[#All],[IUSN]])} -> 0.0040323109 | E3: {=_xlfn.XLOOKUP(_xlfn.XLOOKUP(returns_long_low[[#This Row],[Year]],helper_ya[[#All],[Year]],helper_ya[[#All],[Category]]),br_er_low[[#All],[Ticker]],br_er_low[[#All],[JGHY]])} -> 0.021703703 | F3: {=_xlfn.XLOOKUP(_xlfn.XLOOKUP(returns_long_low[[#This Row],[Year]],helper_ya[[#All],[Year]],helper_ya[[#All],[Category]]),br_er_low[[#All],[Ticker]],br_er_low[[#All],[LYXF]])} -> -0.022496168 | G3: {=_xlfn.XLOOKUP(_xlfn.XLOOKUP(returns_long_low[[#This Row],[Year]],helper_ya[[#All],[Year]],helper_ya[[#All],[Category]]),br_er_low[[#All],[Ticker]],br_er_low[[#All],[SXR4]])} -> 0.0054101717 | I3: {=_xlfn.XLOOKUP(_xlfn.XLOOKUP(returns_long_low[[#This Row],[Year]],helper_ya[[#All],[Year]],helper_ya[[#All],[Category]]),br_er_low[[#All],[Ticker]],br_er_low[[#All],[SYBB]])} -> 0.0061406789 | J3: {=_xlfn.XLOOKUP(_xlfn.XLOOKUP(returns_long_low[[#This Row],[Year]],helper_ya[[#All],[Year]],helper_ya[[#All],[Category]]),br_er_low[[#All],[Ticker]],br_er_low[[#All],[SYBC]])} -> 0.015142479
A4: 2037 | B4: {=_xlfn.XLOOKUP(_xlfn.XLOOKUP(returns_long_low[[#This Row],[Year]],helper_ya[[#All],[Year]],helper_ya[[#All],[Category]]),br_er_low[[#All],[Ticker]],br_er_low[[#All],[EUNK]])} -> 0.022961634 | D4: {=_xlfn.XLOOKUP(_xlfn.XLOOKUP(returns_long_low[[#This Row],[Year]],helper_ya[[#All],[Year]],helper_ya[[#All],[Category]]),br_er_low[[#All],[Ticker]],br_er_low[[#All],[IUSN]])} -> 0.0040323109 | E4: {=_xlfn.XLOOKUP(_xlfn.XLOOKUP(returns_long_low[[#This Row],[Year]],helper_ya[[#All],[Year]],helper_ya[[#All],[Category]]),br_er_low[[#All],[Ticker]],br_er_low[[#All],[JGHY]])} -> 0.021703703 | F4: {=_xlfn.XLOOKUP(_xlfn.XLOOKUP(returns_long_low[[#This Row],[Year]],helper_ya[[#All],[Year]],helper_ya[[#All],[Category]]),br_er_low[[#All],[Ticker]],br_er_low[[#All],[LYXF]])} -> -0.022496168 | G4: {=_xlfn.XLOOKUP(_xlfn.XLOOKUP(returns_long_low[[#This Row],[Year]],helper_ya[[#All],[Year]],helper_ya[[#All],[Category]]),br_er_low[[#All],[Ticker]],br_er_low[[#All],[SXR4]])} -> 0.0054101717 | I4: {=_xlfn.XLOOKUP(_xlfn.XLOOKUP(returns_long_low[[#This Row],[Year]],helper_ya[[#All],[Year]],helper_ya[[#All],[Category]]),br_er_low[[#All],[Ticker]],br_er_low[[#All],[SYBB]])} -> 0.0061406789 | J4: {=_xlfn.XLOOKUP(_xlfn.XLOOKUP(returns_long_low[[#This Row],[Year]],helper_ya[[#All],[Year]],helper_ya[[#All],[Category]]),br_er_low[[#All],[Ticker]],br_er_low[[#All],[SYBC]])} -> 0.015142479
A5: 2038 | B5: {=_xlfn.XLOOKUP(_xlfn.XLOOKUP(returns_long_low[[#This Row],[Year]],helper_ya[[#All],[Year]],helper_ya[[#All],[Category]]),br_er_low[[#All],[Ticker]],br_er_low[[#All],[EUNK]])} -> 0.022961634 | D5: {=_xlfn.XLOOKUP(_xlfn.XLOOKUP(returns_long_low[[#This Row],[Year]],helper_ya[[#All],[Year]],helper_ya[[#All],[Category]]),br_er_low[[#All],[Ticker]],br_er_low[[#All],[IUSN]])} -> 0.0040323109 | E5: {=_xlfn.XLOOKUP(_xlfn.XLOOKUP(returns_long_low[[#This Row],[Year]],helper_ya[[#All],[Year]],helper_ya[[#All],[Category]]),br_er_low[[#All],[Ticker]],br_er_low[[#All],[JGHY]])} -> 0.021703703 | F5: {=_xlfn.XLOOKUP(_xlfn.XLOOKUP(returns_long_low[[#This Row],[Year]],helper_ya[[#All],[Year]],helper_ya[[#All],[Category]]),br_er_low[[#All],[Ticker]],br_er_low[[#All],[LYXF]])} -> -0.022496168 | G5: {=_xlfn.XLOOKUP(_xlfn.XLOOKUP(returns_long_low[[#This Row],[Year]],helper_ya[[#All],[Year]],helper_ya[[#All],[Category]]),br_er_low[[#All],[Ticker]],br_er_low[[#All],[SXR4]])} -> 0.0054101717 | I5: {=_xlfn.XLOOKUP(_xlfn.XLOOKUP(returns_long_low[[#This Row],[Year]],helper_ya[[#All],[Year]],helper_ya[[#All],[Category]]),br_er_low[[#All],[Ticker]],br_er_low[[#All],[SYBB]])} -> 0.0061406789 | J5: {=_xlfn.XLOOKUP(_xlfn.XLOOKUP(returns_long_low[[#This Row],[Year]],helper_ya[[#All],[Year]],helper_ya[[#All],[Category]]),br_er_low[[#All],[Ticker]],br_er_low[[#All],[SYBC]])} -> 0.015142479
A6: 2039 | B6: {=_xlfn.XLOOKUP(_xlfn.XLOOKUP(returns_long_low[[#This Row],[Year]],helper_ya[[#All],[Year]],helper_ya[[#All],[Category]]),br_er_low[[#All],[Ticker]],br_er_low[[#All],[EUNK]])} -> 0.022961634 | D6: {=_xlfn.XLOOKUP(_xlfn.XLOOKUP(returns_long_low[[#This Row],[Year]],helper_ya[[#All],[Year]],helper_ya[[#All],[Category]]),br_er_low[[#All],[Ticker]],br_er_low[[#All],[IUSN]])} -> 0.0040323109 | E6: {=_xlfn.XLOOKUP(_xlfn.XLOOKUP(returns_long_low[[#This Row],[Year]],helper_ya[[#All],[Year]],helper_ya[[#All],[Category]]),br_er_low[[#All],[Ticker]],br_er_low[[#All],[JGHY]])} -> 0.021703703 | F6: {=_xlfn.XLOOKUP(_xlfn.XLOOKUP(returns_long_low[[#This Row],[Year]],helper_ya[[#All],[Year]],helper_ya[[#All],[Category]]),br_er_low[[#All],[Ticker]],br_er_low[[#All],[LYXF]])} -> -0.022496168 | G6: {=_xlfn.XLOOKUP(_xlfn.XLOOKUP(returns_long_low[[#This Row],[Year]],helper_ya[[#All],[Year]],helper_ya[[#All],[Category]]),br_er_low[[#All],[Ticker]],br_er_low[[#All],[SXR4]])} -> 0.0054101717 | I6: {=_xlfn.XLOOKUP(_xlfn.XLOOKUP(returns_long_low[[#This Row],[Year]],helper_ya[[#All],[Year]],helper_ya[[#All],[Category]]),br_er_low[[#All],[Ticker]],br_er_low[[#All],[SYBB]])} -> 0.0061406789 | J6: {=_xlfn.XLOOKUP(_xlfn.XLOOKUP(returns_long_low[[#This Row],[Year]],helper_ya[[#All],[Year]],helper_ya[[#All],[Category]]),br_er_low[[#All],[Ticker]],br_er_low[[#All],[SYBC]])} -> 0.015142479
A7: 2040 | B7: {=_xlfn.XLOOKUP(_xlfn.XLOOKUP(returns_long_low[[#This Row],[Year]],helper_ya[[#All],[Year]],helper_ya[[#All],[Category]]),br_er_low[[#All],[Ticker]],br_er_low[[#All],[EUNK]])} -> 0.022961634 | D7: {=_xlfn.XLOOKUP(_xlfn.XLOOKUP(returns_long_low[[#This Row],[Year]],helper_ya[[#All],[Year]],helper_ya[[#All],[Category]]),br_er_low[[#All],[Ticker]],br_er_low[[#All],[IUSN]])} -> 0.0040323109 | E7: {=_xlfn.XLOOKUP(_xlfn.XLOOKUP(returns_long_low[[#This Row],[Year]],helper_ya[[#All],[Year]],helper_ya[[#All],[Category]]),br_er_low[[#All],[Ticker]],br_er_low[[#All],[JGHY]])} -> 0.021703703 | F7: {=_xlfn.XLOOKUP(_xlfn.XLOOKUP(returns_long_low[[#This Row],[Year]],helper_ya[[#All],[Year]],helper_ya[[#All],[Category]]),br_er_low[[#All],[Ticker]],br_er_low[[#All],[LYXF]])} -> -0.022496168 | G7: {=_xlfn.XLOOKUP(_xlfn.XLOOKUP(returns_long_low[[#This Row],[Year]],helper_ya[[#All],[Year]],helper_ya[[#All],[Category]]),br_er_low[[#All],[Ticker]],br_er_low[[#All],[SXR4]])} -> 0.0054101717 | I7: {=_xlfn.XLOOKUP(_xlfn.XLOOKUP(returns_long_low[[#This Row],[Year]],helper_ya[[#All],[Year]],helper_ya[[#All],[Category]]),br_er_low[[#All],[Ticker]],br_er_low[[#All],[SYBB]])} -> 0.0061406789 | J7: {=_xlfn.XLOOKUP(_xlfn.XLOOKUP(returns_long_low[[#This Row],[Year]],helper_ya[[#All],[Year]],helper_ya[[#All],[Category]]),br_er_low[[#All],[Ticker]],br_er_low[[#All],[SYBC]])} -> 0.015142479
A8: 2041 | B8: {=_xlfn.XLOOKUP(_xlfn.XLOOKUP(returns_long_low[[#This Row],[Year]],helper_ya[[#All],[Year]],helper_ya[[#All],[Category]]),br_er_low[[#All],[Ticker]],br_er_low[[#All],[EUNK]])} -> 0.023101219 | D8: {=_xlfn.XLOOKUP(_xlfn.XLOOKUP(returns_long_low[[#This Row],[Year]],helper_ya[[#All],[Year]],helper_ya[[#All],[Category]]),br_er_low[[#All],[Ticker]],br_er_low[[#All],[IUSN]])} -> 0.0095483542 | E8: {=_xlfn.XLOOKUP(_xlfn.XLOOKUP(returns_long_low[[#This Row],[Year]],helper_ya[[#All],[Year]],helper_ya[[#All],[Category]]),br_er_low[[#All],[Ticker]],br_er_low[[#All],[JGHY]])} -> 0.022572753 | F8: {=_xlfn.XLOOKUP(_xlfn.XLOOKUP(returns_long_low[[#This Row],[Year]],helper_ya[[#All],[Year]],helper_ya[[#All],[Category]]),br_er_low[[#All],[Ticker]],br_er_low[[#All],[LYXF]])} -> -0.019285364 | G8: {=_xlfn.XLOOKUP(_xlfn.XLOOKUP(returns_long_low[[#This Row],[Year]],helper_ya[[#All],[Year]],helper_ya[[#All],[Category]]),br_er_low[[#All],[Ticker]],br_er_low[[#All],[SXR4]])} -> 0.014128045 | I8: {=_xlfn.XLOOKUP(_xlfn.XLOOKUP(returns_long_low[[#This Row],[Year]],helper_ya[[#All],[Year]],helper_ya[[#All],[Category]]),br_er_low[[#All],[Ticker]],br_er_low[[#All],[SYBB]])} -> 0.0065426 | J8: {=_xlfn.XLOOKUP(_xlfn.XLOOKUP(returns_long_low[[#This Row],[Year]],helper_ya[[#All],[Year]],helper_ya[[#All],[Category]]),br_er_low[[#All],[Ticker]],br_er_low[[#All],[SYBC]])} -> 0.015600687
A9: 2042 | B9: {=_xlfn.XLOOKUP(_xlfn.XLOOKUP(returns_long_low[[#This Row],[Year]],helper_ya[[#All],[Year]],helper_ya[[#All],[Category]]),br_er_low[[#All],[Ticker]],br_er_low[[#All],[EUNK]])} -> 0.023101219 | D9: {=_xlfn.XLOOKUP(_xlfn.XLOOKUP(returns_long_low[[#This Row],[Year]],helper_ya[[#All],[Year]],helper_ya[[#All],[Category]]),br_er_low[[#All],[Ticker]],br_er_low[[#All],[IUSN]])} -> 0.0095483542 | E9: {=_xlfn.XLOOKUP(_xlfn.XLOOKUP(returns_long_low[[#This Row],[Year]],helper_ya[[#All],[Year]],helper_ya[[#All],[Category]]),br_er_low[[#All],[Ticker]],br_er_low[[#All],[JGHY]])} -> 0.022572753 | F9: {=_xlfn.XLOOKUP(_xlfn.XLOOKUP(returns_long_low[[#This Row],[Year]],helper_ya[[#All],[Year]],helper_ya[[#All],[Category]]),br_er_low[[#All],[Ticker]],br_er_low[[#All],[LYXF]])} -> -0.019285364 | G9: {=_xlfn.XLOOKUP(_xlfn.XLOOKUP(returns_long_low[[#This Row],[Year]],helper_ya[[#All],[Year]],helper_ya[[#All],[Category]]),br_er_low[[#All],[Ticker]],br_er_low[[#All],[SXR4]])} -> 0.014128045 | I9: {=_xlfn.XLOOKUP(_xlfn.XLOOKUP(returns_long_low[[#This Row],[Year]],helper_ya[[#All],[Year]],helper_ya[[#All],[Category]]),br_er_low[[#All],[Ticker]],br_er_low[[#All],[SYBB]])} -> 0.0065426 | J9: {=_xlfn.XLOOKUP(_xlfn.XLOOKUP(returns_long_low[[#This Row],[Year]],helper_ya[[#All],[Year]],helper_ya[[#All],[Category]]),br_er_low[[#All],[Ticker]],br_er_low[[#All],[SYBC]])} -> 0.015600687
A10: 2043 | B10: {=_xlfn.XLOOKUP(_xlfn.XLOOKUP(returns_long_low[[#This Row],[Year]],helper_ya[[#All],[Year]],helper_ya[[#All],[Category]]),br_er_low[[#All],[Ticker]],br_er_low[[#All],[EUNK]])} -> 0.023101219 | D10: {=_xlfn.XLOOKUP(_xlfn.XLOOKUP(returns_long_low[[#This Row],[Year]],helper_ya[[#All],[Year]],helper_ya[[#All],[Category]]),br_er_low[[#All],[Ticker]],br_er_low[[#All],[IUSN]])} -> 0.0095483542 | E10: {=_xlfn.XLOOKUP(_xlfn.XLOOKUP(returns_long_low[[#This Row],[Year]],helper_ya[[#All],[Year]],helper_ya[[#All],[Category]]),br_er_low[[#All],[Ticker]],br_er_low[[#All],[JGHY]])} -> 0.022572753 | F10: {=_xlfn.XLOOKUP(_xlfn.XLOOKUP(returns_long_low[[#This Row],[Year]],helper_ya[[#All],[Year]],helper_ya[[#All],[Category]]),br_er_low[[#All],[Ticker]],br_er_low[[#All],[LYXF]])} -> -0.019285364 | G10: {=_xlfn.XLOOKUP(_xlfn.XLOOKUP(returns_long_low[[#This Row],[Year]],helper_ya[[#All],[Year]],helper_ya[[#All],[Category]]),br_er_low[[#All],[Ticker]],br_er_low[[#All],[SXR4]])} -> 0.014128045 | I10: {=_xlfn.XLOOKUP(_xlfn.XLOOKUP(returns_long_low[[#This Row],[Year]],helper_ya[[#All],[Year]],helper_ya[[#All],[Category]]),br_er_low[[#All],[Ticker]],br_er_low[[#All],[SYBB]])} -> 0.0065426 | J10: {=_xlfn.XLOOKUP(_xlfn.XLOOKUP(returns_long_low[[#This Row],[Year]],helper_ya[[#All],[Year]],helper_ya[[#All],[Category]]),br_er_low[[#All],[Ticker]],br_er_low[[#All],[SYBC]])} -> 0.015600687
A11: 2044 | B11: {=_xlfn.XLOOKUP(_xlfn.XLOOKUP(returns_long_low[[#This Row],[Year]],helper_ya[[#All],[Year]],helper_ya[[#All],[Category]]),br_er_low[[#All],[Ticker]],br_er_low[[#All],[EUNK]])} -> 0.023101219 | D11: {=_xlfn.XLOOKUP(_xlfn.XLOOKUP(returns_long_low[[#This Row],[Year]],helper_ya[[#All],[Year]],helper_ya[[#All],[Category]]),br_er_low[[#All],[Ticker]],br_er_low[[#All],[IUSN]])} -> 0.0095483542 | E11: {=_xlfn.XLOOKUP(_xlfn.XLOOKUP(returns_long_low[[#This Row],[Year]],helper_ya[[#All],[Year]],helper_ya[[#All],[Category]]),br_er_low[[#All],[Ticker]],br_er_low[[#All],[JGHY]])} -> 0.022572753 | F11: {=_xlfn.XLOOKUP(_xlfn.XLOOKUP(returns_long_low[[#This Row],[Year]],helper_ya[[#All],[Year]],helper_ya[[#All],[Category]]),br_er_low[[#All],[Ticker]],br_er_low[[#All],[LYXF]])} -> -0.019285364 | G11: {=_xlfn.XLOOKUP(_xlfn.XLOOKUP(returns_long_low[[#This Row],[Year]],helper_ya[[#All],[Year]],helper_ya[[#All],[Category]]),br_er_low[[#All],[Ticker]],br_er_low[[#All],[SXR4]])} -> 0.014128045 | I11: {=_xlfn.XLOOKUP(_xlfn.XLOOKUP(returns_long_low[[#This Row],[Year]],helper_ya[[#All],[Year]],helper_ya[[#All],[Category]]),br_er_low[[#All],[Ticker]],br_er_low[[#All],[SYBB]])} -> 0.0065426 | J11: {=_xlfn.XLOOKUP(_xlfn.XLOOKUP(returns_long_low[[#This Row],[Year]],helper_ya[[#All],[Year]],helper_ya[[#All],[Category]]),br_er_low[[#All],[Ticker]],br_er_low[[#All],[SYBC]])} -> 0.015600687
A12: 2045 | B12: {=_xlfn.XLOOKUP(_xlfn.XLOOKUP(returns_long_low[[#This Row],[Year]],helper_ya[[#All],[Year]],helper_ya[[#All],[Category]]),br_er_low[[#All],[Ticker]],br_er_low[[#All],[EUNK]])} -> 0.023101219 | D12: {=_xlfn.XLOOKUP(_xlfn.XLOOKUP(returns_long_low[[#This Row],[Year]],helper_ya[[#All],[Year]],helper_ya[[#All],[Category]]),br_er_low[[#All],[Ticker]],br_er_low[[#All],[IUSN]])} -> 0.0095483542 | E12: {=_xlfn.XLOOKUP(_xlfn.XLOOKUP(returns_long_low[[#This Row],[Year]],helper_ya[[#All],[Year]],helper_ya[[#All],[Category]]),br_er_low[[#All],[Ticker]],br_er_low[[#All],[JGHY]])} -> 0.022572753 | F12: {=_xlfn.XLOOKUP(_xlfn.XLOOKUP(returns_long_low[[#This Row],[Year]],helper_ya[[#All],[Year]],helper_ya[[#All],[Category]]),br_er_low[[#All],[Ticker]],br_er_low[[#All],[LYXF]])} -> -0.019285364 | G12: {=_xlfn.XLOOKUP(_xlfn.XLOOKUP(returns_long_low[[#This Row],[Year]],helper_ya[[#All],[Year]],helper_ya[[#All],[Category]]),br_er_low[[#All],[Ticker]],br_er_low[[#All],[SXR4]])} -> 0.014128045 | I12: {=_xlfn.XLOOKUP(_xlfn.XLOOKUP(returns_long_low[[#This Row],[Year]],helper_ya[[#All],[Year]],helper_ya[[#All],[Category]]),br_er_low[[#All],[Ticker]],br_er_low[[#All],[SYBB]])} -> 0.0065426 | J12: {=_xlfn.XLOOKUP(_xlfn.XLOOKUP(returns_long_low[[#This Row],[Year]],helper_ya[[#All],[Year]],helper_ya[[#All],[Category]]),br_er_low[[#All],[Ticker]],br_er_low[[#All],[SYBC]])} -> 0.015600687
A13: 2046 | B13: {=_xlfn.XLOOKUP(_xlfn.XLOOKUP(returns_long_low[[#This Row],[Year]],helper_ya[[#All],[Year]],helper_ya[[#All],[Category]]),br_er_low[[#All],[Ticker]],br_er_low[[#All],[EUNK]])} -> 0.023751374 | D13: {=_xlfn.XLOOKUP(_xlfn.XLOOKUP(returns_long_low[[#This Row],[Year]],helper_ya[[#All],[Year]],helper_ya[[#All],[Category]]),br_er_low[[#All],[Ticker]],br_er_low[[#All],[IUSN]])} -> 0.012540441 | E13: {=_xlfn.XLOOKUP(_xlfn.XLOOKUP(returns_long_low[[#This Row],[Year]],helper_ya[[#All],[Year]],helper_ya[[#All],[Category]]),br_er_low[[#All],[Ticker]],br_er_low[[#All],[JGHY]])} -> 0.023602686 | F13: {=_xlfn.XLOOKUP(_xlfn.XLOOKUP(returns_long_low[[#This Row],[Year]],helper_ya[[#All],[Year]],helper_ya[[#All],[Category]]),br_er_low[[#All],[Ticker]],br_er_low[[#All],[LYXF]])} -> -0.015493189 | G13: {=_xlfn.XLOOKUP(_xlfn.XLOOKUP(returns_long_low[[#This Row],[Year]],helper_ya[[#All],[Year]],helper_ya[[#All],[Category]]),br_er_low[[#All],[Ticker]],br_er_low[[#All],[SXR4]])} -> 0.019950754 | I13: {=_xlfn.XLOOKUP(_xlfn.XLOOKUP(returns_long_low[[#This Row],[Year]],helper_ya[[#All],[Year]],helper_ya[[#All],[Category]]),br_er_low[[#All],[Ticker]],br_er_low[[#All],[SYBB]])} -> 0.00707352 | J13: {=_xlfn.XLOOKUP(_xlfn.XLOOKUP(returns_long_low[[#This Row],[Year]],helper_ya[[#All],[Year]],helper_ya[[#All],[Category]]),br_er_low[[#All],[Ticker]],br_er_low[[#All],[SYBC]])} -> 0.016604991
... A42: 2075 | B42: {=_xlfn.XLOOKUP(_xlfn.XLOOKUP(returns_long_low[[#This Row],[Year]],helper_ya[[#All],[Year]],helper_ya[[#All],[Category]]),br_er_low[[#All],[Ticker]],br_er_low[[#All],[EUNK]])} -> 0.025179134 | D42: {=_xlfn.XLOOKUP(_xlfn.XLOOKUP(returns_long_low[[#This Row],[Year]],helper_ya[[#All],[Year]],helper_ya[[#All],[Category]]),br_er_low[[#All],[Ticker]],br_er_low[[#All],[IUSN]])} -> 0.016553239 | E42: {=_xlfn.XLOOKUP(_xlfn.XLOOKUP(returns_long_low[[#This Row],[Year]],helper_ya[[#All],[Year]],helper_ya[[#All],[Category]]),br_er_low[[#All],[Ticker]],br_er_low[[#All],[JGHY]])} -> 0.024049386 | F42: {=_xlfn.XLOOKUP(_xlfn.XLOOKUP(returns_long_low[[#This Row],[Year]],helper_ya[[#All],[Year]],helper_ya[[#All],[Category]]),br_er_low[[#All],[Ticker]],br_er_low[[#All],[LYXF]])} -> -0.012386854 | G42: {=_xlfn.XLOOKUP(_xlfn.XLOOKUP(returns_long_low[[#This Row],[Year]],helper_ya[[#All],[Year]],helper_ya[[#All],[Category]]),br_er_low[[#All],[Ticker]],br_er_low[[#All],[SXR4]])} -> 0.02422391 | I42: {=_xlfn.XLOOKUP(_xlfn.XLOOKUP(returns_long_low[[#This Row],[Year]],helper_ya[[#All],[Year]],helper_ya[[#All],[Category]]),br_er_low[[#All],[Ticker]],br_er_low[[#All],[SYBB]])} -> 0.0076495147 | J42: {=_xlfn.XLOOKUP(_xlfn.XLOOKUP(returns_long_low[[#This Row],[Year]],helper_ya[[#All],[Year]],helper_ya[[#All],[Category]]),br_er_low[[#All],[Ticker]],br_er_low[[#All],[SYBC]])} -> 0.017508738

Sheet returns_long_medium
A1: Year | B1: EUNK | C1: SXR8 | D1: IUSN | E1: JGHY | F1: LYXF | G1: SXR4 | H1: SYBA | I1: SYBB | J1: SYBC
