Workbook
Name _DLX1: [1]Rates!#REF!
Name _DLX1.INC: '[2]Car Air'!#REF!
Name _DLX10.INC: '[3]US&Europe'!#REF!
Name _DLX10_INC: #REF!
Name _DLX100.INC: '[3]Bonds Data BIS'!#REF!
Name _DLX14.INC: #REF!
Name _DLX15.INC: '[3]Bonds Data BIS'!#REF!
Name _DLX16.INC: '[3]Bonds Data BIS'!#REF!
Name _DLX2.INC: #REF!
Name _DLX20.INC: #REF!
Name _DLX3.INC: #REF!
Name _DLX4.INC: #REF!
Name _DLX5.INC: #REF!
Name _DLX5_INC: #REF!
Name _DLX50.INC: '[3]US&Europe'!#REF!
Name _DLX52.INC: #REF!
Name _DLX53.INC: '[3]US&Europe'!#REF!
Name _DLX54.INC: '[3]US&Europe'!#REF!
Name _DLX56.INC: '[3]US&Europe'!#REF!
Name _DLX6.INC: #REF!
Name _DLX60.INC: #REF!
Name _DLX7.INC: '[3]US&Europe'!#REF!
Name _DLX8.INC: '[3]US&Europe'!#REF!
Name _DLX80.INC: '[3]Bonds Data BIS'!#REF!
Name _DLX9.INC: '[3]US&Europe'!#REF!
Name AUD_Nom: #REF!
Name AUD_Tenor: #REF!
Name AUD_yr: #REF!
Name CAD_Nom: #REF!
Name CAD_Tenor: #REF!
Name CAD_yr: #REF!
Name CHF_Nom: #REF!
Name CHF_Tenor: #REF!
Name CHF_yr: #REF!
Name cn_asia: [4]Weights!$J$5
Name code: [5]CONSTANT!#REF!
Name Currency_cusip: '[6]Currency bucketing mapping'!$B$35:$B$160
Name Currency_name: '[6]Currency bucketing mapping'!$B$35:$BF$35
Name Currency_table: '[6]Currency bucketing mapping'!$B$35:$BF$160
Name D_0: #REF!
Name D_0_DE: #REF!
Name D_0_FR: #REF!
Name D_0_IT: #REF!
Name D_0_JP: #REF!
Name D_0_UK: #REF!
Name DaysInYear: [7]C!$B$29
Name DE_gwth: #REF!
Name DE_S: #REF!
Name ERP: [8]CF20!$C$18
Name EUR_Nom: #REF!
Name EUR_Tenor: #REF!
Name EUR_yr: #REF!
Name FR_gwth: #REF!
Name FR_S: #REF!
Name GBP_Nom: #REF!
Name GBP_Tenor: #REF!
Name GBP_yr: #REF!
Name gGDP: [8]CF20!$C$14
Name hk_asia: [4]Weights!$J$6
Name hk_nie: [4]Weights!$K$6

Sheet Front Page
B1: Description
B5: TOC Colour Coding
B6: Inputs
B7: Calculation
B8: Raw Report | C8: <-- If we download a report from a source, ex: Djøf, we will store it here and will not directly edit it
B9: Raw Report with Key | C9: <-- Raw Report but a column has been added for lookups
B11: Table Colors
B12: Uploaded to Python
B13: Not Uploaded to Python
B16: Table of Contents
B17: Salary Model
B18: Model Parameters
B19: Modelling the salary path for both investors
B20: Calculating the pension contributions for P1
B21: Calculating the pension contributions for P2
B22: Net Salary Calculation for P1
B23: Net Salary Calculation for P2
B24: Job hopping modelled
... B28: Loop used when executing the python script

Sheet Salary Variables
B2: Inflation | C2: 0.02
B3: Salary Growth
B4: Salary Raise | C4: 0.03
B5: Real Salary Raise | C5: =C4-C2 -> 0.01
B6: Job Hopping "Bonus" | C6: 0.06
B7: Real Job Hopping "Bonus" | C7: =C6-C2 -> 0.04
B8: % of salary dedicated to investments | C8: 0.1
B9: Initial Salary P1 | C9: 43871
B10: Initial Salary P2 | C10: 64001
B11: Contribution to pension
B12: Personal | C12: 0.05
B13: Company | C13: 0.1
B14: Aldersopsparing maximum contribution | C14: 9400
B15: Tax
B16: AM (%) | C16: 0.08
B17: Personal Allowance | C17: 51600
B18: Bottom-Bracket State Tax rate (%) | C18: 0.1201
B19: Top-bracket State Tax rate (%) | C19: 0.15
B20: State Tax Bracket Threshold | C20: 618400
B21: Municipal Tax (%) | C21: 0.25
B22: Capital Gains < 67,500DKK | C22: 0.27
B23: Capital Gains > 67,500DKK | C23: 0.42
B24: Capital Gains Threshold | C24: 67500

Sheet Income
A1: Income!A1
B2: Year | C2: SalaryP1 | D2: SalaryP2 | E2: InvestmentP1 | F2: InvestmentP2 | H2: Inflation | I2: ='Salary Variables'!$C$2 -> 0.02 | L2: NetMonthlySalaryP1 | M2: NetMonthlySalaryP2 | N2: GrossMonthlyInflationAdjustedP1 | O2: GrossMonthlyInflationAdjustedP2 | P2: GrossMonthlySalaryP1 | Q2: GrossMonthlySalaryP2 | R2: SwitchP1 | S2: SwitchP2
B3: 2025 | C3: =(TableIncomeCalculations[[#This Row],[NetMonthlySalaryP1]]*12) -> 286626.15 | D3: =(TableIncomeCalculations[[#This Row],[NetMonthlySalaryP2]]*12) -> 419426.43 | E3: =TableIncome[[#This Row],[SalaryP1]]*$I$7 -> 28662.615 | F3: =TableIncome[[#This Row],[SalaryP2]]*$I$7 -> 41942.643 | H3: Salary Raise | I3: {='Salary Variables'!$C$4:$C$8} -> 0.03 | L3: ='Net Salary P1'!BI2 -> 23885.512 | M3: ='Net Salary P2'!AT2 -> 34952.202 | N3: 43871 | O3: 64001 | P3: 43871 | Q3: 64001 | R3: =_xlfn.XLOOKUP(_xlfn.XLOOKUP(TableIncome[[#This Row],[Year]],Loop!C:C,Loop!D:D),'Job Hopping'!B:B,'Job Hopping'!F:F) -> N | S3: =_xlfn.XLOOKUP(_xlfn.XLOOKUP(TableIncome[[#This Row],[Year]],Loop!C:C,Loop!E:E),'Job Hopping'!B:B,'Job Hopping'!G:G) -> N
B4: 2026 | C4: =(TableIncomeCalculations[[#This Row],[NetMonthlySalaryP1]]*12) -> 289708.75 | D4: =(TableIncomeCalculations[[#This Row],[NetMonthlySalaryP2]]*12) -> 422832.04 | E4: =TableIncome[[#This Row],[SalaryP1]]*$I$7 -> 28970.875 | F4: =TableIncome[[#This Row],[SalaryP2]]*$I$7 -> 42283.204 | H4: Real Salary Raise | I4: 0.01 | L4: ='Net Salary P1'!BI3 -> 24142.396 | M4: ='Net Salary P2'!AT3 -> 35236.003 | N4: =IF(_xlfn.XLOOKUP(TableIncome[[#This Row],[Year]],Loop!C:C,Loop!D:D)<70,(N3*(1+$I$4))+IF(TableIncomeCalculations[[#This Row],[SwitchP1]]="Y",N3*$I$6,0),0) -> 44309.71 | O4: =IF(_xlfn.XLOOKUP(TableIncome[[#This Row],[Year]],Loop!C:C,Loop!E:E)<70,(O3*(1+$I$4))+IF(TableIncomeCalculations[[#This Row],[SwitchP2]]="Y",Q3*$I$6,0),0) -> 64641.01 | P4: =IF(_xlfn.XLOOKUP(TableIncome[[#This Row],[Year]],Loop!C:C,Loop!D:D)<70,(P3*(1+$I$3))+IF(TableIncomeCalculations[[#This Row],[SwitchP1]]="Y",P3*$I$5,0),0) -> 45187.13 | Q4: =IF(_xlfn.XLOOKUP(TableIncome[[#This Row],[Year]],Loop!C:C,Loop!E:E)<70,(Q3*(1+$I$3))+IF(TableIncomeCalculations[[#This Row],[SwitchP2]]="Y",Q3*$I$5,0),0) -> 65921.03 | R4: =_xlfn.XLOOKUP(_xlfn.XLOOKUP(TableIncome[[#This Row],[Year]],Loop!C:C,Loop!D:D),'Job Hopping'!B:B,'Job Hopping'!F:F) -> N | S4: =_xlfn.XLOOKUP(_xlfn.XLOOKUP(TableIncome[[#This Row],[Year]],Loop!C:C,Loop!E:E),'Job Hopping'!B:B,'Job Hopping'!G:G) -> N
B5: 2027 | C5: =(TableIncomeCalculations[[#This Row],[NetMonthlySalaryP1]]*12) -> 304525.82 | D5: =(TableIncomeCalculations[[#This Row],[NetMonthlySalaryP2]]*12) -> 426266.24 | E5: =TableIncome[[#This Row],[SalaryP1]]*$I$7 -> 30452.582 | F5: =TableIncome[[#This Row],[SalaryP2]]*$I$7 -> 42626.624 | H5: Job Hopping "Bonus" | I5: 0.06 | L5: ='Net Salary P1'!BI4 -> 25377.151 | M5: ='Net Salary P2'!AT4 -> 35522.187 | N5: =IF(_xlfn.XLOOKUP(TableIncome[[#This Row],[Year]],Loop!C:C,Loop!D:D)<70,(N4*(1+$I$4))+IF(TableIncomeCalculations[[#This Row],[SwitchP1]]="Y",N4*$I$6,0),0) -> 46525.195 | O5: =IF(_xlfn.XLOOKUP(TableIncome[[#This Row],[Year]],Loop!C:C,Loop!E:E)<70,(O4*(1+$I$4))+IF(TableIncomeCalculations[[#This Row],[SwitchP2]]="Y",Q4*$I$6,0),0) -> 65287.42 | P5: =IF(_xlfn.XLOOKUP(TableIncome[[#This Row],[Year]],Loop!C:C,Loop!D:D)<70,(P4*(1+$I$3))+IF(TableIncomeCalculations[[#This Row],[SwitchP1]]="Y",P4*$I$5,0),0) -> 49253.972 | Q5: =IF(_xlfn.XLOOKUP(TableIncome[[#This Row],[Year]],Loop!C:C,Loop!E:E)<70,(Q4*(1+$I$3))+IF(TableIncomeCalculations[[#This Row],[SwitchP2]]="Y",Q4*$I$5,0),0) -> 67898.661 | R5: =_xlfn.XLOOKUP(_xlfn.XLOOKUP(TableIncome[[#This Row],[Year]],Loop!C:C,Loop!D:D),'Job Hopping'!B:B,'Job Hopping'!F:F) -> Y | S5: =_xlfn.XLOOKUP(_xlfn.XLOOKUP(TableIncome[[#This Row],[Year]],Loop!C:C,Loop!E:E),'Job Hopping'!B:B,'Job Hopping'!G:G) -> N
B6: 2028 | C6: =(TableIncomeCalculations[[#This Row],[NetMonthlySalaryP1]]*12) -> 307776.61 | D6: =(TableIncomeCalculations[[#This Row],[NetMonthlySalaryP2]]*12) -> 443399.32 | E6: =TableIncome[[#This Row],[SalaryP1]]*$I$7 -> 30777.661 | F6: =TableIncome[[#This Row],[SalaryP2]]*$I$7 -> 44339.932 | H6: Real Job Hopping "Bonus" | I6: 0.04 | L6: ='Net Salary P1'!BI5 -> 25648.051 | M6: ='Net Salary P2'!AT5 -> 36949.943 | N6: =IF(_xlfn.XLOOKUP(TableIncome[[#This Row],[Year]],Loop!C:C,Loop!D:D)<70,(N5*(1+$I$4))+IF(TableIncomeCalculations[[#This Row],[SwitchP1]]="Y",N5*$I$6,0),0) -> 46990.447 | O6: =IF(_xlfn.XLOOKUP(TableIncome[[#This Row],[Year]],Loop!C:C,Loop!E:E)<70,(O5*(1+$I$4))+IF(TableIncomeCalculations[[#This Row],[SwitchP2]]="Y",Q5*$I$6,0),0) -> 68656.241 | P6: =IF(_xlfn.XLOOKUP(TableIncome[[#This Row],[Year]],Loop!C:C,Loop!D:D)<70,(P5*(1+$I$3))+IF(TableIncomeCalculations[[#This Row],[SwitchP1]]="Y",P5*$I$5,0),0) -> 50731.591 | Q6: =IF(_xlfn.XLOOKUP(TableIncome[[#This Row],[Year]],Loop!C:C,Loop!E:E)<70,(Q5*(1+$I$3))+IF(TableIncomeCalculations[[#This Row],[SwitchP2]]="Y",Q5*$I$5,0),0) -> 74009.54 | R6: =_xlfn.XLOOKUP(_xlfn.XLOOKUP(TableIncome[[#This Row],[Year]],Loop!C:C,Loop!D:D),'Job Hopping'!B:B,'Job Hopping'!F:F) -> N | S6: =_xlfn.XLOOKUP(_xlfn.XLOOKUP(TableIncome[[#This Row],[Year]],Loop!C:C,Loop!E:E),'Job Hopping'!B:B,'Job Hopping'!G:G) -> Y
B7: 2029 | C7: =(TableIncomeCalculations[[#This Row],[NetMonthlySalaryP1]]*12) -> 311054.66 | D7: =(TableIncomeCalculations[[#This Row],[NetMonthlySalaryP2]]*12) -> 447028.6 | E7: =TableIncome[[#This Row],[SalaryP1]]*$I$7 -> 31105.466 | F7: =TableIncome[[#This Row],[SalaryP2]]*$I$7 -> 44702.86 | H7: % of salary dedicated to investments | I7: 0.1 | L7: ='Net Salary P1'!BI6 -> 25921.222 | M7: ='Net Salary P2'!AT6 -> 37252.383 | N7: =IF(_xlfn.XLOOKUP(TableIncome[[#This Row],[Year]],Loop!C:C,Loop!D:D)<70,(N6*(1+$I$4))+IF(TableIncomeCalculations[[#This Row],[SwitchP1]]="Y",N6*$I$6,0),0) -> 47460.352 | O7: =IF(_xlfn.XLOOKUP(TableIncome[[#This Row],[Year]],Loop!C:C,Loop!E:E)<70,(O6*(1+$I$4))+IF(TableIncomeCalculations[[#This Row],[SwitchP2]]="Y",Q6*$I$6,0),0) -> 69342.803 | P7: =IF(_xlfn.XLOOKUP(TableIncome[[#This Row],[Year]],Loop!C:C,Loop!D:D)<70,(P6*(1+$I$3))+IF(TableIncomeCalculations[[#This Row],[SwitchP1]]="Y",P6*$I$5,0),0) -> 52253.539 | Q7: =IF(_xlfn.XLOOKUP(TableIncome[[#This Row],[Year]],Loop!C:C,Loop!E:E)<70,(Q6*(1+$I$3))+IF(TableIncomeCalculations[[#This Row],[SwitchP2]]="Y",Q6*$I$5,0),0) -> 76229.827 | R7: =_xlfn.XLOOKUP(_xlfn.XLOOKUP(TableIncome[[#This Row],[Year]],Loop!C:C,Loop!D:D),'Job Hopping'!B:B,'Job Hopping'!F:F) -> N | S7: =_xlfn.XLOOKUP(_xlfn.XLOOKUP(TableIncome[[#This Row],[Year]],Loop!C:C,Loop!E:E),'Job Hopping'!B:B,'Job Hopping'!G:G) -> N
B8: 2030 | C8: =(TableIncomeCalculations[[#This Row],[NetMonthlySalaryP1]]*12) -> 333849.92 | D8: =(TableIncomeCalculations[[#This Row],[NetMonthlySalaryP2]]*12) -> 474386.82 | E8: =TableIncome[[#This Row],[SalaryP1]]*$I$7 -> 33384.992 | F8: =TableIncome[[#This Row],[SalaryP2]]*$I$7 -> 47438.682 | L8: ='Net Salary P1'!BI9 -> 27820.827 | M8: ='Net Salary P2'!AT9 -> 39532.235 | N8: =IF(_xlfn.XLOOKUP(TableIncome[[#This Row],[Year]],Loop!C:C,Loop!D:D)<70,(N7*(1+$I$4))+IF(TableIncomeCalculations[[#This Row],[SwitchP1]]="Y",N7*$I$6,0),0) -> 47934.955 | O8: =IF(_xlfn.XLOOKUP(TableIncome[[#This Row],[Year]],Loop!C:C,Loop!E:E)<70,(O7*(1+$I$4))+IF(TableIncomeCalculations[[#This Row],[SwitchP2]]="Y",Q7*$I$6,0),0) -> 70036.231 | P8: =IF(_xlfn.XLOOKUP(TableIncome[[#This Row],[Year]],Loop!C:C,Loop!D:D)<70,(P7*(1+$I$3))+IF(TableIncomeCalculations[[#This Row],[SwitchP1]]="Y",P7*$I$5,0),0) -> 53821.145 | Q8: =IF(_xlfn.XLOOKUP(TableIncome[[#This Row],[Year]],Loop!C:C,Loop!E:E)<70,(Q7*(1+$I$3))+IF(TableIncomeCalculations[[#This Row],[SwitchP2]]="Y",Q7*$I$5,0),0) -> 78516.721 | R8: =_xlfn.XLOOKUP(_xlfn.XLOOKUP(TableIncome[[#This Row],[Year]],Loop!C:C,Loop!D:D),'Job Hopping'!B:B,'Job Hopping'!F:F) -> N | S8: =_xlfn.XLOOKUP(_xlfn.XLOOKUP(TableIncome[[#This Row],[Year]],Loop!C:C,Loop!E:E),'Job Hopping'!B:B,'Job Hopping'!G:G) -> N
B9: 2031 | C9: =(TableIncomeCalculations[[#This Row],[NetMonthlySalaryP1]]*12) -> 337368.74 | D9: =(TableIncomeCalculations[[#This Row],[NetMonthlySalaryP2]]*12) -> 478306 | E9: =TableIncome[[#This Row],[SalaryP1]]*$I$7 -> 33736.874 | F9: =TableIncome[[#This Row],[SalaryP2]]*$I$7 -> 47830.6 | L9: ='Net Salary P1'!BI10 -> 28114.062 | M9: ='Net Salary P2'!AT10 -> 39858.834 | N9: =IF(_xlfn.XLOOKUP(TableIncome[[#This Row],[Year]],Loop!C:C,Loop!D:D)<70,(N8*(1+$I$4))+IF(TableIncomeCalculations[[#This Row],[SwitchP1]]="Y",N8*$I$6,0),0) -> 50331.703 | O9: =IF(_xlfn.XLOOKUP(TableIncome[[#This Row],[Year]],Loop!C:C,Loop!E:E)<70,(O8*(1+$I$4))+IF(TableIncomeCalculations[[#This Row],[SwitchP2]]="Y",Q8*$I$6,0),0) -> 70736.593 | P9: =IF(_xlfn.XLOOKUP(TableIncome[[#This Row],[Year]],Loop!C:C,Loop!D:D)<70,(P8*(1+$I$3))+IF(TableIncomeCalculations[[#This Row],[SwitchP1]]="Y",P8*$I$5,0),0) -> 58665.048 | Q9: =IF(_xlfn.XLOOKUP(TableIncome[[#This Row],[Year]],Loop!C:C,Loop!E:E)<70,(Q8*(1+$I$3))+IF(TableIncomeCalculations[[#This Row],[SwitchP2]]="Y",Q8*$I$5,0),0) -> 80872.223 | R9: =_xlfn.XLOOKUP(_xlfn.XLOOKUP(TableIncome[[#This Row],[Year]],Loop!C:C,Loop!D:D),'Job Hopping'!B:B,'Job Hopping'!F:F) -> Y | S9: =_xlfn.XLOOKUP(_xlfn.XLOOKUP(TableIncome[[#This Row],[Year]],Loop!C:C,Loop!E:E),'Job Hopping'!B:B,'Job Hopping'!G:G) -> N
B10: 2032 | C10: =(TableIncomeCalculations[[#This Row],[NetMonthlySalaryP1]]*12) -> 340918 | D10: =(TableIncomeCalculations[[#This Row],[NetMonthlySalaryP2]]*12) -> 482259.63 | E10: =TableIncome[[#This Row],[SalaryP1]]*$I$7 -> 34091.8 | F10: =TableIncome[[#This Row],[SalaryP2]]*$I$7 -> 48225.963 | L10: ='Net Salary P1'!BI11 -> 28409.833 | M10: ='Net Salary P2'!AT11 -> 40188.302 | N10: =IF(_xlfn.XLOOKUP(TableIncome[[#This Row],[Year]],Loop!C:C,Loop!D:D)<70,(N9*(1+$I$4))+IF(TableIncomeCalculations[[#This Row],[SwitchP1]]="Y",N9*$I$6,0),0) -> 50835.02 | O10: =IF(_xlfn.XLOOKUP(TableIncome[[#This Row],[Year]],Loop!C:C,Loop!E:E)<70,(O9*(1+$I$4))+IF(TableIncomeCalculations[[#This Row],[SwitchP2]]="Y",Q9*$I$6,0),0) -> 74678.848 | P10: =IF(_xlfn.XLOOKUP(TableIncome[[#This Row],[Year]],Loop!C:C,Loop!D:D)<70,(P9*(1+$I$3))+IF(TableIncomeCalculations[[#This Row],[SwitchP1]]="Y",P9*$I$5,0),0) -> 60424.999 | Q10: =IF(_xlfn.XLOOKUP(TableIncome[[#This Row],[Year]],Loop!C:C,Loop!E:E)<70,(Q9*(1+$I$3))+IF(TableIncomeCalculations[[#This Row],[SwitchP2]]="Y",Q9*$I$5,0),0) -> 88150.723 | R10: =_xlfn.XLOOKUP(_xlfn.XLOOKUP(TableIncome[[#This Row],[Year]],Loop!C:C,Loop!D:D),'Job Hopping'!B:B,'Job Hopping'!F:F) -> N | S10: =_xlfn.XLOOKUP(_xlfn.XLOOKUP(TableIncome[[#This Row],[Year]],Loop!C:C,Loop!E:E),'Job Hopping'!B:B,'Job Hopping'!G:G) -> Y
B11: 2033 | C11: =(TableIncomeCalculations[[#This Row],[NetMonthlySalaryP1]]*12) -> 358201.54 | D11: =(TableIncomeCalculations[[#This Row],[NetMonthlySalaryP2]]*12) -> 486248.13 | E11: =TableIncome[[#This Row],[SalaryP1]]*$I$7 -> 35820.154 | F11: =TableIncome[[#This Row],[SalaryP2]]*$I$7 -> 48624.813 | L11: ='Net Salary P1'!BI12 -> 29850.128 | M11: ='Net Salary P2'!AT12 -> 40520.678 | N11: =IF(_xlfn.XLOOKUP(TableIncome[[#This Row],[Year]],Loop!C:C,Loop!D:D)<70,(N10*(1+$I$4))+IF(TableIncomeCalculations[[#This Row],[SwitchP1]]="Y",N10*$I$6,0),0) -> 51343.37 | O11: =IF(_xlfn.XLOOKUP(TableIncome[[#This Row],[Year]],Loop!C:C,Loop!E:E)<70,(O10*(1+$I$4))+IF(TableIncomeCalculations[[#This Row],[SwitchP2]]="Y",Q10*$I$6,0),0) -> 75425.637 | P11: =IF(_xlfn.XLOOKUP(TableIncome[[#This Row],[Year]],Loop!C:C,Loop!D:D)<70,(P10*(1+$I$3))+IF(TableIncomeCalculations[[#This Row],[SwitchP1]]="Y",P10*$I$5,0),0) -> 62237.749 | Q11: =IF(_xlfn.XLOOKUP(TableIncome[[#This Row],[Year]],Loop!C:C,Loop!E:E)<70,(Q10*(1+$I$3))+IF(TableIncomeCalculations[[#This Row],[SwitchP2]]="Y",Q10*$I$5,0),0) -> 90795.245 | R11: =_xlfn.XLOOKUP(_xlfn.XLOOKUP(TableIncome[[#This Row],[Year]],Loop!C:C,Loop!D:D),'Job Hopping'!B:B,'Job Hopping'!F:F) -> N | S11: =_xlfn.XLOOKUP(_xlfn.XLOOKUP(TableIncome[[#This Row],[Year]],Loop!C:C,Loop!E:E),'Job Hopping'!B:B,'Job Hopping'!G:G) -> N
B12: 2034 | C12: =(TableIncomeCalculations[[#This Row],[NetMonthlySalaryP1]]*12) -> 361949.9 | D12: =(TableIncomeCalculations[[#This Row],[NetMonthlySalaryP2]]*12) -> 490271.96 | E12: =TableIncome[[#This Row],[SalaryP1]]*$I$7 -> 36194.99 | F12: =TableIncome[[#This Row],[SalaryP2]]*$I$7 -> 49027.196 | L12: ='Net Salary P1'!BI13 -> 30162.491 | M12: ='Net Salary P2'!AT13 -> 40855.996 | N12: =IF(_xlfn.XLOOKUP(TableIncome[[#This Row],[Year]],Loop!C:C,Loop!D:D)<70,(N11*(1+$I$4))+IF(TableIncomeCalculations[[#This Row],[SwitchP1]]="Y",N11*$I$6,0),0) -> 51856.804 | O12: =IF(_xlfn.XLOOKUP(TableIncome[[#This Row],[Year]],Loop!C:C,Loop!E:E)<70,(O11*(1+$I$4))+IF(TableIncomeCalculations[[#This Row],[SwitchP2]]="Y",Q11*$I$6,0),0) -> 76179.893 | P12: =IF(_xlfn.XLOOKUP(TableIncome[[#This Row],[Year]],Loop!C:C,Loop!D:D)<70,(P11*(1+$I$3))+IF(TableIncomeCalculations[[#This Row],[SwitchP1]]="Y",P11*$I$5,0),0) -> 64104.882 | Q12: =IF(_xlfn.XLOOKUP(TableIncome[[#This Row],[Year]],Loop!C:C,Loop!E:E)<70,(Q11*(1+$I$3))+IF(TableIncomeCalculations[[#This Row],[SwitchP2]]="Y",Q11*$I$5,0),0) -> 93519.102 | R12: =_xlfn.XLOOKUP(_xlfn.XLOOKUP(TableIncome[[#This Row],[Year]],Loop!C:C,Loop!D:D),'Job Hopping'!B:B,'Job Hopping'!F:F) -> N | S12: =_xlfn.XLOOKUP(_xlfn.XLOOKUP(TableIncome[[#This Row],[Year]],Loop!C:C,Loop!E:E),'Job Hopping'!B:B,'Job Hopping'!G:G) -> N
B13: 2035 | C13: =(TableIncomeCalculations[[#This Row],[NetMonthlySalaryP1]]*12) -> 365731.26 | D13: =(TableIncomeCalculations[[#This Row],[NetMonthlySalaryP2]]*12) -> 494331.54 | E13: =TableIncome[[#This Row],[SalaryP1]]*$I$7 -> 36573.126 | F13: =TableIncome[[#This Row],[SalaryP2]]*$I$7 -> 49433.154 | L13: ='Net Salary P1'!BI14 -> 30477.605 | M13: ='Net Salary P2'!AT14 -> 41194.295 | N13: =IF(_xlfn.XLOOKUP(TableIncome[[#This Row],[Year]],Loop!C:C,Loop!D:D)<70,(N12*(1+$I$4))+IF(TableIncomeCalculations[[#This Row],[SwitchP1]]="Y",N12*$I$6,0),0) -> 54449.644 | O13: =IF(_xlfn.XLOOKUP(TableIncome[[#This Row],[Year]],Loop!C:C,Loop!E:E)<70,(O12*(1+$I$4))+IF(TableIncomeCalculations[[#This Row],[SwitchP2]]="Y",Q12*$I$6,0),0) -> 76941.692 | P13: =IF(_xlfn.XLOOKUP(TableIncome[[#This Row],[Year]],Loop!C:C,Loop!D:D)<70,(P12*(1+$I$3))+IF(TableIncomeCalculations[[#This Row],[SwitchP1]]="Y",P12*$I$5,0),0) -> 69874.321 | Q13: =IF(_xlfn.XLOOKUP(TableIncome[[#This Row],[Year]],Loop!C:C,Loop!E:E)<70,(Q12*(1+$I$3))+IF(TableIncomeCalculations[[#This Row],[SwitchP2]]="Y",Q12*$I$5,0),0) -> 96324.675 | R13: =_xlfn.XLOOKUP(_xlfn.XLOOKUP(TableIncome[[#This Row],[Year]],Loop!C:C,Loop!D:D),'Job Hopping'!B:B,'Job Hopping'!F:F) -> Y | S13: =_xlfn.XLOOKUP(_xlfn.XLOOKUP(TableIncome[[#This Row],[Year]],Loop!C:C,Loop!E:E),'Job Hopping'!B:B,'Job Hopping'!G:G) -> N
B14: 2036 | C14: =(TableIncomeCalculations[[#This Row],[NetMonthlySalaryP1]]*12) -> 369546.05 | D14: =(TableIncomeCalculations[[#This Row],[NetMonthlySalaryP2]]*12) -> 498427.34 | E14: =TableIncome[[#This Row],[SalaryP1]]*$I$7 -> 36954.605 | F14: =TableIncome[[#This Row],[SalaryP2]]*$I$7 -> 49842.734 | L14: ='Net Salary P1'!BI15 -> 30795.504 | M14: ='Net Salary P2'!AT15 -> 41535.611 | N14: =IF(_xlfn.XLOOKUP(TableIncome[[#This Row],[Year]],Loop!C:C,Loop!D:D)<70,(N13*(1+$I$4))+IF(TableIncomeCalculations[[#This Row],[SwitchP1]]="Y",N13*$I$6,0),0) -> 54994.141 | O14: =IF(_xlfn.XLOOKUP(TableIncome[[#This Row],[Year]],Loop!C:C,Loop!E:E)<70,(O13*(1+$I$4))+IF(TableIncomeCalculations[[#This Row],[SwitchP2]]="Y",Q13*$I$6,0),0) -> 77711.109 | P14: =IF(_xlfn.XLOOKUP(TableIncome[[#This Row],[Year]],Loop!C:C,Loop!D:D)<70,(P13*(1+$I$3))+IF(TableIncomeCalculations[[#This Row],[SwitchP1]]="Y",P13*$I$5,0),0) -> 71970.551 | Q14: =IF(_xlfn.XLOOKUP(TableIncome[[#This Row],[Year]],Loop!C:C,Loop!E:E)<70,(Q13*(1+$I$3))+IF(TableIncomeCalculations[[#This Row],[SwitchP2]]="Y",Q13*$I$5,0),0) -> 99214.415 | R14: =_xlfn.XLOOKUP(_xlfn.XLOOKUP(TableIncome[[#This Row],[Year]],Loop!C:C,Loop!D:D),'Job Hopping'!B:B,'Job Hopping'!F:F) -> N | S14: =_xlfn.XLOOKUP(_xlfn.XLOOKUP(TableIncome[[#This Row],[Year]],Loop!C:C,Loop!E:E),'Job Hopping'!B:B,'Job Hopping'!G:G) -> N
B15: 2037 | C15: =(TableIncomeCalculations[[#This Row],[NetMonthlySalaryP1]]*12) -> 388219.3 | D15: =(TableIncomeCalculations[[#This Row],[NetMonthlySalaryP2]]*12) -> 502559.78 | E15: =TableIncome[[#This Row],[SalaryP1]]*$I$7 -> 38821.93 | F15: =TableIncome[[#This Row],[SalaryP2]]*$I$7 -> 50255.978 | L15: ='Net Salary P1'!BI16 -> 32351.608 | M15: ='Net Salary P2'!AT16 -> 41879.982 | N15: =IF(_xlfn.XLOOKUP(TableIncome[[#This Row],[Year]],Loop!C:C,Loop!D:D)<70,(N14*(1+$I$4))+IF(TableIncomeCalculations[[#This Row],[SwitchP1]]="Y",N14*$I$6,0),0) -> 55544.082 | O15: =IF(_xlfn.XLOOKUP(TableIncome[[#This Row],[Year]],Loop!C:C,Loop!E:E)<70,(O14*(1+$I$4))+IF(TableIncomeCalculations[[#This Row],[SwitchP2]]="Y",Q14*$I$6,0),0) -> 78488.22 | P15: =IF(_xlfn.XLOOKUP(TableIncome[[#This Row],[Year]],Loop!C:C,Loop!D:D)<70,(P14*(1+$I$3))+IF(TableIncomeCalculations[[#This Row],[SwitchP1]]="Y",P14*$I$5,0),0) -> 74129.667 | Q15: =IF(_xlfn.XLOOKUP(TableIncome[[#This Row],[Year]],Loop!C:C,Loop!E:E)<70,(Q14*(1+$I$3))+IF(TableIncomeCalculations[[#This Row],[SwitchP2]]="Y",Q14*$I$5,0),0) -> 102190.85 | R15: =_xlfn.XLOOKUP(_xlfn.XLOOKUP(TableIncome[[#This Row],[Year]],Loop!C:C,Loop!D:D),'Job Hopping'!B:B,'Job Hopping'!F:F) -> N | S15: =_xlfn.XLOOKUP(_xlfn.XLOOKUP(TableIncome[[#This Row],[Year]],Loop!C:C,Loop!E:E),'Job Hopping'!B:B,'Job Hopping'!G:G) -> N
B16: 2038 | C16: =(TableIncomeCalculations[[#This Row],[NetMonthlySalaryP1]]*12) -> 392250.45 | D16: =(TableIncomeCalculations[[#This Row],[NetMonthlySalaryP2]]*12) -> 506729.34 | E16: =TableIncome[[#This Row],[SalaryP1]]*$I$7 -> 39225.045 | F16: =TableIncome[[#This Row],[SalaryP2]]*$I$7 -> 50672.934 | L16: ='Net Salary P1'!BI17 -> 32687.537 | M16: ='Net Salary P2'!AT17 -> 42227.445 | N16: =IF(_xlfn.XLOOKUP(TableIncome[[#This Row],[Year]],Loop!C:C,Loop!D:D)<70,(N15*(1+$I$4))+IF(TableIncomeCalculations[[#This Row],[SwitchP1]]="Y",N15*$I$6,0),0) -> 56099.523 | O16: =IF(_xlfn.XLOOKUP(TableIncome[[#This Row],[Year]],Loop!C:C,Loop!E:E)<70,(O15*(1+$I$4))+IF(TableIncomeCalculations[[#This Row],[SwitchP2]]="Y",Q15*$I$6,0),0) -> 79273.102 | P16: =IF(_xlfn.XLOOKUP(TableIncome[[#This Row],[Year]],Loop!C:C,Loop!D:D)<70,(P15*(1+$I$3))+IF(TableIncomeCalculations[[#This Row],[SwitchP1]]="Y",P15*$I$5,0),0) -> 76353.557 | Q16: =IF(_xlfn.XLOOKUP(TableIncome[[#This Row],[Year]],Loop!C:C,Loop!E:E)<70,(Q15*(1+$I$3))+IF(TableIncomeCalculations[[#This Row],[SwitchP2]]="Y",Q15*$I$5,0),0) -> 105256.57 | R16: =_xlfn.XLOOKUP(_xlfn.XLOOKUP(TableIncome[[#This Row],[Year]],Loop!C:C,Loop!D:D),'Job Hopping'!B:B,'Job Hopping'!F:F) -> N | S16: =_xlfn.XLOOKUP(_xlfn.XLOOKUP(TableIncome[[#This Row],[Year]],Loop!C:C,Loop!E:E),'Job Hopping'!B:B,'Job Hopping'!G:G) -> N
B17: 2039 | C17: =(TableIncomeCalculations[[#This Row],[NetMonthlySalaryP1]]*12) -> 396317.77 | D17: =(TableIncomeCalculations[[#This Row],[NetMonthlySalaryP2]]*12) -> 510936.45 | E17: =TableIncome[[#This Row],[SalaryP1]]*$I$7 -> 39631.777 | F17: =TableIncome[[#This Row],[SalaryP2]]*$I$7 -> 51093.645 | L17: ='Net Salary P1'!BI18 -> 33026.481 | M17: ='Net Salary P2'!AT18 -> 42578.037 | N17: =IF(_xlfn.XLOOKUP(TableIncome[[#This Row],[Year]],Loop!C:C,Loop!D:D)<70,(N16*(1+$I$4))+IF(TableIncomeCalculations[[#This Row],[SwitchP1]]="Y",N16*$I$6,0),0) -> 58904.499 | O17: =IF(_xlfn.XLOOKUP(TableIncome[[#This Row],[Year]],Loop!C:C,Loop!E:E)<70,(O16*(1+$I$4))+IF(TableIncomeCalculations[[#This Row],[SwitchP2]]="Y",Q16*$I$6,0),0) -> 80065.833 | P17: =IF(_xlfn.XLOOKUP(TableIncome[[#This Row],[Year]],Loop!C:C,Loop!D:D)<70,(P16*(1+$I$3))+IF(TableIncomeCalculations[[#This Row],[SwitchP1]]="Y",P16*$I$5,0),0) -> 83225.377 | Q17: =IF(_xlfn.XLOOKUP(TableIncome[[#This Row],[Year]],Loop!C:C,Loop!E:E)<70,(Q16*(1+$I$3))+IF(TableIncomeCalculations[[#This Row],[SwitchP2]]="Y",Q16*$I$5,0),0) -> 108414.27 | R17: =_xlfn.XLOOKUP(_xlfn.XLOOKUP(TableIncome[[#This Row],[Year]],Loop!C:C,Loop!D:D),'Job Hopping'!B:B,'Job Hopping'!F:F) -> Y | S17: =_xlfn.XLOOKUP(_xlfn.XLOOKUP(TableIncome[[#This Row],[Year]],Loop!C:C,Loop!E:E),'Job Hopping'!B:B,'Job Hopping'!G:G) -> N
B18: 2040 | C18: =(TableIncomeCalculations[[#This Row],[NetMonthlySalaryP1]]*12) -> 400421.71 | D18: =(TableIncomeCalculations[[#This Row],[NetMonthlySalaryP2]]*12) -> 515181.58 | E18: =TableIncome[[#This Row],[SalaryP1]]*$I$7 -> 40042.171 | F18: =TableIncome[[#This Row],[SalaryP2]]*$I$7 -> 51518.158 | L18: ='Net Salary P1'!BI19 -> 33368.476 | M18: ='Net Salary P2'!AT19 -> 42931.798 | N18: =IF(_xlfn.XLOOKUP(TableIncome[[#This Row],[Year]],Loop!C:C,Loop!D:D)<70,(N17*(1+$I$4))+IF(TableIncomeCalculations[[#This Row],[SwitchP1]]="Y",N17*$I$6,0),0) -> 59493.544 | O18: =IF(_xlfn.XLOOKUP(TableIncome[[#This Row],[Year]],Loop!C:C,Loop!E:E)<70,(O17*(1+$I$4))+IF(TableIncomeCalculations[[#This Row],[SwitchP2]]="Y",Q17*$I$6,0),0) -> 80866.492 | P18: =IF(_xlfn.XLOOKUP(TableIncome[[#This Row],[Year]],Loop!C:C,Loop!D:D)<70,(P17*(1+$I$3))+IF(TableIncomeCalculations[[#This Row],[SwitchP1]]="Y",P17*$I$5,0),0) -> 85722.139 | Q18: =IF(_xlfn.XLOOKUP(TableIncome[[#This Row],[Year]],Loop!C:C,Loop!E:E)<70,(Q17*(1+$I$3))+IF(TableIncomeCalculations[[#This Row],[SwitchP2]]="Y",Q17*$I$5,0),0) -> 111666.7 | R18: =_xlfn.XLOOKUP(_xlfn.XLOOKUP(TableIncome[[#This Row],[Year]],Loop!C:C,Loop!D:D),'Job Hopping'!B:B,'Job Hopping'!F:F) -> N | S18: =_xlfn.XLOOKUP(_xlfn.XLOOKUP(TableIncome[[#This Row],[Year]],Loop!C:C,Loop!E:E),'Job Hopping'!B:B,'Job Hopping'!G:G) -> N
B19: 2041 | C19: =(TableIncomeCalculations[[#This Row],[NetMonthlySalaryP1]]*12) -> 420600.23 | D19: =(TableIncomeCalculations[[#This Row],[NetMonthlySalaryP2]]*12) -> 519465.18 | E19: =TableIncome[[#This Row],[SalaryP1]]*$I$7 -> 42060.023 | F19: =TableIncome[[#This Row],[SalaryP2]]*$I$7 -> 51946.518 | L19: ='Net Salary P1'!BI20 -> 35050.019 | M19: ='Net Salary P2'!AT20 -> 43288.765 | N19: =IF(_xlfn.XLOOKUP(TableIncome[[#This Row],[Year]],Loop!C:C,Loop!D:D)<70,(N18*(1+$I$4))+IF(TableIncomeCalculations[[#This Row],[SwitchP1]]="Y",N18*$I$6,0),0) -> 60088.48 | O19: =IF(_xlfn.XLOOKUP(TableIncome[[#This Row],[Year]],Loop!C:C,Loop!E:E)<70,(O18*(1+$I$4))+IF(TableIncomeCalculations[[#This Row],[SwitchP2]]="Y",Q18*$I$6,0),0) -> 81675.157 | P19: =IF(_xlfn.XLOOKUP(TableIncome[[#This Row],[Year]],Loop!C:C,Loop!D:D)<70,(P18*(1+$I$3))+IF(TableIncomeCalculations[[#This Row],[SwitchP1]]="Y",P18*$I$5,0),0) -> 88293.803 | Q19: =IF(_xlfn.XLOOKUP(TableIncome[[#This Row],[Year]],Loop!C:C,Loop!E:E)<70,(Q18*(1+$I$3))+IF(TableIncomeCalculations[[#This Row],[SwitchP2]]="Y",Q18*$I$5,0),0) -> 115016.7 | R19: =_xlfn.XLOOKUP(_xlfn.XLOOKUP(TableIncome[[#This Row],[Year]],Loop!C:C,Loop!D:D),'Job Hopping'!B:B,'Job Hopping'!F:F) -> N | S19: =_xlfn.XLOOKUP(_xlfn.XLOOKUP(TableIncome[[#This Row],[Year]],Loop!C:C,Loop!E:E),'Job Hopping'!B:B,'Job Hopping'!G:G) -> N
... B48: 2070 | C48: =(TableIncomeCalculations[[#This Row],[NetMonthlySalaryP1]]*12) -> 0 | D48: =(TableIncomeCalculations[[#This Row],[NetMonthlySalaryP2]]*12) -> 0 | E48: =TableIncome[[#This Row],[SalaryP1]]*$I$7 -> 0 | F48: =TableIncome[[#This Row],[SalaryP2]]*$I$7 -> 0 | L48: ='Net Salary P1'!BI49 -> 0 | M48: ='Net Salary P2'!AT49 -> 0 | N48: =IF(_xlfn.XLOOKUP(TableIncome[[#This Row],[Year]],Loop!C:C,Loop!D:D)<70,(N47*(1+$I$4))+IF(TableIncomeCalculations[[#This Row],[SwitchP1]]="Y",N47*$I$6,0),0) -> 0 | O48: =IF(_xlfn.XLOOKUP(TableIncome[[#This Row],[Year]],Loop!C:C,Loop!E:E)<70,(O47*(1+$I$4))+IF(TableIncomeCalculations[[#This Row],[SwitchP2]]="Y",Q47*$I$6,0),0) -> 0 | P48: =IF(_xlfn.XLOOKUP(TableIncome[[#This Row],[Year]],Loop!C:C,Loop!D:D)<70,(P47*(1+$I$3))+IF(TableIncomeCalculations[[#This Row],[SwitchP1]]="Y",P47*$I$5,0),0) -> 0 | Q48: =IF(_xlfn.XLOOKUP(TableIncome[[#This Row],[Year]],Loop!C:C,Loop!E:E)<70,(Q47*(1+$I$3))+IF(TableIncomeCalculations[[#This Row],[SwitchP2]]="Y",Q47*$I$5,0),0) -> 0 | R48: =_xlfn.XLOOKUP(_xlfn.XLOOKUP(TableIncome[[#This Row],[Year]],Loop!C:C,Loop!D:D),'Job Hopping'!B:B,'Job Hopping'!F:F) -> N | S48: =_xlfn.XLOOKUP(_xlfn.XLOOKUP(TableIncome[[#This Row],[Year]],Loop!C:C,Loop!E:E),'Job Hopping'!B:B,'Job Hopping'!G:G) -> N

Sheet Pensions P1
A1: Year | B1: 2025 | C1: 2026 | D1: 2027 | E1: 2028 | F1: 2029 | G1: 2030 | H1: 2031 | I1: 2032 | J1: 2033 | K1: 2034 | L1: 2035 | M1: 2036 | N1: 2037 | O1: 2038 | P1: 2039 | Q1: 2040 | R1: 2041 | S1: 2042 | T1: 2043 | U1: 2044 | V1: 2045 | W1: 2046 | X1: 2047 | Y1: 2048 | Z1: 2049 | AA1: 2050 | AB1: 2051 | AC1: 2052 | AD1: 2053 | AE1: 2054 | AF1: 2055 | AG1: 2056 | AH1: 2057 | AI1: 2058 | AJ1: 2059 | AK1: 2060 | AL1: 2061 | AM1: 2062 | AN1: 2063 | AO1: 2064 | AP1: 2065 | AQ1: 2066 | AR1: 2067 | AS1: 2068 | AT1: 2069
A2: Month Salary | B2: {=TRANSPOSE(Income!N3:N47)} -> 43871 | C2: 44309.71 | D2: 46525.195 | E2: 46990.447 | F2: 47460.352 | G2: 47934.955 | H2: 50331.703 | I2: 50835.02 | J2: 51343.37 | K2: 51856.804 | L2: 54449.644 | M2: 54994.141 | N2: 55544.082 | O2: 56099.523 | P2: 58904.499 | Q2: 59493.544 | R2: 60088.48 | S2: 60689.364 | T2: 63723.833 | U2: 64361.071 | V2: 65004.682 | W2: 65654.728 | X2: 68937.465 | Y2: 69626.84 | Z2: 70323.108 | AA2: 71026.339 | AB2: 71736.602 | AC2: 72453.968 | AD2: 73178.508 | AE2: 73910.293 | AF2: 74649.396 | AG2: 75395.89 | AH2: 76149.849 | AI2: 76911.348 | AJ2: 77680.461 | AK2: 81564.484 | AL2: 82380.129 | AM2: 83203.93 | AN2: 84035.969 | AO2: 84876.329 | AP2: 85725.092 | AQ2: 86582.343 | AR2: 87448.167 | AS2: 88322.648 | AT2: 89205.875
A3: Personal Contribution (%) | B3: ='Salary Variables'!$C$12 -> 0.05 | C3: ='Salary Variables'!$C$12 -> 0.05 | D3: ='Salary Variables'!$C$12 -> 0.05 | E3: ='Salary Variables'!$C$12 -> 0.05 | F3: ='Salary Variables'!$C$12 -> 0.05 | G3: ='Salary Variables'!$C$12 -> 0.05 | H3: ='Salary Variables'!$C$12 -> 0.05 | I3: ='Salary Variables'!$C$12 -> 0.05 | ... AT3: ='Salary Variables'!$C$12 -> 0.05
A4: Personal Contribution | B4: =B3*B2 -> 2193.55 | C4: =C3*C2 -> 2215.4855 | D4: =D3*D2 -> 2326.2598 | E4: =E3*E2 -> 2349.5224 | F4: =F3*F2 -> 2373.0176 | G4: =G3*G2 -> 2396.7478 | H4: =H3*H2 -> 2516.5852 | I4: =I3*I2 -> 2541.751 | ... AT4: =AT3*AT2 -> 4460.2937
A5: Company Contribution (%) | B5: ='Salary Variables'!$C$13 -> 0.1 | C5: ='Salary Variables'!$C$13 -> 0.1 | D5: ='Salary Variables'!$C$13 -> 0.1 | E5: ='Salary Variables'!$C$13 -> 0.1 | F5: ='Salary Variables'!$C$13 -> 0.1 | G5: ='Salary Variables'!$C$13 -> 0.1 | H5: ='Salary Variables'!$C$13 -> 0.1 | I5: ='Salary Variables'!$C$13 -> 0.1 | ... AT5: ='Salary Variables'!$C$13 -> 0.1
A6: Company Contribution | B6: =B2*B5 -> 4387.1 | C6: =C4*2 -> 4430.971 | D6: =D4*2 -> 4652.5195 | E6: =E4*2 -> 4699.0447 | F6: =F4*2 -> 4746.0352 | G6: =G4*2 -> 4793.4955 | H6: =H4*2 -> 5033.1703 | I6: =I4*2 -> 5083.502 | J6: =J4*2 -> 5134.337 | ... AT6: =AT4*2 -> 8920.5875
A7: Total Contribution (Monthly) | B7: =SUM(B6,B4) -> 6580.65 | C7: =SUM(C6,C4) -> 6646.4565 | D7: =SUM(D6,D4) -> 6978.7793 | E7: =SUM(E6,E4) -> 7048.5671 | F7: =SUM(F6,F4) -> 7119.0528 | G7: =SUM(G6,G4) -> 7190.2433 | H7: =SUM(H6,H4) -> 7549.7555 | I7: =SUM(I6,I4) -> 7625.253 | ... AT7: =SUM(AT6,AT4) -> 13380.881
A8: Total Contribution (Yearly) | B8: =B7*12 -> 78967.8 | C8: =C7*12 -> 79757.478 | D8: =D7*12 -> 83745.352 | E8: =E7*12 -> 84582.805 | F8: =F7*12 -> 85428.633 | G8: =G7*12 -> 86282.92 | H8: =H7*12 -> 90597.066 | I8: =I7*12 -> 91503.036 | ... AT8: =AT7*12 -> 160570.57
A12: Total Contribution (ratepension) | B12: =SUM(B8:AT8) -> 5410424.1
A13: Divided by 25 years | B13: =B12/25 -> 216416.97 | C13: per year
A14: Monthly | B14: =B13/12 -> 18034.747 | C14: per month (gross)
A15: Taxed in Retirement? | B15: Yes | C15: Income tax
A17: Aldersopsparing | B17: =SUM('Net Salary P1'!E14:AW14) -> 282751.65 | C17: taken from sum of Net Salary P1 page
A18: Divided by 25 years | B18: =B17/25 -> 11310.066
A19: Monthly | B19: =B18/12 -> 942.50551
A20: Taxed in Retirement? | B20: No
A22: Public Pension Average Monthly | B22: 9500
A23: Public Pension Average Yearly | B23: =B22*12 -> 114000
A24: Taxed in Retirement? | B24: Yes
A25: Inflation | B25: ='Salary Variables'!C2 -> 0.02
A27: Year | B27: 2070 | C27: 2071 | D27: 2072 | E27: 2073 | F27: 2074 | G27: 2075 | H27: 2076 | I27: 2077 | J27: 2078 | K27: 2079 | L27: 2080 | M27: 2081 | N27: 2082 | O27: 2083 | P27: 2084 | Q27: 2085 | R27: 2086 | S27: 2087 | T27: 2088 | U27: 2089 | V27: 2090 | W27: 2091 | X27: 2092 | Y27: 2093 | Z27: 2094

Sheet Pensions P2
A1: Year | B1: 2025 | C1: 2026 | D1: 2027 | E1: 2028 | F1: 2029 | G1: 2030 | H1: 2031 | I1: 2032 | J1: 2033 | K1: 2034 | L1: 2035 | M1: 2036 | N1: 2037 | O1: 2038 | P1: 2039 | Q1: 2040 | R1: 2041 | S1: 2042 | T1: 2043 | U1: 2044 | V1: 2045 | W1: 2046 | X1: 2047 | Y1: 2048 | Z1: 2049 | AA1: 2050 | AB1: 2051 | AC1: 2052 | AD1: 2053 | AE1: 2054
A2: Month Salary | B2: {=TRANSPOSE(Income!O3:O32)} -> 64001 | C2: 64641.01 | D2: 65287.42 | E2: 68656.241 | F2: 69342.803 | G2: 70036.231 | H2: 70736.593 | I2: 74678.848 | J2: 75425.637 | K2: 76179.893 | L2: 76941.692 | M2: 77711.109 | N2: 78488.22 | O2: 79273.102 | P2: 80065.833 | Q2: 80866.492 | R2: 81675.157 | S2: 82491.908 | T2: 83316.827 | U2: 84149.996 | V2: 90018.77 | W2: 90918.957 | X2: 91828.147 | Y2: 92746.428 | Z2: 93673.893 | AA2: 94610.632 | AB2: 95556.738 | AC2: 96512.305 | AD2: 97477.428 | AE2: 98452.203
A3: Personal Contribution (%) | B3: ='Salary Variables'!$C$12 -> 0.05 | C3: ='Salary Variables'!$C$12 -> 0.05 | D3: ='Salary Variables'!$C$12 -> 0.05 | E3: ='Salary Variables'!$C$12 -> 0.05 | F3: ='Salary Variables'!$C$12 -> 0.05 | G3: ='Salary Variables'!$C$12 -> 0.05 | H3: ='Salary Variables'!$C$12 -> 0.05 | I3: ='Salary Variables'!$C$12 -> 0.05 | ... AT3: ='Salary Variables'!$C$12 -> 0.05
A4: Personal Contribution | B4: =B3*B2 -> 3200.05 | C4: =C3*C2 -> 3232.0505 | D4: =D3*D2 -> 3264.371 | E4: =E3*E2 -> 3432.812 | F4: =F3*F2 -> 3467.1402 | G4: =G3*G2 -> 3501.8116 | H4: =H3*H2 -> 3536.8297 | I4: =I3*I2 -> 3733.9424 | ... AT4: =AT3*AT2 -> 0
A5: Company Contribution (%) | B5: ='Salary Variables'!$C$13 -> 0.1 | C5: ='Salary Variables'!$C$13 -> 0.1 | D5: ='Salary Variables'!$C$13 -> 0.1 | E5: ='Salary Variables'!$C$13 -> 0.1 | F5: ='Salary Variables'!$C$13 -> 0.1 | G5: ='Salary Variables'!$C$13 -> 0.1 | H5: ='Salary Variables'!$C$13 -> 0.1 | I5: ='Salary Variables'!$C$13 -> 0.1 | ... AT5: ='Salary Variables'!$C$13 -> 0.1
A6: Company Contribution | B6: =B2*B5 -> 6400.1 | C6: =C4*2 -> 6464.101 | D6: =D4*2 -> 6528.742 | E6: =E4*2 -> 6865.6241 | F6: =F4*2 -> 6934.2803 | G6: =G4*2 -> 7003.6231 | H6: =H4*2 -> 7073.6593 | I6: =I4*2 -> 7467.8848 | J6: =J4*2 -> 7542.5637 | ... AT6: =AT4*2 -> 0
A7: Total Contribution (Monthly) | B7: =SUM(B6,B4) -> 9600.15 | C7: =SUM(C6,C4) -> 9696.1515 | D7: =SUM(D6,D4) -> 9793.113 | E7: =SUM(E6,E4) -> 10298.436 | F7: =SUM(F6,F4) -> 10401.42 | G7: =SUM(G6,G4) -> 10505.435 | H7: =SUM(H6,H4) -> 10610.489 | I7: =SUM(I6,I4) -> 11201.827 | ... AT7: =SUM(AT6,AT4) -> 0
A8: Total Contribution (Yearly) | B8: =B7*12 -> 115201.8 | C8: =C7*12 -> 116353.82 | D8: =D7*12 -> 117517.36 | E8: =E7*12 -> 123581.23 | F8: =F7*12 -> 124817.05 | G8: =G7*12 -> 126065.22 | H8: =H7*12 -> 127325.87 | I8: =I7*12 -> 134421.93 | ... AT8: =AT7*12 -> 0
A12: Total Contribution (ratepension) | B12: =SUM(B8:AT8) -> 4402370.7
A13: Divided by 25 years | B13: =B12/25 -> 176094.83 | C13: per year
A14: Monthly | B14: =B13/12 -> 14674.569 | C14: per month (gross)
A15: Taxed in Retirement? | B15: Yes | C15: Income tax
A17: Aldersopsparing | B17: =SUM('Net Salary P2'!E14:AW14) -> 255931.51 | C17: taken from sum of Net Salary P1 page
A18: Divided by 25 years | B18: =B17/25 -> 10237.26
A19: Monthly | B19: =B18/12 -> 853.10504
A20: Taxed in Retirement? | B20: No
A22: Public Pension Average Monthly | B22: 9500
A23: Public Pension Average Yearly | B23: =B22*12 -> 114000
A24: Taxed in Retirement? | B24: Yes
A25: Inflation | B25: ='Salary Variables'!$C$2 -> 0.02
A27: Year | B27: 2070 | C27: 2071 | D27: 2072 | E27: 2073 | F27: 2074 | G27: 2075 | H27: 2076 | I27: 2077 | J27: 2078 | K27: 2079 | L27: 2080 | M27: 2081 | N27: 2082 | O27: 2083 | P27: 2084 | Q27: 2085 | R27: 2086 | S27: 2087 | T27: 2088 | U27: 2089 | V27: 2090 | W27: 2091 | X27: 2092 | Y27: 2093 | Z27: 2094

Sheet Net Salary P1
A1: Inflation | B1: ='Salary Variables'!$C$2 -> 0.02 | D1: Year | E1: 2025 | F1: 2026 | G1: 2027 | H1: 2028 | I1: 2029 | J1: 2030 | K1: 2031 | L1: 2032 | M1: 2033 | N1: 2034 | O1: 2035 | P1: 2036 | Q1: 2037 | R1: 2038 | S1: 2039 | T1: 2040 | U1: 2041 | V1: 2042 | W1: 2043 | X1: 2044 | Y1: 2045 | Z1: 2046 | AA1: 2047 | AB1: 2048 | AC1: 2049 | AD1: 2050 | AE1: 2051 | AF1: 2052 | AG1: 2053 | AH1: 2054 | AI1: 2055 | AJ1: 2056 | AK1: 2057 | AL1: 2058 | AM1: 2059 | AN1: 2060 | AO1: 2061 | AP1: 2062 | AQ1: 2063 | AR1: 2064 | AS1: 2065 | AT1: 2066 | AU1: 2067 | AV1: 2068 | AW1: 2069
A2: Aldersopsparing max | B2: ='Salary Variables'!$C$14 -> 9400 | D2: Month Salary (Inflation Adjusted) | E2: {=TRANSPOSE(Income!N3:N47)} -> 43871 | F2: 44309.71 | G2: 46525.195 | H2: 46990.447 | I2: 47460.352 | J2: 47934.955 | K2: 50331.703 | L2: 50835.02 | M2: 51343.37 | N2: 51856.804 | O2: 54449.644 | P2: 54994.141 | Q2: 55544.082 | R2: 56099.523 | S2: 58904.499 | T2: 59493.544 | U2: 60088.48 | V2: 60689.364 | W2: 63723.833 | X2: 64361.071 | Y2: 65004.682 | Z2: 65654.728 | AA2: 68937.465 | AB2: 69626.84 | AC2: 70323.108 | AD2: 71026.339 | AE2: 71736.602 | AF2: 72453.968 | AG2: 73178.508 | AH2: 73910.293 | AI2: 74649.396 | AJ2: 75395.89 | AK2: 76149.849 | AL2: 76911.348 | AM2: 77680.461 | AN2: 81564.484 | AO2: 82380.129 | AP2: 83203.93 | AQ2: 84035.969 | AR2: 84876.329 | AS2: 85725.092 | AT2: 86582.343 | AU2: 87448.167 | AV2: 88322.648 | AW2: 89205.875 | BH2: helper for other column, do not remove --> | BI2: {=TRANSPOSE(E16:AW16)} -> 23885.512
D3: Yearly Salary | E3: =E2*12 -> 526452 | F3: =F2*12 -> 531716.52 | G3: =G2*12 -> 558302.35 | H3: =H2*12 -> 563885.37 | I3: =I2*12 -> 569524.22 | J3: =J2*12 -> 575219.47 | K3: =K2*12 -> 603980.44 | L3: =L2*12 -> 610020.24 | ... AW3: =AW2*12 -> 1070470.5 | BI3: 24142.396
A4: {='Salary Variables'!$B$16:$C$24} -> AM (%) | B4: 0.08 | D4: Ratepension | E4: ='Pensions P1'!B4*12 -> 26322.6 | F4: ='Pensions P1'!C4*12 -> 26585.826 | G4: ='Pensions P1'!D4*12 -> 27915.117 | H4: ='Pensions P1'!E4*12 -> 28194.268 | I4: ='Pensions P1'!F4*12 -> 28476.211 | J4: ='Pensions P1'!G4*12 -> 28760.973 | K4: ='Pensions P1'!H4*12 -> 30199.022 | L4: ='Pensions P1'!I4*12 -> 30501.012 | ... AW4: ='Pensions P1'!AT4*12 -> 53523.525 | BI4: 25377.151
A5: Personal Allowance | B5: 51600 | D5: Post Pension | E5: =E3-E4 -> 500129.4 | F5: =F3-F4 -> 505130.69 | G5: =G3-G4 -> 530387.23 | H5: =H3-H4 -> 535691.1 | I5: =I3-I4 -> 541048.01 | J5: =J3-J4 -> 546458.49 | K5: =K3-K4 -> 573781.42 | L5: =L3-L4 -> 579519.23 | ... AW5: =AW3-AW4 -> 1016947 | BI5: 25648.051
A6: Bottom-Bracket State Tax rate (%) | B6: 0.1201 | D6: Post AM (Taxable Personal Income) | E6: =E5*(1-$B$4) -> 460119.05 | F6: =F5*(1-$B$4) -> 464720.24 | G6: =G5*(1-$B$4) -> 487956.25 | H6: =H5*(1-$B$4) -> 492835.81 | I6: =I5*(1-$B$4) -> 497764.17 | J6: =J5*(1-$B$4) -> 502741.81 | K6: =K5*(1-$B$4) -> 527878.9 | L6: =L5*(1-$B$4) -> 533157.69 | ... AW6: =AW5*(1-$B$4) -> 935591.22 | BI6: 25921.222
A7: Top-bracket State Tax rate (%) | B7: 0.15 | D7: Personal Allowance | E7: =$B$5 -> 51600 | F7: =$B$5 -> 51600 | G7: =$B$5 -> 51600 | H7: =$B$5 -> 51600 | I7: =$B$5 -> 51600 | J7: =$B$5 -> 51600 | K7: =$B$5 -> 51600 | L7: =$B$5 -> 51600 | ... AW7: =$B$5 -> 51600 | BI7: 26196.697
A8: State Tax Bracket Threshold | B8: 618400 | D8: TPI exceed PA | E8: =E6-E7 -> 408519.05 | F8: =F6-F7 -> 413120.24 | G8: =G6-G7 -> 436356.25 | H8: =H6-H7 -> 441235.81 | I8: =I6-I7 -> 446164.17 | J8: =J6-J7 -> 451141.81 | K8: =K6-K7 -> 476278.9 | L8: =L6-L7 -> 481557.69 | ... AW8: =AW6-AW7 -> 883991.22 | BI8: 27530.096
A9: Municipal Tax (%) | B9: 0.25 | D9: Municipal Tax | E9: =E6*$B$9 -> 115029.76 | F9: =F6*$B$9 -> 116180.06 | G9: =G6*$B$9 -> 121989.06 | H9: =H6*$B$9 -> 123208.95 | I9: =I6*$B$9 -> 124441.04 | J9: =J6*$B$9 -> 125685.45 | K9: =K6*$B$9 -> 131969.73 | L9: =L6*$B$9 -> 133289.42 | ... AW9: =AW6*$B$9 -> 233897.8 | BI9: 27820.827
A10: Capital Gains < 67,500DKK | B10: 0.27 | D10: Top State Tax | E10: =MAX(E8-$B$8,0)*$B$7 -> 0 | F10: =MAX(F8-$B$8,0)*$B$7 -> 0 | G10: =MAX(G8-$B$8,0)*$B$7 -> 0 | H10: =MAX(H8-$B$8,0)*$B$7 -> 0 | I10: =MAX(I8-$B$8,0)*$B$7 -> 0 | J10: =MAX(J8-$B$8,0)*$B$7 -> 0 | K10: =MAX(K8-$B$8,0)*$B$7 -> 0 | L10: =MAX(L8-$B$8,0)*$B$7 -> 0 | ... AW10: =MAX(AW8-$B$8,0)*$B$7 -> 39838.683 | BI10: 28114.062
A11: Capital Gains > 67,500DKK | B11: 0.42 | D11: Bottom State Tax | E11: =E8*$B$6 -> 49063.138 | F11: =F8*$B$6 -> 49615.741 | G11: =G8*$B$6 -> 52406.386 | H11: =H8*$B$6 -> 52992.421 | I11: =I8*$B$6 -> 53584.317 | J11: =J8*$B$6 -> 54182.132 | K11: =K8*$B$6 -> 57201.096 | L11: =L8*$B$6 -> 57835.079 | ... AW11: =AW8*$B$6 -> 106167.35 | BI11: 28409.833
A12: Capital Gains Threshold | B12: 67500 | D12: Total Tax | E12: =SUM(E9:E11) -> 164092.9 | F12: =SUM(F9:F11) -> 165795.8 | G12: =SUM(G9:G11) -> 174395.45 | H12: =SUM(H9:H11) -> 176201.37 | I12: =SUM(I9:I11) -> 178025.36 | J12: =SUM(J9:J11) -> 179867.58 | K12: =SUM(K9:K11) -> 189170.82 | L12: =SUM(L9:L11) -> 191124.5 | ... AW12: =SUM(AW9:AW11) -> 379903.83 | BI12: 29850.128
D13: Post Tax Salary | E13: =E6-E12 -> 296026.15 | F13: =F6-F12 -> 298924.44 | G13: =G6-G12 -> 313560.8 | H13: =H6-H12 -> 316634.44 | I13: =I6-I12 -> 319738.81 | J13: =J6-J12 -> 322874.23 | K13: =K6-K12 -> 338708.08 | L13: =L6-L12 -> 342033.19 | ... AW13: =AW6-AW12 -> 555687.38 | BI13: 30162.491
D14: Aldersopsparing | E14: =$B$2/(1+$B$1)^(E1-$E$1) -> 9400 | F14: =$B$2/(1+$B$1)^(F1-$E$1) -> 9215.6863 | G14: =$B$2/(1+$B$1)^(G1-$E$1) -> 9034.9865 | H14: =$B$2/(1+$B$1)^(H1-$E$1) -> 8857.8299 | I14: =$B$2/(1+$B$1)^(I1-$E$1) -> 8684.147 | J14: =$B$2/(1+$B$1)^(J1-$E$1) -> 8513.8696 | K14: =$B$2/(1+$B$1)^(K1-$E$1) -> 8346.931 | L14: =$B$2/(1+$B$1)^(L1-$E$1) -> 8183.2657 | ... AW14: =$B$2/(1+$B$1)^(AW1-$E$1) -> 3932.9669 | BI14: 30477.605
D15: Net Salary (Yearly) | E15: =E13-E14 -> 286626.15 | F15: =F13-F14 -> 289708.75 | G15: =G13-G14 -> 304525.82 | H15: =H13-H14 -> 307776.61 | I15: =I13-I14 -> 311054.66 | J15: =J13-J14 -> 314360.36 | K15: =K13-K14 -> 330361.15 | L15: =L13-L14 -> 333849.92 | ... AW15: =AW13-AW14 -> 551754.42 | BI15: 30795.504
D16: Net Salary (Monthly) | E16: =E15/12 -> 23885.512 | F16: =F15/12 -> 24142.396 | G16: =G15/12 -> 25377.151 | H16: =H15/12 -> 25648.051 | I16: =I15/12 -> 25921.222 | J16: =J15/12 -> 26196.697 | K16: =K15/12 -> 27530.096 | L16: =L15/12 -> 27820.827 | ... AW16: =AW15/12 -> 45979.535 | BI16: 32351.608
BI17: 32687.537
BI18: 33026.481
BI19: 33368.476
BI20: 35050.019
D21: Year | E21: 2070 | F21: 2071 | G21: 2072 | H21: 2073 | I21: 2074 | J21: 2075 | K21: 2076 | L21: 2077 | M21: 2078 | N21: 2079 | O21: 2080 | P21: 2081 | Q21: 2082 | R21: 2083 | S21: 2084 | T21: 2085 | U21: 2086 | V21: 2087 | W21: 2088 | X21: 2089 | Y21: 2090 | Z21: 2091 | AA21: 2092 | AB21: 2093 | AC21: 2094 | BI21: 35348.857
D22: Monthly Salary | E22: ='Pensions P1'!$B$14+'Pensions P1'!$B$22 -> 27534.747 | F22: ='Pensions P1'!$B$14+'Pensions P1'!$B$22 -> 27534.747 | G22: ='Pensions P1'!$B$14+'Pensions P1'!$B$22 -> 27534.747 | H22: ='Pensions P1'!$B$14+'Pensions P1'!$B$22 -> 27534.747 | I22: ='Pensions P1'!$B$14+'Pensions P1'!$B$22 -> 27534.747 | J22: ='Pensions P1'!$B$14+'Pensions P1'!$B$22 -> 27534.747 | K22: ='Pensions P1'!$B$14+'Pensions P1'!$B$22 -> 27534.747 | L22: ='Pensions P1'!$B$14+'Pensions P1'!$B$22 -> 27534.747 | ... AC22: ='Pensions P1'!$B$14+'Pensions P1'!$B$22 -> 27534.747 | BI22: 35629.352
BI23: 35912.339
D24: Yearly Salary Inflation Adjusted | E24: =E22*12 -> 330416.97 | F24: =F22*12 -> 330416.97 | G24: =G22*12 -> 330416.97 | H24: =H22*12 -> 330416.97 | I24: =I22*12 -> 330416.97 | J24: =J22*12 -> 330416.97 | K24: =K22*12 -> 330416.97 | L24: =L22*12 -> 330416.97 | ... AC24: =AC22*12 -> 330416.97 | BI24: 37299.36
D25: Municipal Tax | E25: =E24*$B$11 -> 138775.13 | F25: =F24*$B$11 -> 138775.13 | G25: =G24*$B$11 -> 138775.13 | H25: =H24*$B$11 -> 138775.13 | I25: =I24*$B$11 -> 138775.13 | J25: =J24*$B$11 -> 138775.13 | K25: =K24*$B$11 -> 138775.13 | L25: =L24*$B$11 -> 138775.13 | ... AC25: =AC24*$B$11 -> 138775.13 | BI25: 37598.441
D26: Top State Tax | E26: =MAX(E24-$B$10,0)*$B$9 -> 82604.174 | F26: =MAX(F24-$B$10,0)*$B$9 -> 82604.174 | G26: =MAX(G24-$B$10,0)*$B$9 -> 82604.174 | H26: =MAX(H24-$B$10,0)*$B$9 -> 82604.174 | I26: =MAX(I24-$B$10,0)*$B$9 -> 82604.174 | J26: =MAX(J24-$B$10,0)*$B$9 -> 82604.174 | K26: =MAX(K24-$B$10,0)*$B$9 -> 82604.174 | L26: =MAX(L24-$B$10,0)*$B$9 -> 82604.174 | ... AC26: =MAX(AC24-$B$10,0)*$B$9 -> 82604.174 | BI26: 37900.219
D27: Bottom State Tax | E27: =E24*$B$6 -> 39683.078 | F27: =F24*$B$6 -> 39683.078 | G27: =G24*$B$6 -> 39683.078 | H27: =H24*$B$6 -> 39683.078 | I27: =I24*$B$6 -> 39683.078 | J27: =J24*$B$6 -> 39683.078 | K27: =K24*$B$6 -> 39683.078 | L27: =L24*$B$6 -> 39683.078 | ... AC27: =AC24*$B$6 -> 39683.078 | BI27: 38204.726
D28: Total Tax | E28: =SUM(E25:E27) -> 261062.38 | F28: =SUM(F25:F27) -> 261062.38 | G28: =SUM(G25:G27) -> 261062.38 | H28: =SUM(H25:H27) -> 261062.38 | I28: =SUM(I25:I27) -> 261062.38 | J28: =SUM(J25:J27) -> 261062.38 | K28: =SUM(K25:K27) -> 261062.38 | L28: =SUM(L25:L27) -> 261062.38 | ... AC28: =SUM(AC25:AC27) -> 261062.38 | BI28: 38511.996
D29: Post Tax Salary | E29: =E24-E28 -> 69354.589 | F29: =F24-F28 -> 69354.589 | G29: =G24-G28 -> 69354.589 | H29: =H24-H28 -> 69354.589 | I29: =I24-I28 -> 69354.589 | J29: =J24-J28 -> 69354.589 | K29: =K24-K28 -> 69354.589 | L29: =L24-L28 -> 69354.589 | ... AC29: =AC24-AC28 -> 69354.589 | BI29: 38822.061
D30: Aldersopsparing benefit | E30: ='Pensions P1'!$B$18 -> 11310.066 | F30: ='Pensions P1'!$B$18 -> 11310.066 | G30: ='Pensions P1'!$B$18 -> 11310.066 | H30: ='Pensions P1'!$B$18 -> 11310.066 | I30: ='Pensions P1'!$B$18 -> 11310.066 | J30: ='Pensions P1'!$B$18 -> 11310.066 | K30: ='Pensions P1'!$B$18 -> 11310.066 | L30: ='Pensions P1'!$B$18 -> 11310.066 | ... AC30: ='Pensions P1'!$B$18 -> 11310.066 | BI30: 39134.955
D31: Net Salary (Yearly) | E31: =E30+E29 -> 80664.655 | F31: =F30+F29 -> 80664.655 | G31: =G30+G29 -> 80664.655 | H31: =H30+H29 -> 80664.655 | I31: =I30+I29 -> 80664.655 | J31: =J30+J29 -> 80664.655 | K31: =K30+K29 -> 80664.655 | L31: =L30+L29 -> 80664.655 | ... AC31: =AC30+AC29 -> 80664.655 | BI31: 39450.712
D32: Net Salary (Monthly) | E32: =E31/12 -> 6722.0546 | F32: =F31/12 -> 6722.0546 | G32: =G31/12 -> 6722.0546 | H32: =H31/12 -> 6722.0546 | I32: =I31/12 -> 6722.0546 | J32: =J31/12 -> 6722.0546 | K32: =K31/12 -> 6722.0546 | L32: =L31/12 -> 6722.0546 | ... AC32: =AC31/12 -> 6722.0546 | BI32: 39769.365
D33: Last Yearly Income from Work | E33: =$AW$16 -> 45979.535 | F33: =$AW$16 -> 45979.535 | G33: =$AW$16 -> 45979.535 | H33: =$AW$16 -> 45979.535 | I33: =$AW$16 -> 45979.535 | J33: =$AW$16 -> 45979.535 | K33: =$AW$16 -> 45979.535 | L33: =$AW$16 -> 45979.535 | ... AC33: =$AW$16 -> 45979.535 | BI33: 40090.948
D34: Diff | E34: =E33-E32 -> 39257.48 | F34: =F33-F32 -> 39257.48 | G34: =G33-G32 -> 39257.48 | H34: =H33-H32 -> 39257.48 | I34: =I33-I32 -> 39257.48 | J34: =J33-J32 -> 39257.48 | K34: =K33-K32 -> 39257.48 | L34: =L33-L32 -> 39257.48 | ... AC34: =AC33-AC32 -> 39257.48 | BI34: 40415.496
E35: =E34*(1+$B$10) -> 49857 | F35: =F34*(1+$B$10) -> 49857 | G35: =G34*(1+$B$10) -> 49857 | H35: =H34*(1+$B$10) -> 49857 | I35: =I34*(1+$B$10) -> 49857 | J35: =J34*(1+$B$10) -> 49857 | K35: =K34*(1+$B$10) -> 49857 | L35: =L34*(1+$B$10) -> 49857 | ... AC35: =AC34*(1+$B$10) -> 49857 | BI35: 40743.044
BI36: 41073.626
BI37: 42710.545
D38: To be financed | E38: =SUM(E35:AC35) -> 1246425 | BI38: 43060.334
BI39: 43413.392
BI40: 43769.759
...

Sheet Net Salary P2
A1: Inflation | B1: =Income!I2 -> 0.02 | D1: Year | E1: 2025 | F1: 2026 | G1: 2027 | H1: 2028 | I1: 2029 | J1: 2030 | K1: 2031 | L1: 2032 | M1: 2033 | N1: 2034 | O1: 2035 | P1: 2036 | Q1: 2037 | R1: 2038 | S1: 2039 | T1: 2040 | U1: 2041 | V1: 2042 | W1: 2043 | X1: 2044 | Y1: 2045 | Z1: 2046 | AA1: 2047 | AB1: 2048 | AC1: 2049 | AD1: 2050 | AE1: 2051 | AF1: 2052 | AG1: 2053 | AH1: 2054
A2: Aldersopsparing max | B2: 9400 | D2: Month Salary (Inflation Adjusted) | E2: {=TRANSPOSE(Income!O3:O32)} -> 64001 | F2: 64641.01 | G2: 65287.42 | H2: 68656.241 | I2: 69342.803 | J2: 70036.231 | K2: 70736.593 | L2: 74678.848 | M2: 75425.637 | N2: 76179.893 | O2: 76941.692 | P2: 77711.109 | Q2: 78488.22 | R2: 79273.102 | S2: 80065.833 | T2: 80866.492 | U2: 81675.157 | V2: 82491.908 | W2: 83316.827 | X2: 84149.996 | Y2: 90018.77 | Z2: 90918.957 | AA2: 91828.147 | AB2: 92746.428 | AC2: 93673.893 | AD2: 94610.632 | AE2: 95556.738 | AF2: 96512.305 | AG2: 97477.428 | AH2: 98452.203 | AS2: helper for other column, do not remove --> | AT2: {=TRANSPOSE(E16:AH16)} -> 34952.202
D3: Yearly Salary | E3: =E2*12 -> 768012 | F3: =F2*12 -> 775692.12 | G3: =G2*12 -> 783449.04 | H3: =H2*12 -> 823874.89 | I3: =I2*12 -> 832113.64 | J3: =J2*12 -> 840434.77 | K3: =K2*12 -> 848839.12 | L3: =L2*12 -> 896146.18 | ... AH3: =AH2*12 -> 1181426.4 | AT3: 35236.003
A4: {='Salary Variables'!$B$16:$C$24} -> AM (%) | B4: 0.08 | D4: Ratepension | E4: ='Pensions P2'!B4*12 -> 38400.6 | F4: ='Pensions P2'!C4*12 -> 38784.606 | G4: ='Pensions P2'!D4*12 -> 39172.452 | H4: ='Pensions P2'!E4*12 -> 41193.744 | I4: ='Pensions P2'!F4*12 -> 41605.682 | J4: ='Pensions P2'!G4*12 -> 42021.739 | K4: ='Pensions P2'!H4*12 -> 42441.956 | L4: ='Pensions P2'!I4*12 -> 44807.309 | ... AH4: ='Pensions P2'!AE4*12 -> 59071.322 | AT4: 35522.187
A5: Personal Allowance | B5: 51600 | D5: Post Pension | E5: =E3-E4 -> 729611.4 | F5: =F3-F4 -> 736907.51 | G5: =G3-G4 -> 744276.59 | H5: =H3-H4 -> 782681.14 | I5: =I3-I4 -> 790507.96 | J5: =J3-J4 -> 798413.04 | K5: =K3-K4 -> 806397.17 | L5: =L3-L4 -> 851338.87 | ... AH5: =AH3-AH4 -> 1122355.1 | AT5: 36949.943
A6: Bottom-Bracket State Tax rate (%) | B6: 0.1201 | D6: Post AM (Taxable Personal Income) | E6: =E5*(1-$B$4) -> 671242.49 | F6: =F5*(1-$B$4) -> 677954.91 | G6: =G5*(1-$B$4) -> 684734.46 | H6: =H5*(1-$B$4) -> 720066.65 | I6: =I5*(1-$B$4) -> 727267.32 | J6: =J5*(1-$B$4) -> 734539.99 | K6: =K5*(1-$B$4) -> 741885.39 | L6: =L5*(1-$B$4) -> 783231.76 | ... AH6: =AH5*(1-$B$4) -> 1032566.7 | AT6: 37252.383
A7: Top-bracket State Tax rate (%) | B7: 0.15 | D7: Personal Allowance | E7: =$B$5 -> 51600 | F7: =$B$5 -> 51600 | G7: =$B$5 -> 51600 | H7: =$B$5 -> 51600 | I7: =$B$5 -> 51600 | J7: =$B$5 -> 51600 | K7: =$B$5 -> 51600 | L7: =$B$5 -> 51600 | ... AH7: =$B$5 -> 51600 | AT7: 37557.419
A8: State Tax Bracket Threshold | B8: 618400 | D8: TPI exceed PA | E8: =E6-E7 -> 619642.49 | F8: =F6-F7 -> 626354.91 | G8: =G6-G7 -> 633134.46 | H8: =H6-H7 -> 668466.65 | I8: =I6-I7 -> 675667.32 | J8: =J6-J7 -> 682939.99 | K8: =K6-K7 -> 690285.39 | L8: =L6-L7 -> 731631.76 | ... AH8: =AH6-AH7 -> 980966.7 | AT8: 37865.086
A9: Municipal Tax (%) | B9: 0.25 | D9: Municipal Tax | E9: =E6*$B$9 -> 167810.62 | F9: =F6*$B$9 -> 169488.73 | G9: =G6*$B$9 -> 171183.62 | H9: =H6*$B$9 -> 180016.66 | I9: =I6*$B$9 -> 181816.83 | J9: =J6*$B$9 -> 183635 | K9: =K6*$B$9 -> 185471.35 | L9: =L6*$B$9 -> 195807.94 | ... AH9: =AH6*$B$9 -> 258141.68 | AT9: 39532.235
A10: Capital Gains < 67,500DKK | B10: 0.27 | D10: Top State Tax | E10: =MAX(E8-$B$8,0)*$B$7 -> 186.3732 | F10: =MAX(F8-$B$8,0)*$B$7 -> 1193.2369 | G10: =MAX(G8-$B$8,0)*$B$7 -> 2210.1693 | H10: =MAX(H8-$B$8,0)*$B$7 -> 7509.9979 | I10: =MAX(I8-$B$8,0)*$B$7 -> 8590.0979 | J10: =MAX(J8-$B$8,0)*$B$7 -> 9680.9989 | K10: =MAX(K8-$B$8,0)*$B$7 -> 10782.809 | L10: =MAX(L8-$B$8,0)*$B$7 -> 16984.764 | ... AH10: =MAX(AH8-$B$8,0)*$B$7 -> 54385.005 | AT10: 39858.834
A11: Capital Gains > 67,500DKK | B11: 0.42 | D11: Bottom State Tax | E11: =E8*$B$6 -> 74419.063 | F11: =F8*$B$6 -> 75225.225 | G11: =G8*$B$6 -> 76039.449 | H11: =H8*$B$6 -> 80282.845 | I11: =I8*$B$6 -> 81147.645 | J11: =J8*$B$6 -> 82021.093 | K11: =K8*$B$6 -> 82903.276 | L11: =L8*$B$6 -> 87868.975 | ... AH11: =AH8*$B$6 -> 117814.1 | AT11: 40188.302
A12: Capital Gains Threshold | B12: 67500 | D12: Total Tax | E12: =SUM(E9:E11) -> 242416.06 | F12: =SUM(F9:F11) -> 245907.19 | G12: =SUM(G9:G11) -> 249433.23 | H12: =SUM(H9:H11) -> 267809.51 | I12: =SUM(I9:I11) -> 271554.57 | J12: =SUM(J9:J11) -> 275337.09 | K12: =SUM(K9:K11) -> 279157.43 | L12: =SUM(L9:L11) -> 300661.68 | ... AH12: =SUM(AH9:AH11) -> 430340.78 | AT12: 40520.678
D13: Post Tax Salary | E13: =E6-E12 -> 428826.43 | F13: =F6-F12 -> 432047.72 | G13: =G6-G12 -> 435301.23 | H13: =H6-H12 -> 452257.15 | I13: =I6-I12 -> 455712.75 | J13: =J6-J12 -> 459202.9 | K13: =K6-K12 -> 462727.96 | L13: =L6-L12 -> 482570.08 | ... AH13: =AH6-AH12 -> 602225.92 | AT13: 40855.996
D14: Aldersopsparing | E14: =$B$2/(1+$B$1)^(E1-$E$1) -> 9400 | F14: =$B$2/(1+$B$1)^(F1-$E$1) -> 9215.6863 | G14: =$B$2/(1+$B$1)^(G1-$E$1) -> 9034.9865 | H14: =$B$2/(1+$B$1)^(H1-$E$1) -> 8857.8299 | I14: =$B$2/(1+$B$1)^(I1-$E$1) -> 8684.147 | J14: =$B$2/(1+$B$1)^(J1-$E$1) -> 8513.8696 | K14: =$B$2/(1+$B$1)^(K1-$E$1) -> 8346.931 | L14: =$B$2/(1+$B$1)^(L1-$E$1) -> 8183.2657 | ... AH14: =$B$2/(1+$B$1)^(AH1-$E$1) -> 5293.2557 | AT14: 41194.295
D15: Net Salary (Yearly) | E15: =E13-E14 -> 419426.43 | F15: =F13-F14 -> 422832.04 | G15: =G13-G14 -> 426266.24 | H15: =H13-H14 -> 443399.32 | I15: =I13-I14 -> 447028.6 | J15: =J13-J14 -> 450689.03 | K15: =K13-K14 -> 454381.03 | L15: =L13-L14 -> 474386.82 | ... AH15: =AH13-AH14 -> 596932.66 | AT15: 41535.611
D16: Net Salary (Monthly) | E16: =E15/12 -> 34952.202 | F16: =F15/12 -> 35236.003 | G16: =G15/12 -> 35522.187 | H16: =H15/12 -> 36949.943 | I16: =I15/12 -> 37252.383 | J16: =J15/12 -> 37557.419 | K16: =K15/12 -> 37865.086 | L16: =L15/12 -> 39532.235 | ... AH16: =AH15/12 -> 49744.389 | AT16: 41879.982
AT17: 42227.445
AT18: 42578.037
AT19: 42931.798
AT20: 43288.765
D21: Year | E21: 2055 | F21: 2056 | G21: 2057 | H21: 2058 | I21: 2059 | J21: 2060 | K21: 2061 | L21: 2062 | M21: 2063 | N21: 2064 | O21: 2065 | P21: 2066 | Q21: 2067 | R21: 2068 | S21: 2069 | T21: 2070 | U21: 2071 | V21: 2072 | W21: 2073 | X21: 2074 | Y21: 2075 | Z21: 2076 | AA21: 2077 | AB21: 2078 | AC21: 2079 | AT21: 43648.977
D22: Monthly Salary | E22: ='Pensions P2'!$B$14+'Pensions P2'!$B$22 -> 24174.569 | F22: ='Pensions P2'!$B$14+'Pensions P2'!$B$22 -> 24174.569 | G22: ='Pensions P2'!$B$14+'Pensions P2'!$B$22 -> 24174.569 | H22: ='Pensions P2'!$B$14+'Pensions P2'!$B$22 -> 24174.569 | I22: ='Pensions P2'!$B$14+'Pensions P2'!$B$22 -> 24174.569 | J22: ='Pensions P2'!$B$14+'Pensions P2'!$B$22 -> 24174.569 | K22: ='Pensions P2'!$B$14+'Pensions P2'!$B$22 -> 24174.569 | L22: ='Pensions P2'!$B$14+'Pensions P2'!$B$22 -> 24174.569 | ... AC22: ='Pensions P2'!$B$14+'Pensions P2'!$B$22 -> 24174.569 | AT22: 46121.076
AT23: 46508.98
D24: Yearly Salary Inflation Adjusted | E24: =E22*12 -> 290094.83 | F24: =F22*12 -> 290094.83 | G24: =G22*12 -> 290094.83 | H24: =H22*12 -> 290094.83 | I24: =I22*12 -> 290094.83 | J24: =J22*12 -> 290094.83 | K24: =K22*12 -> 290094.83 | L24: =L22*12 -> 290094.83 | ... AC24: =AC22*12 -> 290094.83 | AT24: 46900.458
D25: Municipal Tax | E25: =E24*$B$11 -> 121839.83 | F25: =F24*$B$11 -> 121839.83 | G25: =G24*$B$11 -> 121839.83 | H25: =H24*$B$11 -> 121839.83 | I25: =I24*$B$11 -> 121839.83 | J25: =J24*$B$11 -> 121839.83 | K25: =K24*$B$11 -> 121839.83 | L25: =L24*$B$11 -> 121839.83 | ... AC25: =AC24*$B$11 -> 121839.83 | AT25: 47295.55
D26: Top State Tax | E26: =MAX(E24-$B$10,0)*$B$9 -> 72523.64 | F26: =MAX(F24-$B$10,0)*$B$9 -> 72523.64 | G26: =MAX(G24-$B$10,0)*$B$9 -> 72523.64 | H26: =MAX(H24-$B$10,0)*$B$9 -> 72523.64 | I26: =MAX(I24-$B$10,0)*$B$9 -> 72523.64 | J26: =MAX(J24-$B$10,0)*$B$9 -> 72523.64 | K26: =MAX(K24-$B$10,0)*$B$9 -> 72523.64 | L26: =MAX(L24-$B$10,0)*$B$9 -> 72523.64 | ... AC26: =MAX(AC24-$B$10,0)*$B$9 -> 72523.64 | AT26: 47694.299
D27: Bottom State Tax | E27: =E24*$B$6 -> 34840.389 | F27: =F24*$B$6 -> 34840.389 | G27: =G24*$B$6 -> 34840.389 | H27: =H24*$B$6 -> 34840.389 | I27: =I24*$B$6 -> 34840.389 | J27: =J24*$B$6 -> 34840.389 | K27: =K24*$B$6 -> 34840.389 | L27: =L24*$B$6 -> 34840.389 | ... AC27: =AC24*$B$6 -> 34840.389 | AT27: 48096.747
D28: Total Tax | E28: =SUM(E25:E27) -> 229203.86 | F28: =SUM(F25:F27) -> 229203.86 | G28: =SUM(G25:G27) -> 229203.86 | H28: =SUM(H25:H27) -> 229203.86 | I28: =SUM(I25:I27) -> 229203.86 | J28: =SUM(J25:J27) -> 229203.86 | K28: =SUM(K25:K27) -> 229203.86 | L28: =SUM(L25:L27) -> 229203.86 | ... AC28: =SUM(AC25:AC27) -> 229203.86 | AT28: 48502.937
D29: Post Tax Salary | E29: =E24-E28 -> 60890.972 | F29: =F24-F28 -> 60890.972 | G29: =G24-G28 -> 60890.972 | H29: =H24-H28 -> 60890.972 | I29: =I24-I28 -> 60890.972 | J29: =J24-J28 -> 60890.972 | K29: =K24-K28 -> 60890.972 | L29: =L24-L28 -> 60890.972 | ... AC29: =AC24-AC28 -> 60890.972 | AT29: 48912.912
D30: Aldersopsparing benefit | E30: ='Pensions P2'!$B$18 -> 10237.26 | F30: ='Pensions P2'!$B$18 -> 10237.26 | G30: ='Pensions P2'!$B$18 -> 10237.26 | H30: ='Pensions P2'!$B$18 -> 10237.26 | I30: ='Pensions P2'!$B$18 -> 10237.26 | J30: ='Pensions P2'!$B$18 -> 10237.26 | K30: ='Pensions P2'!$B$18 -> 10237.26 | L30: ='Pensions P2'!$B$18 -> 10237.26 | ... AC30: ='Pensions P2'!$B$18 -> 10237.26 | AT30: 49326.714
D31: Net Salary (Yearly) | E31: =E30+E29 -> 71128.233 | F31: =F30+F29 -> 71128.233 | G31: =G30+G29 -> 71128.233 | H31: =H30+H29 -> 71128.233 | I31: =I30+I29 -> 71128.233 | J31: =J30+J29 -> 71128.233 | K31: =K30+K29 -> 71128.233 | L31: =L30+L29 -> 71128.233 | ... AC31: =AC30+AC29 -> 71128.233 | AT31: 49744.389
D32: Net Salary (Monthly) | E32: =E31/12 -> 5927.3527 | F32: =F31/12 -> 5927.3527 | G32: =G31/12 -> 5927.3527 | H32: =H31/12 -> 5927.3527 | I32: =I31/12 -> 5927.3527 | J32: =J31/12 -> 5927.3527 | K32: =K31/12 -> 5927.3527 | L32: =L31/12 -> 5927.3527 | ... AC32: =AC31/12 -> 5927.3527
D33: Last Yearly Income from Work | E33: =$AH$16 -> 49744.389 | F33: =$AH$16 -> 49744.389 | G33: =$AH$16 -> 49744.389 | H33: =$AH$16 -> 49744.389 | I33: =$AH$16 -> 49744.389 | J33: =$AH$16 -> 49744.389 | K33: =$AH$16 -> 49744.389 | L33: =$AH$16 -> 49744.389 | ... AC33: =$AH$16 -> 49744.389
D34: Diff | E34: =E33-E32 -> 43817.036 | F34: =F33-F32 -> 43817.036 | G34: =G33-G32 -> 43817.036 | H34: =H33-H32 -> 43817.036 | I34: =I33-I32 -> 43817.036 | J34: =J33-J32 -> 43817.036 | K34: =K33-K32 -> 43817.036 | L34: =L33-L32 -> 43817.036 | ... AC34: =AC33-AC32 -> 43817.036
E35: =E34*(1+$B$10) -> 55647.636 | F35: =F34*(1+$B$10) -> 55647.636 | G35: =G34*(1+$B$10) -> 55647.636 | H35: =H34*(1+$B$10) -> 55647.636 | I35: =I34*(1+$B$10) -> 55647.636 | J35: =J34*(1+$B$10) -> 55647.636 | K35: =K34*(1+$B$10) -> 55647.636 | L35: =L34*(1+$B$10) -> 55647.636 | ... AC35: =AC34*(1+$B$10) -> 55647.636
D38: To be financed | E38: =SUM(E35:AC35) -> 1391190.9

Sheet Job Hopping
B2: Age | C2: Age Group | D2: FH/FW | E2: Switch | F2: SwitchP1Static | G2: SwitchP2Static | M2: Year | N2: Age Group | O2: Finance Workers | P2: Finance Hoppers | Q2: FH/FW | S2: Age Group | T2: FH/FV
B3: 25 | C3: =IF(B3<30, "25-29 år", IF(B3<35, "30-34 år", IF(B3<40, "35-39 år", IF(B3<45, "40-44 år", IF(B3<50, "45-49 år", IF(B3<55, "50-54 år", IF(B3<60, "55-59 år", IF(B3<65, "60-64 år", "65+ år")))))))) -> 25-29 år | D3: =_xlfn.XLOOKUP(C3,S:S,T:T) -> 0.51651948 | E3: =IF(OR(JobHopping[[#This Row],[Age]]=25,JobHopping[[#This Row],[Age]]>69),"N",IF(AND(E1="N",E2="N", RAND()<=D3), "Y", "N")) -> N | F3: N | G3: =IF(JobHopping[[#This Row],[Age]]<40,"",JobHopping[[#This Row],[SwitchP1Static]]) | M3: 2013 | N3: 25-29 år | O3: =_xlfn.XLOOKUP(M3&"-"&N3,'Djøf Finance Workers'!D:D,'Djøf Finance Workers'!C:C,0,1) -> 6202 | P3: =_xlfn.XLOOKUP(M3&"-"&N3,'Djøf Finance Hoppers'!D:D,'Djøf Finance Hoppers'!C:C,0,1) -> 2524 | Q3: =IF(O3>0, P3/O3, 0) -> 0.4069655 | S3: 25-29 år | T3: =SUMIFS(Q:Q,N:N,S3)/(MAX($M$3:$M$101)-MIN($M$3:$M$101)) -> 0.51651948
B4: 26 | C4: =IF(B4<30, "25-29 år", IF(B4<35, "30-34 år", IF(B4<40, "35-39 år", IF(B4<45, "40-44 år", IF(B4<50, "45-49 år", IF(B4<55, "50-54 år", IF(B4<60, "55-59 år", IF(B4<65, "60-64 år", "65+ år")))))))) -> 25-29 år | D4: =_xlfn.XLOOKUP(C4,S:S,T:T) -> 0.51651948 | E4: =IF(OR(JobHopping[[#This Row],[Age]]=25,JobHopping[[#This Row],[Age]]>69),"N",IF(AND(E2="N",E3="N", RAND()<=D4), "Y", "N")) -> N | F4: N | G4: =IF(JobHopping[[#This Row],[Age]]<40,"",JobHopping[[#This Row],[SwitchP1Static]]) | M4: 2013 | N4: 30-34 år | O4: =_xlfn.XLOOKUP(M4&"-"&N4,'Djøf Finance Workers'!D:D,'Djøf Finance Workers'!C:C,0,1) -> 8560 | P4: =_xlfn.XLOOKUP(M4&"-"&N4,'Djøf Finance Hoppers'!D:D,'Djøf Finance Hoppers'!C:C,0,1) -> 2176 | Q4: =IF(O4>0, P4/O4, 0) -> 0.25420561 | S4: 30-34 år | T4: =SUMIFS(Q:Q,N:N,S4)/(MAX($M$3:$M$101)-MIN($M$3:$M$101)) -> 0.3390802
