Workbook
Name _DLX1: [1]Rates!#REF!
Name _DLX1.INC: '[2]Car Air'!#REF!
Name _DLX10.INC: '[3]US&Europe'!#REF!
Name _DLX10_INC: #REF!
Name _DLX100.INC: '[3]Bonds Data BIS'!#REF!
Name _DLX14.INC: #REF!
Name _DLX15.INC: '[3]Bonds Data BIS'!#REF!
Name _DLX16.INC: '[3]Bonds Data BIS'!#REF!
Name _DLX2.INC: #REF!
Name _DLX20.INC: #REF!
Name _DLX3.INC: #REF!
Name _DLX4.INC: #REF!
Name _DLX5.INC: #REF!
Name _DLX5_INC: #REF!
Name _DLX50.INC: '[3]US&Europe'!#REF!
Name _DLX52.INC: #REF!
Name _DLX53.INC: '[3]US&Europe'!#REF!
Name _DLX54.INC: '[3]US&Europe'!#REF!
Name _DLX56.INC: '[3]US&Europe'!#REF!
Name _DLX6.INC: #REF!
Name _DLX60.INC: #REF!
Name _DLX7.INC: '[3]US&Europe'!#REF!
Name _DLX8.INC: '[3]US&Europe'!#REF!
Name _DLX80.INC: '[3]Bonds Data BIS'!#REF!
Name _DLX9.INC: '[3]US&Europe'!#REF!
Name AUD_Nom: #REF!
Name AUD_Tenor: #REF!
Name AUD_yr: #REF!
Name CAD_Nom: #REF!
Name CAD_Tenor: #REF!
Name CAD_yr: #REF!
Name CHF_Nom: #REF!
Name CHF_Tenor: #REF!
Name CHF_yr: #REF!
Name cn_asia: [4]Weights!$J$5
Name code: [5]CONSTANT!#REF!
Name Currency_cusip: '[6]Currency bucketing mapping'!$B$35:$B$160
Name Currency_name: '[6]Currency bucketing mapping'!$B$35:$BF$35
Name Currency_table: '[6]Currency bucketing mapping'!$B$35:$BF$160
Name D_0: #REF!
Name D_0_DE: #REF!
Name D_0_FR: #REF!
Name D_0_IT: #REF!
Name D_0_JP: #REF!
Name D_0_UK: #REF!
Name DaysInYear: [7]C!$B$29
Name DE_gwth: #REF!
Name DE_S: #REF!
Name ERP: [8]CF20!$C$18
Name EUR_Nom: #REF!
Name EUR_Tenor: #REF!
Name EUR_yr: #REF!
Name FR_gwth: #REF!
Name FR_S: #REF!
Name GBP_Nom: #REF!
Name GBP_Tenor: #REF!
Name GBP_yr: #REF!
Name gGDP: [8]CF20!$C$14
Name hk_asia: [4]Weights!$J$6
Name hk_nie: [4]Weights!$K$6

Sheet Front Page
B1: Description
B5: TOC Colour Coding
B6: Inputs
B7: Calculation
B8: Raw Report
B9: Raw Report with Key
B11: Table Colors
B12: Uploaded to Python
B13: Not Uploaded to Python
B16: Table of Contents
B17: Salary Model
B18: Model Parameters
... B29: Loop used when executing the python script

Sheet Salary Variables
B2: Inflation | C2: 0.02
B3: Salary Growth
B4: Salary Raise | C4: 0.03
B5: Real Salary Raise | C5: =C4-C2 -> 0.01
B6: Job Hopping "Bonus" | C6: 0.06
B7: Real Job Hopping "Bonus" | C7: =C6-C2 -> 0.04
B8: % of salary dedicated to investments | C8: 0.2
B9: Initial Salary P1 | C9: 43871
B10: Initial Salary P2 | C10: 72000
B11: Contribution to pension
B12: Personal | C12: 0.05
B13: Company | C13: 0.1
B14: Aldersopsparing maximum contribution | C14: 9400
B15: Tax
B16: AM (%) | C16: 0.08
B17: Personal Allowance | C17: 51600
B18: Bottom-Bracket State Tax rate (%) | C18: 0.1201
B19: Top-bracket State Tax rate (%) | C19: 0.15
B20: State Tax Bracket Threshold | C20: 618400
B21: Municipal Tax (%) | C21: 0.25
B22: Capital Gains < 67,500DKK | C22: 0.27
B23: Capital Gains > 67,500DKK | C23: 0.42
B24: Capital Gains Threshold | C24: 67500

Sheet Income - P2 Helper
B2: Inflation | C2: =Income!I2 -> 0.02 | G2: GrossMonthlyInflationAdjustedP2 | H2: GrossMonthlySalaryP2 | I2: SwitchP2 | J2: Inverse | K2: Year | M2: Year | N2: GrossMonthlyInflationAdjustedP2 | O2: GrossMonthlySalaryP2
B3: Salary Raise | C3: =Income!I3 -> 0.03 | G3: =TableIncomeCalculations11[[#This Row],[GrossMonthlySalaryP2]]/(1+C2) -> 72874.52 | H3: =TableIncomeCalculations[[#This Row],[GrossMonthlySalaryP2]] -> 74332.01 | I3: =JobHopping[[#This Row],[SwitchP2Static]] -> N | J3: {=INDEX($I$3:$I$18,ROWS($I$3:$I$18)+ROW($I$3)-ROW())} -> N | K3: 2025 | M3: {=INDEX($K$3:$K$18,ROWS($K$3:$K$18)+ROW($K$3)-ROW())} -> 2010 | N3: {=INDEX($G$3:$G$18,ROWS($G$3:$G$18)+ROW($G$3)-ROW())} -> 53225.047 | O3: {=INDEX($H$3:$H$18,ROWS($H$3:$H$18)+ROW($H$3)-ROW())} -> 36965.724 | Q3: =Table11[[#This Row],[GrossMonthlyInflationAdjustedP2]]*0.2 -> 10645.009
B4: Real Salary Raise | C4: =Income!I4 -> 0.01 | G4: =(G3/(1+$C$4))-IF(TableIncomeCalculations11[[#This Row],[Inverse]]="Y",G3*$C$6,0) -> 72152.99 | H4: =(H3/(1+$C$3))-IF(TableIncomeCalculations11[[#This Row],[Inverse]]="Y",H3*$C$5,0) -> 72167 | I4: =JobHopping[[#This Row],[SwitchP2Static]] -> N | J4: {=INDEX($I$3:$I$18,ROWS($I$3:$I$18)+ROW($I$3)-ROW())} -> N | K4: 2024 | M4: {=INDEX($K$3:$K$18,ROWS($K$3:$K$18)+ROW($K$3)-ROW())} -> 2011 | N4: {=INDEX($G$3:$G$18,ROWS($G$3:$G$18)+ROW($G$3)-ROW())} -> 53757.298 | O4: {=INDEX($H$3:$H$18,ROWS($H$3:$H$18)+ROW($H$3)-ROW())} -> 38074.696 | Q4: =Table11[[#This Row],[GrossMonthlyInflationAdjustedP2]]*0.2 -> 10751.46
B5: Job Hopping "Bonus" | C5: =Income!I5 -> 0.06 | G5: =(G4/(1+$C$4))-IF(TableIncomeCalculations11[[#This Row],[Inverse]]="Y",G4*$C$6,0) -> 68552.484 | H5: =(H4/(1+$C$3))-IF(TableIncomeCalculations11[[#This Row],[Inverse]]="Y",H4*$C$5,0) -> 65735.029 | I5: =JobHopping[[#This Row],[SwitchP2Static]] -> Y | J5: {=INDEX($I$3:$I$18,ROWS($I$3:$I$18)+ROW($I$3)-ROW())} -> Y | K5: 2023 | M5: {=INDEX($K$3:$K$18,ROWS($K$3:$K$18)+ROW($K$3)-ROW())} -> 2012 | N5: {=INDEX($G$3:$G$18,ROWS($G$3:$G$18)+ROW($G$3)-ROW())} -> 54294.871 | O5: {=INDEX($H$3:$H$18,ROWS($H$3:$H$18)+ROW($H$3)-ROW())} -> 39216.937 | Q5: =Table11[[#This Row],[GrossMonthlyInflationAdjustedP2]]*0.2 -> 10858.974
B6: Real Job Hopping "Bonus" | C6: =Income!I6 -> 0.04 | G6: =(G5/(1+$C$4))-IF(TableIncomeCalculations11[[#This Row],[Inverse]]="Y",G5*$C$6,0) -> 67873.747 | H6: =(H5/(1+$C$3))-IF(TableIncomeCalculations11[[#This Row],[Inverse]]="Y",H5*$C$5,0) -> 63820.416 | I6: =JobHopping[[#This Row],[SwitchP2Static]] -> N | J6: {=INDEX($I$3:$I$18,ROWS($I$3:$I$18)+ROW($I$3)-ROW())} -> N | K6: 2022 | M6: {=INDEX($K$3:$K$18,ROWS($K$3:$K$18)+ROW($K$3)-ROW())} -> 2013 | N6: {=INDEX($G$3:$G$18,ROWS($G$3:$G$18)+ROW($G$3)-ROW())} -> 57146.54 | O6: {=INDEX($H$3:$H$18,ROWS($H$3:$H$18)+ROW($H$3)-ROW())} -> 43054.194 | Q6: =Table11[[#This Row],[GrossMonthlyInflationAdjustedP2]]*0.2 -> 11429.308
B7: % of salary dedicated to investments | C7: =Income!I7 -> 0.2 | G7: =(G6/(1+$C$4))-IF(TableIncomeCalculations11[[#This Row],[Inverse]]="Y",G6*$C$6,0) -> 67201.729 | H7: =(H6/(1+$C$3))-IF(TableIncomeCalculations11[[#This Row],[Inverse]]="Y",H6*$C$5,0) -> 61961.569 | I7: =JobHopping[[#This Row],[SwitchP2Static]] -> N | J7: {=INDEX($I$3:$I$18,ROWS($I$3:$I$18)+ROW($I$3)-ROW())} -> N | K7: 2021 | M7: {=INDEX($K$3:$K$18,ROWS($K$3:$K$18)+ROW($K$3)-ROW())} -> 2014 | N7: {=INDEX($G$3:$G$18,ROWS($G$3:$G$18)+ROW($G$3)-ROW())} -> 57718.005 | O7: {=INDEX($H$3:$H$18,ROWS($H$3:$H$18)+ROW($H$3)-ROW())} -> 44345.82 | Q7: =Table11[[#This Row],[GrossMonthlyInflationAdjustedP2]]*0.2 -> 11543.601
G8: =(G7/(1+$C$4))-IF(TableIncomeCalculations11[[#This Row],[Inverse]]="Y",G7*$C$6,0) -> 63848.296 | H8: =(H7/(1+$C$3))-IF(TableIncomeCalculations11[[#This Row],[Inverse]]="Y",H7*$C$5,0) -> 56439.169 | I8: =JobHopping[[#This Row],[SwitchP2Static]] -> N | J8: {=INDEX($I$3:$I$18,ROWS($I$3:$I$18)+ROW($I$3)-ROW())} -> Y | K8: 2020 | M8: {=INDEX($K$3:$K$18,ROWS($K$3:$K$18)+ROW($K$3)-ROW())} -> 2015 | N8: {=INDEX($G$3:$G$18,ROWS($G$3:$G$18)+ROW($G$3)-ROW())} -> 58295.185 | O8: {=INDEX($H$3:$H$18,ROWS($H$3:$H$18)+ROW($H$3)-ROW())} -> 45676.195 | Q8: =Table11[[#This Row],[GrossMonthlyInflationAdjustedP2]]*0.2 -> 11659.037
G9: =(G8/(1+$C$4))-IF(TableIncomeCalculations11[[#This Row],[Inverse]]="Y",G8*$C$6,0) -> 63216.135 | H9: =(H8/(1+$C$3))-IF(TableIncomeCalculations11[[#This Row],[Inverse]]="Y",H8*$C$5,0) -> 54795.31 | I9: =JobHopping[[#This Row],[SwitchP2Static]] -> Y | J9: {=INDEX($I$3:$I$18,ROWS($I$3:$I$18)+ROW($I$3)-ROW())} -> N | K9: 2019 | M9: {=INDEX($K$3:$K$18,ROWS($K$3:$K$18)+ROW($K$3)-ROW())} -> 2016 | N9: {=INDEX($G$3:$G$18,ROWS($G$3:$G$18)+ROW($G$3)-ROW())} -> 58878.137 | O9: {=INDEX($H$3:$H$18,ROWS($H$3:$H$18)+ROW($H$3)-ROW())} -> 47046.481 | Q9: =Table11[[#This Row],[GrossMonthlyInflationAdjustedP2]]*0.2 -> 11775.627
G10: =(G9/(1+$C$4))-IF(TableIncomeCalculations11[[#This Row],[Inverse]]="Y",G9*$C$6,0) -> 62590.233 | H10: =(H9/(1+$C$3))-IF(TableIncomeCalculations11[[#This Row],[Inverse]]="Y",H9*$C$5,0) -> 53199.33 | I10: =JobHopping[[#This Row],[SwitchP2Static]] -> N | J10: {=INDEX($I$3:$I$18,ROWS($I$3:$I$18)+ROW($I$3)-ROW())} -> N | K10: 2018 | M10: {=INDEX($K$3:$K$18,ROWS($K$3:$K$18)+ROW($K$3)-ROW())} -> 2017 | N10: {=INDEX($G$3:$G$18,ROWS($G$3:$G$18)+ROW($G$3)-ROW())} -> 61970.528 | O10: {=INDEX($H$3:$H$18,ROWS($H$3:$H$18)+ROW($H$3)-ROW())} -> 51649.835 | Q10: =Table11[[#This Row],[GrossMonthlyInflationAdjustedP2]]*0.2 -> 12394.106
G11: =(G10/(1+$C$4))-IF(TableIncomeCalculations11[[#This Row],[Inverse]]="Y",G10*$C$6,0) -> 61970.528 | H11: =(H10/(1+$C$3))-IF(TableIncomeCalculations11[[#This Row],[Inverse]]="Y",H10*$C$5,0) -> 51649.835 | I11: =JobHopping[[#This Row],[SwitchP2Static]] -> N | J11: {=INDEX($I$3:$I$18,ROWS($I$3:$I$18)+ROW($I$3)-ROW())} -> N | K11: 2017 | M11: {=INDEX($K$3:$K$18,ROWS($K$3:$K$18)+ROW($K$3)-ROW())} -> 2018 | N11: {=INDEX($G$3:$G$18,ROWS($G$3:$G$18)+ROW($G$3)-ROW())} -> 62590.233 | O11: {=INDEX($H$3:$H$18,ROWS($H$3:$H$18)+ROW($H$3)-ROW())} -> 53199.33 | Q11: =Table11[[#This Row],[GrossMonthlyInflationAdjustedP2]]*0.2 -> 12518.047
G12: =(G11/(1+$C$4))-IF(TableIncomeCalculations11[[#This Row],[Inverse]]="Y",G11*$C$6,0) -> 58878.137 | H12: =(H11/(1+$C$3))-IF(TableIncomeCalculations11[[#This Row],[Inverse]]="Y",H11*$C$5,0) -> 47046.481 | I12: =JobHopping[[#This Row],[SwitchP2Static]] -> N | J12: {=INDEX($I$3:$I$18,ROWS($I$3:$I$18)+ROW($I$3)-ROW())} -> Y | K12: 2016 | M12: {=INDEX($K$3:$K$18,ROWS($K$3:$K$18)+ROW($K$3)-ROW())} -> 2019 | N12: {=INDEX($G$3:$G$18,ROWS($G$3:$G$18)+ROW($G$3)-ROW())} -> 63216.135 | O12: {=INDEX($H$3:$H$18,ROWS($H$3:$H$18)+ROW($H$3)-ROW())} -> 54795.31 | Q12: =Table11[[#This Row],[GrossMonthlyInflationAdjustedP2]]*0.2 -> 12643.227
G13: =(G12/(1+$C$4))-IF(TableIncomeCalculations11[[#This Row],[Inverse]]="Y",G12*$C$6,0) -> 58295.185 | H13: =(H12/(1+$C$3))-IF(TableIncomeCalculations11[[#This Row],[Inverse]]="Y",H12*$C$5,0) -> 45676.195 | I13: =JobHopping[[#This Row],[SwitchP2Static]] -> Y | J13: {=INDEX($I$3:$I$18,ROWS($I$3:$I$18)+ROW($I$3)-ROW())} -> N | K13: 2015 | M13: {=INDEX($K$3:$K$18,ROWS($K$3:$K$18)+ROW($K$3)-ROW())} -> 2020 | N13: {=INDEX($G$3:$G$18,ROWS($G$3:$G$18)+ROW($G$3)-ROW())} -> 63848.296 | O13: {=INDEX($H$3:$H$18,ROWS($H$3:$H$18)+ROW($H$3)-ROW())} -> 56439.169 | Q13: =Table11[[#This Row],[GrossMonthlyInflationAdjustedP2]]*0.2 -> 12769.659
G14: =(G13/(1+$C$4))-IF(TableIncomeCalculations11[[#This Row],[Inverse]]="Y",G13*$C$6,0) -> 57718.005 | H14: =(H13/(1+$C$3))-IF(TableIncomeCalculations11[[#This Row],[Inverse]]="Y",H13*$C$5,0) -> 44345.82 | I14: =JobHopping[[#This Row],[SwitchP2Static]] -> N | J14: {=INDEX($I$3:$I$18,ROWS($I$3:$I$18)+ROW($I$3)-ROW())} -> N | K14: 2014 | M14: {=INDEX($K$3:$K$18,ROWS($K$3:$K$18)+ROW($K$3)-ROW())} -> 2021 | N14: {=INDEX($G$3:$G$18,ROWS($G$3:$G$18)+ROW($G$3)-ROW())} -> 67201.729 | O14: {=INDEX($H$3:$H$18,ROWS($H$3:$H$18)+ROW($H$3)-ROW())} -> 61961.569 | Q14: =Table11[[#This Row],[GrossMonthlyInflationAdjustedP2]]*0.2 -> 13440.346
G15: =(G14/(1+$C$4))-IF(TableIncomeCalculations11[[#This Row],[Inverse]]="Y",G14*$C$6,0) -> 57146.54 | H15: =(H14/(1+$C$3))-IF(TableIncomeCalculations11[[#This Row],[Inverse]]="Y",H14*$C$5,0) -> 43054.194 | I15: =JobHopping[[#This Row],[SwitchP2Static]] -> N | J15: {=INDEX($I$3:$I$18,ROWS($I$3:$I$18)+ROW($I$3)-ROW())} -> N | K15: 2013 | M15: {=INDEX($K$3:$K$18,ROWS($K$3:$K$18)+ROW($K$3)-ROW())} -> 2022 | N15: {=INDEX($G$3:$G$18,ROWS($G$3:$G$18)+ROW($G$3)-ROW())} -> 67873.747 | O15: {=INDEX($H$3:$H$18,ROWS($H$3:$H$18)+ROW($H$3)-ROW())} -> 63820.416 | Q15: =Table11[[#This Row],[GrossMonthlyInflationAdjustedP2]]*0.2 -> 13574.749
G16: =(G15/(1+$C$4))-IF(TableIncomeCalculations11[[#This Row],[Inverse]]="Y",G15*$C$6,0) -> 54294.871 | H16: =(H15/(1+$C$3))-IF(TableIncomeCalculations11[[#This Row],[Inverse]]="Y",H15*$C$5,0) -> 39216.937 | I16: =JobHopping[[#This Row],[SwitchP2Static]] -> Y | J16: {=INDEX($I$3:$I$18,ROWS($I$3:$I$18)+ROW($I$3)-ROW())} -> Y | K16: 2012 | M16: {=INDEX($K$3:$K$18,ROWS($K$3:$K$18)+ROW($K$3)-ROW())} -> 2023 | N16: {=INDEX($G$3:$G$18,ROWS($G$3:$G$18)+ROW($G$3)-ROW())} -> 68552.484 | O16: {=INDEX($H$3:$H$18,ROWS($H$3:$H$18)+ROW($H$3)-ROW())} -> 65735.029 | Q16: =Table11[[#This Row],[GrossMonthlyInflationAdjustedP2]]*0.2 -> 13710.497
G17: =(G16/(1+$C$4))-IF(TableIncomeCalculations11[[#This Row],[Inverse]]="Y",G16*$C$6,0) -> 53757.298 | H17: =(H16/(1+$C$3))-IF(TableIncomeCalculations11[[#This Row],[Inverse]]="Y",H16*$C$5,0) -> 38074.696 | I17: =JobHopping[[#This Row],[SwitchP2Static]] -> N | J17: {=INDEX($I$3:$I$18,ROWS($I$3:$I$18)+ROW($I$3)-ROW())} -> N | K17: 2011 | M17: {=INDEX($K$3:$K$18,ROWS($K$3:$K$18)+ROW($K$3)-ROW())} -> 2024 | N17: {=INDEX($G$3:$G$18,ROWS($G$3:$G$18)+ROW($G$3)-ROW())} -> 72152.99 | O17: {=INDEX($H$3:$H$18,ROWS($H$3:$H$18)+ROW($H$3)-ROW())} -> 72167 | Q17: =Table11[[#This Row],[GrossMonthlyInflationAdjustedP2]]*0.2 -> 14430.598
G18: =(G17/(1+$C$4))-IF(TableIncomeCalculations11[[#This Row],[Inverse]]="Y",G17*$C$6,0) -> 53225.047 | H18: =(H17/(1+$C$3))-IF(TableIncomeCalculations11[[#This Row],[Inverse]]="Y",H17*$C$5,0) -> 36965.724 | I18: =JobHopping[[#This Row],[SwitchP2Static]] -> N | J18: {=INDEX($I$3:$I$18,ROWS($I$3:$I$18)+ROW($I$3)-ROW())} -> N | K18: 2010 | M18: {=INDEX($K$3:$K$18,ROWS($K$3:$K$18)+ROW($K$3)-ROW())} -> 2025 | N18: {=INDEX($G$3:$G$18,ROWS($G$3:$G$18)+ROW($G$3)-ROW())} -> 72874.52 | O18: {=INDEX($H$3:$H$18,ROWS($H$3:$H$18)+ROW($H$3)-ROW())} -> 74332.01 | Q18: =Table11[[#This Row],[GrossMonthlyInflationAdjustedP2]]*0.2 -> 14574.904
Q21: =SUM(Q3:Q18) -> 198719.15

Sheet Income
A1: Income!A1
B2: Year | C2: SalaryP1 | D2: SalaryP2 | E2: InvestmentP1 | F2: InvestmentP2 | H2: Inflation | I2: ='Salary Variables'!$C$2 -> 0.02 | K2: Post Investing | L2: Post Investing | M2: NetMonthlySalaryP1 | N2: NetMonthlySalaryP2 | O2: GrossMonthlyInflationAdjustedP1 | P2: GrossMonthlyInflationAdjustedP2 | Q2: GrossMonthlySalaryP1 | R2: GrossMonthlySalaryP2 | S2: SwitchP1 | T2: SwitchP2
B3: 2025 | C3: =(TableIncomeCalculations[[#This Row],[NetMonthlySalaryP1]]*12) -> 282968.57 | D3: =(TableIncomeCalculations[[#This Row],[NetMonthlySalaryP2]]*12) -> 463564.04 | E3: =TableIncome[[#This Row],[SalaryP1]]*$I$7 -> 56593.715 | F3: =TableIncome[[#This Row],[SalaryP2]]*$I$7 -> 92712.808 | H3: Salary Raise | I3: {='Salary Variables'!$C$4:$C$8} -> 0.03 | K3: =(TableIncome[[#This Row],[SalaryP1]]-TableIncome[[#This Row],[InvestmentP1]])/12 -> 18864.572 | L3: =(TableIncome[[#This Row],[SalaryP2]]-TableIncome[[#This Row],[InvestmentP2]])/12 -> 30904.269 | M3: ='Net Salary P1'!BI2 -> 23580.714 | N3: ='Net Salary P2'!BI2 -> 38630.337 | O3: =TableIncomeCalculations[[#This Row],[GrossMonthlySalaryP1]]/(1+I2) -> 43421.569 | P3: =TableIncomeCalculations[[#This Row],[GrossMonthlySalaryP2]]/(1+I2) -> 72874.52 | Q3: =43000*(1+I3) -> 44290 | R3: =72167*(1+I3) -> 74332.01 | S3: =JobHopping[[#This Row],[SwitchP1Static]] -> N | T3: =JobHopping[[#This Row],[SwitchP2Static]] -> N
B4: 2026 | C4: =(TableIncomeCalculations[[#This Row],[NetMonthlySalaryP1]]*12) -> 285837.17 | D4: =(TableIncomeCalculations[[#This Row],[NetMonthlySalaryP2]]*12) -> 467231.95 | E4: =TableIncome[[#This Row],[SalaryP1]]*$I$7 -> 57167.434 | F4: =TableIncome[[#This Row],[SalaryP2]]*$I$7 -> 93446.391 | H4: Real Salary Raise | I4: 0.01 | K4: =(TableIncome[[#This Row],[SalaryP1]]-TableIncome[[#This Row],[InvestmentP1]])/12 -> 19055.811 | L4: =(TableIncome[[#This Row],[SalaryP2]]-TableIncome[[#This Row],[InvestmentP2]])/12 -> 31148.797 | M4: ='Net Salary P1'!BI3 -> 23819.764 | N4: ='Net Salary P2'!BI3 -> 38935.996 | O4: =IF(_xlfn.XLOOKUP(TableIncome[[#This Row],[Year]],Loop!C:C,Loop!D:D)<75,(O3*(1+$I$4))+IF(TableIncomeCalculations[[#This Row],[SwitchP1]]="Y",O3*$I$6,0),0) -> 43855.784 | P4: =IF(_xlfn.XLOOKUP(TableIncome[[#This Row],[Year]],Loop!C:C,Loop!E:E)<75,(P3*(1+$I$4))+IF(TableIncomeCalculations[[#This Row],[SwitchP2]]="Y",P3*$I$6,0),0) -> 73603.265 | Q4: =IF(_xlfn.XLOOKUP(TableIncome[[#This Row],[Year]],Loop!C:C,Loop!D:D)<75,(Q3*(1+$I$3))+IF(TableIncomeCalculations[[#This Row],[SwitchP1]]="Y",Q3*$I$5,0),0) -> 45618.7 | R4: =IF(_xlfn.XLOOKUP(TableIncome[[#This Row],[Year]],Loop!C:C,Loop!E:E)<75,(R3*(1+$I$3))+IF(TableIncomeCalculations[[#This Row],[SwitchP2]]="Y",R3*$I$5,0),0) -> 76561.97 | S4: =JobHopping[[#This Row],[SwitchP1Static]] -> N | T4: =JobHopping[[#This Row],[SwitchP2Static]] -> N
B5: 2027 | C5: =(TableIncomeCalculations[[#This Row],[NetMonthlySalaryP1]]*12) -> 300323.6 | D5: =(TableIncomeCalculations[[#This Row],[NetMonthlySalaryP2]]*12) -> 485754.92 | E5: =TableIncome[[#This Row],[SalaryP1]]*$I$7 -> 60064.719 | F5: =TableIncome[[#This Row],[SalaryP2]]*$I$7 -> 97150.984 | H5: Job Hopping "Bonus" | I5: 0.06 | K5: =(TableIncome[[#This Row],[SalaryP1]]-TableIncome[[#This Row],[InvestmentP1]])/12 -> 20021.573 | L5: =(TableIncome[[#This Row],[SalaryP2]]-TableIncome[[#This Row],[InvestmentP2]])/12 -> 32383.661 | M5: ='Net Salary P1'!BI4 -> 25026.966 | N5: ='Net Salary P2'!BI4 -> 40479.577 | O5: =IF(_xlfn.XLOOKUP(TableIncome[[#This Row],[Year]],Loop!C:C,Loop!D:D)<75,(O4*(1+$I$4))+IF(TableIncomeCalculations[[#This Row],[SwitchP1]]="Y",O4*$I$6,0),0) -> 46048.574 | P5: =IF(_xlfn.XLOOKUP(TableIncome[[#This Row],[Year]],Loop!C:C,Loop!E:E)<75,(P4*(1+$I$4))+IF(TableIncomeCalculations[[#This Row],[SwitchP2]]="Y",P4*$I$6,0),0) -> 77283.428 | Q5: =IF(_xlfn.XLOOKUP(TableIncome[[#This Row],[Year]],Loop!C:C,Loop!D:D)<75,(Q4*(1+$I$3))+IF(TableIncomeCalculations[[#This Row],[SwitchP1]]="Y",Q4*$I$5,0),0) -> 49724.383 | R5: =IF(_xlfn.XLOOKUP(TableIncome[[#This Row],[Year]],Loop!C:C,Loop!E:E)<75,(R4*(1+$I$3))+IF(TableIncomeCalculations[[#This Row],[SwitchP2]]="Y",R4*$I$5,0),0) -> 83452.548 | S5: =JobHopping[[#This Row],[SwitchP1Static]] -> Y | T5: =JobHopping[[#This Row],[SwitchP2Static]] -> Y
B6: 2028 | C6: =(TableIncomeCalculations[[#This Row],[NetMonthlySalaryP1]]*12) -> 303365.74 | D6: =(TableIncomeCalculations[[#This Row],[NetMonthlySalaryP2]]*12) -> 489644.74 | E6: =TableIncome[[#This Row],[SalaryP1]]*$I$7 -> 60673.149 | F6: =TableIncome[[#This Row],[SalaryP2]]*$I$7 -> 97928.948 | H6: Real Job Hopping "Bonus" | I6: 0.04 | K6: =(TableIncome[[#This Row],[SalaryP1]]-TableIncome[[#This Row],[InvestmentP1]])/12 -> 20224.383 | L6: =(TableIncome[[#This Row],[SalaryP2]]-TableIncome[[#This Row],[InvestmentP2]])/12 -> 32642.983 | M6: ='Net Salary P1'!BI5 -> 25280.479 | N6: ='Net Salary P2'!BI5 -> 40803.728 | O6: =IF(_xlfn.XLOOKUP(TableIncome[[#This Row],[Year]],Loop!C:C,Loop!D:D)<75,(O5*(1+$I$4))+IF(TableIncomeCalculations[[#This Row],[SwitchP1]]="Y",O5*$I$6,0),0) -> 46509.059 | P6: =IF(_xlfn.XLOOKUP(TableIncome[[#This Row],[Year]],Loop!C:C,Loop!E:E)<75,(P5*(1+$I$4))+IF(TableIncomeCalculations[[#This Row],[SwitchP2]]="Y",P5*$I$6,0),0) -> 78056.262 | Q6: =IF(_xlfn.XLOOKUP(TableIncome[[#This Row],[Year]],Loop!C:C,Loop!D:D)<75,(Q5*(1+$I$3))+IF(TableIncomeCalculations[[#This Row],[SwitchP1]]="Y",Q5*$I$5,0),0) -> 51216.114 | R6: =IF(_xlfn.XLOOKUP(TableIncome[[#This Row],[Year]],Loop!C:C,Loop!E:E)<75,(R5*(1+$I$3))+IF(TableIncomeCalculations[[#This Row],[SwitchP2]]="Y",R5*$I$5,0),0) -> 85956.124 | S6: =JobHopping[[#This Row],[SwitchP1Static]] -> N | T6: =JobHopping[[#This Row],[SwitchP2Static]] -> N
B7: 2029 | C7: =(TableIncomeCalculations[[#This Row],[NetMonthlySalaryP1]]*12) -> 306438.31 | D7: =(TableIncomeCalculations[[#This Row],[NetMonthlySalaryP2]]*12) -> 493573.46 | E7: =TableIncome[[#This Row],[SalaryP1]]*$I$7 -> 61287.663 | F7: =TableIncome[[#This Row],[SalaryP2]]*$I$7 -> 98714.692 | H7: % of salary dedicated to investments | I7: 0.2 | K7: =(TableIncome[[#This Row],[SalaryP1]]-TableIncome[[#This Row],[InvestmentP1]])/12 -> 20429.221 | L7: =(TableIncome[[#This Row],[SalaryP2]]-TableIncome[[#This Row],[InvestmentP2]])/12 -> 32904.897 | M7: ='Net Salary P1'!BI6 -> 25536.526 | N7: ='Net Salary P2'!BI6 -> 41131.122 | O7: =IF(_xlfn.XLOOKUP(TableIncome[[#This Row],[Year]],Loop!C:C,Loop!D:D)<75,(O6*(1+$I$4))+IF(TableIncomeCalculations[[#This Row],[SwitchP1]]="Y",O6*$I$6,0),0) -> 46974.15 | P7: =IF(_xlfn.XLOOKUP(TableIncome[[#This Row],[Year]],Loop!C:C,Loop!E:E)<75,(P6*(1+$I$4))+IF(TableIncomeCalculations[[#This Row],[SwitchP2]]="Y",P6*$I$6,0),0) -> 78836.825 | Q7: =IF(_xlfn.XLOOKUP(TableIncome[[#This Row],[Year]],Loop!C:C,Loop!D:D)<75,(Q6*(1+$I$3))+IF(TableIncomeCalculations[[#This Row],[SwitchP1]]="Y",Q6*$I$5,0),0) -> 52752.598 | R7: =IF(_xlfn.XLOOKUP(TableIncome[[#This Row],[Year]],Loop!C:C,Loop!E:E)<75,(R6*(1+$I$3))+IF(TableIncomeCalculations[[#This Row],[SwitchP2]]="Y",R6*$I$5,0),0) -> 88534.808 | S7: =JobHopping[[#This Row],[SwitchP1Static]] -> N | T7: =JobHopping[[#This Row],[SwitchP2Static]] -> N
B8: 2030 | C8: =(TableIncomeCalculations[[#This Row],[NetMonthlySalaryP1]]*12) -> 309541.61 | D8: =(TableIncomeCalculations[[#This Row],[NetMonthlySalaryP2]]*12) -> 497541.47 | E8: =TableIncome[[#This Row],[SalaryP1]]*$I$7 -> 61908.322 | F8: =TableIncome[[#This Row],[SalaryP2]]*$I$7 -> 99508.294 | K8: =(TableIncome[[#This Row],[SalaryP1]]-TableIncome[[#This Row],[InvestmentP1]])/12 -> 20636.107 | L8: =(TableIncome[[#This Row],[SalaryP2]]-TableIncome[[#This Row],[InvestmentP2]])/12 -> 33169.431 | M8: ='Net Salary P1'!BI7 -> 25795.134 | N8: ='Net Salary P2'!BI7 -> 41461.789 | O8: =IF(_xlfn.XLOOKUP(TableIncome[[#This Row],[Year]],Loop!C:C,Loop!D:D)<75,(O7*(1+$I$4))+IF(TableIncomeCalculations[[#This Row],[SwitchP1]]="Y",O7*$I$6,0),0) -> 47443.891 | P8: =IF(_xlfn.XLOOKUP(TableIncome[[#This Row],[Year]],Loop!C:C,Loop!E:E)<75,(P7*(1+$I$4))+IF(TableIncomeCalculations[[#This Row],[SwitchP2]]="Y",P7*$I$6,0),0) -> 79625.193 | Q8: =IF(_xlfn.XLOOKUP(TableIncome[[#This Row],[Year]],Loop!C:C,Loop!D:D)<75,(Q7*(1+$I$3))+IF(TableIncomeCalculations[[#This Row],[SwitchP1]]="Y",Q7*$I$5,0),0) -> 54335.176 | R8: =IF(_xlfn.XLOOKUP(TableIncome[[#This Row],[Year]],Loop!C:C,Loop!E:E)<75,(R7*(1+$I$3))+IF(TableIncomeCalculations[[#This Row],[SwitchP2]]="Y",R7*$I$5,0),0) -> 91190.852 | S8: =JobHopping[[#This Row],[SwitchP1Static]] -> N | T8: =JobHopping[[#This Row],[SwitchP2Static]] -> N
B9: 2031 | C9: =(TableIncomeCalculations[[#This Row],[NetMonthlySalaryP1]]*12) -> 325213.26 | D9: =(TableIncomeCalculations[[#This Row],[NetMonthlySalaryP2]]*12) -> 517579.91 | E9: =TableIncome[[#This Row],[SalaryP1]]*$I$7 -> 65042.651 | F9: =TableIncome[[#This Row],[SalaryP2]]*$I$7 -> 103515.98 | K9: =(TableIncome[[#This Row],[SalaryP1]]-TableIncome[[#This Row],[InvestmentP1]])/12 -> 21680.884 | L9: =(TableIncome[[#This Row],[SalaryP2]]-TableIncome[[#This Row],[InvestmentP2]])/12 -> 34505.327 | M9: ='Net Salary P1'!BI8 -> 27101.105 | N9: ='Net Salary P2'!BI8 -> 43131.659 | O9: =IF(_xlfn.XLOOKUP(TableIncome[[#This Row],[Year]],Loop!C:C,Loop!D:D)<75,(O8*(1+$I$4))+IF(TableIncomeCalculations[[#This Row],[SwitchP1]]="Y",O8*$I$6,0),0) -> 49816.086 | P9: =IF(_xlfn.XLOOKUP(TableIncome[[#This Row],[Year]],Loop!C:C,Loop!E:E)<75,(P8*(1+$I$4))+IF(TableIncomeCalculations[[#This Row],[SwitchP2]]="Y",P8*$I$6,0),0) -> 83606.453 | Q9: =IF(_xlfn.XLOOKUP(TableIncome[[#This Row],[Year]],Loop!C:C,Loop!D:D)<75,(Q8*(1+$I$3))+IF(TableIncomeCalculations[[#This Row],[SwitchP1]]="Y",Q8*$I$5,0),0) -> 59225.342 | R9: =IF(_xlfn.XLOOKUP(TableIncome[[#This Row],[Year]],Loop!C:C,Loop!E:E)<75,(R8*(1+$I$3))+IF(TableIncomeCalculations[[#This Row],[SwitchP2]]="Y",R8*$I$5,0),0) -> 99398.029 | S9: =JobHopping[[#This Row],[SwitchP1Static]] -> Y | T9: =JobHopping[[#This Row],[SwitchP2Static]] -> Y
B10: 2032 | C10: =(TableIncomeCalculations[[#This Row],[NetMonthlySalaryP1]]*12) -> 328504.3 | D10: =(TableIncomeCalculations[[#This Row],[NetMonthlySalaryP2]]*12) -> 521787.98 | E10: =TableIncome[[#This Row],[SalaryP1]]*$I$7 -> 65700.86 | F10: =TableIncome[[#This Row],[SalaryP2]]*$I$7 -> 104357.6 | K10: =(TableIncome[[#This Row],[SalaryP1]]-TableIncome[[#This Row],[InvestmentP1]])/12 -> 21900.287 | L10: =(TableIncome[[#This Row],[SalaryP2]]-TableIncome[[#This Row],[InvestmentP2]])/12 -> 34785.866 | M10: ='Net Salary P1'!BI9 -> 27375.358 | N10: ='Net Salary P2'!BI9 -> 43482.332 | O10: =IF(_xlfn.XLOOKUP(TableIncome[[#This Row],[Year]],Loop!C:C,Loop!D:D)<75,(O9*(1+$I$4))+IF(TableIncomeCalculations[[#This Row],[SwitchP1]]="Y",O9*$I$6,0),0) -> 50314.247 | P10: =IF(_xlfn.XLOOKUP(TableIncome[[#This Row],[Year]],Loop!C:C,Loop!E:E)<75,(P9*(1+$I$4))+IF(TableIncomeCalculations[[#This Row],[SwitchP2]]="Y",P9*$I$6,0),0) -> 84442.517 | Q10: =IF(_xlfn.XLOOKUP(TableIncome[[#This Row],[Year]],Loop!C:C,Loop!D:D)<75,(Q9*(1+$I$3))+IF(TableIncomeCalculations[[#This Row],[SwitchP1]]="Y",Q9*$I$5,0),0) -> 61002.102 | R10: =IF(_xlfn.XLOOKUP(TableIncome[[#This Row],[Year]],Loop!C:C,Loop!E:E)<75,(R9*(1+$I$3))+IF(TableIncomeCalculations[[#This Row],[SwitchP2]]="Y",R9*$I$5,0),0) -> 102379.97 | S10: =JobHopping[[#This Row],[SwitchP1Static]] -> N | T10: =JobHopping[[#This Row],[SwitchP2Static]] -> N
B11: 2033 | C11: =(TableIncomeCalculations[[#This Row],[NetMonthlySalaryP1]]*12) -> 331828.26 | D11: =(TableIncomeCalculations[[#This Row],[NetMonthlySalaryP2]]*12) -> 526038.14 | E11: =TableIncome[[#This Row],[SalaryP1]]*$I$7 -> 66365.652 | F11: =TableIncome[[#This Row],[SalaryP2]]*$I$7 -> 105207.63 | K11: =(TableIncome[[#This Row],[SalaryP1]]-TableIncome[[#This Row],[InvestmentP1]])/12 -> 22121.884 | L11: =(TableIncome[[#This Row],[SalaryP2]]-TableIncome[[#This Row],[InvestmentP2]])/12 -> 35069.209 | M11: ='Net Salary P1'!BI10 -> 27652.355 | N11: ='Net Salary P2'!BI10 -> 43836.511 | O11: =IF(_xlfn.XLOOKUP(TableIncome[[#This Row],[Year]],Loop!C:C,Loop!D:D)<75,(O10*(1+$I$4))+IF(TableIncomeCalculations[[#This Row],[SwitchP1]]="Y",O10*$I$6,0),0) -> 50817.389 | P11: =IF(_xlfn.XLOOKUP(TableIncome[[#This Row],[Year]],Loop!C:C,Loop!E:E)<75,(P10*(1+$I$4))+IF(TableIncomeCalculations[[#This Row],[SwitchP2]]="Y",P10*$I$6,0),0) -> 85286.943 | Q11: =IF(_xlfn.XLOOKUP(TableIncome[[#This Row],[Year]],Loop!C:C,Loop!D:D)<75,(Q10*(1+$I$3))+IF(TableIncomeCalculations[[#This Row],[SwitchP1]]="Y",Q10*$I$5,0),0) -> 62832.165 | R11: =IF(_xlfn.XLOOKUP(TableIncome[[#This Row],[Year]],Loop!C:C,Loop!E:E)<75,(R10*(1+$I$3))+IF(TableIncomeCalculations[[#This Row],[SwitchP2]]="Y",R10*$I$5,0),0) -> 105451.37 | S11: =JobHopping[[#This Row],[SwitchP1Static]] -> N | T11: =JobHopping[[#This Row],[SwitchP2Static]] -> N
B12: 2034 | C12: =(TableIncomeCalculations[[#This Row],[NetMonthlySalaryP1]]*12) -> 335185.45 | D12: =(TableIncomeCalculations[[#This Row],[NetMonthlySalaryP2]]*12) -> 530330.79 | E12: =TableIncome[[#This Row],[SalaryP1]]*$I$7 -> 67037.091 | F12: =TableIncome[[#This Row],[SalaryP2]]*$I$7 -> 106066.16 | K12: =(TableIncome[[#This Row],[SalaryP1]]-TableIncome[[#This Row],[InvestmentP1]])/12 -> 22345.697 | L12: =(TableIncome[[#This Row],[SalaryP2]]-TableIncome[[#This Row],[InvestmentP2]])/12 -> 35355.386 | M12: ='Net Salary P1'!BI11 -> 27932.121 | N12: ='Net Salary P2'!BI11 -> 44194.233 | O12: =IF(_xlfn.XLOOKUP(TableIncome[[#This Row],[Year]],Loop!C:C,Loop!D:D)<75,(O11*(1+$I$4))+IF(TableIncomeCalculations[[#This Row],[SwitchP1]]="Y",O11*$I$6,0),0) -> 51325.563 | P12: =IF(_xlfn.XLOOKUP(TableIncome[[#This Row],[Year]],Loop!C:C,Loop!E:E)<75,(P11*(1+$I$4))+IF(TableIncomeCalculations[[#This Row],[SwitchP2]]="Y",P11*$I$6,0),0) -> 86139.812 | Q12: =IF(_xlfn.XLOOKUP(TableIncome[[#This Row],[Year]],Loop!C:C,Loop!D:D)<75,(Q11*(1+$I$3))+IF(TableIncomeCalculations[[#This Row],[SwitchP1]]="Y",Q11*$I$5,0),0) -> 64717.13 | R12: =IF(_xlfn.XLOOKUP(TableIncome[[#This Row],[Year]],Loop!C:C,Loop!E:E)<75,(R11*(1+$I$3))+IF(TableIncomeCalculations[[#This Row],[SwitchP2]]="Y",R11*$I$5,0),0) -> 108614.91 | S12: =JobHopping[[#This Row],[SwitchP1Static]] -> N | T12: =JobHopping[[#This Row],[SwitchP2Static]] -> N
B13: 2035 | C13: =(TableIncomeCalculations[[#This Row],[NetMonthlySalaryP1]]*12) -> 352139.29 | D13: =(TableIncomeCalculations[[#This Row],[NetMonthlySalaryP2]]*12) -> 552008.7 | E13: =TableIncome[[#This Row],[SalaryP1]]*$I$7 -> 70427.858 | F13: =TableIncome[[#This Row],[SalaryP2]]*$I$7 -> 110401.74 | K13: =(TableIncome[[#This Row],[SalaryP1]]-TableIncome[[#This Row],[InvestmentP1]])/12 -> 23475.953 | L13: =(TableIncome[[#This Row],[SalaryP2]]-TableIncome[[#This Row],[InvestmentP2]])/12 -> 36800.58 | M13: ='Net Salary P1'!BI12 -> 29344.941 | N13: ='Net Salary P2'!BI12 -> 46000.725 | O13: =IF(_xlfn.XLOOKUP(TableIncome[[#This Row],[Year]],Loop!C:C,Loop!D:D)<75,(O12*(1+$I$4))+IF(TableIncomeCalculations[[#This Row],[SwitchP1]]="Y",O12*$I$6,0),0) -> 53891.841 | P13: =IF(_xlfn.XLOOKUP(TableIncome[[#This Row],[Year]],Loop!C:C,Loop!E:E)<75,(P12*(1+$I$4))+IF(TableIncomeCalculations[[#This Row],[SwitchP2]]="Y",P12*$I$6,0),0) -> 90446.803 | Q13: =IF(_xlfn.XLOOKUP(TableIncome[[#This Row],[Year]],Loop!C:C,Loop!D:D)<75,(Q12*(1+$I$3))+IF(TableIncomeCalculations[[#This Row],[SwitchP1]]="Y",Q12*$I$5,0),0) -> 70541.672 | R13: =IF(_xlfn.XLOOKUP(TableIncome[[#This Row],[Year]],Loop!C:C,Loop!E:E)<75,(R12*(1+$I$3))+IF(TableIncomeCalculations[[#This Row],[SwitchP2]]="Y",R12*$I$5,0),0) -> 118390.25 | S13: =JobHopping[[#This Row],[SwitchP1Static]] -> Y | T13: =JobHopping[[#This Row],[SwitchP2Static]] -> Y
B14: 2036 | C14: =(TableIncomeCalculations[[#This Row],[NetMonthlySalaryP1]]*12) -> 355699.6 | D14: =(TableIncomeCalculations[[#This Row],[NetMonthlySalaryP2]]*12) -> 556561.06 | E14: =TableIncome[[#This Row],[SalaryP1]]*$I$7 -> 71139.919 | F14: =TableIncome[[#This Row],[SalaryP2]]*$I$7 -> 111312.21 | K14: =(TableIncome[[#This Row],[SalaryP1]]-TableIncome[[#This Row],[InvestmentP1]])/12 -> 23713.306 | L14: =(TableIncome[[#This Row],[SalaryP2]]-TableIncome[[#This Row],[InvestmentP2]])/12 -> 37104.071 | M14: ='Net Salary P1'!BI13 -> 29641.633 | N14: ='Net Salary P2'!BI13 -> 46380.088 | O14: =IF(_xlfn.XLOOKUP(TableIncome[[#This Row],[Year]],Loop!C:C,Loop!D:D)<75,(O13*(1+$I$4))+IF(TableIncomeCalculations[[#This Row],[SwitchP1]]="Y",O13*$I$6,0),0) -> 54430.76 | P14: =IF(_xlfn.XLOOKUP(TableIncome[[#This Row],[Year]],Loop!C:C,Loop!E:E)<75,(P13*(1+$I$4))+IF(TableIncomeCalculations[[#This Row],[SwitchP2]]="Y",P13*$I$6,0),0) -> 91351.271 | Q14: =IF(_xlfn.XLOOKUP(TableIncome[[#This Row],[Year]],Loop!C:C,Loop!D:D)<75,(Q13*(1+$I$3))+IF(TableIncomeCalculations[[#This Row],[SwitchP1]]="Y",Q13*$I$5,0),0) -> 72657.922 | R14: =IF(_xlfn.XLOOKUP(TableIncome[[#This Row],[Year]],Loop!C:C,Loop!E:E)<75,(R13*(1+$I$3))+IF(TableIncomeCalculations[[#This Row],[SwitchP2]]="Y",R13*$I$5,0),0) -> 121941.96 | S14: =JobHopping[[#This Row],[SwitchP1Static]] -> N | T14: =JobHopping[[#This Row],[SwitchP2Static]] -> N
B15: 2037 | C15: =(TableIncomeCalculations[[#This Row],[NetMonthlySalaryP1]]*12) -> 359295.51 | D15: =(TableIncomeCalculations[[#This Row],[NetMonthlySalaryP2]]*12) -> 561158.94 | E15: =TableIncome[[#This Row],[SalaryP1]]*$I$7 -> 71859.101 | F15: =TableIncome[[#This Row],[SalaryP2]]*$I$7 -> 112231.79 | K15: =(TableIncome[[#This Row],[SalaryP1]]-TableIncome[[#This Row],[InvestmentP1]])/12 -> 23953.034 | L15: =(TableIncome[[#This Row],[SalaryP2]]-TableIncome[[#This Row],[InvestmentP2]])/12 -> 37410.596 | M15: ='Net Salary P1'!BI14 -> 29941.292 | N15: ='Net Salary P2'!BI14 -> 46763.245 | O15: =IF(_xlfn.XLOOKUP(TableIncome[[#This Row],[Year]],Loop!C:C,Loop!D:D)<75,(O14*(1+$I$4))+IF(TableIncomeCalculations[[#This Row],[SwitchP1]]="Y",O14*$I$6,0),0) -> 54975.067 | P15: =IF(_xlfn.XLOOKUP(TableIncome[[#This Row],[Year]],Loop!C:C,Loop!E:E)<75,(P14*(1+$I$4))+IF(TableIncomeCalculations[[#This Row],[SwitchP2]]="Y",P14*$I$6,0),0) -> 92264.783 | Q15: =IF(_xlfn.XLOOKUP(TableIncome[[#This Row],[Year]],Loop!C:C,Loop!D:D)<75,(Q14*(1+$I$3))+IF(TableIncomeCalculations[[#This Row],[SwitchP1]]="Y",Q14*$I$5,0),0) -> 74837.659 | R15: =IF(_xlfn.XLOOKUP(TableIncome[[#This Row],[Year]],Loop!C:C,Loop!E:E)<75,(R14*(1+$I$3))+IF(TableIncomeCalculations[[#This Row],[SwitchP2]]="Y",R14*$I$5,0),0) -> 125600.22 | S15: =JobHopping[[#This Row],[SwitchP1Static]] -> N | T15: =JobHopping[[#This Row],[SwitchP2Static]] -> N
B16: 2038 | C16: =(TableIncomeCalculations[[#This Row],[NetMonthlySalaryP1]]*12) -> 377454.85 | D16: =(TableIncomeCalculations[[#This Row],[NetMonthlySalaryP2]]*12) -> 584378.26 | E16: =TableIncome[[#This Row],[SalaryP1]]*$I$7 -> 75490.969 | F16: =TableIncome[[#This Row],[SalaryP2]]*$I$7 -> 116875.65 | K16: =(TableIncome[[#This Row],[SalaryP1]]-TableIncome[[#This Row],[InvestmentP1]])/12 -> 25163.656 | L16: =(TableIncome[[#This Row],[SalaryP2]]-TableIncome[[#This Row],[InvestmentP2]])/12 -> 38958.551 | M16: ='Net Salary P1'!BI15 -> 31454.57 | N16: ='Net Salary P2'!BI15 -> 48698.188 | O16: =IF(_xlfn.XLOOKUP(TableIncome[[#This Row],[Year]],Loop!C:C,Loop!D:D)<75,(O15*(1+$I$4))+IF(TableIncomeCalculations[[#This Row],[SwitchP1]]="Y",O15*$I$6,0),0) -> 57723.821 | P16: =IF(_xlfn.XLOOKUP(TableIncome[[#This Row],[Year]],Loop!C:C,Loop!E:E)<75,(P15*(1+$I$4))+IF(TableIncomeCalculations[[#This Row],[SwitchP2]]="Y",P15*$I$6,0),0) -> 96878.022 | Q16: =IF(_xlfn.XLOOKUP(TableIncome[[#This Row],[Year]],Loop!C:C,Loop!D:D)<75,(Q15*(1+$I$3))+IF(TableIncomeCalculations[[#This Row],[SwitchP1]]="Y",Q15*$I$5,0),0) -> 81573.049 | R16: =IF(_xlfn.XLOOKUP(TableIncome[[#This Row],[Year]],Loop!C:C,Loop!E:E)<75,(R15*(1+$I$3))+IF(TableIncomeCalculations[[#This Row],[SwitchP2]]="Y",R15*$I$5,0),0) -> 136904.24 | S16: =JobHopping[[#This Row],[SwitchP1Static]] -> Y | T16: =JobHopping[[#This Row],[SwitchP2Static]] -> Y
B17: 2039 | C17: =(TableIncomeCalculations[[#This Row],[NetMonthlySalaryP1]]*12) -> 381268.31 | D17: =(TableIncomeCalculations[[#This Row],[NetMonthlySalaryP2]]*12) -> 589254.31 | E17: =TableIncome[[#This Row],[SalaryP1]]*$I$7 -> 76253.661 | F17: =TableIncome[[#This Row],[SalaryP2]]*$I$7 -> 117850.86 | K17: =(TableIncome[[#This Row],[SalaryP1]]-TableIncome[[#This Row],[InvestmentP1]])/12 -> 25417.887 | L17: =(TableIncome[[#This Row],[SalaryP2]]-TableIncome[[#This Row],[InvestmentP2]])/12 -> 39283.621 | M17: ='Net Salary P1'!BI16 -> 31772.359 | N17: ='Net Salary P2'!BI16 -> 49104.526 | O17: =IF(_xlfn.XLOOKUP(TableIncome[[#This Row],[Year]],Loop!C:C,Loop!D:D)<75,(O16*(1+$I$4))+IF(TableIncomeCalculations[[#This Row],[SwitchP1]]="Y",O16*$I$6,0),0) -> 58301.059 | P17: =IF(_xlfn.XLOOKUP(TableIncome[[#This Row],[Year]],Loop!C:C,Loop!E:E)<75,(P16*(1+$I$4))+IF(TableIncomeCalculations[[#This Row],[SwitchP2]]="Y",P16*$I$6,0),0) -> 97846.803 | Q17: =IF(_xlfn.XLOOKUP(TableIncome[[#This Row],[Year]],Loop!C:C,Loop!D:D)<75,(Q16*(1+$I$3))+IF(TableIncomeCalculations[[#This Row],[SwitchP1]]="Y",Q16*$I$5,0),0) -> 84020.24 | R17: =IF(_xlfn.XLOOKUP(TableIncome[[#This Row],[Year]],Loop!C:C,Loop!E:E)<75,(R16*(1+$I$3))+IF(TableIncomeCalculations[[#This Row],[SwitchP2]]="Y",R16*$I$5,0),0) -> 141011.36 | S17: =JobHopping[[#This Row],[SwitchP1Static]] -> N | T17: =JobHopping[[#This Row],[SwitchP2Static]] -> N
B18: 2040 | C18: =(TableIncomeCalculations[[#This Row],[NetMonthlySalaryP1]]*12) -> 385119.9 | D18: =(TableIncomeCalculations[[#This Row],[NetMonthlySalaryP2]]*12) -> 594179.13 | E18: =TableIncome[[#This Row],[SalaryP1]]*$I$7 -> 77023.981 | F18: =TableIncome[[#This Row],[SalaryP2]]*$I$7 -> 118835.83 | K18: =(TableIncome[[#This Row],[SalaryP1]]-TableIncome[[#This Row],[InvestmentP1]])/12 -> 25674.66 | L18: =(TableIncome[[#This Row],[SalaryP2]]-TableIncome[[#This Row],[InvestmentP2]])/12 -> 39611.942 | M18: ='Net Salary P1'!BI17 -> 32093.325 | N18: ='Net Salary P2'!BI17 -> 49514.928 | O18: =IF(_xlfn.XLOOKUP(TableIncome[[#This Row],[Year]],Loop!C:C,Loop!D:D)<75,(O17*(1+$I$4))+IF(TableIncomeCalculations[[#This Row],[SwitchP1]]="Y",O17*$I$6,0),0) -> 58884.069 | P18: =IF(_xlfn.XLOOKUP(TableIncome[[#This Row],[Year]],Loop!C:C,Loop!E:E)<75,(P17*(1+$I$4))+IF(TableIncomeCalculations[[#This Row],[SwitchP2]]="Y",P17*$I$6,0),0) -> 98825.271 | Q18: =IF(_xlfn.XLOOKUP(TableIncome[[#This Row],[Year]],Loop!C:C,Loop!D:D)<75,(Q17*(1+$I$3))+IF(TableIncomeCalculations[[#This Row],[SwitchP1]]="Y",Q17*$I$5,0),0) -> 86540.847 | R18: =IF(_xlfn.XLOOKUP(TableIncome[[#This Row],[Year]],Loop!C:C,Loop!E:E)<75,(R17*(1+$I$3))+IF(TableIncomeCalculations[[#This Row],[SwitchP2]]="Y",R17*$I$5,0),0) -> 145241.71 | S18: =JobHopping[[#This Row],[SwitchP1Static]] -> N | T18: =JobHopping[[#This Row],[SwitchP2Static]] -> N
B19: 2041 | C19: =(TableIncomeCalculations[[#This Row],[NetMonthlySalaryP1]]*12) -> 389010.01 | D19: =(TableIncomeCalculations[[#This Row],[NetMonthlySalaryP2]]*12) -> 599153.2 | E19: =TableIncome[[#This Row],[SalaryP1]]*$I$7 -> 77802.003 | F19: =TableIncome[[#This Row],[SalaryP2]]*$I$7 -> 119830.64 | K19: =(TableIncome[[#This Row],[SalaryP1]]-TableIncome[[#This Row],[InvestmentP1]])/12 -> 25934.001 | L19: =(TableIncome[[#This Row],[SalaryP2]]-TableIncome[[#This Row],[InvestmentP2]])/12 -> 39943.546 | M19: ='Net Salary P1'!BI18 -> 32417.501 | N19: ='Net Salary P2'!BI18 -> 49929.433 | O19: =IF(_xlfn.XLOOKUP(TableIncome[[#This Row],[Year]],Loop!C:C,Loop!D:D)<75,(O18*(1+$I$4))+IF(TableIncomeCalculations[[#This Row],[SwitchP1]]="Y",O18*$I$6,0),0) -> 59472.91 | P19: =IF(_xlfn.XLOOKUP(TableIncome[[#This Row],[Year]],Loop!C:C,Loop!E:E)<75,(P18*(1+$I$4))+IF(TableIncomeCalculations[[#This Row],[SwitchP2]]="Y",P18*$I$6,0),0) -> 99813.523 | Q19: =IF(_xlfn.XLOOKUP(TableIncome[[#This Row],[Year]],Loop!C:C,Loop!D:D)<75,(Q18*(1+$I$3))+IF(TableIncomeCalculations[[#This Row],[SwitchP1]]="Y",Q18*$I$5,0),0) -> 89137.073 | R19: =IF(_xlfn.XLOOKUP(TableIncome[[#This Row],[Year]],Loop!C:C,Loop!E:E)<75,(R18*(1+$I$3))+IF(TableIncomeCalculations[[#This Row],[SwitchP2]]="Y",R18*$I$5,0),0) -> 149598.96 | S19: =JobHopping[[#This Row],[SwitchP1Static]] -> N | T19: =JobHopping[[#This Row],[SwitchP2Static]] -> N
... B48: 2070 | C48: =(TableIncomeCalculations[[#This Row],[NetMonthlySalaryP1]]*12) -> 545607.15 | D48: =(TableIncomeCalculations[[#This Row],[NetMonthlySalaryP2]]*12) -> 0 | E48: =TableIncome[[#This Row],[SalaryP1]]*$I$7 -> 109121.43 | F48: =TableIncome[[#This Row],[SalaryP2]]*$I$7 -> 0 | K48: =(TableIncome[[#This Row],[SalaryP1]]-TableIncome[[#This Row],[InvestmentP1]])/12 -> 36373.81 | L48: =(TableIncome[[#This Row],[SalaryP2]]-TableIncome[[#This Row],[InvestmentP2]])/12 -> 0 | M48: ='Net Salary P1'!BI47 -> 45467.263 | N48: ='Net Salary P2'!BI47 -> 0 | O48: =IF(_xlfn.XLOOKUP(TableIncome[[#This Row],[Year]],Loop!C:C,Loop!D:D)<75,(O47*(1+$I$4))+IF(TableIncomeCalculations[[#This Row],[SwitchP1]]="Y",O47*$I$6,0),0) -> 89174.936 | P48: =IF(_xlfn.XLOOKUP(TableIncome[[#This Row],[Year]],Loop!C:C,Loop!E:E)<75,(P47*(1+$I$4))+IF(TableIncomeCalculations[[#This Row],[SwitchP2]]="Y",P47*$I$6,0),0) -> 0 | Q48: =IF(_xlfn.XLOOKUP(TableIncome[[#This Row],[Year]],Loop!C:C,Loop!D:D)<75,(Q47*(1+$I$3))+IF(TableIncomeCalculations[[#This Row],[SwitchP1]]="Y",Q47*$I$5,0),0) -> 248946.32 | R48: =IF(_xlfn.XLOOKUP(TableIncome[[#This Row],[Year]],Loop!C:C,Loop!E:E)<75,(R47*(1+$I$3))+IF(TableIncomeCalculations[[#This Row],[SwitchP2]]="Y",R47*$I$5,0),0) -> 0 | S48: =JobHopping[[#This Row],[SwitchP1Static]] -> N | T48: =JobHopping[[#This Row],[SwitchP2Static]] -> N
B49: 2071 | C49: =(TableIncomeCalculations[[#This Row],[NetMonthlySalaryP1]]*12) -> 550095.5 | D49: =(TableIncomeCalculations[[#This Row],[NetMonthlySalaryP2]]*12) -> 0 | E49: =TableIncome[[#This Row],[SalaryP1]]*$I$7 -> 110019.1 | F49: =TableIncome[[#This Row],[SalaryP2]]*$I$7 -> 0 | K49: =(TableIncome[[#This Row],[SalaryP1]]-TableIncome[[#This Row],[InvestmentP1]])/12 -> 36673.033 | L49: =(TableIncome[[#This Row],[SalaryP2]]-TableIncome[[#This Row],[InvestmentP2]])/12 -> 0 | M49: ='Net Salary P1'!BI48 -> 45841.291 | N49: ='Net Salary P2'!BI48 -> 0 | O49: =IF(_xlfn.XLOOKUP(TableIncome[[#This Row],[Year]],Loop!C:C,Loop!D:D)<75,(O48*(1+$I$4))+IF(TableIncomeCalculations[[#This Row],[SwitchP1]]="Y",O48*$I$6,0),0) -> 90066.685 | P49: =IF(_xlfn.XLOOKUP(TableIncome[[#This Row],[Year]],Loop!C:C,Loop!E:E)<75,(P48*(1+$I$4))+IF(TableIncomeCalculations[[#This Row],[SwitchP2]]="Y",P48*$I$6,0),0) -> 0 | Q49: =IF(_xlfn.XLOOKUP(TableIncome[[#This Row],[Year]],Loop!C:C,Loop!D:D)<75,(Q48*(1+$I$3))+IF(TableIncomeCalculations[[#This Row],[SwitchP1]]="Y",Q48*$I$5,0),0) -> 256414.71 | S49: =JobHopping[[#This Row],[SwitchP1Static]] -> N | T49: =JobHopping[[#This Row],[SwitchP2Static]] -> N
B50: 2072 | C50: =(TableIncomeCalculations[[#This Row],[NetMonthlySalaryP1]]*12) -> 554628.72 | D50: =(TableIncomeCalculations[[#This Row],[NetMonthlySalaryP2]]*12) -> 0 | E50: =TableIncome[[#This Row],[SalaryP1]]*$I$7 -> 110925.74 | F50: =TableIncome[[#This Row],[SalaryP2]]*$I$7 -> 0 | K50: =(TableIncome[[#This Row],[SalaryP1]]-TableIncome[[#This Row],[InvestmentP1]])/12 -> 36975.248 | L50: =(TableIncome[[#This Row],[SalaryP2]]-TableIncome[[#This Row],[InvestmentP2]])/12 -> 0 | M50: ='Net Salary P1'!BI49 -> 46219.06 | N50: ='Net Salary P2'!BI49 -> 0 | O50: =IF(_xlfn.XLOOKUP(TableIncome[[#This Row],[Year]],Loop!C:C,Loop!D:D)<75,(O49*(1+$I$4))+IF(TableIncomeCalculations[[#This Row],[SwitchP1]]="Y",O49*$I$6,0),0) -> 90967.352 | P50: =IF(_xlfn.XLOOKUP(TableIncome[[#This Row],[Year]],Loop!C:C,Loop!E:E)<75,(P49*(1+$I$4))+IF(TableIncomeCalculations[[#This Row],[SwitchP2]]="Y",P49*$I$6,0),0) -> 0 | Q50: =IF(_xlfn.XLOOKUP(TableIncome[[#This Row],[Year]],Loop!C:C,Loop!D:D)<75,(Q49*(1+$I$3))+IF(TableIncomeCalculations[[#This Row],[SwitchP1]]="Y",Q49*$I$5,0),0) -> 264107.15 | S50: =JobHopping[[#This Row],[SwitchP1Static]] -> N | T50: =JobHopping[[#This Row],[SwitchP2Static]] -> N
B51: 2073 | C51: =(TableIncomeCalculations[[#This Row],[NetMonthlySalaryP1]]*12) -> 559207.29 | D51: =(TableIncomeCalculations[[#This Row],[NetMonthlySalaryP2]]*12) -> 0 | E51: =TableIncome[[#This Row],[SalaryP1]]*$I$7 -> 111841.46 | F51: =TableIncome[[#This Row],[SalaryP2]]*$I$7 -> 0 | K51: =(TableIncome[[#This Row],[SalaryP1]]-TableIncome[[#This Row],[InvestmentP1]])/12 -> 37280.486 | L51: =(TableIncome[[#This Row],[SalaryP2]]-TableIncome[[#This Row],[InvestmentP2]])/12 -> 0 | M51: ='Net Salary P1'!BI50 -> 46600.607 | N51: ='Net Salary P2'!BI50 -> 0 | O51: =IF(_xlfn.XLOOKUP(TableIncome[[#This Row],[Year]],Loop!C:C,Loop!D:D)<75,(O50*(1+$I$4))+IF(TableIncomeCalculations[[#This Row],[SwitchP1]]="Y",O50*$I$6,0),0) -> 91877.026 | P51: =IF(_xlfn.XLOOKUP(TableIncome[[#This Row],[Year]],Loop!C:C,Loop!E:E)<75,(P50*(1+$I$4))+IF(TableIncomeCalculations[[#This Row],[SwitchP2]]="Y",P50*$I$6,0),0) -> 0 | Q51: =IF(_xlfn.XLOOKUP(TableIncome[[#This Row],[Year]],Loop!C:C,Loop!D:D)<75,(Q50*(1+$I$3))+IF(TableIncomeCalculations[[#This Row],[SwitchP1]]="Y",Q50*$I$5,0),0) -> 272030.36 | S51: =JobHopping[[#This Row],[SwitchP1Static]] -> N | T51: =JobHopping[[#This Row],[SwitchP2Static]] -> N
B52: 2074 | C52: =(TableIncomeCalculations[[#This Row],[NetMonthlySalaryP1]]*12) -> 563831.63 | D52: =(TableIncomeCalculations[[#This Row],[NetMonthlySalaryP2]]*12) -> 0 | E52: =TableIncome[[#This Row],[SalaryP1]]*$I$7 -> 112766.33 | F52: =TableIncome[[#This Row],[SalaryP2]]*$I$7 -> 0 | K52: =(TableIncome[[#This Row],[SalaryP1]]-TableIncome[[#This Row],[InvestmentP1]])/12 -> 37588.775 | L52: =(TableIncome[[#This Row],[SalaryP2]]-TableIncome[[#This Row],[InvestmentP2]])/12 -> 0 | M52: ='Net Salary P1'!BI51 -> 46985.969 | N52: ='Net Salary P2'!BI51 -> 0 | O52: =IF(_xlfn.XLOOKUP(TableIncome[[#This Row],[Year]],Loop!C:C,Loop!D:D)<75,(O51*(1+$I$4))+IF(TableIncomeCalculations[[#This Row],[SwitchP1]]="Y",O51*$I$6,0),0) -> 92795.796 | P52: =IF(_xlfn.XLOOKUP(TableIncome[[#This Row],[Year]],Loop!C:C,Loop!E:E)<75,(P51*(1+$I$4))+IF(TableIncomeCalculations[[#This Row],[SwitchP2]]="Y",P51*$I$6,0),0) -> 0 | Q52: =IF(_xlfn.XLOOKUP(TableIncome[[#This Row],[Year]],Loop!C:C,Loop!D:D)<75,(Q51*(1+$I$3))+IF(TableIncomeCalculations[[#This Row],[SwitchP1]]="Y",Q51*$I$5,0),0) -> 280191.27 | S52: =JobHopping[[#This Row],[SwitchP1Static]] -> N | T52: =JobHopping[[#This Row],[SwitchP2Static]] -> N
B53: 2075 | C53: =(TableIncomeCalculations[[#This Row],[NetMonthlySalaryP1]]*12) -> 0 | D53: =(TableIncomeCalculations[[#This Row],[NetMonthlySalaryP2]]*12) -> 0 | E53: =TableIncome[[#This Row],[SalaryP1]]*$I$7 -> 0 | F53: =TableIncome[[#This Row],[SalaryP2]]*$I$7 -> 0 | K53: =(TableIncome[[#This Row],[SalaryP1]]-TableIncome[[#This Row],[InvestmentP1]])/12 -> 0 | L53: =(TableIncome[[#This Row],[SalaryP2]]-TableIncome[[#This Row],[InvestmentP2]])/12 -> 0 | M53: ='Net Salary P1'!BI52 -> 0 | N53: ='Net Salary P2'!BI52 -> 0 | O53: =IF(_xlfn.XLOOKUP(TableIncome[[#This Row],[Year]],Loop!C:C,Loop!D:D)<75,(O52*(1+$I$4))+IF(TableIncomeCalculations[[#This Row],[SwitchP1]]="Y",O52*$I$6,0),0) -> 0 | P53: =IF(_xlfn.XLOOKUP(TableIncome[[#This Row],[Year]],Loop!C:C,Loop!E:E)<75,(P52*(1+$I$4))+IF(TableIncomeCalculations[[#This Row],[SwitchP2]]="Y",P52*$I$6,0),0) -> 0 | Q53: =IF(_xlfn.XLOOKUP(TableIncome[[#This Row],[Year]],Loop!C:C,Loop!D:D)<75,(Q52*(1+$I$3))+IF(TableIncomeCalculations[[#This Row],[SwitchP1]]="Y",Q52*$I$5,0),0) -> 0 | S53: =JobHopping[[#This Row],[SwitchP1Static]] -> N | T53: =JobHopping[[#This Row],[SwitchP2Static]] -> N

Sheet Pensions P1
A1: Year | B1: 2025 | C1: 2026 | D1: 2027 | E1: 2028 | F1: 2029 | G1: 2030 | H1: 2031 | I1: 2032 | J1: 2033 | K1: 2034 | L1: 2035 | M1: 2036 | N1: 2037 | O1: 2038 | P1: 2039 | Q1: 2040 | R1: 2041 | S1: 2042 | T1: 2043 | U1: 2044 | V1: 2045 | W1: 2046 | X1: 2047 | Y1: 2048 | Z1: 2049 | AA1: 2050 | AB1: 2051 | AC1: 2052 | AD1: 2053 | AE1: 2054 | AF1: 2055 | AG1: 2056 | AH1: 2057 | AI1: 2058 | AJ1: 2059 | AK1: 2060 | AL1: 2061 | AM1: 2062 | AN1: 2063 | AO1: 2064 | AP1: 2065 | AQ1: 2066 | AR1: 2067 | AS1: 2068 | AT1: 2069 | AU1: 2070 | AV1: 2071 | AW1: 2072 | AX1: 2073 | AY1: 2074
A2: Month Salary | B2: {=TRANSPOSE(Income!O3:O52)} -> 43421.569 | C2: 43855.784 | D2: 46048.574 | E2: 46509.059 | F2: 46974.15 | G2: 47443.891 | H2: 49816.086 | I2: 50314.247 | J2: 50817.389 | K2: 51325.563 | L2: 53891.841 | M2: 54430.76 | N2: 54975.067 | O2: 57723.821 | P2: 58301.059 | Q2: 58884.069 | R2: 59472.91 | S2: 60067.639 | T2: 63071.021 | U2: 63701.731 | V2: 64338.749 | W2: 64982.136 | X2: 68231.243 | Y2: 68913.555 | Z2: 69602.691 | AA2: 70298.718 | AB2: 71001.705 | AC2: 71711.722 | AD2: 72428.839 | AE2: 73153.128 | AF2: 73884.659 | AG2: 74623.506 | AH2: 75369.741 | AI2: 76123.438 | AJ2: 76884.673 | AK2: 80728.906 | AL2: 81536.195 | AM2: 82351.557 | AN2: 83175.073 | AO2: 84006.823 | AP2: 84846.892 | AQ2: 85695.361 | AR2: 86552.314 | AS2: 87417.837 | AT2: 88292.016 | AU2: 89174.936 | AV2: 90066.685 | AW2: 90967.352 | AX2: 91877.026 | AY2: 92795.796
A3: Personal Contribution (%) | B3: ='Salary Variables'!$C$12 -> 0.05 | C3: ='Salary Variables'!$C$12 -> 0.05 | D3: ='Salary Variables'!$C$12 -> 0.05 | E3: ='Salary Variables'!$C$12 -> 0.05 | F3: ='Salary Variables'!$C$12 -> 0.05 | G3: ='Salary Variables'!$C$12 -> 0.05 | H3: ='Salary Variables'!$C$12 -> 0.05 | I3: ='Salary Variables'!$C$12 -> 0.05 | ... AY3: ='Salary Variables'!$C$12 -> 0.05
A4: Personal Contribution | B4: =B3*B2 -> 2171.0784 | C4: =C3*C2 -> 2192.7892 | D4: =D3*D2 -> 2302.4287 | E4: =E3*E2 -> 2325.453 | F4: =F3*F2 -> 2348.7075 | G4: =G3*G2 -> 2372.1946 | H4: =H3*H2 -> 2490.8043 | I4: =I3*I2 -> 2515.7123 | ... AY4: =AY3*AY2 -> 4639.7898
A5: Company Contribution (%) | B5: ='Salary Variables'!$C$13 -> 0.1 | C5: ='Salary Variables'!$C$13 -> 0.1 | D5: ='Salary Variables'!$C$13 -> 0.1 | E5: ='Salary Variables'!$C$13 -> 0.1 | F5: ='Salary Variables'!$C$13 -> 0.1 | G5: ='Salary Variables'!$C$13 -> 0.1 | H5: ='Salary Variables'!$C$13 -> 0.1 | I5: ='Salary Variables'!$C$13 -> 0.1 | ... AY5: ='Salary Variables'!$C$13 -> 0.1
A6: Company Contribution | B6: =B2*B5 -> 4342.1569 | C6: =C4*2 -> 4385.5784 | D6: =D4*2 -> 4604.8574 | E6: =E4*2 -> 4650.9059 | F6: =F4*2 -> 4697.415 | G6: =G4*2 -> 4744.3891 | H6: =H4*2 -> 4981.6086 | I6: =I4*2 -> 5031.4247 | J6: =J4*2 -> 5081.7389 | ... AY6: =AY4*2 -> 9279.5796
A7: Total Contribution (Monthly) | B7: =SUM(B6,B4) -> 6513.2353 | C7: =SUM(C6,C4) -> 6578.3676 | D7: =SUM(D6,D4) -> 6907.286 | E7: =SUM(E6,E4) -> 6976.3589 | F7: =SUM(F6,F4) -> 7046.1225 | G7: =SUM(G6,G4) -> 7116.5837 | H7: =SUM(H6,H4) -> 7472.4129 | I7: =SUM(I6,I4) -> 7547.137 | ... AY7: =SUM(AY6,AY4) -> 13919.369
A8: Total Contribution (Yearly) | B8: =B7*12 -> 78158.824 | C8: =C7*12 -> 78940.412 | D8: =D7*12 -> 82887.432 | E8: =E7*12 -> 83716.307 | F8: =F7*12 -> 84553.47 | G8: =G7*12 -> 85399.004 | H8: =H7*12 -> 89668.955 | I8: =I7*12 -> 90565.644 | ... AY8: =AY7*12 -> 167032.43
A11: Aldersopsparing Total | B11: =AY54 -> 950809.37
A12: Divided by 25 | B12: =B11/25 -> 38032.375
A13: Monthly | B13: =B12/12 -> 3169.3646
A14: Taxed in retirement? | B14: No
A16: Total Contribution (Work Pension) | B16: =AY38 -> 11542486
A17: Divided by 25 years | B17: =B16/25 -> 461699.42 | C17: per year
A18: Monthly | B18: =B17/12 -> 38474.952 | C18: per month (gross)
A19: Taxed in Retirement? | B19: Yes | C19: Income tax
C21: base | D21: supplement
A22: Public Pension Average Monthly | B22: =C22 -> 7198 | C22: 7198 | D22: =8329*(1-30.9%) -> 5755.339
A23: Public Pension Average Yearly | B23: =B22*12 -> 86376
A24: Taxed in Retirement? | B24: Yes
A25: Inflation | B25: ='Salary Variables'!C2 -> 0.02
A26: Pension growth | B26: 0.03
A27: PAL tax | B27: 0.153
A29: ATP | B29: =AY47 -> 360498.36
A30: ATP Yearly | B30: =B29/25 -> 14419.934
A31: ATP Monthly | B31: =B30/12 -> 1201.6612
A33: Year | B33: 2025 | C33: 2026 | D33: 2027 | E33: 2028 | F33: 2029 | G33: 2030 | H33: 2031 | I33: 2032 | J33: 2033 | K33: 2034 | L33: 2035 | M33: 2036 | N33: 2037 | O33: 2038 | P33: 2039 | Q33: 2040 | R33: 2041 | S33: 2042 | T33: 2043 | U33: 2044 | V33: 2045 | W33: 2046 | X33: 2047 | Y33: 2048 | Z33: 2049 | AA33: 2050 | AB33: 2051 | AC33: 2052 | AD33: 2053 | AE33: 2054 | AF33: 2055 | AG33: 2056 | AH33: 2057 | AI33: 2058 | AJ33: 2059 | AK33: 2060 | AL33: 2061 | AM33: 2062 | AN33: 2063 | AO33: 2064 | AP33: 2065 | AQ33: 2066 | AR33: 2067 | AS33: 2068 | AT33: 2069 | AU33: 2070 | AV33: 2071 | AW33: 2072 | AX33: 2073 | AY33: 2074
A34: Work Pension Start of Year | B34: =B8 -> 78158.824 | C34: =B38+C8 -> 159085.25 | D34: =C38+D8 -> 246015.04 | E34: =D38+E8 -> 335982.59 | F34: =E38+F8 -> 429073.38 | G34: =F38+G8 -> 525375.13 | H34: =G38+H8 -> 628393.87 | I34: =H38+I8 -> 734927 | J34: =I38+J8 -> 845072.8 | ... AY34: =AX38+AY8 -> 11256459
A35: Work Pension growth (%) | B35: =$B$26 -> 0.03 | C35: =$B$26 -> 0.03 | D35: =$B$26 -> 0.03 | E35: =$B$26 -> 0.03 | F35: =$B$26 -> 0.03 | G35: =$B$26 -> 0.03 | H35: =$B$26 -> 0.03 | I35: =$B$26 -> 0.03 | ... AY35: =$B$26 -> 0.03
A36: Work pension growth | B36: =B35*B34 -> 2344.7647 | C36: =C35*C34 -> 4772.5575 | D36: =D35*D34 -> 7380.4512 | E36: =E35*E34 -> 10079.478 | F36: =F35*F34 -> 12872.201 | G36: =G35*G34 -> 15761.254 | H36: =H35*H34 -> 18851.816 | I36: =I35*I34 -> 22047.81 | ... AY36: =AY35*AY34 -> 337693.77
A37: Tax | B37: =B36*$B$27 -> 358.749 | C37: =C36*$B$27 -> 730.2013 | D37: =D36*$B$27 -> 1129.209 | E37: =E36*$B$27 -> 1542.1601 | F37: =F36*$B$27 -> 1969.4468 | G37: =G36*$B$27 -> 2411.4719 | H37: =H36*$B$27 -> 2884.3279 | I37: =I36*$B$27 -> 3373.3149 | ... AY37: =AY36*$B$27 -> 51667.147
A38: Work Pension End of Year | B38: =B34+(B36-B37) -> 80144.839 | C38: =C34+(C36-C37) -> 163127.61 | D38: =D34+(D36-D37) -> 252266.28 | E38: =E34+(E36-E37) -> 344519.91 | F38: =F34+(F36-F37) -> 439976.13 | G38: =G34+(G36-G37) -> 538724.92 | H38: =H34+(H36-H37) -> 644361.36 | I38: =I34+(I36-I37) -> 753601.5 | ... AY38: =AY34+(AY36-AY37) -> 11542486
A40: Total Work Pension | B40: =AT38 -> 9402684.3
A42: ATP | B42: https://businessindenmark.virk.dk/guidance/atp-livslang-pension-bid/atp-employer/atp-contribution-rates2024/
A43: ATP start of year | B43: ='Net Salary P1'!B14*3 -> 3564 | C43: =B47+$B$43 -> 7218.5612 | D43: =C47+$B$43 -> 10965.985 | E43: =D47+$B$43 -> 14808.631 | F43: =E47+$B$43 -> 18748.918 | G43: =F47+$B$43 -> 22789.328 | H43: =G47+$B$43 -> 26932.405 | I43: =H47+$B$43 -> 31180.757 | J43: =I47+$B$43 -> 35537.06 | ... AY43: =AX47+$B$43 -> 351565.09
A44: Pension growth (%) | B44: =$B$26 -> 0.03 | C44: =$B$26 -> 0.03 | D44: =$B$26 -> 0.03 | E44: =$B$26 -> 0.03 | F44: =$B$26 -> 0.03 | G44: =$B$26 -> 0.03 | H44: =$B$26 -> 0.03 | I44: =$B$26 -> 0.03 | ... AY44: =$B$26 -> 0.03
A45: Pension growth | B45: =B44*B43 -> 106.92 | C45: =C44*C43 -> 216.55684 | D45: =D44*D43 -> 328.97955 | E45: =E44*E43 -> 444.25892 | F45: =F44*F43 -> 562.46754 | G45: =G44*G43 -> 683.67984 | H45: =H44*H43 -> 807.97214 | I45: =I44*I43 -> 935.42271 | ... AY45: =AY44*AY43 -> 10546.953
A46: Tax | B46: =B45*$B$27 -> 16.35876 | C46: =C45*$B$27 -> 33.133196 | D46: =D45*$B$27 -> 50.333871 | E46: =E45*$B$27 -> 67.971614 | F46: =F45*$B$27 -> 86.057533 | G46: =G45*$B$27 -> 104.60301 | H46: =H45*$B$27 -> 123.61974 | I46: =I45*$B$27 -> 143.11968 | ... AY46: =AY45*$B$27 -> 1613.6838
A47: Post Tax | B47: =B43+(B45-B46) -> 3654.5612 | C47: =C43+(C45-C46) -> 7401.9849 | D47: =D43+(D45-D46) -> 11244.631 | E47: =E43+(E45-E46) -> 15184.918 | F47: =F43+(F45-F46) -> 19225.328 | G47: =G43+(G45-G46) -> 23368.405 | H47: =H43+(H45-H46) -> 27616.757 | I47: =I43+(I45-I46) -> 31973.06 | ... AY47: =AY43+(AY45-AY46) -> 360498.36
A49: Aldersopsparing
...

Sheet Pensions P2
A1: Year | B1: 2010 | C1: 2011 | D1: 2012 | E1: 2013 | F1: 2014 | G1: 2015 | H1: 2016 | I1: 2017 | J1: 2018 | K1: 2019 | L1: 2020 | M1: 2021 | N1: 2022 | O1: 2023 | P1: 2024 | Q1: 2025 | R1: 2026 | S1: 2027 | T1: 2028 | U1: 2029 | V1: 2030 | W1: 2031 | X1: 2032 | Y1: 2033 | Z1: 2034 | AA1: 2035 | AB1: 2036 | AC1: 2037 | AD1: 2038 | AE1: 2039 | AF1: 2040 | AG1: 2041 | AH1: 2042 | AI1: 2043 | AJ1: 2044 | AK1: 2045 | AL1: 2046 | AM1: 2047 | AN1: 2048 | AO1: 2049 | AP1: 2050 | AQ1: 2051 | AR1: 2052 | AS1: 2053 | AT1: 2054 | AU1: 2055 | AV1: 2056 | AW1: 2057 | AX1: 2058 | AY1: 2059
A2: Month Salary | B2: {=TRANSPOSE('Income - P2 Helper'!N3:N17)} -> 53225.047 | C2: 53757.298 | D2: 54294.871 | E2: 57146.54 | F2: 57718.005 | G2: 58295.185 | H2: 58878.137 | I2: 61970.528 | J2: 62590.233 | K2: 63216.135 | L2: 63848.296 | M2: 67201.729 | N2: 67873.747 | O2: 68552.484 | P2: 72152.99 | Q2: {=TRANSPOSE(Income!P3:P37)} -> 72874.52 | R2: 73603.265 | S2: 77283.428 | T2: 78056.262 | U2: 78836.825 | V2: 79625.193 | W2: 83606.453 | X2: 84442.517 | Y2: 85286.943 | Z2: 86139.812 | AA2: 90446.803 | AB2: 91351.271 | AC2: 92264.783 | AD2: 96878.022 | AE2: 97846.803 | AF2: 98825.271 | AG2: 99813.523 | AH2: 100811.66 | AI2: 105852.24 | AJ2: 106910.76 | AK2: 107979.87 | AL2: 109059.67 | AM2: 114512.65 | AN2: 115657.78 | AO2: 116814.36 | AP2: 117982.5 | AQ2: 119162.33 | AR2: 120353.95 | AS2: 121557.49 | AT2: 122773.06 | AU2: 124000.8 | AV2: 125240.8 | AW2: 126493.21 | AX2: 127758.14 | AY2: 129035.72
A3: Personal Contribution (%) | B3: ='Salary Variables'!$C$12 -> 0.05 | C3: ='Salary Variables'!$C$12 -> 0.05 | D3: ='Salary Variables'!$C$12 -> 0.05 | E3: ='Salary Variables'!$C$12 -> 0.05 | F3: ='Salary Variables'!$C$12 -> 0.05 | G3: ='Salary Variables'!$C$12 -> 0.05 | H3: ='Salary Variables'!$C$12 -> 0.05 | I3: ='Salary Variables'!$C$12 -> 0.05 | ... AY3: ='Salary Variables'!$C$12 -> 0.05
A4: Personal Contribution | B4: =B3*B2 -> 2661.2524 | C4: =C3*C2 -> 2687.8649 | D4: =D3*D2 -> 2714.7435 | E4: =E3*E2 -> 2857.327 | F4: =F3*F2 -> 2885.9002 | G4: =G3*G2 -> 2914.7593 | H4: =H3*H2 -> 2943.9068 | I4: =I3*I2 -> 3098.5264 | ... AY4: =AY3*AY2 -> 6451.7862
A5: Company Contribution (%) | B5: ='Salary Variables'!$C$13 -> 0.1 | C5: ='Salary Variables'!$C$13 -> 0.1 | D5: ='Salary Variables'!$C$13 -> 0.1 | E5: ='Salary Variables'!$C$13 -> 0.1 | F5: ='Salary Variables'!$C$13 -> 0.1 | G5: ='Salary Variables'!$C$13 -> 0.1 | H5: ='Salary Variables'!$C$13 -> 0.1 | I5: ='Salary Variables'!$C$13 -> 0.1 | ... AY5: ='Salary Variables'!$C$13 -> 0.1
A6: Company Contribution | B6: =B2*B5 -> 5322.5047 | C6: =C4*2 -> 5375.7298 | D6: =D4*2 -> 5429.4871 | E6: =E4*2 -> 5714.654 | F6: =F4*2 -> 5771.8005 | G6: =G4*2 -> 5829.5185 | H6: =H4*2 -> 5887.8137 | I6: =I4*2 -> 6197.0528 | J6: =J4*2 -> 6259.0233 | ... AY6: =AY4*2 -> 12903.572
A7: Total Contribution (Monthly) | B7: =SUM(B6,B4) -> 7983.7571 | C7: =SUM(C6,C4) -> 8063.5947 | D7: =SUM(D6,D4) -> 8144.2306 | E7: =SUM(E6,E4) -> 8571.9809 | F7: =SUM(F6,F4) -> 8657.7007 | G7: =SUM(G6,G4) -> 8744.2778 | H7: =SUM(H6,H4) -> 8831.7205 | I7: =SUM(I6,I4) -> 9295.5791 | ... AY7: =SUM(AY6,AY4) -> 19355.359
A8: Total Contribution (Yearly) | B8: =B7*12 -> 95805.085 | C8: =C7*12 -> 96763.136 | D8: =D7*12 -> 97730.767 | E8: =E7*12 -> 102863.77 | F8: =F7*12 -> 103892.41 | G8: =G7*12 -> 104931.33 | H8: =H7*12 -> 105980.65 | I8: =I7*12 -> 111546.95 | ... AY8: =AY7*12 -> 232264.3
A11: Aldersopsparing Total | B11: =AY54 -> 950809.37
A12: Divided by 25 | B12: =B11/25 -> 38032.375
A13: Monthly | B13: =B12/12 -> 3169.3646
A14: Taxed in retirement? | B14: No
A16: Total Contribution (Work Pension) | B16: =AY38 -> 14854176
A17: Divided by 25 years | B17: =B16/25 -> 594167.06 | C17: per year
A18: Monthly | B18: =B17/12 -> 49513.921 | C18: per month (gross)
A19: Taxed in Retirement? | B19: Yes | C19: Income tax
C21: base | D21: supplement
A22: Public Pension Average Monthly | B22: =C22 -> 7198 | C22: 7198 | D22: =8329*(1-30.9%) -> 5755.339
A23: Public Pension Average Yearly | B23: =B22*12 -> 86376
A24: Taxed in Retirement? | B24: Yes
A25: Inflation | B25: ='Salary Variables'!C2 -> 0.02
A26: Pension growth | B26: 0.03
A27: PAL tax | B27: 0.153
A29: ATP | B29: =AY47 -> 360498.36
A30: ATP Yearly | B30: =B29/25 -> 14419.934
A31: ATP Monthly | B31: =B30/12 -> 1201.6612
A33: Year | B33: 2010 | C33: 2011 | D33: 2012 | E33: 2013 | F33: 2014 | G33: 2015 | H33: 2016 | I33: 2017 | J33: 2018 | K33: 2019 | L33: 2020 | M33: 2021 | N33: 2022 | O33: 2023 | P33: 2024 | Q33: 2025 | R33: 2026 | S33: 2027 | T33: 2028 | U33: 2029 | V33: 2030 | W33: 2031 | X33: 2032 | Y33: 2033 | Z33: 2034 | AA33: 2035 | AB33: 2036 | AC33: 2037 | AD33: 2038 | AE33: 2039 | AF33: 2040 | AG33: 2041 | AH33: 2042 | AI33: 2043 | AJ33: 2044 | AK33: 2045 | AL33: 2046 | AM33: 2047 | AN33: 2048 | AO33: 2049 | AP33: 2050 | AQ33: 2051 | AR33: 2052 | AS33: 2053 | AT33: 2054 | AU33: 2055 | AV33: 2056 | AW33: 2057 | AX33: 2058 | AY33: 2059
A34: Work Pension Start of Year | B34: =B8 -> 95805.085 | C34: =B38+C8 -> 195002.63 | D34: =C38+D8 -> 297688.41 | E34: =D38+E8 -> 408116.45 | F34: =E38+F8 -> 522379.09 | G34: =F38+G8 -> 640584.08 | H34: =G38+H8 -> 762841.97 | I34: =H38+I8 -> 893772.73 | J34: =I38+J8 -> 1029145.9 | ... AY34: =AX38+AY8 -> 14486085
A35: Work Pension growth (%) | B35: =$B$26 -> 0.03 | C35: =$B$26 -> 0.03 | D35: =$B$26 -> 0.03 | E35: =$B$26 -> 0.03 | F35: =$B$26 -> 0.03 | G35: =$B$26 -> 0.03 | H35: =$B$26 -> 0.03 | I35: =$B$26 -> 0.03 | ... AY35: =$B$26 -> 0.03
A36: Work pension growth | B36: =B35*B34 -> 2874.1525 | C36: =C35*C34 -> 5850.0788 | D36: =D35*D34 -> 8930.6524 | E36: =E35*E34 -> 12243.493 | F36: =F35*F34 -> 15671.373 | G36: =G35*G34 -> 19217.522 | H36: =H35*H34 -> 22885.259 | I36: =I35*I34 -> 26813.182 | ... AY36: =AY35*AY34 -> 434582.55
A37: Tax | B37: =B36*$B$27 -> 439.74534 | C37: =C36*$B$27 -> 895.06206 | D37: =D36*$B$27 -> 1366.3898 | E37: =E36*$B$27 -> 1873.2545 | F37: =F36*$B$27 -> 2397.72 | G37: =G36*$B$27 -> 2940.2809 | H37: =H36*$B$27 -> 3501.4446 | I37: =I36*$B$27 -> 4102.4168 | ... AY37: =AY36*$B$27 -> 66491.13
A38: Work Pension End of Year | B38: =B34+(B36-B37) -> 98239.492 | C38: =C34+(C36-C37) -> 199957.64 | D38: =D34+(D36-D37) -> 305252.67 | E38: =E34+(E36-E37) -> 418486.68 | F38: =F34+(F36-F37) -> 535652.75 | G38: =G34+(G36-G37) -> 656861.32 | H38: =H34+(H36-H37) -> 782225.78 | I38: =I34+(I36-I37) -> 916483.5 | ... AY38: =AY34+(AY36-AY37) -> 14854176
A42: ATP | B42: https://businessindenmark.virk.dk/guidance/atp-livslang-pension-bid/atp-employer/atp-contribution-rates2024/
A43: ATP start of year | B43: ='Net Salary P2'!B14*3 -> 3564 | C43: =B47+$B$43 -> 7218.5612 | D43: =C47+$B$43 -> 10965.985 | E43: =D47+$B$43 -> 14808.631 | F43: =E47+$B$43 -> 18748.918 | G43: =F47+$B$43 -> 22789.328 | H43: =G47+$B$43 -> 26932.405 | I43: =H47+$B$43 -> 31180.757 | J43: =I47+$B$43 -> 35537.06 | ... AY43: =AX47+$B$43 -> 351565.09
A44: Pension growth (%) | B44: =$B$26 -> 0.03 | C44: =$B$26 -> 0.03 | D44: =$B$26 -> 0.03 | E44: =$B$26 -> 0.03 | F44: =$B$26 -> 0.03 | G44: =$B$26 -> 0.03 | H44: =$B$26 -> 0.03 | I44: =$B$26 -> 0.03 | ... AY44: =$B$26 -> 0.03
