Workbook
Name _DLX1: [1]Rates!#REF!
Name _DLX1.INC: '[2]Car Air'!#REF!
Name _DLX10.INC: '[3]US&Europe'!#REF!
Name _DLX10_INC: #REF!
Name _DLX100.INC: '[3]Bonds Data BIS'!#REF!
Name _DLX14.INC: #REF!
Name _DLX15.INC: '[3]Bonds Data BIS'!#REF!
Name _DLX16.INC: '[3]Bonds Data BIS'!#REF!
Name _DLX2.INC: #REF!
Name _DLX20.INC: #REF!
Name _DLX3.INC: #REF!
Name _DLX4.INC: #REF!
Name _DLX5.INC: #REF!
Name _DLX5_INC: #REF!
Name _DLX50.INC: '[3]US&Europe'!#REF!
Name _DLX52.INC: #REF!
Name _DLX53.INC: '[3]US&Europe'!#REF!
Name _DLX54.INC: '[3]US&Europe'!#REF!
Name _DLX56.INC: '[3]US&Europe'!#REF!
Name _DLX6.INC: #REF!
Name _DLX60.INC: #REF!
Name _DLX7.INC: '[3]US&Europe'!#REF!
Name _DLX8.INC: '[3]US&Europe'!#REF!
Name _DLX80.INC: '[3]Bonds Data BIS'!#REF!
Name _DLX9.INC: '[3]US&Europe'!#REF!
Name AUD_Nom: #REF!
Name AUD_Tenor: #REF!
Name AUD_yr: #REF!
Name CAD_Nom: #REF!
Name CAD_Tenor: #REF!
Name CAD_yr: #REF!
Name CHF_Nom: #REF!
Name CHF_Tenor: #REF!
Name CHF_yr: #REF!
Name cn_asia: [4]Weights!$J$5
Name code: [5]CONSTANT!#REF!
Name Currency_cusip: '[6]Currency bucketing mapping'!$B$35:$B$160
Name Currency_name: '[6]Currency bucketing mapping'!$B$35:$BF$35
Name Currency_table: '[6]Currency bucketing mapping'!$B$35:$BF$160
Name D_0: #REF!
Name D_0_DE: #REF!
Name D_0_FR: #REF!
Name D_0_IT: #REF!
Name D_0_JP: #REF!
Name D_0_UK: #REF!
Name DaysInYear: [7]C!$B$29
Name DE_gwth: #REF!
Name DE_S: #REF!
Name ERP: [8]CF20!$C$18
Name EUR_Nom: #REF!
Name EUR_Tenor: #REF!
Name EUR_yr: #REF!
Name FR_gwth: #REF!
Name FR_S: #REF!
Name GBP_Nom: #REF!
Name GBP_Tenor: #REF!
Name GBP_yr: #REF!
Name gGDP: [8]CF20!$C$14
Name hk_asia: [4]Weights!$J$6
Name hk_nie: [4]Weights!$K$6

Sheet Index
B3: Sheet Colors
B4: Calculation
B5: Raw Report | C5: <-- If we download a report from a source, ex: Djøf, we will store it here and will not directly edit it
B6: Raw Report with Key | C6: <-- Raw Report but a column has been added for lookups
B8: Table Colors
B9: Uploaded to Python
B10: Not Uploaded to Python

Sheet Loop
B2: N | C2: Year | D2: AgeP1 | E2: AgeP2 | F2: LoopStatus
B3: 1 | C3: 2025 | D3: 25 | E3: 40 | F3: N
B4: 2 | C4: 2026 | D4: =D3+1 -> 26 | E4: =E3+1 -> 41 | F4: N
B5: 3 | C5: 2027 | D5: =D4+1 -> 27 | E5: =E4+1 -> 42 | F5: N
B6: 4 | C6: 2028 | D6: =D5+1 -> 28 | E6: =E5+1 -> 43 | F6: N
B7: 5 | C7: 2029 | D7: =D6+1 -> 29 | E7: =E6+1 -> 44 | F7: N
B8: 6 | C8: 2030 | D8: =D7+1 -> 30 | E8: =E7+1 -> 45 | F8: N
B9: 7 | C9: 2031 | D9: =D8+1 -> 31 | E9: =E8+1 -> 46 | F9: N
B10: 8 | C10: 2032 | D10: =D9+1 -> 32 | E10: =E9+1 -> 47 | F10: N
B11: 9 | C11: 2033 | D11: =D10+1 -> 33 | E11: =E10+1 -> 48 | F11: N
B12: 10 | C12: 2034 | D12: =D11+1 -> 34 | E12: =E11+1 -> 49 | F12: N
B13: 11 | C13: 2035 | D13: =D12+1 -> 35 | E13: =E12+1 -> 50 | F13: N
B14: 12 | C14: 2036 | D14: =D13+1 -> 36 | E14: =E13+1 -> 51 | F14: N
B15: 13 | C15: 2037 | D15: =D14+1 -> 37 | E15: =E14+1 -> 52 | F15: N
... B53: 51 | C53: 2075 | D53: =D52+1 -> 75 | E53: =E52+1 -> 90 | F53: N

Sheet Sheet2
A3: Row Labels | B3: Sum of Weight | C3: Invested Amt | D3: End Values | E3: FinalWealth | F3: Salary | G3: Invested Amt Calculated | H3: Invested Amt DIFF | I3: Diff End | K3: =A3&", "&B3&", "&C3&", "&D3&", "&E3&", "&F3&", "&G3&", "&H3&", "&I3 -> Row Labels, Sum of Weight, Invested Amt, End Values, FinalWealth, Salary, Invested Amt Calculated, Invested Amt DIFF, Diff End | N3: Sum of Invested | O3: Column Labels
A4: 2026 | B4: 1 | C4: 52645.202 | D4: 56284.388 | E4: {=TRANSPOSE(FinalWealth!C2:AZ2)} -> 55399.768 | F4: {=TRANSPOSE(Salary!C2:AZ2)} -> 52645.2 | G4: =F4 -> 52645.2 | H4: =G4-C4 -> -0.0024478143 | I4: =E4-D4 -> -884.62013 | K4: =A4&", "&B4&", "&C4&", "&D4&", "&E4&", "&F4&", "&G4&", "&H4&", "&I4 -> 2026, 1.00000004649644, 52645.2024478143, 56284.3884355971, 55399.7683048962, 52645.2, 52645.2, -0.00244781433138996, -884.620130700932 | N4: Row Labels | O4: ASK | P4: NORMAL | Q4: Grand Total | U4: Goals | V4: {=GoalsP1[[#This Row],[GOAL A]:[GOAL D]]} -> 7000000 | W4: 250000 | X4: 4000000 | Y4: 300000
A5: 2027 | B5: 0.99999998 | C5: 109456.04 | D5: 117012.47 | E5: 114307.77 | F5: 53171.652 | G5: =F5+E4 -> 108571.42 | H5: =G5-C5 -> -884.61756 | I5: =E5-D5 -> -2704.6999 | K5: =A5&", "&B5&", "&C5&", "&D5&", "&E5&", "&F5&", "&G5&", "&H5&", "&I5 -> 2027, 0.999999976484748, 109456.037861711, 117012.471699718, 114307.771828338, 53171.652, 108571.420304896, -884.617556814628, -2704.69987137985 | N5: 2026 | O5: 36343.34 | P5: 16301.854 | Q5: 52645.194 | U5: Amt | V5: {=_xlfn.UNIQUE(Sheet1!M3:M500)} -> 0 | W5: {=_xlfn.UNIQUE(Sheet1!O3:O500)} -> 0 | X5: {=_xlfn.UNIQUE(Sheet1!Q3:Q500)} -> 0 | Y5: {=_xlfn.UNIQUE(Sheet1!S3:S500)} -> 0
A6: 2028 | B6: 0.99999997 | C6: 176033 | D6: 187389.07 | E6: 181896.04 | F6: 59020.534 | G6: =F6+E5 -> 173328.31 | H6: =G6-C6 -> -2704.6938 | I6: =E6-D6 -> -5493.0293 | K6: =A6&", "&B6&", "&C6&", "&D6&", "&E6&", "&F6&", "&G6&", "&H6&", "&I6 -> 2028, 0.999999965271283, 176032.999306318, 187389.073777771, 181896.044477971, 59020.53372, 173328.305548338, -2704.69375797946, -5493.02929979929 | N6: 2027 | O6: 33657.55 | P6: 75179.85 | Q6: 108837.4 | V6: 400000 | W6: 400000 | X6: 300000 | Y6: 9500000
A7: 2029 | B7: 1 | C7: 246999.82 | D7: 262187.91 | E7: 252938.81 | F7: 59610.739 | G7: =F7+E6 -> 241506.78 | H7: =G7-C7 -> -5493.0348 | I7: =E7-D7 -> -9249.0946 | K7: =A7&", "&B7&", "&C7&", "&D7&", "&E7&", "&F7&", "&G7&", "&H7&", "&I7 -> 2029, 1.00000002223436, 246999.818326853, 262187.907561561, 252938.812961311, 59610.7390572, 241506.783535171, -5493.03479168128, -9249.09460024943 | N7: 2028 | O7: 95994.8 | P7: 75769.882 | Q7: 171764.68
A8: 2030 | B8: 1 | C8: 322394.77 | D8: 342383.2 | E8: 327924.55 | F8: 60206.846 | G8: =F8+E7 -> 313145.66 | H8: =G8-C8 -> -9249.1073 | I8: =E8-D8 -> -14458.652 | K8: =A8&", "&B8&", "&C8&", "&D8&", "&E8&", "&F8&", "&G8&", "&H8&", "&I8 -> 2030, 1.00000003935902, 322394.766698474, 342383.203915868, 327924.551634546, 60206.846447772, 313145.659409083, -9249.10728939064, -14458.6522813221 | N8: 2029 | O8: 101647.25 | P8: 137990.13 | Q8: 239637.38 | V8: =V4-V6 -> 6600000 | W8: =W4-W6 -> -150000 | X8: =X4-X6 -> 3700000 | Y8: =Y4-Y6 -> -9200000
A9: 2031 | B9: 1 | C9: 403192.12 | D9: 418531.51 | E9: 407032.31 | F9: 60808.915 | G9: =F9+E8 -> 388733.47 | H9: =G9-C9 -> -14458.652 | I9: =E9-D9 -> -11499.197 | K9: =A9&", "&B9&", "&C9&", "&D9&", "&E9&", "&F9&", "&G9&", "&H9&", "&I9 -> 2031, 0.999999998159313, 403192.118085967, 418531.505196239, 407032.308313149, 60808.9149122497, 388733.466546796, -14458.6515391715, -11499.1968830908 | N9: 2030 | O9: 33856.84 | P9: 278287.5 | Q9: 312144.34
A10: 2032 | B10: 0.99999999 | C10: 486029.39 | D10: 500011.45 | E10: 484254.19 | F10: 67497.896 | G10: =F10+E9 -> 474530.2 | H10: =G10-C10 -> -11499.19 | I10: =E10-D10 -> -15757.267 | K10: =A10&", "&B10&", "&C10&", "&D10&", "&E10&", "&F10&", "&G10&", "&H10&", "&I10 -> 2032, 0.999999985960815, 486029.39392538, 500011.453911802, 484254.187063494, 67497.8955525972, 474530.203865746, -11499.1900596339, -15757.2668483075 | N10: 2031 | O10: 38139.72 | P10: 350934.69 | Q10: 389074.41
A11: 2033 | B11: 1 | C11: 568184.33 | D11: 586722.9 | E11: 565868.62 | F11: 68172.875 | G11: =F11+E10 -> 552427.06 | H11: =G11-C11 -> -15757.265 | I11: =E11-D11 -> -20854.278 | K11: =A11&", "&B11&", "&C11&", "&D11&", "&E11&", "&F11&", "&G11&", "&H11&", "&I11 -> 2033, 0.999999996214515, 568184.326269072, 586722.899316492, 565868.620842578, 68172.8745081231, 552427.061571617, -15757.2646974549, -20854.278473914 | N11: 2032 | O11: 26031.9 | P11: 452829.34 | Q11: 478861.24
A12: 2034 | B12: 1 | C12: 655577.51 | D12: 679430.35 | E12: 652103.3 | F12: 68854.603 | G12: =F12+E11 -> 634723.22 | H12: =G12-C12 -> -20854.287 | I12: =E12-D12 -> -27327.048 | K12: =A12&", "&B12&", "&C12&", "&D12&", "&E12&", "&F12&", "&G12&", "&H12&", "&I12 -> 2034, 1.00000001269864, 655577.510894638, 679430.349947785, 652103.302180395, 68854.6032532044, 634723.224095783, -20854.2867988553, -27327.0477673896 | N12: 2033 | O12: 65331.88 | P12: 493074.14 | Q12: 558406.02
A13: 2035 | B13: 1 | C13: 348973.51 | D13: 365308.87 | E13: 737996.1 | F13: 69543.149 | G13: =F13+E12 -> 721646.45 | H13: =G13-C13 -> 372672.94 | I13: =E13-D13 -> 372687.23 | K13: =A13&", "&B13&", "&C13&", "&D13&", "&E13&", "&F13&", "&G13&", "&H13&", "&I13 -> 2035, 1.00000002391716, 348973.507579977, 365308.873538452, 737996.099876939, 69543.1492857364, 721646.451466132, 372672.943886155, 372687.226338486 | N13: 2034 | O13: 54521.92 | P13: 587548.24 | Q13: 642070.16
A14: 2036 | B14: 0.99999999 | C14: 442501.77 | D14: 454489.06 | E14: 834414.46 | F14: 77192.896 | G14: =F14+E13 -> 815189 | H14: =G14-C14 -> 372687.23 | I14: =E14-D14 -> 379925.4 | K14: =A14&", "&B14&", "&C14&", "&D14&", "&E14&", "&F14&", "&G14&", "&H14&", "&I14 -> 2036, 0.999999993900632, 442501.766546638, 454489.05710032, 834414.461256713, 77192.8957071674, 815188.995584106, 372687.229037468, 379925.404156394 | N14: 2035 | O14: 61418.94 | P14: 257289.4 | Q14: 318708.34
A15: 2037 | B15: 0.99999999 | C15: 532453.88 | D15: 549043.46 | E15: 934912.95 | F15: 77964.825 | G15: =F15+E14 -> 912379.29 | H15: =G15-C15 -> 379925.41 | I15: =E15-D15 -> 385869.49 | K15: =A15&", "&B15&", "&C15&", "&D15&", "&E15&", "&F15&", "&G15&", "&H15&", "&I15 -> 2037, 0.999999992365166, 532453.877699362, 549043.455175446, 934912.947914517, 77964.8246642391, 912379.285920953, 379925.40822159, 385869.492739071 | N15: 2036 | O15: 13421.92 | P15: 395921.11 | Q15: 409343.03
A16: 2038 | B16: 0.99999999 | C16: 627787.92 | D16: 648728.27 | E16: 1038914.4 | F16: 78744.473 | G16: =F16+E15 -> 1013657.4 | H16: =G16-C16 -> 385869.5 | I16: =E16-D16 -> 390186.09 | K16: =A16&", "&B16&", "&C16&", "&D16&", "&E16&", "&F16&", "&G16&", "&H16&", "&I16 -> 2038, 0.999999990017447, 627787.921819402, 648728.273557779, 1038914.36089813, 78744.4729108815, 1013657.4208254, 385869.499005996, 390186.087340354 | N16: 2037 | O16: 109639.49 | P16: 388283.67 | Q16: 497923.16
A17: 2039 | B17: 1 | C17: 728260.19 | D17: 746521.71 | E17: 1147490.3 | F17: 79531.918 | G17: =F17+E16 -> 1118446.3 | H17: =G17-C17 -> 390186.08 | I17: =E17-D17 -> 400968.57 | K17: =A17&", "&B17&", "&C17&", "&D17&", "&E17&", "&F17&", "&G17&", "&H17&", "&I17 -> 2039, 1.00000000348275, 728260.193734116, 746521.706421345, 1147490.27925548, 79531.9176399903, 1118446.27853812, 390186.084804006, 400968.572834133 | N17: 2038 | O17: 111868.08 | P17: 480254.84 | Q17: 592122.92
A18: 2040 | B18: 1 | C18: 434802.14 | D18: 448624.68 | E18: 1267553.8 | F18: 88280.429 | G18: =F18+E17 -> 1235770.7 | H18: =G18-C18 -> 800968.57 | I18: =E18-D18 -> 818929.08 | K18: =A18&", "&B18&", "&C18&", "&D18&", "&E18&", "&F18&", "&G18&", "&H18&", "&I18 -> 2040, 1.00000001041683, 434802.139530996, 448624.675711961, 1267553.75103456, 88280.4285803893, 1235770.70783587, 800968.568304872, 818929.075322599 | N18: 2039 | O18: 98907.01 | P18: 592620.7 | Q18: 691527.71
A19: 2041 | B19: 1 | C19: 537787.91 | D19: 557464.59 | E19: 1392963.2 | F19: 89163.233 | G19: =F19+E18 -> 1356717 | H19: =G19-C19 -> 818929.07 | I19: =E19-D19 -> 835498.63 | K19: =A19&", "&B19&", "&C19&", "&D19&", "&E19&", "&F19&", "&G19&", "&H19&", "&I19 -> 2041, 1.00000000731987, 537787.912514695, 557464.593895101, 1392963.22634725, 89163.2328661932, 1356716.98390075, 818929.071386059, 835498.632452151 | N19: 2040 | O19: 111418.75 | P19: 606789.86 | Q19: 718208.61
A20: 2042 | B20: 1 | C20: 647519.46 | D20: 671595.27 | E20: 1522876.5 | F20: 90054.865 | G20: =F20+E19 -> 1483018.1 | H20: =G20-C20 -> 835498.63 | I20: =E20-D20 -> 851281.19 | K20: =A20&", "&B20&", "&C20&", "&D20&", "&E20&", "&F20&", "&G20&", "&H20&", "&I20 -> 2042, 1.00000000658956, 647519.463356823, 671595.272206624, 1522876.46520083, 90054.8651948551, 1483018.09154211, 835498.628185283, 851281.192994202 | N20: 2041 | O20: 125513.22 | P20: 709044.86 | Q20: 834558.08
... A28: 2050 | B28: 1 | C28: 1527999.9 | D28: 1598501.8 | E28: 2548429.8 | F28: 117782.67 | G28: =F28+E27 -> 2477089 | H28: =G28-C28 -> 949089.11 | I28: =E28-D28 -> 949927.95 | K28: =A28&", "&B28&", "&C28&", "&D28&", "&E28&", "&F28&", "&G28&", "&H28&", "&I28 -> 2050, 0.999999999806956, 1527999.93475025, 1598501.84865791, 2548429.80353042, 117782.666112249, 2477089.04329059, 949089.108540334, 949927.954872513 | N28: 2049 | O28: 325491.05 | P28: 1380806.1 | Q28: 1706297.1
A29: 2051 | B29: 1 | C29: 1717462.3 | D29: 1796380.4 | E29: 2746751.7 | F29: 118960.49 | G29: =F29+E28 -> 2667390.3 | H29: =G29-C29 -> 949927.95 | I29: =E29-D29 -> 950371.25 | N29: 2050 | O29: 366665.67 | P29: 1533778.4 | Q29: 1900444.1
A30: 2052 | B30: 1 | C30: 1916530.5 | D30: 2001205.3 | E30: 2952348.7 | F30: 120150.1 | G30: =F30+E29 -> 2866901.8 | H30: =G30-C30 -> 950371.25 | I30: =E30-D30 -> 951143.37 | N30: 2051 | O30: 413048.87 | P30: 1691078.1 | Q30: 2104126.9
A31: 2053 | B31: 1 | C31: 2122556.9 | D31: 2216817.9 | E31: 3162887.2 | F31: 121351.6 | G31: =F31+E30 -> 3073700.3 | H31: =G31-C31 -> 951143.36 | I31: =E31-D31 -> 946069.25 | N31: 2052 | O31: 465299.57 | P31: 1850450.4 | Q31: 2315750
A32: 2054 | B32: 1 | C32: 2339383 | D32: 2442345.7 | E32: 3382311.2 | F32: 122565.11 | G32: =F32+E31 -> 3285452.3 | H32: =G32-C32 -> 946069.25 | I32: =E32-D32 -> 939965.43 | N32: 2053 | O32: 524159.95 | P32: 2014044.6 | Q32: 2538204.6
A33: 2055 | B33: 1 | C33: 2566136.5 | D33: 2677745.1 | E33: 3607257.9 | F33: 123790.77 | G33: =F33+E32 -> 3506101.9 | H33: =G33-C33 -> 939965.44 | I33: =E33-D33 -> 929512.78 | N33: 2054 | O33: 590466.19 | P33: 2178895 | Q33: 2769361.2
A34: 2056 | B34: 1 | C34: 2802773.7 | D34: 2925484.1 | E34: 3840559.5 | F34: 125028.67 | G34: =F34+E33 -> 3732286.5 | H34: =G34-C34 -> 929512.79 | I34: =E34-D34 -> 915075.42 | N34: 2055 | O34: 665160.16 | P34: 2346868.8 | Q34: 3012029
A35: 2057 | B35: 1 | C35: 3051763 | D35: 3182872.7 | E35: 4079675.1 | F35: 126278.96 | G35: =F35+E34 -> 3966838.4 | H35: =G35-C35 -> 915075.41 | I35: =E35-D35 -> 896802.46 | N35: 2056 | O35: 749302.92 | P35: 2514444.4 | Q35: 3263747.3
A36: 2058 | B36: 1 | C36: 3310414.4 | D36: 3452687 | E36: 4328342.6 | F36: 127541.75 | G36: =F36+E35 -> 4207216.9 | H36: =G36-C36 -> 896802.45 | I36: =E36-D36 -> 875655.54 | N36: 2057 | O36: 844089.74 | P36: 2684263.9 | Q36: 3528353.6
A37: 2059 | B37: 1 | C37: 3581504.2 | D37: 3735828.8 | E37: 4585050.7 | F37: 128817.17 | G37: =F37+E36 -> 4457159.7 | H37: =G37-C37 -> 875655.55 | I37: =E37-D37 -> 849221.87 | N37: 2058 | O37: 950867.09 | P37: 2854167.4 | Q37: 3805034.5
A38: 2060 | B38: 1 | C38: 3865934.2 | D38: 4032398 | E38: 4850647.6 | F38: 130105.34 | G38: =F38+E37 -> 4715156.1 | H38: =G38-C38 -> 849221.87 | I38: =E38-D38 -> 818249.61 | N38: 2059 | O38: 1071151.8 | P38: 3021079 | Q38: 4092230.8
A39: 2061 | B39: 1 | C39: 4176814.9 | D39: 4359806.9 | E39: 5140696 | F39: 144416.93 | G39: =F39+E38 -> 4995064.5 | H39: =G39-C39 -> 818249.62 | I39: =E39-D39 -> 780889.14 | N39: 2060 | O39: 1206652.5 | P39: 3191108.9 | Q39: 4397761.4
A40: 2062 | B40: 1 | C40: 4505667.9 | D40: 4701348 | E40: 5439570.9 | F40: 145861.1 | G40: =F40+E39 -> 5286557.1 | H40: =G40-C40 -> 780889.15 | I40: =E40-D40 -> 738222.9 | N40: 2061 | O40: 1359294 | P40: 3367911.5 | Q40: 4727205.5
... A48: 2070 | B48: 1 | C48: 7758298.5 | D48: 8103167 | E48: 7821891.6 | F48: 157946.67 | G48: =F48+E47 -> 7747508.7 | H48: =G48-C48 -> -10789.737 | I48: =E48-D48 -> -281275.47 | N48: 2069 | O48: 1566316.7 | P48: 6157483.2 | Q48: 7723799.9
A49: 2071 | B49: 1 | C49: 8103167 | D49: 8476322.1 | E49: 7897163.3 | F49: 0 | G49: =F49+E48 -> 7821891.6 | H49: =G49-C49 -> -281275.47 | I49: =E49-D49 -> -579158.8 | N49: 2070 | P49: 8096271.2 | Q49: 8096271.2
A50: 2072 | B50: 1 | C50: 8476322.1 | D50: 8862899.5 | E50: 7973348.8 | F50: 0 | G50: =F50+E49 -> 7897163.3 | H50: =G50-C50 -> -579158.8 | I50: =E50-D50 -> -889550.75 | N50: 2071 | O50: 1602295.2 | P50: 6665168.2 | Q50: 8267463.5
A51: 2073 | B51: 1 | C51: 8862899.5 | D51: 9274987.7 | E51: 8050165.7 | F51: 0 | G51: =F51+E50 -> 7973348.8 | H51: =G51-C51 -> -889550.75 | I51: =E51-D51 -> -1224822 | N51: 2072 | P51: 8493969.3 | Q51: 8493969.3
A52: 2074 | B52: 1 | C52: 9274987.7 | D52: 9718233.3 | E52: 1127058.8 | F52: 0 | G52: =F52+E51 -> 8050165.7 | H52: =G52-C52 -> -1224822 | I52: =E52-D52 -> -8591174.5 | N52: 2073 | P52: 8673073.4 | Q52: 8673073.4
A53: (blank) | E53: 1141211.6 | F53: 0 | G53: =F53+E52 -> 1127058.8 | H53: =G53-C53 -> 1127058.8 | I53: =E53-D53 -> 1141211.6 | N53: 2074 | P53: 8855740.5 | Q53: 8855740.5
A54: 2075 | B54: 0.99999997 | C54: 218233.34 | D54: 225058.14 | N54: Grand Total | O54: 29852601 | P54: 1.1919483e+08 | Q54: 1.4904744e+08
A55: Grand Total | B55: 50 | C55: 1.3638318e+08 | D55: 1.4240151e+08

Sheet Sheet1
A1: Year | B1: Account | C1: Asset | D1: Invested | E1: Weight | F1: Return | G1: Gross Gain | H1: Tax | I1: Net Gain | J1: End Value | K1: TOTAL ASK Cap (DKK) | L1: Goal A Allocation (%) | M1: Goal A Amount Taken (DKK) | N1: Goal B Allocation (%) | O1: Goal B Amount Taken (DKK) | P1: Goal C Allocation (%) | Q1: Goal C Amount Taken (DKK) | R1: Goal D Allocation (%) | S1: Goal D Amount Taken (DKK)
A2: 2026 | B2: ASK | C2: Emerging Markets - Equities | D2: 51664.91 | E2: 0.98137931 | F2: 0.084 | G2: 4339.8524 | H2: 737.77491 | I2: 3602.0775 | J2: 55266.988 | K2: 187224.3
A3: 2026 | B3: ASK | C3: Developed Markets - Equities | D3: 247.48 | E3: 0.0047009034 | F3: 0.068 | G3: 16.82864 | H3: 2.8608688 | I3: 13.967771 | J3: 261.44777 | K3: 187224.3
A4: 2026 | B4: NORMAL | C4: Emerging Markets State - Obligations | D4: 55.623945 | E4: 0.0010565815 | F4: 0.0483 | G4: 2.6866366 | H4: 0.72539187 | I4: 1.9612447 | J4: 57.58519 | K4: 187224.3
A5: 2026 | B5: NORMAL | C5: High Yield Bonds - Obligations | D5: 433.80104 | E5: 0.0082400872 | F5: 0.0493 | G5: 21.386391 | H5: 5.7743256 | I5: 15.612066 | J5: 449.4131 | K5: 187224.3
A6: 2026 | B6: NORMAL | C6: Investment Grade Bonds - Obligations | D6: 92.33553 | E6: 0.0017539212 | F6: 0.0363 | G6: 3.3517797 | H6: 0.90498053 | I6: 2.4467992 | J6: 94.782329 | K6: 187224.3
A7: 2026 | B7: NORMAL | C7: Government ZC Bonds - Obligations | D7: 151.05193 | E7: 0.0028692442 | F7: 0.0283 | G7: 4.2747697 | H7: 1.1541878 | I7: 3.1205819 | J7: 154.17252 | K7: 187224.3
A8: 2027 | B8: ASK | C8: Emerging Markets - Equities | D8: 106933.18 | E8: 0.97695093 | F8: 0.084 | G8: 8982.3871 | H8: 1527.0058 | I8: 7455.3813 | J8: 114388.56 | K8: 210908.17
A9: 2027 | B9: ASK | C9: Developed Markets - Equities | D9: 940.84 | E9: 0.0085955969 | F9: 0.068 | G9: 63.97712 | H9: 10.87611 | I9: 53.10101 | J9: 993.94101 | K9: 210908.17
A10: 2027 | B10: NORMAL | C10: Emerging Markets State - Obligations | D10: 455.77998 | E10: 0.0041640459 | F10: 0.0483 | G10: 22.014173 | H10: 5.9438267 | I10: 16.070346 | J10: 471.85033 | K10: 210908.17
A11: 2027 | B11: NORMAL | C11: High Yield Bonds - Obligations | D11: 540.63606 | E11: 0.0049392986 | F11: 0.0493 | G11: 26.653358 | H11: 7.1964066 | I11: 19.456951 | J11: 560.09301 | K11: 210908.17
A12: 2027 | B12: NORMAL | C12: Investment Grade Bonds - Obligations | D12: 55.868709 | E12: 0.00051042144 | F12: 0.0363 | G12: 2.0280341 | H12: 0.54756922 | I12: 1.4804649 | J12: 57.349174 | K12: 210908.17
A13: 2027 | B13: NORMAL | C13: Government ZC Bonds - Obligations | D13: 529.73311 | E13: 0.0048396882 | F13: 0.0283 | G13: 14.991447 | H13: 4.0476907 | I13: 10.943756 | J13: 540.67687 | K13: 210908.17
... A61: 2033 | B61: NORMAL | C61: Government ZC Bonds - Obligations | D61: 405862.53 | E61: 0.71431489 | F61: 0.0283 | G61: 11485.91 | H61: 3101.1956 | I61: 8384.714 | J61: 414247.24 | K61: 431003.29
A62: 2034 | B62: ASK | C62: Emerging Markets - Equities | D62: 53007.7 | E62: 0.080856496 | F62: 0.084 | G62: 4452.6468 | H62: 756.94996 | I62: 3695.6968 | J62: 56703.397 | K62: 485525.21 | L62: 62 | M62: 400000
A63: 2034 | B63: NORMAL | C63: Emerging Markets - Equities | D63: 183171.23 | E63: 0.27940439 | F63: 0.084 | G63: 15386.383 | H63: 4154.3235 | I63: 11232.06 | J63: 194403.29 | K63: 485525.21 | L63: 62 | M63: 400000
A64: 2034 | B64: ASK | C64: Developed Markets - Equities | D64: 1514.22 | E64: 0.0023097498 | F64: 0.068 | G64: 102.96696 | H64: 17.504383 | I64: 85.462577 | J64: 1599.6826 | K64: 485525.21 | L64: 62 | M64: 400000
A65: 2034 | B65: NORMAL | C65: Developed Markets - Equities | D65: 5232.46 | E65: 0.0079814514 | F65: 0.068 | G65: 355.80728 | H65: 96.067966 | I65: 259.73931 | J65: 5492.1993 | K65: 485525.21 | L65: 62 | M65: 400000
A66: 2034 | B66: NORMAL | C66: Emerging Markets State - Obligations | D66: 2647.4889 | E66: 0.0040384072 | F66: 0.0483 | G66: 127.87371 | H66: 34.525903 | I66: 93.347811 | J66: 2740.8367 | K66: 485525.21 | L66: 62 | M66: 400000
A67: 2034 | B67: NORMAL | C67: High Yield Bonds - Obligations | D67: 639.13144 | E67: 0.00097491363 | F67: 0.0493 | G67: 31.50918 | H67: 8.5074787 | I67: 23.001702 | J67: 662.13315 | K67: 485525.21 | L67: 62 | M67: 400000
A68: 2034 | B68: NORMAL | C68: Investment Grade Bonds - Obligations | D68: 1105.0772 | E68: 0.0016856546 | F68: 0.0363 | G68: 40.114303 | H68: 10.830862 | I68: 29.283441 | J68: 1134.3607 | K68: 485525.21 | L68: 62 | M68: 400000
A69: 2034 | B69: NORMAL | C69: Government ZC Bonds - Obligations | D69: 408260.2 | E69: 0.62274895 | F69: 0.0283 | G69: 11553.764 | H69: 3119.5162 | I69: 8434.2475 | J69: 416694.45 | K69: 485525.21 | L69: 62 | M69: 400000
A70: 2035 | B70: ASK | C70: Emerging Markets - Equities | D70: 17031.61 | E70: 0.048804881 | F70: 0.063 | G70: 1072.9914 | H70: 182.40854 | I70: 890.58289 | J70: 17922.193 | K70: 546944.15
A71: 2035 | B71: NORMAL | C71: Emerging Markets - Equities | D71: 78404.49 | E71: 0.22467176 | F71: 0.063 | G71: 4939.4829 | H71: 1333.6604 | I71: 3605.8225 | J71: 82010.312 | K71: 546944.15
A72: 2035 | B72: ASK | C72: Developed Markets - Equities | D72: 44387.33 | E72: 0.12719398 | F72: 0.063 | G72: 2796.4018 | H72: 475.3883 | I72: 2321.0135 | J72: 46708.343 | K72: 546944.15
A73: 2035 | B73: NORMAL | C73: Developed Markets - Equities | D73: 204335.75 | E73: 0.58553372 | F73: 0.063 | G73: 12873.152 | H73: 3475.7511 | I73: 9397.4011 | J73: 213733.15 | K73: 546944.15
A74: 2035 | B74: NORMAL | C74: Emerging Markets State - Obligations | D74: 1170.1568 | E74: 0.0033531393 | F74: 0.0343 | G74: 40.136377 | H74: 10.836822 | I74: 29.299555 | J74: 1199.4563 | K74: 546944.15
A75: 2035 | B75: NORMAL | C75: High Yield Bonds - Obligations | D75: 631.64324 | E75: 0.0018100034 | F75: 0.0343 | G75: 21.665363 | H75: 5.849648 | I75: 15.815715 | J75: 647.45895 | K75: 546944.15
A76: 2035 | B76: NORMAL | C76: Investment Grade Bonds - Obligations | D76: 1576.4836 | E76: 0.0045174879 | F76: 0.0343 | G76: 54.073386 | H76: 14.599814 | I76: 39.473572 | J76: 1615.9571 | K76: 546944.15
A77: 2035 | B77: NORMAL | C77: Government ZC Bonds - Obligations | D77: 1436.044 | E77: 0.0041150518 | F77: 0.0343 | G77: 49.25631 | H77: 13.299204 | I77: 35.957106 | J77: 1472.0011 | K77: 546944.15
A78: 2036 | B78: ASK | C78: Emerging Markets - Equities | D78: 32485.7 | E78: 0.073413718 | F78: 0.063 | G78: 2046.5991 | H78: 347.92185 | I78: 1698.6773 | J78: 34184.377 | K78: 616132.58
A79: 2036 | B79: ASK | C79: Developed Markets - Equities | D79: 815.42 | E79: 0.0018427497 | F79: 0.063 | G79: 51.37146 | H79: 8.7331482 | I79: 42.638312 | J79: 858.05831 | K79: 616132.58
A80: 2036 | B80: NORMAL | C80: Emerging Markets State - Obligations | D80: 3022.3766 | E80: 0.0068302023 | F80: 0.0343 | G80: 103.66752 | H80: 27.99023 | I80: 75.677288 | J80: 3098.0539 | K80: 616132.58
A81: 2036 | B81: NORMAL | C81: High Yield Bonds - Obligations | D81: 316.2375 | E81: 0.00071465816 | F81: 0.0343 | G81: 10.846946 | H81: 2.9286755 | I81: 7.9182708 | J81: 324.15577 | K81: 616132.58
... A96: 2038 | B96: NORMAL | C96: Government ZC Bonds - Obligations | D96: 402295.56 | E96: 0.64081443 | F96: 0.0343 | G96: 13798.738 | H96: 3725.6592 | I96: 10073.079 | J96: 412368.64 | K96: 781873.63
A97: 2039 | B97: ASK | C97: Emerging Markets - Equities | D97: 12.74 | E97: 1.7493748e-05 | F97: 0.063 | G97: 0.80262 | H97: 0.1364454 | I97: 0.6661746 | J97: 13.406175 | K97: 880780.65 | N97: 56 | O97: 400000
A98: 2039 | B98: ASK | C98: Developed Markets - Equities | D98: 963.58 | E98: 0.001323126 | F98: 0.063 | G98: 60.70554 | H98: 10.319942 | I98: 50.385598 | J98: 1013.9656 | K98: 880780.65 | N98: 56 | O98: 400000
A99: 2039 | B99: NORMAL | C99: Emerging Markets State - Obligations | D99: 119.7169 | E99: 0.00016438754 | F99: 0.0343 | G99: 4.1062897 | H99: 1.1086982 | I99: 2.9975915 | J99: 122.71449 | K99: 880780.65 | N99: 56 | O99: 400000
A100: 2039 | B100: NORMAL | C100: High Yield Bonds - Obligations | D100: 5058.5389 | E100: 0.00694606 | F100: 0.0343 | G100: 173.50789 | H100: 46.847129 | I100: 126.66076 | J100: 5185.1997 | K100: 880780.65 | N100: 56 | O100: 400000
A101: 2039 | B101: NORMAL | C101: Investment Grade Bonds - Obligations | D101: 3982.0656 | E101: 0.005467916 | F101: 0.0343 | G101: 136.58485 | H101: 36.877909 | I101: 99.70694 | J101: 4081.7725 | K101: 880780.65 | N101: 56 | O101: 400000
...

Sheet Aktiesparekonto Increase
A1: https://skat.dk/borger/aktier-og-andre-vaerdipapirer/aktiesparekonto?
A2: Year | B2: Max cap | C2: Change (%)
A3: 2019 | B3: 50000
A4: 2020 | B4: =100000 -> 100000 | C4: =(B4-B3)/B3 -> 1
A5: 2021 | B5: 102300 | C5: =(B5-B4)/B4 -> 0.023
A6: 2022 | B6: 103500 | C6: =(B6-B5)/B5 -> 0.011730205 | E6: median: | F6: without 2020:
A7: 2023 | B7: 106600 | C7: =(B7-B6)/B6 -> 0.029951691 | E7: =MEDIAN(C4:C9) -> 0.12645487 | F7: =MEDIAN(C5:C9) -> 0.029951691
A8: 2024 | B8: 135900 | C8: =(B8-B7)/B7 -> 0.27485929
A9: 2025 | B9: 166200 | C9: =(B9-B8)/B8 -> 0.22295806

Sheet Goals
B2: Goal Info | C2: GOAL A | D2: GOAL B | E2: GOAL C | F2: GOAL D | G2: P1
B3: Value Ratio | C3: 1 | D3: 0.8 | E3: 0.3 | F3: 0.6
B4: Funding Requirement | C4: 7000000 | D4: 250000 | E4: 4000000 | F4: 300000
B5: Time Horizon | C5: 50 | D5: 5 | E5: 10 | F5: 15
B7: Goal Info | C7: GOAL A | D7: GOAL B | E7: GOAL C | F7: GOAL D | G7: P2
B8: Value Ratio | C8: 1 | D8: 0.45 | E8: 0.5 | F8: 0.58
B9: Funding Requirement | C9: 400000 | D9: 75000 | E9: 300000 | F9: 7500000
B10: Time Horizon | C10: 10 | D10: 30 | E10: 4 | F10: 18

Sheet GBI Goals P1
B1: 2025 | C1: 2026 | D1: 2027 | E1: 2028 | F1: 2029 | G1: 2030 | H1: 2031 | I1: 2032 | J1: 2033 | K1: 2034 | L1: 2035 | M1: 2036 | N1: 2037 | O1: 2038 | P1: 2039 | Q1: 2040 | R1: 2041 | S1: 2042 | T1: 2043 | U1: 2044 | V1: 2045 | W1: 2046 | X1: 2047 | Y1: 2048 | Z1: 2049 | AA1: 2050 | AB1: 2051 | AC1: 2052 | AD1: 2053 | AE1: 2054 | AF1: 2055 | AG1: 2056 | AH1: 2057 | AI1: 2058 | AJ1: 2059 | AK1: 2060 | AL1: 2061 | AM1: 2062 | AN1: 2063 | AO1: 2064 | AP1: 2065 | AQ1: 2066 | AR1: 2067 | AS1: 2068 | AT1: 2069 | AU1: 2070 | AV1: 2071 | AW1: 2072 | AX1: 2073 | AY1: 2074 | AZ1: 2075
A2: A | B2: 0.3733 | C2: 0.63 | D2: 0.58 | E2: 0.56 | F2: 0.5743 | G2: 0.59 | H2: 0.6238 | I2: 0.3434 | J2: 0.4343 | K2: 0.505 | L2: 0.5657 | M2: 0.6224 | N2: 0.6667 | O2: 0.6842 | P2: 0.7273 | Q2: 0.7368 | R2: 0.7629 | S2: 0.7778 | T2: 0.8 | U2: 0.78 | V2: 0.8351 | W2: 0.8438 | X2: 0.8542 | Y2: 0.8687 | Z2: 0.8333 | AA2: 1 | AB2: 1 | AC2: 1 | AD2: 1 | AE2: 1 | AF2: 1 | AG2: 1 | AH2: 1 | AI2: 1 | AJ2: 1 | AK2: 1 | AL2: 1 | AM2: 1 | AN2: 1 | AO2: 1 | AP2: 1 | AQ2: 1 | AR2: 1 | AS2: 1 | AT2: 1 | AU2: 1 | AV2: 1 | AW2: 1 | AX2: 1 | AY2: 1 | AZ2: 0
A3: B | B3: 0.1733 | C3: 0.36 | D3: 0.41 | E3: 0.43 | F3: 0.4158 | G3: 0.4 | H3: 0.3663 | I3: 0.6465 | J3: 0.5556 | K3: 0.4851 | L3: 0.4343 | M3: 0.3776 | N3: 0.3333 | O3: 0.3158 | P3: 0.2727 | Q3: 0.2632 | R3: 0.2371 | S3: 0.2222 | T3: 0.2 | U3: 0.22 | V3: 0.1649 | W3: 0.1562 | X3: 0.1458 | Y3: 0.1313 | Z3: 0.1667 | AA3: 0 | AB3: 0 | AC3: 0 | AD3: 0 | AE3: 0 | AF3: 0 | AG3: 0 | AH3: 0 | AI3: 0 | AJ3: 0 | AK3: 0 | AL3: 0 | AM3: 0 | AN3: 0 | AO3: 0 | AP3: 0 | AQ3: 0 | AR3: 0 | AS3: 0 | AT3: 0 | AU3: 0 | AV3: 0 | AW3: 0 | AX3: 0 | AY3: 0 | AZ3: 0
A4: C | B4: 0.4533 | C4: 0.01 | D4: 0.01 | E4: 0.01 | F4: 0.0099 | G4: 0.01 | H4: 0.0099 | I4: 0.0101 | J4: 0.0101 | K4: 0.0099 | L4: 0 | M4: 0 | N4: 0 | O4: 0 | P4: 0 | Q4: 0 | R4: 0 | S4: 0 | T4: 0 | U4: 0 | V4: 0 | W4: 0 | X4: 0 | Y4: 0 | Z4: 0 | AA4: 0 | AB4: 0 | AC4: 0 | AD4: 0 | AE4: 0 | AF4: 0 | AG4: 0 | AH4: 0 | AI4: 0 | AJ4: 0 | AK4: 0 | AL4: 0 | AM4: 0 | AN4: 0 | AO4: 0 | AP4: 0 | AQ4: 0 | AR4: 0 | AS4: 0 | AT4: 0 | AU4: 0 | AV4: 0 | AW4: 0 | AX4: 0 | AY4: 0 | AZ4: 0
A5: D | B5: 0 | C5: 0 | D5: 0 | E5: 0 | F5: 0 | G5: 0 | H5: 0 | I5: 0 | J5: 0 | K5: 0 | L5: 0 | M5: 0 | N5: 0 | O5: 0 | P5: 0 | Q5: 0 | R5: 0 | S5: 0 | T5: 0 | U5: 0 | V5: 0 | W5: 0 | X5: 0 | Y5: 0 | Z5: 0 | AA5: 0 | AB5: 0 | AC5: 0 | AD5: 0 | AE5: 0 | AF5: 0 | AG5: 0 | AH5: 0 | AI5: 0 | AJ5: 0 | AK5: 0 | AL5: 0 | AM5: 0 | AN5: 0 | AO5: 0 | AP5: 0 | AQ5: 0 | AR5: 0 | AS5: 0 | AT5: 0 | AU5: 0 | AV5: 0 | AW5: 0 | AX5: 0 | AY5: 0 | AZ5: 0

Sheet FinalWealth
B1: 2025 | C1: 2026 | D1: 2027 | E1: 2028 | F1: 2029 | G1: 2030 | H1: 2031 | I1: 2032 | J1: 2033 | K1: 2034 | L1: 2035 | M1: 2036 | N1: 2037 | O1: 2038 | P1: 2039 | Q1: 2040 | R1: 2041 | S1: 2042 | T1: 2043 | U1: 2044 | V1: 2045 | W1: 2046 | X1: 2047 | Y1: 2048 | Z1: 2049 | AA1: 2050 | AB1: 2051 | AC1: 2052 | AD1: 2053 | AE1: 2054 | AF1: 2055 | AG1: 2056 | AH1: 2057 | AI1: 2058 | AJ1: 2059 | AK1: 2060 | AL1: 2061 | AM1: 2062 | AN1: 2063 | AO1: 2064 | AP1: 2065 | AQ1: 2066 | AR1: 2067 | AS1: 2068 | AT1: 2069 | AU1: 2070 | AV1: 2071 | AW1: 2072 | AX1: 2073 | AY1: 2074 | AZ1: 2075
A2: P1 | B2: 0 | C2: 55399.768 | D2: 114307.77 | E2: 181896.04 | F2: 252938.81 | G2: 327924.55 | H2: 407032.31 | I2: 484254.19 | J2: 565868.62 | K2: 652103.3 | L2: 737996.1 | M2: 834414.46 | N2: 934912.95 | O2: 1038914.4 | P2: 1147490.3 | Q2: 1267553.8 | R2: 1392963.2 | S2: 1522876.5 | T2: 1658412.7 | U2: 1807016 | V2: 1962506.5 | W2: 2123155.1 | X2: 2289236.4 | Y2: 2472646.3 | Z2: 2359306.4 | AA2: 2548429.8 | AB2: 2746751.7 | AC2: 2952348.7 | AD2: 3162887.2 | AE2: 3382311.2 | AF2: 3607257.9 | AG2: 3840559.5 | AH2: 4079675.1 | AI2: 4328342.6 | AJ2: 4585050.7 | AK2: 4850647.6 | AL2: 5140696 | AM2: 5439570.9 | AN2: 5752563.5 | AO2: 6071053.1 | AP2: 6404745 | AQ2: 6745628 | AR2: 7060443.8 | AS2: 7359525.8 | AT2: 7589562.1 | AU2: 7821891.6 | AV2: 7897163.3 | AW2: 7973348.8 | AX2: 8050165.7 | AY2: 1127058.8 | AZ2: 1141211.6
A3: P2
C4: =(C2-B2)/B2 -> #DIV/0! | D4: =(D2-C2)/C2 -> 1.0633258 | E4: =(E2-D2)/D2 -> 0.59128327 | F4: =(F2-E2)/E2 -> 0.39056797 | G4: =(G2-F2)/F2 -> 0.29645802 | H4: =(H2-G2)/G2 -> 0.24123768 | I4: =(I2-H2)/H2 -> 0.18971929 | J4: =(J2-I2)/I2 -> 0.16853635 | ... AZ4: =(AZ2-AY2)/AY2 -> 0.012557261

Sheet Salary
B1: 2025 | C1: 2026 | D1: 2027 | E1: 2028 | F1: 2029 | G1: 2030 | H1: 2031 | I1: 2032 | J1: 2033 | K1: 2034 | L1: 2035 | M1: 2036 | N1: 2037 | O1: 2038 | P1: 2039 | Q1: 2040 | R1: 2041 | S1: 2042 | T1: 2043 | U1: 2044 | V1: 2045 | W1: 2046 | X1: 2047 | Y1: 2048 | Z1: 2049 | AA1: 2050 | AB1: 2051 | AC1: 2052 | AD1: 2053 | AE1: 2054 | AF1: 2055 | AG1: 2056 | AH1: 2057 | AI1: 2058 | AJ1: 2059 | AK1: 2060 | AL1: 2061 | AM1: 2062 | AN1: 2063 | AO1: 2064 | AP1: 2065 | AQ1: 2066 | AR1: 2067 | AS1: 2068 | AT1: 2069 | AU1: 2070 | AV1: 2071 | AW1: 2072 | AX1: 2073 | AY1: 2074 | AZ1: 2075
A2: P1 | B2: 0 | C2: {=TRANSPOSE(TableIncome[InvestmentP1])} -> 52645.2 | D2: 53171.652 | E2: 59020.534 | F2: 59610.739 | G2: 60206.846 | H2: 60808.915 | I2: 67497.896 | J2: 68172.875 | K2: 68854.603 | L2: 69543.149 | M2: 77192.896 | N2: 77964.825 | O2: 78744.473 | P2: 79531.918 | Q2: 88280.429 | R2: 89163.233 | S2: 90054.865 | T2: 90955.414 | U2: 100960.51 | V2: 101970.11 | W2: 102989.82 | X2: 104019.71 | Y2: 115461.88 | Z2: 116616.5 | AA2: 117782.67 | AB2: 118960.49 | AC2: 120150.1 | AD2: 121351.6 | AE2: 122565.11 | AF2: 123790.77 | AG2: 125028.67 | AH2: 126278.96 | AI2: 127541.75 | AJ2: 128817.17 | AK2: 130105.34 | AL2: 144416.93 | AM2: 145861.1 | AN2: 147319.71 | AO2: 148792.9 | AP2: 150280.83 | AQ2: 151783.64 | AR2: 153301.48 | AS2: 154834.49 | AT2: 156382.84 | AU2: 157946.67 | AV2: 0 | AW2: 0 | AX2: 0 | AY2: 0 | AZ2: 0
A3: P2 | B3: 200000 | C3: {=TRANSPOSE(TableIncome[InvestmentP2])} -> 76801.2 | D3: 77569.212 | E3: 78344.904 | F3: 86962.844 | G3: 87832.472 | H3: 88710.797 | I3: 89597.905 | J3: 99453.674 | K3: 100448.21 | L3: 101452.69 | M3: 102467.22 | N3: 103491.89 | O3: 104526.81 | P3: 105572.08 | Q3: 106627.8 | R3: 107694.08 | S3: 108771.02 | T3: 109858.73 | U3: 110957.32 | V3: 112066.89 | W3: 124394.25 | X3: 125638.19 | Y3: 126894.57 | Z3: 128163.52 | AA3: 129445.15 | AB3: 130739.6 | AC3: 132047 | AD3: 133367.47 | AE3: 134701.14 | AF3: 136048.16 | AG3: 0 | AH3: 0 | AI3: 0 | AJ3: 0 | AK3: 0 | AL3: 0 | AM3: 0 | AN3: 0 | AO3: 0 | AP3: 0 | AQ3: 0 | AR3: 0 | AS3: 0 | AT3: 0 | AU3: 0 | AV3: 0 | AW3: 0 | AX3: 0 | AY3: 0 | AZ3: 0

Sheet Wealth
B1: 2025 | C1: 2026 | D1: 2027 | E1: 2028 | F1: 2029 | G1: 2030 | H1: 2031 | I1: 2032 | J1: 2033 | K1: 2034 | L1: 2035 | M1: 2036 | N1: 2037 | O1: 2038 | P1: 2039 | Q1: 2040 | R1: 2041 | S1: 2042 | T1: 2043 | U1: 2044 | V1: 2045 | W1: 2046 | X1: 2047 | Y1: 2048 | Z1: 2049 | AA1: 2050 | AB1: 2051 | AC1: 2052 | AD1: 2053 | AE1: 2054 | AF1: 2055 | AG1: 2056 | AH1: 2057 | AI1: 2058 | AJ1: 2059 | AK1: 2060 | AL1: 2061 | AM1: 2062 | AN1: 2063 | AO1: 2064 | AP1: 2065 | AQ1: 2066 | AR1: 2067 | AS1: 2068 | AT1: 2069 | AU1: 2070 | AV1: 2071 | AW1: 2072 | AX1: 2073 | AY1: 2074 | AZ1: 2075
A2: P1 | B2: =SUMIF(TableIncome[Year], "<=" & B1, TableIncome[InvestmentP1]) -> 52645.2 | C2: =SUMIF(TableIncome[Year], "<=" & C1, TableIncome[InvestmentP1]) -> 105816.85 | D2: =SUMIF(TableIncome[Year], "<=" & D1, TableIncome[InvestmentP1]) -> 164837.39 | E2: =SUMIF(TableIncome[Year], "<=" & E1, TableIncome[InvestmentP1]) -> 224448.12 | F2: =SUMIF(TableIncome[Year], "<=" & F1, TableIncome[InvestmentP1]) -> 284654.97 | G2: =SUMIF(TableIncome[Year], "<=" & G1, TableIncome[InvestmentP1]) -> 345463.89 | H2: =SUMIF(TableIncome[Year], "<=" & H1, TableIncome[InvestmentP1]) -> 412961.78 | I2: =SUMIF(TableIncome[Year], "<=" & I1, TableIncome[InvestmentP1]) -> 481134.66 | ... AZ2: =SUMIF(TableIncome[Year], "<=" & AZ1, TableIncome[InvestmentP1]) -> 4806732.2
A3: P2 | B3: =SUMIF(TableIncome[Year], "<=" & B1, TableIncome[InvestmentP2]) -> 76801.2 | C3: =SUMIF(TableIncome[Year], "<=" & C1, TableIncome[InvestmentP2]) -> 154370.41 | D3: =SUMIF(TableIncome[Year], "<=" & D1, TableIncome[InvestmentP2]) -> 232715.32 | E3: =SUMIF(TableIncome[Year], "<=" & E1, TableIncome[InvestmentP2]) -> 319678.16 | F3: =SUMIF(TableIncome[Year], "<=" & F1, TableIncome[InvestmentP2]) -> 407510.63 | G3: =SUMIF(TableIncome[Year], "<=" & G1, TableIncome[InvestmentP2]) -> 496221.43 | H3: =SUMIF(TableIncome[Year], "<=" & H1, TableIncome[InvestmentP2]) -> 585819.33 | I3: =SUMIF(TableIncome[Year], "<=" & I1, TableIncome[InvestmentP2]) -> 685273.01 | ... AZ3: =SUMIF(TableIncome[Year], "<=" & AZ1, TableIncome[InvestmentP2]) -> 3260646.8

Sheet GBI Allocations P1
B1: 2025 | C1: 2026 | D1: 2027 | E1: 2028 | F1: 2029 | G1: 2030 | H1: 2031 | I1: 2032 | J1: 2033 | K1: 2034 | L1: 2035 | M1: 2036 | N1: 2037 | O1: 2038 | P1: 2039 | Q1: 2040 | R1: 2041 | S1: 2042 | T1: 2043 | U1: 2044 | V1: 2045 | W1: 2046 | X1: 2047 | Y1: 2048 | Z1: 2049 | AA1: 2050 | AB1: 2051 | AC1: 2052 | AD1: 2053 | AE1: 2054 | AF1: 2055 | AG1: 2056 | AH1: 2057 | AI1: 2058 | AJ1: 2059 | AK1: 2060 | AL1: 2061 | AM1: 2062 | AN1: 2063 | AO1: 2064 | AP1: 2065 | AQ1: 2066 | AR1: 2067 | AS1: 2068 | AT1: 2069 | AU1: 2070 | AV1: 2071 | AW1: 2072 | AX1: 2073 | AY1: 2074 | AZ1: 2075
A2: Emerging Markets - Equities | B2: 0.0945 | C2: 0.9803 | D2: 0.9922 | E2: 0.9932 | F2: 0.9932 | G2: 0.9915 | H2: 0.9905 | I2: 0.3382 | J2: 0.4326 | K2: 0.5072 | L2: 0.5657 | M2: 0.61 | N2: 0.6629 | O2: 0.6695 | P2: 0.7212 | Q2: 0.7102 | R2: 0.7531 | S2: 0.7633 | T2: 0.8 | U2: 0.7724 | V2: 0.8182 | W2: 0.8116 | X2: 0.8248 | Y2: 0.8687 | Z2: 0.8044 | AA2: 0.8884 | AB2: 0.9556 | AC2: 0.2567 | AD2: 0.2404 | AE2: 0.2562 | AF2: 0.2337 | AG2: 0.2474 | AH2: 0.2398 | AI2: 0.2451 | AJ2: 0.2378 | AK2: 0.2394 | AL2: 0.2465 | AM2: 0.2421 | AN2: 0.25 | AO2: 0.2335 | AP2: 0.2465 | AQ2: 0.239 | AR2: 0.1917 | AS2: 0.1667 | AT2: 0.0055 | AU2: 0 | AV2: 0.0013 | AW2: 0.0026 | AX2: 0.0026 | AY2: 0 | AZ2: 0.0254
A3: Developed Markets - Equities | B3: 0.1071 | C3: 0.0022 | D3: 0.0007 | E3: 0.0013 | F3: 0.0017 | G3: 0.0025 | H3: 0.0021 | I3: 0.0013 | J3: 0.0018 | K3: 0.0026 | L3: 0 | M3: 0 | N3: 0.0002 | O3: 0.0037 | P3: 0.0019 | Q3: 0.0006 | R3: 0.0048 | S3: 0.0017 | T3: 0 | U3: 0.0009 | V3: 0 | W3: 0.0014 | X3: 0.0035 | Y3: 0 | Z3: 0.0064 | AA3: 0.0024 | AB3: 0.0054 | AC3: 0.7185 | AD3: 0.6964 | AE3: 0.7155 | AF3: 0.7053 | AG3: 0.7045 | AH3: 0.68 | AI3: 0.6956 | AJ3: 0.696 | AK3: 0.6943 | AL3: 0.7092 | AM3: 0.6963 | AN3: 0.7249 | AO3: 0.68 | AP3: 0.7014 | AQ3: 0.6597 | AR3: 0.3683 | AS3: 0.2116 | AT3: 0.0002 | AU3: 0 | AV3: 0 | AW3: 0 | AX3: 0 | AY3: 0 | AZ3: 0.0585
A4: Emerging Markets State - Obligations | B4: 0.1839 | C4: 0.0017 | D4: 0.0018 | E4: 0.0031 | F4: 0.0021 | G4: 0.0022 | H4: 0.0024 | I4: 0.0014 | J4: 0.0019 | K4: 0.0021 | L4: 0 | M4: 0 | N4: 0.001 | O4: 0.0065 | P4: 0.002 | Q4: 0.0019 | R4: 0.002 | S4: 0.0025 | T4: 0 | U4: 0.0018 | V4: 0 | W4: 0.002 | X4: 0.0045 | Y4: 0 | Z4: 0.0016 | AA4: 0.0067 | AB4: 0.0007 | AC4: 0.0082 | AD4: 0.005 | AE4: 0.0088 | AF4: 0.0045 | AG4: 0.0068 | AH4: 0.0047 | AI4: 0.0024 | AJ4: 0.0037 | AK4: 0.0092 | AL4: 0.0005 | AM4: 0 | AN4: 0.0028 | AO4: 0.0027 | AP4: 0 | AQ4: 0.0012 | AR4: 0 | AS4: 0 | AT4: 0 | AU4: 0 | AV4: 0 | AW4: 0 | AX4: 0 | AY4: 0 | AZ4: 0.0578
A5: High Yield Bonds - Obligations | B5: 0.0607 | C5: 0.0004 | D5: 0.0011 | E5: 0.001 | F5: 0.0003 | G5: 0.0016 | H5: 0.0002 | I5: 0.0015 | J5: 0.0024 | K5: 0.0029 | L5: 0 | M5: 0 | N5: 0.0016 | O5: 0.0016 | P5: 0.0015 | Q5: 0.0001 | R5: 0.0006 | S5: 0.0001 | T5: 0 | U5: 0.0029 | V5: 0 | W5: 0.0014 | X5: 0.0014 | Y5: 0 | Z5: 0.0054 | AA5: 0.0173 | AB5: 0.0023 | AC5: 0.0052 | AD5: 0.0004 | AE5: 0.0044 | AF5: 0.0053 | AG5: 0.0093 | AH5: 0.0018 | AI5: 0.0006 | AJ5: 0.0046 | AK5: 0 | AL5: 0.0034 | AM5: 0.0003 | AN5: 0.0024 | AO5: 0.001 | AP5: 0 | AQ5: 0.001 | AR5: 0.0004 | AS5: 0 | AT5: 0 | AU5: 0 | AV5: 0 | AW5: 0 | AX5: 0 | AY5: 0 | AZ5: 0.0753
A6: Investment Grade Bonds - Obligations | B6: 0.1856 | C6: 0.0036 | D6: 0.0028 | E6: 0.0009 | F6: 0.002 | G6: 0.0003 | H6: 0.0022 | I6: 0.0037 | J6: 0.001 | K6: 0 | L6: 0 | M6: 0 | N6: 0.0026 | O6: 0.0053 | P6: 0.0025 | Q6: 0.0041 | R6: 0.0058 | S6: 0.0025 | T6: 0 | U6: 0.0023 | V6: 0 | W6: 0.0005 | X6: 0.0041 | Y6: 0 | Z6: 0.0072 | AA6: 0.0352 | AB6: 0.006 | AC6: 0.0108 | AD6: 0.0057 | AE6: 0.0017 | AF6: 0.0164 | AG6: 0.0104 | AH6: 0.0055 | AI6: 0.0185 | AJ6: 0.0079 | AK6: 0.0053 | AL6: 0.0211 | AM6: 0.011 | AN6: 0.0113 | AO6: 0.0062 | AP6: 0.0101 | AQ6: 0.0045 | AR6: 0.0067 | AS6: 0.0234 | AT6: 0.0062 | AU6: 0 | AV6: 0.0045 | AW6: 0.0029 | AX6: 0.0023 | AY6: 0 | AZ6: 0.0734
A7: Government ZC Bonds - Obligations | B7: 0.3683 | C7: 0.0117 | D7: 0.0015 | E7: 0.0004 | F7: 0.0008 | G7: 0.0019 | H7: 0.0026 | I7: 0.6539 | J7: 0.5603 | K7: 0.4852 | L7: 0.4343 | M7: 0.39 | N7: 0.3318 | O7: 0.3134 | P7: 0.2709 | Q7: 0.283 | R7: 0.2337 | S7: 0.2299 | T7: 0.2 | U7: 0.2197 | V7: 0.1818 | W7: 0.1831 | X7: 0.1617 | Y7: 0.1313 | Z7: 0.175 | AA7: 0.05 | AB7: 0.03 | AC7: 0.0006 | AD7: 0.052 | AE7: 0.0135 | AF7: 0.0348 | AG7: 0.0216 | AH7: 0.0682 | AI7: 0.0378 | AJ7: 0.0499 | AK7: 0.0517 | AL7: 0.0193 | AM7: 0.0502 | AN7: 0.0086 | AO7: 0.0766 | AP7: 0.0421 | AQ7: 0.0945 | AR7: 0.4329 | AS7: 0.5982 | AT7: 0.988 | AU7: 1 | AV7: 0.9943 | AW7: 0.9945 | AX7: 0.9952 | AY7: 1 | AZ7: 0.7096

Sheet GBI Allocations P2
B1: 2025 | C1: 2026 | D1: 2027 | E1: 2028 | F1: 2029 | G1: 2030 | H1: 2031 | I1: 2032 | J1: 2033 | K1: 2034 | L1: 2035 | M1: 2036 | N1: 2037 | O1: 2038 | P1: 2039 | Q1: 2040 | R1: 2041 | S1: 2042 | T1: 2043 | U1: 2044 | V1: 2045 | W1: 2046 | X1: 2047 | Y1: 2048 | Z1: 2049 | AA1: 2050 | AB1: 2051 | AC1: 2052 | AD1: 2053 | AE1: 2054 | AF1: 2055 | AG1: 2056 | AH1: 2057 | AI1: 2058 | AJ1: 2059 | AK1: 2060 | AL1: 2061 | AM1: 2062 | AN1: 2063 | AO1: 2064 | AP1: 2065 | AQ1: 2066 | AR1: 2067 | AS1: 2068 | AT1: 2069 | AU1: 2070 | AV1: 2071 | AW1: 2072 | AX1: 2073 | AY1: 2074 | AZ1: 2075
A2: Emerging Markets - Equities
A3: Developed Markets - Equities
A4: Emerging Markets State - Obligations
A5: High Yield Bonds - Obligations
A6: Investment Grade Bonds - Obligations
A7: Government ZC Bonds - Obligations

Sheet notes next time talk
B3: Excel side:
B4: Goal calculation
B5: Investment income calculation
B6: For retirement goal: Calculate what the amount needed is and also research from denmark statistik what is the median returns by retirement age.
B7: Returns input with samsseewfwfuweerhugf for long term, and simulation for short term
B9: Python side:
B13: Question for Johan:
B14: Vasicek ready, what do we use bond simulation for? How does it correlate to bond ETF
B18: From last meeting Johan mentioned you can put the tax money back into the account???? What does this mean I am not sure: Saxo bank shows this below which might explain
B37: Update: I KNOW WHAT HE MEANT AHAHAHA IM A GENIOUS!!!! So basically it means that (from what I understand) the 17% tax deducts from your available input amount, allowing to deposit more into the account.
C41: Here
D42: Return | E42: Vol
C43: ZC Bond | D43: 0.03 | E43: 0.01 | H43: 2025 | I43: 2026 | J43: 2027 | M43: Use value simulated for each year or the average | N43: Split each goal into a per year goal, so achieve a % of the total goal in that year, and then the model would actually work as is
C44: SP | D44: 0.1 | E44: 0.03 | H44: 0.03 | I44: 0.04 | J44: 0.06 | K44: 0.07 | L44: 0.1
H46: =AVERAGE(H44:L44) -> 0.06 | I46: =AVERAGE(I44:L44) -> 0.0675
J51: Goal: House | L51: in 10 years
J53: 2025 | K53: 2026 | L53: 2027 | M53: 2028 | N53: 2029 | O53: 2030 | P53: 2031 | Q53: 2032 | R53: 2033 | S53: 2034 | U53: Total
J54: =$U$54*10% -> 200000 | K54: =$U$54*10% -> 200000 | L54: =$U$54*10% -> 200000 | M54: =$U$54*10% -> 200000 | N54: =$U$54*10% -> 200000 | O54: =$U$54*10% -> 200000 | P54: =$U$54*10% -> 200000 | Q54: =$U$54*10% -> 200000 | ... S54: =$U$54*10% -> 200000 | U54: 2000000
B57: Task for the master file

Sheet GBI Goals P2
B1: 2025 | C1: 2026 | D1: 2027 | E1: 2028 | F1: 2029 | G1: 2030 | H1: 2031 | I1: 2032 | J1: 2033 | K1: 2034 | L1: 2035 | M1: 2036 | N1: 2037 | O1: 2038 | P1: 2039 | Q1: 2040 | R1: 2041 | S1: 2042 | T1: 2043 | U1: 2044 | V1: 2045 | W1: 2046 | X1: 2047 | Y1: 2048 | Z1: 2049 | AA1: 2050 | AB1: 2051 | AC1: 2052 | AD1: 2053 | AE1: 2054 | AF1: 2055 | AG1: 2056 | AH1: 2057 | AI1: 2058 | AJ1: 2059 | AK1: 2060 | AL1: 2061 | AM1: 2062 | AN1: 2063 | AO1: 2064 | AP1: 2065 | AQ1: 2066 | AR1: 2067 | AS1: 2068 | AT1: 2069 | AU1: 2070 | AV1: 2071 | AW1: 2072 | AX1: 2073 | AY1: 2074 | AZ1: 2075
A2: A
A3: B
A4: C
A5: D

Sheet Returns
B1: 2025 | C1: 2026 | D1: 2027 | E1: 2028 | F1: 2029 | G1: 2030 | H1: 2031 | I1: 2032 | J1: 2033 | K1: 2034 | L1: 2035 | M1: 2036 | N1: 2037 | O1: 2038 | P1: 2039 | Q1: 2040 | R1: 2041 | S1: 2042 | T1: 2043 | U1: 2044 | V1: 2045 | W1: 2046 | X1: 2047 | Y1: 2048 | Z1: 2049 | AA1: 2050 | AB1: 2051 | AC1: 2052 | AD1: 2053 | AE1: 2054 | AF1: 2055 | AG1: 2056 | AH1: 2057 | AI1: 2058 | AJ1: 2059 | AK1: 2060 | AL1: 2061 | AM1: 2062 | AN1: 2063 | AO1: 2064 | AP1: 2065 | AQ1: 2066 | AR1: 2067 | AS1: 2068 | AT1: 2069 | AU1: 2070 | AV1: 2071 | AW1: 2072 | AX1: 2073 | AY1: 2074 | AZ1: 2075
A2: Emerging Markets - Equities | B2: =8.6%-_xlfn.XLOOKUP(A2,BasisPointCost!$A:$A,BasisPointCost!$B:$B) -> 0.084 | C2: =B2 -> 0.084 | D2: =C2 -> 0.084 | E2: =D2 -> 0.084 | F2: =E2 -> 0.084 | G2: =F2 -> 0.084 | H2: =G2 -> 0.084 | I2: =H2 -> 0.084 | J2: =I2 -> 0.084 | K2: =J2 -> 0.084 | L2: =6.5%-0.2% -> 0.063 | M2: =L2 -> 0.063 | N2: =M2 -> 0.063 | O2: =N2 -> 0.063 | P2: =O2 -> 0.063 | Q2: =P2 -> 0.063 | R2: =Q2 -> 0.063 | S2: =R2 -> 0.063 | T2: =S2 -> 0.063 | ... AZ2: =AY2 -> 0.063
A3: Developed Markets - Equities | B3: =7%-_xlfn.XLOOKUP(A3,BasisPointCost!$A:$A,BasisPointCost!$B:$B) -> 0.068 | C3: =B3 -> 0.068 | D3: =C3 -> 0.068 | E3: =D3 -> 0.068 | F3: =E3 -> 0.068 | G3: =F3 -> 0.068 | H3: =G3 -> 0.068 | I3: =H3 -> 0.068 | J3: =I3 -> 0.068 | K3: =J3 -> 0.068 | L3: =6.5%-0.2% -> 0.063 | M3: =L3 -> 0.063 | N3: =M3 -> 0.063 | O3: =N3 -> 0.063 | P3: =O3 -> 0.063 | Q3: =P3 -> 0.063 | R3: =Q3 -> 0.063 | S3: =R3 -> 0.063 | T3: =S3 -> 0.063 | ... AZ3: =AY3 -> 0.063
A4: Emerging Markets State - Obligations | B4: =4.9%-_xlfn.XLOOKUP(A4,BasisPointCost!$A:$A,BasisPointCost!$B:$B) -> 0.0483 | C4: =B4 -> 0.0483 | D4: =C4 -> 0.0483 | E4: =D4 -> 0.0483 | F4: =E4 -> 0.0483 | G4: =F4 -> 0.0483 | H4: =G4 -> 0.0483 | I4: =H4 -> 0.0483 | J4: =I4 -> 0.0483 | K4: =J4 -> 0.0483 | L4: =3.5%-0.07% -> 0.0343 | M4: =L4 -> 0.0343 | N4: =M4 -> 0.0343 | O4: =N4 -> 0.0343 | P4: =O4 -> 0.0343 | Q4: =P4 -> 0.0343 | R4: =Q4 -> 0.0343 | S4: =R4 -> 0.0343 | T4: =S4 -> 0.0343 | ... AZ4: =AY4 -> 0.0343
A5: High Yield Bonds - Obligations | B5: =5%-_xlfn.XLOOKUP(A5,BasisPointCost!$A:$A,BasisPointCost!$B:$B) -> 0.0493 | C5: =B5 -> 0.0493 | D5: =C5 -> 0.0493 | E5: =D5 -> 0.0493 | F5: =E5 -> 0.0493 | G5: =F5 -> 0.0493 | H5: =G5 -> 0.0493 | I5: =H5 -> 0.0493 | J5: =I5 -> 0.0493 | K5: =J5 -> 0.0493 | L5: =3.5%-0.07% -> 0.0343 | M5: =L5 -> 0.0343 | N5: =M5 -> 0.0343 | O5: =N5 -> 0.0343 | P5: =O5 -> 0.0343 | Q5: =P5 -> 0.0343 | R5: =Q5 -> 0.0343 | S5: =R5 -> 0.0343 | T5: =S5 -> 0.0343 | ... AZ5: =AY5 -> 0.0343
A6: Investment Grade Bonds - Obligations | B6: =3.7%-_xlfn.XLOOKUP(A6,BasisPointCost!$A:$A,BasisPointCost!$B:$B) -> 0.0363 | C6: =B6 -> 0.0363 | D6: =C6 -> 0.0363 | E6: =D6 -> 0.0363 | F6: =E6 -> 0.0363 | G6: =F6 -> 0.0363 | H6: =G6 -> 0.0363 | I6: =H6 -> 0.0363 | J6: =I6 -> 0.0363 | K6: =J6 -> 0.0363 | L6: =3.5%-0.07% -> 0.0343 | M6: =L6 -> 0.0343 | N6: =M6 -> 0.0343 | O6: =N6 -> 0.0343 | P6: =O6 -> 0.0343 | Q6: =P6 -> 0.0343 | R6: =Q6 -> 0.0343 | S6: =R6 -> 0.0343 | T6: =S6 -> 0.0343 | ... AZ6: =AY6 -> 0.0343
A7: Government ZC Bonds - Obligations | B7: =2.9%-_xlfn.XLOOKUP($A7,BasisPointCost!$A:$A,BasisPointCost!$B:$B) -> 0.0283 | C7: =B7 -> 0.0283 | D7: =C7 -> 0.0283 | E7: =D7 -> 0.0283 | F7: =E7 -> 0.0283 | G7: =F7 -> 0.0283 | H7: =G7 -> 0.0283 | I7: =H7 -> 0.0283 | J7: =I7 -> 0.0283 | K7: =J7 -> 0.0283 | L7: =3.5%-0.07% -> 0.0343 | M7: =L7 -> 0.0343 | N7: =M7 -> 0.0343 | O7: =N7 -> 0.0343 | P7: =O7 -> 0.0343 | Q7: =P7 -> 0.0343 | R7: =Q7 -> 0.0343 | S7: =R7 -> 0.0343 | T7: =S7 -> 0.0343 | ... AZ7: =AY7 -> 0.0343

Sheet BasisPointCost
A1: Asset | B1: Cost (Basis Point) | C1: Link
A2: Emerging Markets - Equities | B2: =0.2% -> 0.002
A3: Developed Markets - Equities | B3: =0.2% -> 0.002
A4: Emerging Markets State - Obligations | B4: =0.07% -> 0.0007
A5: High Yield Bonds - Obligations | B5: =0.07% -> 0.0007
A6: Investment Grade Bonds - Obligations | B6: =0.07% -> 0.0007
A7: Government ZC Bonds - Obligations | B7: =0.07% -> 0.0007

Sheet Returns2
B1: 2035 | C1: 2036 | D1: 2037 | E1: 2038 | F1: 2039 | G1: 2040 | H1: 2041 | I1: 2042 | J1: 2043 | K1: 2044 | L1: 2045 | M1: 2046 | N1: 2047 | O1: 2048 | P1: 2049 | Q1: 2050 | R1: 2051 | S1: 2052 | T1: 2053 | U1: 2054 | V1: 2055 | W1: 2056 | X1: 2057 | Y1: 2058 | Z1: 2059 | AA1: 2060 | AB1: 2061 | AC1: 2062 | AD1: 2063 | AE1: 2064 | AF1: 2065 | AG1: 2066 | AH1: 2067 | AI1: 2068 | AJ1: 2069 | AK1: 2070 | AL1: 2071 | AM1: 2072 | AN1: 2073 | AO1: 2074 | AP1: 2075
A2: Equities | B2: =6.5%-0.2% -> 0.063 | C2: =B2 -> 0.063 | D2: =C2 -> 0.063 | E2: =D2 -> 0.063 | F2: =E2 -> 0.063 | G2: =F2 -> 0.063 | H2: =G2 -> 0.063 | I2: =H2 -> 0.063 | J2: =I2 -> 0.063 | ... AP2: =AO2 -> 0.063
A3: Obligations | B3: =3.5%-0.07% -> 0.0343 | C3: =B3 -> 0.0343 | D3: =C3 -> 0.0343 | E3: =D3 -> 0.0343 | F3: =E3 -> 0.0343 | G3: =F3 -> 0.0343 | H3: =G3 -> 0.0343 | I3: =H3 -> 0.0343 | J3: =I3 -> 0.0343 | ... AP3: =AO3 -> 0.0343

Sheet Volatilities
B1: volatility
A2: Emerging Markets - Equities | B2: 0.086
A3: Developed Markets - Equities | B3: 0.07
A4: Emerging Markets State - Obligations | B4: 0.049
A5: High Yield Bonds - Obligations | B5: 0.05
A6: Investment Grade Bonds - Obligations | B6: 0.037
A7: Government ZC Bonds - Obligations | B7: 0.029

Sheet Volatilities2
B1: volatility
A2: Equities | B2: 0.18
A3: Obligations | B3: 0.08

Sheet Correlation
B1: Government ZC Bonds - Obligations | C1: Investment Grade Bonds - Obligations | D1: High Yield Bonds - Obligations | E1: Emerging Markets State - Obligations | F1: Developed Markets - Equities | G1: Emerging Markets - Equities
A2: Government ZC Bonds - Obligations | B2: 1 | C2: 0.6 | D2: 0.2 | E2: 0.4 | F2: 0 | G2: 0
A3: Investment Grade Bonds - Obligations | B3: 0.6 | C3: 1 | D3: 0.7 | E3: 0.6 | F3: 0.3 | G3: 0.3
A4: High Yield Bonds - Obligations | B4: 0.2 | C4: 0.7 | D4: 1 | E4: 0.7 | F4: 0.7 | G4: 0.6
A5: Emerging Markets State - Obligations | B5: 0.4 | C5: 0.6 | D5: 0.7 | E5: 1 | F5: 0.5 | G5: 0.7
A6: Developed Markets - Equities | B6: 0 | C6: 0.3 | D6: 0.7 | E6: 0.5 | F6: 1 | G6: 0.7
A7: Emerging Markets - Equities | B7: 0 | C7: 0.3 | D7: 0.6 | E7: 0.7 | F7: 0.7 | G7: 1

Sheet Correlation2
B1: Obligations | C1: Equities
A2: {=TRANSPOSE(B1:C1)} -> Obligations | B2: 1 | C2: 0
A3: Equities | B3: 0 | C3: 1

Sheet Income
B2: Year | C2: SalaryP1 | D2: SalaryP2 | E2: InvestmentP1 | F2: InvestmentP2 | H2: Inflation | I2: 0.04 | M2: GrossMonthlySalaryP1 | N2: GrossMonthlySalaryP2 | O2: SwitchP1 | P2: SwitchP2
B3: 2025 | C3: =(TableIncomeCalculations[[#This Row],[GrossMonthlySalaryP1]]*12) -> 526452 | D3: =(TableIncomeCalculations[[#This Row],[GrossMonthlySalaryP2]]*12) -> 768012 | E3: =TableIncome[[#This Row],[SalaryP1]]*$I$6 -> 52645.2 | F3: =TableIncome[[#This Row],[SalaryP2]]*$I$6 -> 76801.2 | H3: Salary Raise | I3: 0.05 | M3: 43871 | N3: 64001 | O3: =_xlfn.XLOOKUP(_xlfn.XLOOKUP(TableIncome[[#This Row],[Year]],Loop!C:C,Loop!D:D),'Job Hopping'!B:B,'Job Hopping'!F:F) -> N | P3: =_xlfn.XLOOKUP(_xlfn.XLOOKUP(TableIncome[[#This Row],[Year]],Loop!C:C,Loop!E:E),'Job Hopping'!B:B,'Job Hopping'!G:G) -> N
B4: 2026 | C4: =(TableIncomeCalculations[[#This Row],[GrossMonthlySalaryP1]]*12) -> 531716.52 | D4: =(TableIncomeCalculations[[#This Row],[GrossMonthlySalaryP2]]*12) -> 775692.12 | E4: =TableIncome[[#This Row],[SalaryP1]]*$I$6 -> 53171.652 | F4: =TableIncome[[#This Row],[SalaryP2]]*$I$6 -> 77569.212 | H4: Real Salary Raise | I4: =I3-I2 -> 0.01 | M4: =IF(_xlfn.XLOOKUP(TableIncome[[#This Row],[Year]],Loop!C:C,Loop!D:D)<70,(M3*(1+$I$4))+IF(TableIncomeCalculations[[#This Row],[SwitchP1]]="Y",M3*$I$5,0),0) -> 44309.71 | N4: =IF(_xlfn.XLOOKUP(TableIncome[[#This Row],[Year]],Loop!C:C,Loop!E:E)<70,(N3*(1+$I$4))+IF(TableIncomeCalculations[[#This Row],[SwitchP2]]="Y",N3*$I$5,0),0) -> 64641.01 | O4: =_xlfn.XLOOKUP(_xlfn.XLOOKUP(TableIncome[[#This Row],[Year]],Loop!C:C,Loop!D:D),'Job Hopping'!B:B,'Job Hopping'!F:F) -> N | P4: =_xlfn.XLOOKUP(_xlfn.XLOOKUP(TableIncome[[#This Row],[Year]],Loop!C:C,Loop!E:E),'Job Hopping'!B:B,'Job Hopping'!G:G) -> N
B5: 2027 | C5: =(TableIncomeCalculations[[#This Row],[GrossMonthlySalaryP1]]*12) -> 590205.34 | D5: =(TableIncomeCalculations[[#This Row],[GrossMonthlySalaryP2]]*12) -> 783449.04 | E5: =TableIncome[[#This Row],[SalaryP1]]*$I$6 -> 59020.534 | F5: =TableIncome[[#This Row],[SalaryP2]]*$I$6 -> 78344.904 | H5: Job Hopping "Bonus" | I5: 0.1 | M5: =IF(_xlfn.XLOOKUP(TableIncome[[#This Row],[Year]],Loop!C:C,Loop!D:D)<70,(M4*(1+$I$4))+IF(TableIncomeCalculations[[#This Row],[SwitchP1]]="Y",M4*$I$5,0),0) -> 49183.778 | N5: =IF(_xlfn.XLOOKUP(TableIncome[[#This Row],[Year]],Loop!C:C,Loop!E:E)<70,(N4*(1+$I$4))+IF(TableIncomeCalculations[[#This Row],[SwitchP2]]="Y",N4*$I$5,0),0) -> 65287.42 | O5: =_xlfn.XLOOKUP(_xlfn.XLOOKUP(TableIncome[[#This Row],[Year]],Loop!C:C,Loop!D:D),'Job Hopping'!B:B,'Job Hopping'!F:F) -> Y | P5: =_xlfn.XLOOKUP(_xlfn.XLOOKUP(TableIncome[[#This Row],[Year]],Loop!C:C,Loop!E:E),'Job Hopping'!B:B,'Job Hopping'!G:G) -> N
B6: 2028 | C6: =(TableIncomeCalculations[[#This Row],[GrossMonthlySalaryP1]]*12) -> 596107.39 | D6: =(TableIncomeCalculations[[#This Row],[GrossMonthlySalaryP2]]*12) -> 869628.44 | E6: =TableIncome[[#This Row],[SalaryP1]]*$I$6 -> 59610.739 | F6: =TableIncome[[#This Row],[SalaryP2]]*$I$6 -> 86962.844 | H6: % of salary dedicated to investments | I6: 0.1 | M6: =IF(_xlfn.XLOOKUP(TableIncome[[#This Row],[Year]],Loop!C:C,Loop!D:D)<70,(M5*(1+$I$4))+IF(TableIncomeCalculations[[#This Row],[SwitchP1]]="Y",M5*$I$5,0),0) -> 49675.616 | N6: =IF(_xlfn.XLOOKUP(TableIncome[[#This Row],[Year]],Loop!C:C,Loop!E:E)<70,(N5*(1+$I$4))+IF(TableIncomeCalculations[[#This Row],[SwitchP2]]="Y",N5*$I$5,0),0) -> 72469.036 | O6: =_xlfn.XLOOKUP(_xlfn.XLOOKUP(TableIncome[[#This Row],[Year]],Loop!C:C,Loop!D:D),'Job Hopping'!B:B,'Job Hopping'!F:F) -> N | P6: =_xlfn.XLOOKUP(_xlfn.XLOOKUP(TableIncome[[#This Row],[Year]],Loop!C:C,Loop!E:E),'Job Hopping'!B:B,'Job Hopping'!G:G) -> Y
B7: 2029 | C7: =(TableIncomeCalculations[[#This Row],[GrossMonthlySalaryP1]]*12) -> 602068.46 | D7: =(TableIncomeCalculations[[#This Row],[GrossMonthlySalaryP2]]*12) -> 878324.72 | E7: =TableIncome[[#This Row],[SalaryP1]]*$I$6 -> 60206.846 | F7: =TableIncome[[#This Row],[SalaryP2]]*$I$6 -> 87832.472 | M7: =IF(_xlfn.XLOOKUP(TableIncome[[#This Row],[Year]],Loop!C:C,Loop!D:D)<70,(M6*(1+$I$4))+IF(TableIncomeCalculations[[#This Row],[SwitchP1]]="Y",M6*$I$5,0),0) -> 50172.372 | N7: =IF(_xlfn.XLOOKUP(TableIncome[[#This Row],[Year]],Loop!C:C,Loop!E:E)<70,(N6*(1+$I$4))+IF(TableIncomeCalculations[[#This Row],[SwitchP2]]="Y",N6*$I$5,0),0) -> 73193.727 | O7: =_xlfn.XLOOKUP(_xlfn.XLOOKUP(TableIncome[[#This Row],[Year]],Loop!C:C,Loop!D:D),'Job Hopping'!B:B,'Job Hopping'!F:F) -> N | P7: =_xlfn.XLOOKUP(_xlfn.XLOOKUP(TableIncome[[#This Row],[Year]],Loop!C:C,Loop!E:E),'Job Hopping'!B:B,'Job Hopping'!G:G) -> N
B8: 2030 | C8: =(TableIncomeCalculations[[#This Row],[GrossMonthlySalaryP1]]*12) -> 608089.15 | D8: =(TableIncomeCalculations[[#This Row],[GrossMonthlySalaryP2]]*12) -> 887107.97 | E8: =TableIncome[[#This Row],[SalaryP1]]*$I$6 -> 60808.915 | F8: =TableIncome[[#This Row],[SalaryP2]]*$I$6 -> 88710.797 | M8: =IF(_xlfn.XLOOKUP(TableIncome[[#This Row],[Year]],Loop!C:C,Loop!D:D)<70,(M7*(1+$I$4))+IF(TableIncomeCalculations[[#This Row],[SwitchP1]]="Y",M7*$I$5,0),0) -> 50674.096 | N8: =IF(_xlfn.XLOOKUP(TableIncome[[#This Row],[Year]],Loop!C:C,Loop!E:E)<70,(N7*(1+$I$4))+IF(TableIncomeCalculations[[#This Row],[SwitchP2]]="Y",N7*$I$5,0),0) -> 73925.664 | O8: =_xlfn.XLOOKUP(_xlfn.XLOOKUP(TableIncome[[#This Row],[Year]],Loop!C:C,Loop!D:D),'Job Hopping'!B:B,'Job Hopping'!F:F) -> N | P8: =_xlfn.XLOOKUP(_xlfn.XLOOKUP(TableIncome[[#This Row],[Year]],Loop!C:C,Loop!E:E),'Job Hopping'!B:B,'Job Hopping'!G:G) -> N
B9: 2031 | C9: =(TableIncomeCalculations[[#This Row],[GrossMonthlySalaryP1]]*12) -> 674978.96 | D9: =(TableIncomeCalculations[[#This Row],[GrossMonthlySalaryP2]]*12) -> 895979.05 | E9: =TableIncome[[#This Row],[SalaryP1]]*$I$6 -> 67497.896 | F9: =TableIncome[[#This Row],[SalaryP2]]*$I$6 -> 89597.905 | M9: =IF(_xlfn.XLOOKUP(TableIncome[[#This Row],[Year]],Loop!C:C,Loop!D:D)<70,(M8*(1+$I$4))+IF(TableIncomeCalculations[[#This Row],[SwitchP1]]="Y",M8*$I$5,0),0) -> 56248.246 | N9: =IF(_xlfn.XLOOKUP(TableIncome[[#This Row],[Year]],Loop!C:C,Loop!E:E)<70,(N8*(1+$I$4))+IF(TableIncomeCalculations[[#This Row],[SwitchP2]]="Y",N8*$I$5,0),0) -> 74664.921 | O9: =_xlfn.XLOOKUP(_xlfn.XLOOKUP(TableIncome[[#This Row],[Year]],Loop!C:C,Loop!D:D),'Job Hopping'!B:B,'Job Hopping'!F:F) -> Y | P9: =_xlfn.XLOOKUP(_xlfn.XLOOKUP(TableIncome[[#This Row],[Year]],Loop!C:C,Loop!E:E),'Job Hopping'!B:B,'Job Hopping'!G:G) -> N
B10: 2032 | C10: =(TableIncomeCalculations[[#This Row],[GrossMonthlySalaryP1]]*12) -> 681728.75 | D10: =(TableIncomeCalculations[[#This Row],[GrossMonthlySalaryP2]]*12) -> 994536.74 | E10: =TableIncome[[#This Row],[SalaryP1]]*$I$6 -> 68172.875 | F10: =TableIncome[[#This Row],[SalaryP2]]*$I$6 -> 99453.674 | M10: =IF(_xlfn.XLOOKUP(TableIncome[[#This Row],[Year]],Loop!C:C,Loop!D:D)<70,(M9*(1+$I$4))+IF(TableIncomeCalculations[[#This Row],[SwitchP1]]="Y",M9*$I$5,0),0) -> 56810.729 | N10: =IF(_xlfn.XLOOKUP(TableIncome[[#This Row],[Year]],Loop!C:C,Loop!E:E)<70,(N9*(1+$I$4))+IF(TableIncomeCalculations[[#This Row],[SwitchP2]]="Y",N9*$I$5,0),0) -> 82878.062 | O10: =_xlfn.XLOOKUP(_xlfn.XLOOKUP(TableIncome[[#This Row],[Year]],Loop!C:C,Loop!D:D),'Job Hopping'!B:B,'Job Hopping'!F:F) -> N | P10: =_xlfn.XLOOKUP(_xlfn.XLOOKUP(TableIncome[[#This Row],[Year]],Loop!C:C,Loop!E:E),'Job Hopping'!B:B,'Job Hopping'!G:G) -> Y
B11: 2033 | C11: =(TableIncomeCalculations[[#This Row],[GrossMonthlySalaryP1]]*12) -> 688546.03 | D11: =(TableIncomeCalculations[[#This Row],[GrossMonthlySalaryP2]]*12) -> 1004482.1 | E11: =TableIncome[[#This Row],[SalaryP1]]*$I$6 -> 68854.603 | F11: =TableIncome[[#This Row],[SalaryP2]]*$I$6 -> 100448.21 | M11: =IF(_xlfn.XLOOKUP(TableIncome[[#This Row],[Year]],Loop!C:C,Loop!D:D)<70,(M10*(1+$I$4))+IF(TableIncomeCalculations[[#This Row],[SwitchP1]]="Y",M10*$I$5,0),0) -> 57378.836 | N11: =IF(_xlfn.XLOOKUP(TableIncome[[#This Row],[Year]],Loop!C:C,Loop!E:E)<70,(N10*(1+$I$4))+IF(TableIncomeCalculations[[#This Row],[SwitchP2]]="Y",N10*$I$5,0),0) -> 83706.842 | O11: =_xlfn.XLOOKUP(_xlfn.XLOOKUP(TableIncome[[#This Row],[Year]],Loop!C:C,Loop!D:D),'Job Hopping'!B:B,'Job Hopping'!F:F) -> N | P11: =_xlfn.XLOOKUP(_xlfn.XLOOKUP(TableIncome[[#This Row],[Year]],Loop!C:C,Loop!E:E),'Job Hopping'!B:B,'Job Hopping'!G:G) -> N
B12: 2034 | C12: =(TableIncomeCalculations[[#This Row],[GrossMonthlySalaryP1]]*12) -> 695431.49 | D12: =(TableIncomeCalculations[[#This Row],[GrossMonthlySalaryP2]]*12) -> 1014526.9 | E12: =TableIncome[[#This Row],[SalaryP1]]*$I$6 -> 69543.149 | F12: =TableIncome[[#This Row],[SalaryP2]]*$I$6 -> 101452.69 | M12: =IF(_xlfn.XLOOKUP(TableIncome[[#This Row],[Year]],Loop!C:C,Loop!D:D)<70,(M11*(1+$I$4))+IF(TableIncomeCalculations[[#This Row],[SwitchP1]]="Y",M11*$I$5,0),0) -> 57952.624 | N12: =IF(_xlfn.XLOOKUP(TableIncome[[#This Row],[Year]],Loop!C:C,Loop!E:E)<70,(N11*(1+$I$4))+IF(TableIncomeCalculations[[#This Row],[SwitchP2]]="Y",N11*$I$5,0),0) -> 84543.911 | O12: =_xlfn.XLOOKUP(_xlfn.XLOOKUP(TableIncome[[#This Row],[Year]],Loop!C:C,Loop!D:D),'Job Hopping'!B:B,'Job Hopping'!F:F) -> N | P12: =_xlfn.XLOOKUP(_xlfn.XLOOKUP(TableIncome[[#This Row],[Year]],Loop!C:C,Loop!E:E),'Job Hopping'!B:B,'Job Hopping'!G:G) -> N
B13: 2035 | C13: =(TableIncomeCalculations[[#This Row],[GrossMonthlySalaryP1]]*12) -> 771928.96 | D13: =(TableIncomeCalculations[[#This Row],[GrossMonthlySalaryP2]]*12) -> 1024672.2 | E13: =TableIncome[[#This Row],[SalaryP1]]*$I$6 -> 77192.896 | F13: =TableIncome[[#This Row],[SalaryP2]]*$I$6 -> 102467.22 | M13: =IF(_xlfn.XLOOKUP(TableIncome[[#This Row],[Year]],Loop!C:C,Loop!D:D)<70,(M12*(1+$I$4))+IF(TableIncomeCalculations[[#This Row],[SwitchP1]]="Y",M12*$I$5,0),0) -> 64327.413 | N13: =IF(_xlfn.XLOOKUP(TableIncome[[#This Row],[Year]],Loop!C:C,Loop!E:E)<70,(N12*(1+$I$4))+IF(TableIncomeCalculations[[#This Row],[SwitchP2]]="Y",N12*$I$5,0),0) -> 85389.35 | O13: =_xlfn.XLOOKUP(_xlfn.XLOOKUP(TableIncome[[#This Row],[Year]],Loop!C:C,Loop!D:D),'Job Hopping'!B:B,'Job Hopping'!F:F) -> Y | P13: =_xlfn.XLOOKUP(_xlfn.XLOOKUP(TableIncome[[#This Row],[Year]],Loop!C:C,Loop!E:E),'Job Hopping'!B:B,'Job Hopping'!G:G) -> N
B14: 2036 | C14: =(TableIncomeCalculations[[#This Row],[GrossMonthlySalaryP1]]*12) -> 779648.25 | D14: =(TableIncomeCalculations[[#This Row],[GrossMonthlySalaryP2]]*12) -> 1034918.9 | E14: =TableIncome[[#This Row],[SalaryP1]]*$I$6 -> 77964.825 | F14: =TableIncome[[#This Row],[SalaryP2]]*$I$6 -> 103491.89 | M14: =IF(_xlfn.XLOOKUP(TableIncome[[#This Row],[Year]],Loop!C:C,Loop!D:D)<70,(M13*(1+$I$4))+IF(TableIncomeCalculations[[#This Row],[SwitchP1]]="Y",M13*$I$5,0),0) -> 64970.687 | N14: =IF(_xlfn.XLOOKUP(TableIncome[[#This Row],[Year]],Loop!C:C,Loop!E:E)<70,(N13*(1+$I$4))+IF(TableIncomeCalculations[[#This Row],[SwitchP2]]="Y",N13*$I$5,0),0) -> 86243.243 | O14: =_xlfn.XLOOKUP(_xlfn.XLOOKUP(TableIncome[[#This Row],[Year]],Loop!C:C,Loop!D:D),'Job Hopping'!B:B,'Job Hopping'!F:F) -> N | P14: =_xlfn.XLOOKUP(_xlfn.XLOOKUP(TableIncome[[#This Row],[Year]],Loop!C:C,Loop!E:E),'Job Hopping'!B:B,'Job Hopping'!G:G) -> N
