Workbook
Name _DLX1: [1]Rates!#REF!
Name _DLX1.INC: '[2]Car Air'!#REF!
Name _DLX10.INC: '[3]US&Europe'!#REF!
Name _DLX10_INC: #REF!
Name _DLX100.INC: '[3]Bonds Data BIS'!#REF!
Name _DLX14.INC: #REF!
Name _DLX15.INC: '[3]Bonds Data BIS'!#REF!
Name _DLX16.INC: '[3]Bonds Data BIS'!#REF!
Name _DLX2.INC: #REF!
Name _DLX20.INC: #REF!
Name _DLX3.INC: #REF!
Name _DLX4.INC: #REF!
Name _DLX5.INC: #REF!
Name _DLX5_INC: #REF!
Name _DLX50.INC: '[3]US&Europe'!#REF!
Name _DLX52.INC: #REF!
Name _DLX53.INC: '[3]US&Europe'!#REF!
Name _DLX54.INC: '[3]US&Europe'!#REF!
Name _DLX56.INC: '[3]US&Europe'!#REF!
Name _DLX6.INC: #REF!
Name _DLX60.INC: #REF!
Name _DLX7.INC: '[3]US&Europe'!#REF!
Name _DLX8.INC: '[3]US&Europe'!#REF!
Name _DLX80.INC: '[3]Bonds Data BIS'!#REF!
Name _DLX9.INC: '[3]US&Europe'!#REF!
Name AUD_Nom: #REF!
Name AUD_Tenor: #REF!
Name AUD_yr: #REF!
Name CAD_Nom: #REF!
Name CAD_Tenor: #REF!
Name CAD_yr: #REF!
Name CHF_Nom: #REF!
Name CHF_Tenor: #REF!
Name CHF_yr: #REF!
Name cn_asia: [4]Weights!$J$5
Name code: [5]CONSTANT!#REF!
Name Currency_cusip: '[6]Currency bucketing mapping'!$B$35:$B$160
Name Currency_name: '[6]Currency bucketing mapping'!$B$35:$BF$35
Name Currency_table: '[6]Currency bucketing mapping'!$B$35:$BF$160
Name D_0: #REF!
Name D_0_DE: #REF!
Name D_0_FR: #REF!
Name D_0_IT: #REF!
Name D_0_JP: #REF!
Name D_0_UK: #REF!
Name DaysInYear: [7]C!$B$29
Name DE_gwth: #REF!
Name DE_S: #REF!
Name ERP: [8]CF20!$C$18
Name EUR_Nom: #REF!
Name EUR_Tenor: #REF!
Name EUR_yr: #REF!
Name FR_gwth: #REF!
Name FR_S: #REF!
Name GBP_Nom: #REF!
Name GBP_Tenor: #REF!
Name GBP_yr: #REF!
Name gGDP: [8]CF20!$C$14
Name hk_asia: [4]Weights!$J$6
Name hk_nie: [4]Weights!$K$6

Sheet Index
B3: Sheet Colors
B4: Calculation
B5: Raw Report | C5: <-- If we download a report from a source, ex: Djøf, we will store it here and will not directly edit it
B6: Raw Report with Key | C6: <-- Raw Report but a column has been added for lookups
B8: Table Colors
B9: Uploaded to Python
B10: Not Uploaded to Python

Sheet Loop
B2: N | C2: Year | D2: AgeP1 | E2: AgeP2 | F2: LoopStatus
B3: 1 | C3: 2025 | D3: 25 | E3: 40 | F3: Y
B4: 2 | C4: 2026 | D4: =D3+1 -> 26 | E4: =E3+1 -> 41 | F4: Y
B5: 3 | C5: 2027 | D5: =D4+1 -> 27 | E5: =E4+1 -> 42 | F5: Y
B6: 4 | C6: 2028 | D6: =D5+1 -> 28 | E6: =E5+1 -> 43 | F6: Y
B7: 5 | C7: 2029 | D7: =D6+1 -> 29 | E7: =E6+1 -> 44 | F7: Y
B8: 6 | C8: 2030 | D8: =D7+1 -> 30 | E8: =E7+1 -> 45 | F8: Y
B9: 7 | C9: 2031 | D9: =D8+1 -> 31 | E9: =E8+1 -> 46 | F9: Y
B10: 8 | C10: 2032 | D10: =D9+1 -> 32 | E10: =E9+1 -> 47 | F10: Y
B11: 9 | C11: 2033 | D11: =D10+1 -> 33 | E11: =E10+1 -> 48 | F11: Y
B12: 10 | C12: 2034 | D12: =D11+1 -> 34 | E12: =E11+1 -> 49 | F12: Y
B13: 11 | C13: 2035 | D13: =D12+1 -> 35 | E13: =E12+1 -> 50 | F13: Y
B14: 12 | C14: 2036 | D14: =D13+1 -> 36 | E14: =E13+1 -> 51 | F14: Y
B15: 13 | C15: 2037 | D15: =D14+1 -> 37 | E15: =E14+1 -> 52 | F15: Y
... B53: 51 | C53: 2075 | D53: =D52+1 -> 75 | E53: =E52+1 -> 90 | F53: Y

Sheet Salary
B1: 2025 | C1: 2026 | D1: 2027 | E1: 2028 | F1: 2029 | G1: 2030 | H1: 2031 | I1: 2032 | J1: 2033 | K1: 2034 | L1: 2035 | M1: 2036 | N1: 2037 | O1: 2038 | P1: 2039 | Q1: 2040 | R1: 2041 | S1: 2042 | T1: 2043 | U1: 2044 | V1: 2045 | W1: 2046 | X1: 2047 | Y1: 2048 | Z1: 2049 | AA1: 2050 | AB1: 2051 | AC1: 2052 | AD1: 2053 | AE1: 2054 | AF1: 2055 | AG1: 2056 | AH1: 2057 | AI1: 2058 | AJ1: 2059 | AK1: 2060 | AL1: 2061 | AM1: 2062 | AN1: 2063 | AO1: 2064 | AP1: 2065 | AQ1: 2066 | AR1: 2067 | AS1: 2068 | AT1: 2069 | AU1: 2070 | AV1: 2071 | AW1: 2072 | AX1: 2073 | AY1: 2074
A2: P1 | B2: 0 | C2: {=TRANSPOSE(TableIncome[InvestmentP1])} -> 52645.2 | D2: 53171.652 | E2: 59020.534 | F2: 59610.739 | G2: 60206.846 | H2: 60808.915 | I2: 67497.896 | J2: 68172.875 | K2: 68854.603 | L2: 69543.149 | M2: 77192.896 | N2: 77964.825 | O2: 78744.473 | P2: 79531.918 | Q2: 88280.429 | R2: 89163.233 | S2: 90054.865 | T2: 90955.414 | U2: 100960.51 | V2: 101970.11 | W2: 102989.82 | X2: 104019.71 | Y2: 115461.88 | Z2: 116616.5 | AA2: 117782.67 | AB2: 118960.49 | AC2: 120150.1 | AD2: 121351.6 | AE2: 122565.11 | AF2: 123790.77 | AG2: 125028.67 | AH2: 126278.96 | AI2: 127541.75 | AJ2: 128817.17 | AK2: 130105.34 | AL2: 144416.93 | AM2: 145861.1 | AN2: 147319.71 | AO2: 148792.9 | AP2: 150280.83 | AQ2: 151783.64 | AR2: 153301.48 | AS2: 154834.49 | AT2: 156382.84 | AU2: 157946.67 | AV2: 0
A3: P2 | B3: 200000 | C3: {=TRANSPOSE(TableIncome[InvestmentP2])} -> 76801.2 | D3: 77569.212 | E3: 78344.904 | F3: 86962.844 | G3: 87832.472 | H3: 88710.797 | I3: 89597.905 | J3: 99453.674 | K3: 100448.21 | L3: 101452.69 | M3: 102467.22 | N3: 103491.89 | O3: 104526.81 | P3: 105572.08 | Q3: 106627.8 | R3: 107694.08 | S3: 108771.02 | T3: 109858.73 | U3: 110957.32 | V3: 112066.89 | W3: 124394.25 | X3: 125638.19 | Y3: 126894.57 | Z3: 128163.52 | AA3: 129445.15 | AB3: 130739.6 | AC3: 132047 | AD3: 133367.47 | AE3: 134701.14 | AF3: 136048.16 | AG3: 0 | AH3: 0 | AI3: 0 | AJ3: 0 | AK3: 0 | AL3: 0 | AM3: 0 | AN3: 0 | AO3: 0 | AP3: 0 | AQ3: 0 | AR3: 0 | AS3: 0 | AT3: 0 | AU3: 0 | AV3: 0

Sheet Wealth
B1: 2025 | C1: 2026 | D1: 2027 | E1: 2028 | F1: 2029 | G1: 2030 | H1: 2031 | I1: 2032 | J1: 2033 | K1: 2034 | L1: 2035 | M1: 2036 | N1: 2037 | O1: 2038 | P1: 2039 | Q1: 2040 | R1: 2041 | S1: 2042 | T1: 2043 | U1: 2044 | V1: 2045 | W1: 2046 | X1: 2047 | Y1: 2048 | Z1: 2049 | AA1: 2050 | AB1: 2051 | AC1: 2052 | AD1: 2053 | AE1: 2054 | AF1: 2055 | AG1: 2056 | AH1: 2057 | AI1: 2058 | AJ1: 2059 | AK1: 2060 | AL1: 2061 | AM1: 2062 | AN1: 2063 | AO1: 2064 | AP1: 2065 | AQ1: 2066 | AR1: 2067 | AS1: 2068 | AT1: 2069 | AU1: 2070 | AV1: 2071 | AW1: 2072 | AX1: 2073 | AY1: 2074 | AZ1: 2075
A2: P1 | B2: =SUMIF(TableIncome[Year], "<=" & B1, TableIncome[InvestmentP1]) -> 52645.2 | C2: =SUMIF(TableIncome[Year], "<=" & C1, TableIncome[InvestmentP1]) -> 105816.85 | D2: =SUMIF(TableIncome[Year], "<=" & D1, TableIncome[InvestmentP1]) -> 164837.39 | E2: =SUMIF(TableIncome[Year], "<=" & E1, TableIncome[InvestmentP1]) -> 224448.12 | F2: =SUMIF(TableIncome[Year], "<=" & F1, TableIncome[InvestmentP1]) -> 284654.97 | G2: =SUMIF(TableIncome[Year], "<=" & G1, TableIncome[InvestmentP1]) -> 345463.89 | H2: =SUMIF(TableIncome[Year], "<=" & H1, TableIncome[InvestmentP1]) -> 412961.78 | I2: =SUMIF(TableIncome[Year], "<=" & I1, TableIncome[InvestmentP1]) -> 481134.66 | ... AZ2: =SUMIF(TableIncome[Year], "<=" & AZ1, TableIncome[InvestmentP1]) -> 4806732.2
A3: P2 | B3: =SUMIF(TableIncome[Year], "<=" & B1, TableIncome[InvestmentP2]) -> 76801.2 | C3: =SUMIF(TableIncome[Year], "<=" & C1, TableIncome[InvestmentP2]) -> 154370.41 | D3: =SUMIF(TableIncome[Year], "<=" & D1, TableIncome[InvestmentP2]) -> 232715.32 | E3: =SUMIF(TableIncome[Year], "<=" & E1, TableIncome[InvestmentP2]) -> 319678.16 | F3: =SUMIF(TableIncome[Year], "<=" & F1, TableIncome[InvestmentP2]) -> 407510.63 | G3: =SUMIF(TableIncome[Year], "<=" & G1, TableIncome[InvestmentP2]) -> 496221.43 | H3: =SUMIF(TableIncome[Year], "<=" & H1, TableIncome[InvestmentP2]) -> 585819.33 | I3: =SUMIF(TableIncome[Year], "<=" & I1, TableIncome[InvestmentP2]) -> 685273.01 | ... AZ3: =SUMIF(TableIncome[Year], "<=" & AZ1, TableIncome[InvestmentP2]) -> 3260646.8

Sheet GBI Investment
B1: 2025 | C1: 2026 | D1: 2027 | E1: 2028 | F1: 2029 | G1: 2030 | H1: 2031 | I1: 2032 | J1: 2033 | K1: 2034 | L1: 2035 | M1: 2036 | N1: 2037 | O1: 2038 | P1: 2039 | Q1: 2040 | R1: 2041 | S1: 2042 | T1: 2043 | U1: 2044 | V1: 2045 | W1: 2046 | X1: 2047 | Y1: 2048 | Z1: 2049 | AA1: 2050 | AB1: 2051 | AC1: 2052 | AD1: 2053 | AE1: 2054 | AF1: 2055 | AG1: 2056 | AH1: 2057 | AI1: 2058 | AJ1: 2059 | AK1: 2060 | AL1: 2061 | AM1: 2062 | AN1: 2063 | AO1: 2064 | AP1: 2065 | AQ1: 2066 | AR1: 2067 | AS1: 2068 | AT1: 2069 | AU1: 2070 | AV1: 2071 | AW1: 2072 | AX1: 2073 | AY1: 2074 | AZ1: 2075
A2: Small Cap | B2: ='GBI Allocations P1'!B2*Wealth!B$2 -> 2279.5372 | C2: ='GBI Allocations P1'!C2*Wealth!C$2 -> 40379.711 | D2: ='GBI Allocations P1'!D2*Wealth!D$2 -> 155787.81 | E2: ='GBI Allocations P1'!E2*Wealth!E$2 -> 3119.8289 | F2: ='GBI Allocations P1'!F2*Wealth!F$2 -> 273610.36 | G2: ='GBI Allocations P1'!G2*Wealth!G$2 -> 339867.37 | H2: ='GBI Allocations P1'!H2*Wealth!H$2 -> 389670.74 | I2: ='GBI Allocations P1'!I2*Wealth!I$2 -> 450775.06 | ... AZ2: ='GBI Allocations P1'!AZ2*Wealth!AZ$2 -> 14900.87
A3: US Agg Bond | B3: ='GBI Allocations P1'!B3*Wealth!B$2 -> 7507.2055 | C3: ='GBI Allocations P1'!C3*Wealth!C$2 -> 275.12382 | D3: ='GBI Allocations P1'!D3*Wealth!D$2 -> 2373.6584 | E3: ='GBI Allocations P1'!E3*Wealth!E$2 -> 211430.13 | F3: ='GBI Allocations P1'!F3*Wealth!F$2 -> 1793.3263 | G3: ='GBI Allocations P1'!G3*Wealth!G$2 -> 1485.4947 | H3: ='GBI Allocations P1'!H3*Wealth!H$2 -> 6318.3153 | I3: ='GBI Allocations P1'!I3*Wealth!I$2 -> 4378.3254 | ... AZ3: ='GBI Allocations P1'!AZ3*Wealth!AZ$2 -> 27398.374
A4: Gold | B4: ='GBI Allocations P1'!B4*Wealth!B$2 -> 10.52904 | C4: ='GBI Allocations P1'!C4*Wealth!C$2 -> 1026.4235 | D4: ='GBI Allocations P1'!D4*Wealth!D$2 -> 989.02431 | E4: ='GBI Allocations P1'!E4*Wealth!E$2 -> 1773.1402 | F4: ='GBI Allocations P1'!F4*Wealth!F$2 -> 2277.2398 | G4: ='GBI Allocations P1'!G4*Wealth!G$2 -> 863.65972 | H4: ='GBI Allocations P1'!H4*Wealth!H$2 -> 3551.4713 | I4: ='GBI Allocations P1'!I4*Wealth!I$2 -> 8131.1757 | ... AZ4: ='GBI Allocations P1'!AZ4*Wealth!AZ$2 -> 1442.0197
A5: Private Equity | B5: ='GBI Allocations P1'!B5*Wealth!B$2 -> 17636.142 | C5: ='GBI Allocations P1'!C5*Wealth!C$2 -> 1386.2008 | D5: ='GBI Allocations P1'!D5*Wealth!D$2 -> 2439.5933 | E5: ='GBI Allocations P1'!E5*Wealth!E$2 -> 1458.9128 | F5: ='GBI Allocations P1'!F5*Wealth!F$2 -> 2561.8947 | G5: ='GBI Allocations P1'!G5*Wealth!G$2 -> 1381.8555 | H5: ='GBI Allocations P1'!H5*Wealth!H$2 -> 3386.2866 | I5: ='GBI Allocations P1'!I5*Wealth!I$2 -> 6543.4313 | ... AZ5: ='GBI Allocations P1'!AZ5*Wealth!AZ$2 -> 44221.936
A6: Venture Capital | B6: ='GBI Allocations P1'!B6*Wealth!B$2 -> 17625.613 | C6: ='GBI Allocations P1'!C6*Wealth!C$2 -> 61521.918 | D6: ='GBI Allocations P1'!D6*Wealth!D$2 -> 1714.3088 | E6: ='GBI Allocations P1'!E6*Wealth!E$2 -> 3501.3907 | F6: ='GBI Allocations P1'!F6*Wealth!F$2 -> 284.65497 | G6: ='GBI Allocations P1'!G6*Wealth!G$2 -> 1623.6803 | H6: ='GBI Allocations P1'!H6*Wealth!H$2 -> 4583.8758 | I6: ='GBI Allocations P1'!I6*Wealth!I$2 -> 288.68079 | ... AZ6: ='GBI Allocations P1'!AZ6*Wealth!AZ$2 -> 92769.931
A7: Angel Venture | B7: ='GBI Allocations P1'!B7*Wealth!B$2 -> 7586.1733 | C7: ='GBI Allocations P1'!C7*Wealth!C$2 -> 1227.4755 | D7: ='GBI Allocations P1'!D7*Wealth!D$2 -> 1532.9877 | E7: ='GBI Allocations P1'!E7*Wealth!E$2 -> 3164.7186 | F7: ='GBI Allocations P1'!F7*Wealth!F$2 -> 4099.0316 | G7: ='GBI Allocations P1'!G7*Wealth!G$2 -> 207.27833 | H7: ='GBI Allocations P1'!H7*Wealth!H$2 -> 5451.0955 | I7: ='GBI Allocations P1'!I7*Wealth!I$2 -> 11017.984 | ... AZ7: ='GBI Allocations P1'!AZ7*Wealth!AZ$2 -> 4625999.1

Sheet Aktiesparekonto
B1: 2025 | C1: 2026 | D1: 2027 | E1: 2028 | F1: 2029 | G1: 2030 | H1: 2031 | I1: 2032 | J1: 2033 | K1: 2034 | L1: 2035 | M1: 2036 | N1: 2037 | O1: 2038 | P1: 2039 | Q1: 2040 | R1: 2041 | S1: 2042 | T1: 2043 | U1: 2044 | V1: 2045 | W1: 2046 | X1: 2047 | Y1: 2048 | Z1: 2049 | AA1: 2050 | AB1: 2051 | AC1: 2052 | AD1: 2053 | AE1: 2054 | AF1: 2055 | AG1: 2056 | AH1: 2057 | AI1: 2058 | AJ1: 2059 | AK1: 2060 | AL1: 2061 | AM1: 2062 | AN1: 2063 | AO1: 2064 | AP1: 2065 | AQ1: 2066 | AR1: 2067 | AS1: 2068 | AT1: 2069 | AU1: 2070 | AV1: 2071 | AW1: 2072 | AX1: 2073 | AY1: 2074
A2: P1
A3: P2

Sheet GBI Allocations P1
B1: 2025 | C1: 2026 | D1: 2027 | E1: 2028 | F1: 2029 | G1: 2030 | H1: 2031 | I1: 2032 | J1: 2033 | K1: 2034 | L1: 2035 | M1: 2036 | N1: 2037 | O1: 2038 | P1: 2039 | Q1: 2040 | R1: 2041 | S1: 2042 | T1: 2043 | U1: 2044 | V1: 2045 | W1: 2046 | X1: 2047 | Y1: 2048 | Z1: 2049 | AA1: 2050 | AB1: 2051 | AC1: 2052 | AD1: 2053 | AE1: 2054 | AF1: 2055 | AG1: 2056 | AH1: 2057 | AI1: 2058 | AJ1: 2059 | AK1: 2060 | AL1: 2061 | AM1: 2062 | AN1: 2063 | AO1: 2064 | AP1: 2065 | AQ1: 2066 | AR1: 2067 | AS1: 2068 | AT1: 2069 | AU1: 2070 | AV1: 2071 | AW1: 2072 | AX1: 2073 | AY1: 2074 | AZ1: 2075
A2: Emerging Markets - Equities | B2: 0.0433 | C2: 0.3816 | D2: 0.9451 | E2: 0.0139 | F2: 0.9612 | G2: 0.9838 | H2: 0.9436 | I2: 0.9369 | J2: 0.0086 | K2: 0.9742 | L2: 0.0198 | M2: 0.0525 | N2: 0.5834 | O2: 0.0013 | P2: 0.0136 | Q2: 0.968 | R2: 0.0097 | S2: 0.9748 | T2: 0.0007 | U2: 0.3801 | V2: 0.0032 | W2: 0.0049 | X2: 0.3474 | Y2: 0.1505 | Z2: 0.0691 | AA2: 0.9468 | AB2: 0.2854 | AC2: 0.0952 | AD2: 0.1136 | AE2: 0.0611 | AF2: 0.0313 | AG2: 0.055 | AH2: 0.0838 | AI2: 0.1792 | AJ2: 0.0433 | AK2: 0.0294 | AL2: 0.0119 | AM2: 0.0073 | AN2: 0.0168 | AO2: 0.0472 | AP2: 0.0101 | AQ2: 0 | AR2: 0.0048 | AS2: 0.0038 | AT2: 0.0182 | AU2: 0.0124 | AV2: 0.006 | AW2: 0.0088 | AX2: 0.0071 | AY2: 0.007 | AZ2: 0.0031
A3: Developed Markets - Equities | B3: 0.1426 | C3: 0.0026 | D3: 0.0144 | E3: 0.942 | F3: 0.0063 | G3: 0.0043 | H3: 0.0153 | I3: 0.0091 | J3: 0.0064 | K3: 0.0037 | L3: 0.0471 | M3: 0.0038 | N3: 0.0533 | O3: 0.9373 | P3: 0.0007 | Q3: 0.0051 | R3: 0.0009 | S3: 0.003 | T3: 0.0003 | U3: 0.3445 | V3: 0.9394 | W3: 0.9504 | X3: 0.0152 | Y3: 0.0735 | Z3: 0.1361 | AA3: 0.0141 | AB3: 0.2473 | AC3: 0.0372 | AD3: 0.0551 | AE3: 0.0721 | AF3: 0.0624 | AG3: 0.0056 | AH3: 0.0016 | AI3: 0.0551 | AJ3: 0.1078 | AK3: 0.011 | AL3: 0.0219 | AM3: 0.0114 | AN3: 0.0064 | AO3: 0.0095 | AP3: 0.0116 | AQ3: 0 | AR3: 0.0253 | AS3: 0.0068 | AT3: 0.0373 | AU3: 0.005 | AV3: 0.0051 | AW3: 0.0235 | AX3: 0.0016 | AY3: 0.0119 | AZ3: 0.0057
A4: Emerging Markets State - Obligations | B4: 0.0002 | C4: 0.0097 | D4: 0.006 | E4: 0.0079 | F4: 0.008 | G4: 0.0025 | H4: 0.0086 | I4: 0.0169 | J4: 0.9585 | K4: 0.0122 | L4: 0.0115 | M4: 0.0006 | N4: 0.0571 | O4: 0.0205 | P4: 0.956 | Q4: 0.0096 | R4: 0.0048 | S4: 0.0023 | T4: 0.0096 | U4: 0.0193 | V4: 0.0194 | W4: 0.0128 | X4: 0.0077 | Y4: 0.2119 | Z4: 0.1147 | AA4: 0.0148 | AB4: 0.2588 | AC4: 0.1309 | AD4: 0.1384 | AE4: 0.0649 | AF4: 0.0667 | AG4: 0.1135 | AH4: 0.1231 | AI4: 0.0249 | AJ4: 0.0874 | AK4: 0.0031 | AL4: 0.0226 | AM4: 0.0002 | AN4: 0.0051 | AO4: 0.037 | AP4: 0.0152 | AQ4: 0.0526 | AR4: 0.0176 | AS4: 0.0002 | AT4: 0.034 | AU4: 0.0018 | AV4: 0.0033 | AW4: 0.0143 | AX4: 0.0016 | AY4: 0.0141 | AZ4: 0.0003
A5: High Yield Bonds - Obligations | B5: 0.335 | C5: 0.0131 | D5: 0.0148 | E5: 0.0065 | F5: 0.009 | G5: 0.004 | H5: 0.0082 | I5: 0.0136 | J5: 0.0099 | K5: 0.0066 | L5: 0.8737 | M5: 0.9287 | N5: 0.1385 | O5: 0.0005 | P5: 0.0066 | Q5: 0.0041 | R5: 0.9728 | S5: 0.0083 | T5: 0.6053 | U5: 0.2337 | V5: 0.0179 | W5: 0.0086 | X5: 0.1947 | Y5: 0.0486 | Z5: 0.1732 | AA5: 0.0091 | AB5: 0.0573 | AC5: 0.1225 | AD5: 0.03 | AE5: 0.044 | AF5: 0.0618 | AG5: 0.2052 | AH5: 0.0677 | AI5: 0.1835 | AJ5: 0.0856 | AK5: 0.033 | AL5: 0.018 | AM5: 0.0035 | AN5: 0.0075 | AO5: 0.0359 | AP5: 0.0127 | AQ5: 0.0017 | AR5: 0.0037 | AS5: 0.0068 | AT5: 0.0529 | AU5: 0.0038 | AV5: 0.0144 | AW5: 0.001 | AX5: 0.0014 | AY5: 0.0151 | AZ5: 0.0092
A6: Investment Grade Bonds - Obligations | B6: 0.3348 | C6: 0.5814 | D6: 0.0104 | E6: 0.0156 | F6: 0.001 | G6: 0.0047 | H6: 0.0111 | I6: 0.0006 | J6: 0.0098 | K6: 0.0008 | L6: 0.0036 | M6: 0.0071 | N6: 0.0878 | O6: 0.0197 | P6: 0.012 | Q6: 0.0115 | R6: 0.0019 | S6: 0.008 | T6: 0.3792 | U6: 0.0172 | V6: 0.0028 | W6: 0.0064 | X6: 0.1947 | Y6: 0.1169 | Z6: 0.0764 | AA6: 0.0149 | AB6: 0.0943 | AC6: 0.0827 | AD6: 0.0886 | AE6: 0.0684 | AF6: 0.1056 | AG6: 0.1 | AH6: 0.0391 | AI6: 0.027 | AJ6: 0.2406 | AK6: 0.0157 | AL6: 0.0144 | AM6: 0.0064 | AN6: 0.0088 | AO6: 0.0364 | AP6: 0.0129 | AQ6: 0.0324 | AR6: 0.0235 | AS6: 0.0098 | AT6: 0.012 | AU6: 0.058 | AV6: 0.001 | AW6: 0.0405 | AX6: 0.0042 | AY6: 0.0057 | AZ6: 0.0193
A7: Government ZC Bonds - Obligations | B7: 0.1441 | C7: 0.0116 | D7: 0.0093 | E7: 0.0141 | F7: 0.0144 | G7: 0.0006 | H7: 0.0132 | I7: 0.0229 | J7: 0.0068 | K7: 0.0025 | L7: 0.0442 | M7: 0.0074 | N7: 0.0799 | O7: 0.0207 | P7: 0.0112 | Q7: 0.0017 | R7: 0.0099 | S7: 0.0035 | T7: 0.0049 | U7: 0.0053 | V7: 0.0175 | W7: 0.0169 | X7: 0.2403 | Y7: 0.3986 | Z7: 0.4306 | AA7: 0.0002 | AB7: 0.0569 | AC7: 0.5315 | AD7: 0.5743 | AE7: 0.6895 | AF7: 0.6722 | AG7: 0.5207 | AH7: 0.6848 | AI7: 0.5302 | AJ7: 0.4353 | AK7: 0.9078 | AL7: 0.9112 | AM7: 0.9712 | AN7: 0.9553 | AO7: 0.834 | AP7: 0.9375 | AQ7: 0.9133 | AR7: 0.9251 | AS7: 0.9726 | AT7: 0.8456 | AU7: 0.919 | AV7: 0.9702 | AW7: 0.9119 | AX7: 0.984 | AY7: 0.9462 | AZ7: 0.9624

Sheet GBI Goals P1
B1: 2025 | C1: 2026 | D1: 2027 | E1: 2028 | F1: 2029 | G1: 2030 | H1: 2031 | I1: 2032 | J1: 2033 | K1: 2034 | L1: 2035 | M1: 2036 | N1: 2037 | O1: 2038 | P1: 2039 | Q1: 2040 | R1: 2041 | S1: 2042 | T1: 2043 | U1: 2044 | V1: 2045 | W1: 2046 | X1: 2047 | Y1: 2048 | Z1: 2049 | AA1: 2050 | AB1: 2051 | AC1: 2052 | AD1: 2053 | AE1: 2054 | AF1: 2055 | AG1: 2056 | AH1: 2057 | AI1: 2058 | AJ1: 2059 | AK1: 2060 | AL1: 2061 | AM1: 2062 | AN1: 2063 | AO1: 2064 | AP1: 2065 | AQ1: 2066 | AR1: 2067 | AS1: 2068 | AT1: 2069 | AU1: 2070 | AV1: 2071 | AW1: 2072 | AX1: 2073 | AY1: 2074 | AZ1: 2075
A2: A | B2: 0.01 | C2: 0.0099 | D2: 0.0297 | E2: 0.03 | F2: 0.0198 | G2: 0.0098 | H2: 0.01 | I2: 0.0495 | J2: 0.0297 | K2: 0.01 | L2: 0.03 | M2: 0.0099 | N2: 0.01 | O2: 0.02 | P2: 0.0099 | Q2: 0.0198 | R2: 0.02 | S2: 0.01 | T2: 0.0099 | U2: 0.0198 | V2: 0.0198 | W2: 0.0495 | X2: 0.03 | Y2: 0.01 | Z2: 0.0101 | AA2: 0.01 | AB2: 0.0099 | AC2: 0.01 | AD2: 0.0099 | AE2: 0.01 | AF2: 0.101 | AG2: 0.06 | AH2: 0.0891 | AI2: 0.0101 | AJ2: 0.0099 | AK2: 0.02 | AL2: 0.03 | AM2: 0.03 | AN2: 0.02 | AO2: 0.0404 | AP2: 0.01 | AQ2: 0.01 | AR2: 0.0099 | AS2: 0.01 | AT2: 0.0099 | AU2: 0.0202 | AV2: 0.01 | AW2: 0.0198 | AX2: 0.01 | AY2: 0.01 | AZ2: 0.0099
A3: B | B3: 0.89 | C3: 0.9604 | D3: 0.9307 | E3: 0.94 | F3: 0.9604 | G3: 0.2941 | H3: 0.93 | I3: 0.9307 | J3: 0.9505 | K3: 0.95 | L3: 0.9 | M3: 0.9703 | N3: 0.57 | O3: 0.93 | P3: 0.9406 | Q3: 0.9604 | R3: 0.96 | S3: 0.97 | T3: 0.9703 | U3: 0.9307 | V3: 0.9307 | W3: 0.9307 | X3: 0.93 | Y3: 0.59 | Z3: 0.6263 | AA3: 0.94 | AB3: 0.9703 | AC3: 0.4 | AD3: 0.4752 | AE3: 0.35 | AF3: 0.101 | AG3: 0.51 | AH3: 0.3267 | AI3: 0.5253 | AJ3: 0.5941 | AK3: 0.08 | AL3: 0.06 | AM3: 0.01 | AN3: 0.02 | AO3: 0.1717 | AP3: 0.05 | AQ3: 0.14 | AR3: 0.0594 | AS3: 0.01 | AT3: 0.1485 | AU3: 0.0101 | AV3: 0.02 | AW3: 0.0495 | AX3: 0.01 | AY3: 0.02 | AZ3: 0.0297
A4: C | B4: 0.04 | C4: 0.0099 | D4: 0.0099 | E4: 0.02 | F4: 0.0099 | G4: 0.0098 | H4: 0.04 | I4: 0.0099 | J4: 0.0099 | K4: 0.01 | L4: 0.06 | M4: 0.0099 | N4: 0.01 | O4: 0.04 | P4: 0.0198 | Q4: 0.0099 | R4: 0.01 | S4: 0.01 | T4: 0.0099 | U4: 0.0396 | V4: 0.0396 | W4: 0.0099 | X4: 0.02 | Y4: 0.39 | Z4: 0.3535 | AA4: 0.03 | AB4: 0.0099 | AC4: 0.5 | AD4: 0.4752 | AE4: 0.61 | AF4: 0.5657 | AG4: 0.42 | AH4: 0.5743 | AI4: 0.4444 | AJ4: 0.3663 | AK4: 0.89 | AL4: 0.9 | AM4: 0.95 | AN4: 0.95 | AO4: 0.7778 | AP4: 0.92 | AQ4: 0.83 | AR4: 0.901 | AS4: 0.97 | AT4: 0.7921 | AU4: 0.8687 | AV4: 0.96 | AW4: 0.901 | AX4: 0.95 | AY4: 0.94 | AZ4: 0.9406
A5: D | B5: 0.06 | C5: 0.0198 | D5: 0.0297 | E5: 0.01 | F5: 0.0099 | G5: 0.6863 | H5: 0.02 | I5: 0.0099 | J5: 0.0099 | K5: 0.03 | L5: 0.01 | M5: 0.0099 | N5: 0.41 | O5: 0.01 | P5: 0.0297 | Q5: 0.0099 | R5: 0.01 | S5: 0.01 | T5: 0.0099 | U5: 0.0099 | V5: 0.0099 | W5: 0.0099 | X5: 0.02 | Y5: 0.01 | Z5: 0.0101 | AA5: 0.02 | AB5: 0.0099 | AC5: 0.09 | AD5: 0.0396 | AE5: 0.03 | AF5: 0.2323 | AG5: 0.01 | AH5: 0.0099 | AI5: 0.0202 | AJ5: 0.0297 | AK5: 0.01 | AL5: 0.01 | AM5: 0.01 | AN5: 0.01 | AO5: 0.0101 | AP5: 0.02 | AQ5: 0.02 | AR5: 0.0297 | AS5: 0.01 | AT5: 0.0495 | AU5: 0.101 | AV5: 0.01 | AW5: 0.0297 | AX5: 0.03 | AY5: 0.03 | AZ5: 0.0198

Sheet GBI Allocations P2
B1: 2025 | C1: 2026 | D1: 2027 | E1: 2028 | F1: 2029 | G1: 2030 | H1: 2031 | I1: 2032 | J1: 2033 | K1: 2034 | L1: 2035 | M1: 2036 | N1: 2037 | O1: 2038 | P1: 2039 | Q1: 2040 | R1: 2041 | S1: 2042 | T1: 2043 | U1: 2044 | V1: 2045 | W1: 2046 | X1: 2047 | Y1: 2048 | Z1: 2049 | AA1: 2050 | AB1: 2051 | AC1: 2052 | AD1: 2053 | AE1: 2054 | AF1: 2055 | AG1: 2056 | AH1: 2057 | AI1: 2058 | AJ1: 2059 | AK1: 2060 | AL1: 2061 | AM1: 2062 | AN1: 2063 | AO1: 2064 | AP1: 2065 | AQ1: 2066 | AR1: 2067 | AS1: 2068 | AT1: 2069 | AU1: 2070 | AV1: 2071 | AW1: 2072 | AX1: 2073 | AY1: 2074 | AZ1: 2075
A2: Emerging Markets - Equities | B2: 0.9621 | C2: 0.3357 | D2: 0.9872 | E2: 0.0054 | F2: 0.974 | G2: 0.6974 | H2: 0.9629 | I2: 0.9334 | J2: 0.0508 | K2: 0.9333 | L2: 0.0173 | M2: 0.0683 | N2: 0.9477 | O2: 0.0101 | P2: 0.0033 | Q2: 0.9356 | R2: 0.0025 | S2: 0.8602 | T2: 0.011 | U2: 0.3612 | V2: 0.0169 | W2: 0.0145 | X2: 0.0001 | Y2: 0.0131 | Z2: 0.0681 | AA2: 0.9355 | AB2: 0.0072 | AC2: 0.0055 | AD2: 0.0748 | AE2: 0.1209 | AF2: 0.0672 | AG2: 0.0416 | AH2: 0.0053 | AI2: 0.0845 | AJ2: 0.0561 | AK2: 0.0366 | AL2: 0.0188 | AM2: 0.0407 | AN2: 0.0176 | AO2: 0.0183 | AP2: 0.0108 | AQ2: 0.0023 | AR2: 0.1196 | AS2: 0.0207 | AT2: 0.1642 | AU2: 0.0114 | AV2: 0.011 | AW2: 0.0153 | AX2: 0.0075 | AY2: 0.0065 | AZ2: 0.0026
A3: Developed Markets - Equities | B3: 0.0116 | C3: 0.0023 | D3: 0.0051 | E3: 0.9615 | F3: 0.0067 | G3: 0.2639 | H3: 0.0011 | I3: 0.0128 | J3: 0.0118 | K3: 0.0119 | L3: 0.063 | M3: 0.0005 | N3: 0.0039 | O3: 0.0016 | P3: 0.006 | Q3: 0.0041 | R3: 0.0048 | S3: 0.0877 | T3: 0.0022 | U3: 0.4143 | V3: 0.919 | W3: 0.9452 | X3: 0.967 | Y3: 0.9224 | Z3: 0.1866 | AA3: 0.0173 | AB3: 0.0076 | AC3: 0.001 | AD3: 0.0015 | AE3: 0.0661 | AF3: 0.2011 | AG3: 0.1665 | AH3: 0.1169 | AI3: 0.0824 | AJ3: 0.0826 | AK3: 0.0259 | AL3: 0.0215 | AM3: 0.0348 | AN3: 0.0066 | AO3: 0.0021 | AP3: 0.0052 | AQ3: 0.0018 | AR3: 0.0732 | AS3: 0.0174 | AT3: 0.0855 | AU3: 0.0136 | AV3: 0.0148 | AW3: 0.0012 | AX3: 0.0095 | AY3: 0.0221 | AZ3: 0.0052
A4: Emerging Markets State - Obligations | B4: 0.0094 | C4: 0.0038 | D4: 0.0002 | E4: 0.0066 | F4: 0.0059 | G4: 0.0094 | H4: 0.008 | I4: 0.0152 | J4: 0.9051 | K4: 0.0005 | L4: 0.0097 | M4: 0.0496 | N4: 0.0113 | O4: 0.0051 | P4: 0.9405 | Q4: 0.0246 | R4: 0.0098 | S4: 0.0017 | T4: 0.023 | U4: 0.0306 | V4: 0.0278 | W4: 0.0104 | X4: 0.0093 | Y4: 0.0177 | Z4: 0.1929 | AA4: 0.0001 | AB4: 0.013 | AC4: 0.0259 | AD4: 0.151 | AE4: 0.0169 | AF4: 0.1469 | AG4: 0.108 | AH4: 0.1179 | AI4: 0.0823 | AJ4: 0.0571 | AK4: 0.0193 | AL4: 0.0502 | AM4: 0.0494 | AN4: 0.0301 | AO4: 0.0016 | AP4: 0.0056 | AQ4: 0.0351 | AR4: 0.1344 | AS4: 0.0245 | AT4: 0.2059 | AU4: 0.0054 | AV4: 0.0251 | AW4: 0.0006 | AX4: 0.0014 | AY4: 0.0067 | AZ4: 0.0092
A5: High Yield Bonds - Obligations | B5: 0.0072 | C5: 0.0035 | D5: 0.0049 | E5: 0.0131 | F5: 0.0039 | G5: 0.0111 | H5: 0.0011 | I5: 0.0147 | J5: 0.0144 | K5: 0.012 | L5: 0.8967 | M5: 0.8513 | N5: 0.0106 | O5: 0.0063 | P5: 0.0082 | Q5: 0.0246 | R5: 0.4386 | S5: 0.0302 | T5: 0.4661 | U5: 0.1527 | V5: 0.0111 | W5: 0.008 | X5: 0.0015 | Y5: 0.0123 | Z5: 0.0347 | AA5: 0.0359 | AB5: 0.9637 | AC5: 0.0612 | AD5: 0.085 | AE5: 0.1511 | AF5: 0.0807 | AG5: 0.0342 | AH5: 0.0267 | AI5: 0.0366 | AJ5: 0.0803 | AK5: 0.026 | AL5: 0.0081 | AM5: 0.0365 | AN5: 0.0308 | AO5: 0.0022 | AP5: 0.0164 | AQ5: 0.0008 | AR5: 0.0185 | AS5: 0.0286 | AT5: 0.0992 | AU5: 0.0147 | AV5: 0.0166 | AW5: 0.0161 | AX5: 0 | AY5: 0.0123 | AZ5: 0.0087
A6: Investment Grade Bonds - Obligations | B6: 0.0037 | C6: 0.651 | D6: 0.0005 | E6: 0.0121 | F6: 0.0002 | G6: 0.0072 | H6: 0.0131 | I6: 0.0108 | J6: 0.0043 | K6: 0.0281 | L6: 0.001 | M6: 0.0236 | N6: 0.0154 | O6: 0.9714 | P6: 0.0122 | Q6: 0.0063 | R6: 0.5321 | S6: 0.0011 | T6: 0.4768 | U6: 0.0387 | V6: 0.0017 | W6: 0.0077 | X6: 0.0086 | Y6: 0.0127 | Z6: 0.146 | AA6: 0.0092 | AB6: 0.0046 | AC6: 0.033 | AD6: 0.0634 | AE6: 0.0092 | AF6: 0.0147 | AG6: 0.1606 | AH6: 0.0151 | AI6: 0.0352 | AJ6: 0.0649 | AK6: 0.058 | AL6: 0.1219 | AM6: 0.0246 | AN6: 0.0313 | AO6: 0.0114 | AP6: 0.011 | AQ6: 0.0468 | AR6: 0.0966 | AS6: 0.0482 | AT6: 0.0261 | AU6: 0.0199 | AV6: 0.0132 | AW6: 0.0007 | AX6: 0.0289 | AY6: 0.0193 | AZ6: 0.0244
A7: Government ZC Bonds - Obligations | B7: 0.006 | C7: 0.0038 | D7: 0.0022 | E7: 0.0012 | F7: 0.0093 | G7: 0.011 | H7: 0.0138 | I7: 0.0131 | J7: 0.0136 | K7: 0.0143 | L7: 0.0123 | M7: 0.0068 | N7: 0.0112 | O7: 0.0056 | P7: 0.0298 | Q7: 0.0048 | R7: 0.0123 | S7: 0.0191 | T7: 0.0208 | U7: 0.0026 | V7: 0.0234 | W7: 0.0142 | X7: 0.0135 | Y7: 0.0218 | Z7: 0.3717 | AA7: 0.002 | AB7: 0.0039 | AC7: 0.8734 | AD7: 0.6242 | AE7: 0.6357 | AF7: 0.4893 | AG7: 0.4892 | AH7: 0.7181 | AI7: 0.679 | AJ7: 0.659 | AK7: 0.8343 | AL7: 0.7794 | AM7: 0.814 | AN7: 0.8836 | AO7: 0.9644 | AP7: 0.951 | AQ7: 0.9132 | AR7: 0.5577 | AS7: 0.8606 | AT7: 0.4191 | AU7: 0.935 | AV7: 0.9193 | AW7: 0.9662 | AX7: 0.9527 | AY7: 0.933 | AZ7: 0.95

Sheet notes next time talk
B3: Excel side:
B4: Goal calculation
B5: Investment income calculation
B6: For retirement goal: Calculate what the amount needed is and also research from denmark statistik what is the median returns by retirement age.
B7: Returns input with samsseewfwfuweerhugf for long term, and simulation for short term
B9: Python side:
B13: Question for Johan:
B14: Vasicek ready, what do we use bond simulation for? How does it correlate to bond ETF
B18: From last meeting Johan mentioned you can put the tax money back into the account???? What does this mean I am not sure: Saxo bank shows this below which might explain
B37: Update: I KNOW WHAT HE MEANT AHAHAHA IM A GENIOUS!!!! So basically it means that (from what I understand) the 17% tax deducts from your available input amount, allowing to deposit more into the account.
C41: Here
D42: Return | E42: Vol
C43: ZC Bond | D43: 0.03 | E43: 0.01 | H43: 2025 | I43: 2026 | J43: 2027 | M43: Use value simulated for each year or the average | N43: Split each goal into a per year goal, so achieve a % of the total goal in that year, and then the model would actually work as is
C44: SP | D44: 0.1 | E44: 0.03 | H44: 0.03 | I44: 0.04 | J44: 0.06 | K44: 0.07 | L44: 0.1
H46: =AVERAGE(H44:L44) -> 0.06 | I46: =AVERAGE(I44:L44) -> 0.0675
J51: Goal: House | L51: in 10 years
J53: 2025 | K53: 2026 | L53: 2027 | M53: 2028 | N53: 2029 | O53: 2030 | P53: 2031 | Q53: 2032 | R53: 2033 | S53: 2034 | U53: Total
J54: =$U$54*10% -> 200000 | K54: =$U$54*10% -> 200000 | L54: =$U$54*10% -> 200000 | M54: =$U$54*10% -> 200000 | N54: =$U$54*10% -> 200000 | O54: =$U$54*10% -> 200000 | P54: =$U$54*10% -> 200000 | Q54: =$U$54*10% -> 200000 | ... S54: =$U$54*10% -> 200000 | U54: 2000000
B57: Task for the master file

Sheet GBI Goals P2
B1: 2025 | C1: 2026 | D1: 2027 | E1: 2028 | F1: 2029 | G1: 2030 | H1: 2031 | I1: 2032 | J1: 2033 | K1: 2034 | L1: 2035 | M1: 2036 | N1: 2037 | O1: 2038 | P1: 2039 | Q1: 2040 | R1: 2041 | S1: 2042 | T1: 2043 | U1: 2044 | V1: 2045 | W1: 2046 | X1: 2047 | Y1: 2048 | Z1: 2049 | AA1: 2050 | AB1: 2051 | AC1: 2052 | AD1: 2053 | AE1: 2054 | AF1: 2055 | AG1: 2056 | AH1: 2057 | AI1: 2058 | AJ1: 2059 | AK1: 2060 | AL1: 2061 | AM1: 2062 | AN1: 2063 | AO1: 2064 | AP1: 2065 | AQ1: 2066 | AR1: 2067 | AS1: 2068 | AT1: 2069 | AU1: 2070 | AV1: 2071 | AW1: 2072 | AX1: 2073 | AY1: 2074 | AZ1: 2075
A2: A | B2: 0.0099 | C2: 0.01 | D2: 0.0099 | E2: 0.0297 | F2: 0.01 | G2: 0.0198 | H2: 0.02 | I2: 0.04 | J2: 0.0303 | K2: 0.0099 | L2: 0.04 | M2: 0.03 | N2: 0.0099 | O2: 0.0099 | P2: 0.03 | Q2: 0.0099 | R2: 0.0099 | S2: 0.0198 | T2: 0.01 | U2: 0.02 | V2: 0.0495 | W2: 0.0396 | X2: 0.0099 | Y2: 0.0686 | Z2: 0.01 | AA2: 0.0099 | AB2: 0.02 | AC2: 0.01 | AD2: 0.0099 | AE2: 0.01 | AF2: 0.02 | AG2: 0.03 | AH2: 0.02 | AI2: 0.01 | AJ2: 0.01 | AK2: 0.02 | AL2: 0.0101 | AM2: 0.02 | AN2: 0.0099 | AO2: 0.03 | AP2: 0.03 | AQ2: 0.02 | AR2: 0.01 | AS2: 0.0594 | AT2: 0.1414 | AU2: 0.0099 | AV2: 0.0101 | AW2: 0.01 | AX2: 0.01 | AY2: 0.01 | AZ2: 0.01
A3: B | B3: 0.9505 | C3: 0.97 | D3: 0.4752 | E3: 0.9505 | F3: 0.2 | G3: 0.9505 | H3: 0.95 | I3: 0.93 | J3: 0.9394 | K3: 0.9307 | L3: 0.93 | M3: 0.93 | N3: 0.9307 | O3: 0.9604 | P3: 0.94 | Q3: 0.9208 | R3: 0.9604 | S3: 0.9208 | T3: 0.92 | U3: 0.87 | V3: 0.901 | W3: 0.9406 | X3: 0.9604 | Y3: 0.9118 | Z3: 0.66 | AA3: 0.9208 | AB3: 0.95 | AC3: 0.15 | AD3: 0.4653 | AE3: 0.57 | AF3: 0.26 | AG3: 0.51 | AH3: 0.34 | AI3: 0.34 | AJ3: 0.36 | AK3: 0.05 | AL3: 0.2828 | AM3: 0.2 | AN3: 0.099 | AO3: 0.02 | AP3: 0.02 | AQ3: 0.01 | AR3: 0.35 | AS3: 0.099 | AT3: 0.5758 | AU3: 0.0693 | AV3: 0.0707 | AW3: 0.02 | AX3: 0.09 | AY3: 0.06 | AZ3: 0.05
A4: C | B4: 0.0099 | C4: 0.01 | D4: 0.0099 | E4: 0.0099 | F4: 0.02 | G4: 0.0198 | H4: 0.01 | I4: 0.02 | J4: 0.0202 | K4: 0.0297 | L4: 0.02 | M4: 0.03 | N4: 0.0099 | O4: 0.0198 | P4: 0.02 | Q4: 0.0099 | R4: 0.0198 | S4: 0.0495 | T4: 0.01 | U4: 0.01 | V4: 0.0099 | W4: 0.0099 | X4: 0.0198 | Y4: 0.0098 | Z4: 0.29 | AA4: 0.0297 | AB4: 0.01 | AC4: 0.81 | AD4: 0.495 | AE4: 0.33 | AF4: 0.42 | AG4: 0.45 | AH4: 0.63 | AI4: 0.59 | AJ4: 0.61 | AK4: 0.79 | AL4: 0.6869 | AM4: 0.77 | AN4: 0.8812 | AO4: 0.94 | AP4: 0.9 | AQ4: 0.81 | AR4: 0.51 | AS4: 0.8317 | AT4: 0.2525 | AU4: 0.9109 | AV4: 0.899 | AW4: 0.96 | AX4: 0.86 | AY4: 0.92 | AZ4: 0.93
A5: D | B5: 0.0297 | C5: 0.01 | D5: 0.505 | E5: 0.0099 | F5: 0.77 | G5: 0.0099 | H5: 0.02 | I5: 0.01 | J5: 0.0101 | K5: 0.0297 | L5: 0.01 | M5: 0.01 | N5: 0.0495 | O5: 0.0099 | P5: 0.01 | Q5: 0.0594 | R5: 0.0099 | S5: 0.0099 | T5: 0.06 | U5: 0.1 | V5: 0.0396 | W5: 0.0099 | X5: 0.0099 | Y5: 0.0098 | Z5: 0.04 | AA5: 0.0396 | AB5: 0.02 | AC5: 0.03 | AD5: 0.0297 | AE5: 0.09 | AF5: 0.3 | AG5: 0.01 | AH5: 0.01 | AI5: 0.06 | AJ5: 0.02 | AK5: 0.14 | AL5: 0.0202 | AM5: 0.01 | AN5: 0.0099 | AO5: 0.01 | AP5: 0.05 | AQ5: 0.16 | AR5: 0.13 | AS5: 0.0099 | AT5: 0.0303 | AU5: 0.0099 | AV5: 0.0202 | AW5: 0.01 | AX5: 0.04 | AY5: 0.01 | AZ5: 0.01

Sheet Returns2
B1: 2025 | C1: 2026 | D1: 2027 | E1: 2028 | F1: 2029 | G1: 2030 | H1: 2031 | I1: 2032 | J1: 2033 | K1: 2034 | L1: 2035 | M1: 2036 | N1: 2037 | O1: 2038 | P1: 2039 | Q1: 2040 | R1: 2041 | S1: 2042 | T1: 2043 | U1: 2044 | V1: 2045 | W1: 2046 | X1: 2047 | Y1: 2048 | Z1: 2049 | AA1: 2050 | AB1: 2051 | AC1: 2052 | AD1: 2053 | AE1: 2054 | AF1: 2055 | AG1: 2056 | AH1: 2057 | AI1: 2058 | AJ1: 2059 | AK1: 2060 | AL1: 2061 | AM1: 2062 | AN1: 2063 | AO1: 2064 | AP1: 2065 | AQ1: 2066 | AR1: 2067 | AS1: 2068 | AT1: 2069 | AU1: 2070 | AV1: 2071 | AW1: 2072 | AX1: 2073 | AY1: 2074
A2: Small Cap
A3: US Agg Bond
A4: Gold
A5: Private Equity
A6: Venture Capital
A7: Angel Venture

Sheet Returns
B1: 2025 | C1: 2026 | D1: 2027 | E1: 2028 | F1: 2029 | G1: 2030 | H1: 2031 | I1: 2032 | J1: 2033 | K1: 2034 | L1: 2035 | M1: 2036 | N1: 2037 | O1: 2038 | P1: 2039 | Q1: 2040 | R1: 2041 | S1: 2042 | T1: 2043 | U1: 2044 | V1: 2045 | W1: 2046 | X1: 2047 | Y1: 2048 | Z1: 2049 | AA1: 2050 | AB1: 2051 | AC1: 2052 | AD1: 2053 | AE1: 2054 | AF1: 2055 | AG1: 2056 | AH1: 2057 | AI1: 2058 | AJ1: 2059 | AK1: 2060 | AL1: 2061 | AM1: 2062 | AN1: 2063 | AO1: 2064 | AP1: 2065 | AQ1: 2066 | AR1: 2067 | AS1: 2068 | AT1: 2069 | AU1: 2070 | AV1: 2071 | AW1: 2072 | AX1: 2073 | AY1: 2074 | AZ1: 2075
A2: Emerging Markets - Equities | B2: -0.046374625 | C2: 0.25193929 | D2: 0.25632261 | E2: -0.059773063 | F2: 0.40378256 | G2: 0.31172393 | H2: 0.059218288 | I2: 0.10707307 | J2: 0.11435577 | K2: 0.12346019 | L2: 0.090155243 | M2: 0.16489957 | N2: -0.032891724 | O2: -0.028709221 | P2: -0.029700593 | Q2: 0.053046739 | R2: 0.040017379 | S2: 0.31809496 | T2: -0.030274921 | U2: 0.42106698 | V2: -0.1511464 | W2: 0.11903432 | X2: -0.14501134 | Y2: -0.098981451 | Z2: -0.28480526 | AA2: 0.16386844 | AB2: -0.049048039 | AC2: 0.10968519 | AD2: -0.079101955 | AE2: 0.11709659 | AF2: 0.42713821 | AG2: -0.26668675 | AH2: -0.15306485 | AI2: 0.23493865 | AJ2: 0.06041257 | AK2: 0.014204164 | AL2: -0.069574102 | AM2: 0.073240334 | AN2: 0.103626 | AO2: 0.051557176 | AP2: -0.052116699 | AQ2: -0.23205744 | AR2: 0.46613428 | AS2: 0.074472391 | AT2: 0.71150702 | AU2: 0.020245655 | AV2: 0.27735917 | AW2: 0.11781713 | AX2: -0.0041329986 | AY2: 0.070092809 | AZ2: 0
A3: Developed Markets - Equities | B3: -0.034134004 | C3: 0.19511077 | D3: 0.069691772 | E3: 0.10330575 | F3: 0.076016163 | G3: 0.23027145 | H3: 0.032689218 | I3: -0.088332981 | J3: -0.1092319 | K3: -0.043963023 | L3: 0.20956142 | M3: -0.015205666 | N3: -0.059960029 | O3: 0.057027602 | P3: -0.035388428 | Q3: -0.041584959 | R3: -0.006662417 | S3: 0.21043094 | T3: 0.068683867 | U3: 0.37689317 | V3: 0.04253204 | W3: 0.18667479 | X3: -0.023315534 | Y3: 0.020929003 | Z3: -0.033223354 | AA3: 0.14205355 | AB3: -0.031351511 | AC3: 0.0772723 | AD3: -0.076933006 | AE3: 0.0042148946 | AF3: 0.39390059 | AG3: -0.098489003 | AH3: -0.096519893 | AI3: 0.17365698 | AJ3: 0.13561299 | AK3: 0.062760251 | AL3: -0.019523506 | AM3: 0.13169239 | AN3: 0.16529749 | AO3: 0.069245798 | AP3: -0.13108726 | AQ3: -0.12086994 | AR3: 0.26810918 | AS3: 0.021392416 | AT3: 0.29513881 | AU3: -0.0016946599 | AV3: 0.076425522 | AW3: 0.10705453 | AX3: -0.0117783 | AY3: 0.12849202 | AZ3: 0
A4: Emerging Markets State - Obligations | B4: -0.024348051 | C4: 0.17899998 | D4: 0.053592043 | E4: -0.097456791 | F4: 0.099075543 | G4: -0.012404189 | H4: -0.020112401 | I4: 0.00088319813 | J4: 0.13739337 | K4: 0.049310204 | L4: 0.1634634 | M4: 0.15165499 | N4: -0.037833919 | O4: -0.032854561 | P4: 0.088478775 | Q4: 0.052819549 | R4: 0.079197987 | S4: 0.020094933 | T4: 0.16754144 | U4: 0.1310382 | V4: 0.052266956 | W4: 0.014832553 | X4: -0.019128736 | Y4: -0.10185033 | Z4: -0.10937817 | AA4: 0.05443421 | AB4: 0.032901853 | AC4: 0.13941134 | AD4: -0.0019714931 | AE4: 0.095073761 | AF4: 0.23102348 | AG4: -0.055404052 | AH4: -0.016079316 | AI4: 0.17435245 | AJ4: 0.068288645 | AK4: -0.10568758 | AL4: 0.007789076 | AM4: -0.097682374 | AN4: -0.048483465 | AO4: -0.0030515459 | AP4: 0.0027520956 | AQ4: 0.034665731 | AR4: 0.16682696 | AS4: 0.039148103 | AT4: 0.19318839 | AU4: -0.0066513779 | AV4: 0.15805629 | AW4: 0.061989058 | AX4: -0.1010299 | AY4: 0.04757048 | AZ4: 0
A5: High Yield Bonds - Obligations | B5: 0.0020947373 | C5: 0.16863527 | D5: -0.0439889 | E5: 0.0092439085 | F5: -0.058187201 | G5: 0.063934627 | H5: 0.039390305 | I5: -0.0048821519 | J5: -0.010087751 | K5: -0.040523477 | L5: 0.22293805 | M5: 0.17926819 | N5: -0.013958242 | O5: 0.062920736 | P5: -0.0005848837 | Q5: -0.024558542 | R5: 0.099825644 | S5: 0.095745177 | T5: 0.18763395 | U5: 0.25076435 | V5: 0.0431843 | W5: 0.014553844 | X5: -0.064654304 | Y5: -0.068264578 | Z5: -0.061684509 | AA5: 0.095210856 | AB5: 0.11893618 | AC5: -0.031171782 | AD5: 0.018900136 | AE5: 0.012824899 | AF5: 0.21820203 | AG5: -0.024014377 | AH5: 0.038296852 | AI5: 0.019952542 | AJ5: 0.15024428 | AK5: -0.0090532127 | AL5: 0.0078239785 | AM5: 0.012720265 | AN5: 0.11698173 | AO5: 0.013563193 | AP5: -0.031307857 | AQ5: -0.017042856 | AR5: 0.20639672 | AS5: 0.059892816 | AT5: 0.15184774 | AU5: 0.0053546078 | AV5: 0.065052612 | AW5: 0.078823819 | AX5: -0.14338179 | AY5: 0.11585203 | AZ5: 0
A6: Investment Grade Bonds - Obligations | B6: 0.020306584 | C6: 0.17407089 | D6: -0.046518789 | E6: 0.0086784081 | F6: -0.010949916 | G6: 0.042874327 | H6: 0.042086602 | I6: -0.01731686 | J6: 0.0058994449 | K6: 0.015660463 | L6: 0.13556024 | M6: 0.099561145 | N6: -0.011234137 | O6: 0.077927824 | P6: 0.076843928 | Q6: -0.02368976 | R6: 0.095850568 | S6: -0.0016291818 | T6: 0.15662866 | U6: 0.11023687 | V6: 0.023511467 | W6: 0.036602318 | X6: -0.048538279 | Y6: -0.03006736 | Z6: -0.034510362 | AA6: 0.095364119 | AB6: 0.014863394 | AC6: -0.029047233 | AD6: -0.015385538 | AE6: -0.00073986273 | AF6: 0.1189947 | AG6: 0.072047867 | AH6: 0.0057388719 | AI6: 0.13027793 | AJ6: 0.11335457 | AK6: 0.0060231825 | AL6: 0.025378987 | AM6: -0.0033197301 | AN6: 0.035408805 | AO6: -0.011836193 | AP6: 0.0034041737 | AQ6: -0.015798285 | AR6: 0.12280627 | AS6: 0.043636186 | AT6: 0.11189226 | AU6: 0.042019733 | AV6: 0.0483009 | AW6: 0.011953864 | AX6: -0.059960933 | AY6: 0.036272181 | AZ6: 0
A7: Government ZC Bonds - Obligations | B7: 0.042149821 | C7: 0.10310123 | D7: 0.031754404 | E7: 0.025015652 | F7: 0.019348111 | G7: 0.010157775 | H7: 0.049364963 | I7: -0.010190624 | J7: 0.039711315 | K7: 0.0017363414 | L7: 0.052922022 | M7: 0.07107086 | N7: -0.01757714 | O7: 0.0030519436 | P7: 0.077577744 | Q7: 0.0030400247 | R7: 0.083761181 | S7: -0.025010586 | T7: 0.11157191 | U7: 0.039371754 | V7: 0.020310458 | W7: 0.059640325 | X7: 0.059617912 | Y7: 0.0042957098 | Z7: 0.016193351 | AA7: 0.058660681 | AB7: -0.01401438 | AC7: 0.031370645 | AD7: -0.0089829463 | AE7: 0.016586273 | AF7: 0.064740849 | AG7: 0.010540152 | AH7: 0.039379023 | AI7: 0.065580331 | AJ7: 0.07625438 | AK7: -0.024022285 | AL7: 0.076718609 | AM7: -0.0051493088 | AN7: -0.01144903 | AO7: 0.025745024 | AP7: 0.020794227 | AQ7: 0.076564055 | AR7: 0.012164389 | AS7: 0.059620058 | AT7: 0.020534111 | AU7: 0.026882987 | AV7: 0.032178991 | AW7: 0.035080281 | AX7: 0.0077056709 | AY7: 0.024774392 | AZ7: 0

Sheet Volatilities2
B1: volatility
A2: Small Cap | B2: 0.17
A3: US Agg Bond | B3: 0.05
A4: Gold | B4: 0.19
A5: Private Equity | B5: 0.28
A6: Venture Capital | B6: 0.3
A7: Angel Venture | B7: 0.82

Sheet Volatilities
B1: volatility
A2: Emerging Markets - Equities | B2: 0.086
A3: Developed Markets - Equities | B3: 0.07
A4: Emerging Markets State - Obligations | B4: 0.049
A5: High Yield Bonds - Obligations | B5: 0.05
A6: Investment Grade Bonds - Obligations | B6: 0.037
A7: Government ZC Bonds - Obligations | B7: 0.029

Sheet Correlation
B1: Government ZC Bonds - Obligations | C1: Investment Grade Bonds - Obligations | D1: High Yield Bonds - Obligations | E1: Emerging Markets State - Obligations | F1: Developed Markets - Equities | G1: Emerging Markets - Equities
A2: Government ZC Bonds - Obligations | B2: 1 | C2: 0.6 | D2: 0.2 | E2: 0.4 | F2: 0 | G2: 0
A3: Investment Grade Bonds - Obligations | B3: 0.6 | C3: 1 | D3: 0.7 | E3: 0.6 | F3: 0.3 | G3: 0.3
A4: High Yield Bonds - Obligations | B4: 0.2 | C4: 0.7 | D4: 1 | E4: 0.7 | F4: 0.7 | G4: 0.6
A5: Emerging Markets State - Obligations | B5: 0.4 | C5: 0.6 | D5: 0.7 | E5: 1 | F5: 0.5 | G5: 0.7
A6: Developed Markets - Equities | B6: 0 | C6: 0.3 | D6: 0.7 | E6: 0.5 | F6: 1 | G6: 0.7
A7: Emerging Markets - Equities | B7: 0 | C7: 0.3 | D7: 0.6 | E7: 0.7 | F7: 0.7 | G7: 1

Sheet Correlation2
B1: {=TRANSPOSE(A2:A7)} -> Small Cap | C1: US Agg Bond | D1: Gold | E1: Private Equity | F1: Venture Capital | G1: Angel Venture
A2: Small Cap | B2: 1 | C2: -0.087 | D2: -0.01 | E2: 0.786 | F2: 0.687 | G2: 0.458
A3: US Agg Bond | B3: -0.087 | C3: 1 | D3: 0.408 | E3: 0.034 | F3: -0.11 | G3: -0.01
A4: Gold | B4: -0.01 | C4: 0.408 | D4: 1 | E4: 0.03 | F4: 0.026 | G4: -0.01
A5: Private Equity | B5: 0.786 | C5: 0.034 | D5: 0.03 | E5: 1 | F5: 0.57 | G5: 0.922
A6: Venture Capital | B6: 0.687 | C6: -0.11 | D6: 0.026 | E6: 0.57 | F6: 1 | G6: 0.825
A7: Angel Venture | B7: 0.458 | C7: -0.01 | D7: -0.01 | E7: 0.922 | F7: 0.825 | G7: 1

Sheet Goals
B2: Goal Info | C2: GOAL A | D2: GOAL B | E2: GOAL C | F2: GOAL D | G2: P1
B3: Value Ratio | C3: 1 | D3: 0.45 | E3: 0.5 | F3: 0.58
B4: Funding Requirement | C4: 5157000 | D4: 5000000 | E4: 713500 | F4: 8812000
B5: Time Horizon | C5: 10 | D5: 30 | E5: 4 | F5: 18
B7: Goal Info | C7: GOAL A | D7: GOAL B | E7: GOAL C | F7: GOAL D | G7: P2
B8: Value Ratio | C8: 1 | D8: 0.45 | E8: 0.5 | F8: 0.58
B9: Funding Requirement | C9: 1000000 | D9: 2000000 | E9: 20000 | F9: 100000
B10: Time Horizon | C10: 10 | D10: 30 | E10: 4 | F10: 18

Sheet Income
B2: Year | C2: SalaryP1 | D2: SalaryP2 | E2: InvestmentP1 | F2: InvestmentP2 | H2: Inflation | I2: 0.04 | M2: GrossMonthlySalaryP1 | N2: GrossMonthlySalaryP2 | O2: SwitchP1 | P2: SwitchP2
B3: 2025 | C3: =(TableIncomeCalculations[[#This Row],[GrossMonthlySalaryP1]]*12) -> 526452 | D3: =(TableIncomeCalculations[[#This Row],[GrossMonthlySalaryP2]]*12) -> 768012 | E3: =TableIncome[[#This Row],[SalaryP1]]*$I$6 -> 52645.2 | F3: =TableIncome[[#This Row],[SalaryP2]]*$I$6 -> 76801.2 | H3: Salary Raise | I3: 0.05 | M3: 43871 | N3: 64001 | O3: =_xlfn.XLOOKUP(_xlfn.XLOOKUP(TableIncome[[#This Row],[Year]],Loop!C:C,Loop!D:D),'Job Hopping'!B:B,'Job Hopping'!F:F) -> N | P3: =_xlfn.XLOOKUP(_xlfn.XLOOKUP(TableIncome[[#This Row],[Year]],Loop!C:C,Loop!E:E),'Job Hopping'!B:B,'Job Hopping'!G:G) -> N
B4: 2026 | C4: =(TableIncomeCalculations[[#This Row],[GrossMonthlySalaryP1]]*12) -> 531716.52 | D4: =(TableIncomeCalculations[[#This Row],[GrossMonthlySalaryP2]]*12) -> 775692.12 | E4: =TableIncome[[#This Row],[SalaryP1]]*$I$6 -> 53171.652 | F4: =TableIncome[[#This Row],[SalaryP2]]*$I$6 -> 77569.212 | H4: Real Salary Raise | I4: =I3-I2 -> 0.01 | M4: =IF(_xlfn.XLOOKUP(TableIncome[[#This Row],[Year]],Loop!C:C,Loop!D:D)<70,(M3*(1+$I$4))+IF(TableIncomeCalculations[[#This Row],[SwitchP1]]="Y",M3*$I$5,0),0) -> 44309.71 | N4: =IF(_xlfn.XLOOKUP(TableIncome[[#This Row],[Year]],Loop!C:C,Loop!E:E)<70,(N3*(1+$I$4))+IF(TableIncomeCalculations[[#This Row],[SwitchP2]]="Y",N3*$I$5,0),0) -> 64641.01 | O4: =_xlfn.XLOOKUP(_xlfn.XLOOKUP(TableIncome[[#This Row],[Year]],Loop!C:C,Loop!D:D),'Job Hopping'!B:B,'Job Hopping'!F:F) -> N | P4: =_xlfn.XLOOKUP(_xlfn.XLOOKUP(TableIncome[[#This Row],[Year]],Loop!C:C,Loop!E:E),'Job Hopping'!B:B,'Job Hopping'!G:G) -> N
B5: 2027 | C5: =(TableIncomeCalculations[[#This Row],[GrossMonthlySalaryP1]]*12) -> 590205.34 | D5: =(TableIncomeCalculations[[#This Row],[GrossMonthlySalaryP2]]*12) -> 783449.04 | E5: =TableIncome[[#This Row],[SalaryP1]]*$I$6 -> 59020.534 | F5: =TableIncome[[#This Row],[SalaryP2]]*$I$6 -> 78344.904 | H5: Job Hopping "Bonus" | I5: 0.1 | M5: =IF(_xlfn.XLOOKUP(TableIncome[[#This Row],[Year]],Loop!C:C,Loop!D:D)<70,(M4*(1+$I$4))+IF(TableIncomeCalculations[[#This Row],[SwitchP1]]="Y",M4*$I$5,0),0) -> 49183.778 | N5: =IF(_xlfn.XLOOKUP(TableIncome[[#This Row],[Year]],Loop!C:C,Loop!E:E)<70,(N4*(1+$I$4))+IF(TableIncomeCalculations[[#This Row],[SwitchP2]]="Y",N4*$I$5,0),0) -> 65287.42 | O5: =_xlfn.XLOOKUP(_xlfn.XLOOKUP(TableIncome[[#This Row],[Year]],Loop!C:C,Loop!D:D),'Job Hopping'!B:B,'Job Hopping'!F:F) -> Y | P5: =_xlfn.XLOOKUP(_xlfn.XLOOKUP(TableIncome[[#This Row],[Year]],Loop!C:C,Loop!E:E),'Job Hopping'!B:B,'Job Hopping'!G:G) -> N
B6: 2028 | C6: =(TableIncomeCalculations[[#This Row],[GrossMonthlySalaryP1]]*12) -> 596107.39 | D6: =(TableIncomeCalculations[[#This Row],[GrossMonthlySalaryP2]]*12) -> 869628.44 | E6: =TableIncome[[#This Row],[SalaryP1]]*$I$6 -> 59610.739 | F6: =TableIncome[[#This Row],[SalaryP2]]*$I$6 -> 86962.844 | H6: % of salary dedicated to investments | I6: 0.1 | M6: =IF(_xlfn.XLOOKUP(TableIncome[[#This Row],[Year]],Loop!C:C,Loop!D:D)<70,(M5*(1+$I$4))+IF(TableIncomeCalculations[[#This Row],[SwitchP1]]="Y",M5*$I$5,0),0) -> 49675.616 | N6: =IF(_xlfn.XLOOKUP(TableIncome[[#This Row],[Year]],Loop!C:C,Loop!E:E)<70,(N5*(1+$I$4))+IF(TableIncomeCalculations[[#This Row],[SwitchP2]]="Y",N5*$I$5,0),0) -> 72469.036 | O6: =_xlfn.XLOOKUP(_xlfn.XLOOKUP(TableIncome[[#This Row],[Year]],Loop!C:C,Loop!D:D),'Job Hopping'!B:B,'Job Hopping'!F:F) -> N | P6: =_xlfn.XLOOKUP(_xlfn.XLOOKUP(TableIncome[[#This Row],[Year]],Loop!C:C,Loop!E:E),'Job Hopping'!B:B,'Job Hopping'!G:G) -> Y
B7: 2029 | C7: =(TableIncomeCalculations[[#This Row],[GrossMonthlySalaryP1]]*12) -> 602068.46 | D7: =(TableIncomeCalculations[[#This Row],[GrossMonthlySalaryP2]]*12) -> 878324.72 | E7: =TableIncome[[#This Row],[SalaryP1]]*$I$6 -> 60206.846 | F7: =TableIncome[[#This Row],[SalaryP2]]*$I$6 -> 87832.472 | M7: =IF(_xlfn.XLOOKUP(TableIncome[[#This Row],[Year]],Loop!C:C,Loop!D:D)<70,(M6*(1+$I$4))+IF(TableIncomeCalculations[[#This Row],[SwitchP1]]="Y",M6*$I$5,0),0) -> 50172.372 | N7: =IF(_xlfn.XLOOKUP(TableIncome[[#This Row],[Year]],Loop!C:C,Loop!E:E)<70,(N6*(1+$I$4))+IF(TableIncomeCalculations[[#This Row],[SwitchP2]]="Y",N6*$I$5,0),0) -> 73193.727 | O7: =_xlfn.XLOOKUP(_xlfn.XLOOKUP(TableIncome[[#This Row],[Year]],Loop!C:C,Loop!D:D),'Job Hopping'!B:B,'Job Hopping'!F:F) -> N | P7: =_xlfn.XLOOKUP(_xlfn.XLOOKUP(TableIncome[[#This Row],[Year]],Loop!C:C,Loop!E:E),'Job Hopping'!B:B,'Job Hopping'!G:G) -> N
B8: 2030 | C8: =(TableIncomeCalculations[[#This Row],[GrossMonthlySalaryP1]]*12) -> 608089.15 | D8: =(TableIncomeCalculations[[#This Row],[GrossMonthlySalaryP2]]*12) -> 887107.97 | E8: =TableIncome[[#This Row],[SalaryP1]]*$I$6 -> 60808.915 | F8: =TableIncome[[#This Row],[SalaryP2]]*$I$6 -> 88710.797 | M8: =IF(_xlfn.XLOOKUP(TableIncome[[#This Row],[Year]],Loop!C:C,Loop!D:D)<70,(M7*(1+$I$4))+IF(TableIncomeCalculations[[#This Row],[SwitchP1]]="Y",M7*$I$5,0),0) -> 50674.096 | N8: =IF(_xlfn.XLOOKUP(TableIncome[[#This Row],[Year]],Loop!C:C,Loop!E:E)<70,(N7*(1+$I$4))+IF(TableIncomeCalculations[[#This Row],[SwitchP2]]="Y",N7*$I$5,0),0) -> 73925.664 | O8: =_xlfn.XLOOKUP(_xlfn.XLOOKUP(TableIncome[[#This Row],[Year]],Loop!C:C,Loop!D:D),'Job Hopping'!B:B,'Job Hopping'!F:F) -> N | P8: =_xlfn.XLOOKUP(_xlfn.XLOOKUP(TableIncome[[#This Row],[Year]],Loop!C:C,Loop!E:E),'Job Hopping'!B:B,'Job Hopping'!G:G) -> N
B9: 2031 | C9: =(TableIncomeCalculations[[#This Row],[GrossMonthlySalaryP1]]*12) -> 674978.96 | D9: =(TableIncomeCalculations[[#This Row],[GrossMonthlySalaryP2]]*12) -> 895979.05 | E9: =TableIncome[[#This Row],[SalaryP1]]*$I$6 -> 67497.896 | F9: =TableIncome[[#This Row],[SalaryP2]]*$I$6 -> 89597.905 | M9: =IF(_xlfn.XLOOKUP(TableIncome[[#This Row],[Year]],Loop!C:C,Loop!D:D)<70,(M8*(1+$I$4))+IF(TableIncomeCalculations[[#This Row],[SwitchP1]]="Y",M8*$I$5,0),0) -> 56248.246 | N9: =IF(_xlfn.XLOOKUP(TableIncome[[#This Row],[Year]],Loop!C:C,Loop!E:E)<70,(N8*(1+$I$4))+IF(TableIncomeCalculations[[#This Row],[SwitchP2]]="Y",N8*$I$5,0),0) -> 74664.921 | O9: =_xlfn.XLOOKUP(_xlfn.XLOOKUP(TableIncome[[#This Row],[Year]],Loop!C:C,Loop!D:D),'Job Hopping'!B:B,'Job Hopping'!F:F) -> Y | P9: =_xlfn.XLOOKUP(_xlfn.XLOOKUP(TableIncome[[#This Row],[Year]],Loop!C:C,Loop!E:E),'Job Hopping'!B:B,'Job Hopping'!G:G) -> N
B10: 2032 | C10: =(TableIncomeCalculations[[#This Row],[GrossMonthlySalaryP1]]*12) -> 681728.75 | D10: =(TableIncomeCalculations[[#This Row],[GrossMonthlySalaryP2]]*12) -> 994536.74 | E10: =TableIncome[[#This Row],[SalaryP1]]*$I$6 -> 68172.875 | F10: =TableIncome[[#This Row],[SalaryP2]]*$I$6 -> 99453.674 | M10: =IF(_xlfn.XLOOKUP(TableIncome[[#This Row],[Year]],Loop!C:C,Loop!D:D)<70,(M9*(1+$I$4))+IF(TableIncomeCalculations[[#This Row],[SwitchP1]]="Y",M9*$I$5,0),0) -> 56810.729 | N10: =IF(_xlfn.XLOOKUP(TableIncome[[#This Row],[Year]],Loop!C:C,Loop!E:E)<70,(N9*(1+$I$4))+IF(TableIncomeCalculations[[#This Row],[SwitchP2]]="Y",N9*$I$5,0),0) -> 82878.062 | O10: =_xlfn.XLOOKUP(_xlfn.XLOOKUP(TableIncome[[#This Row],[Year]],Loop!C:C,Loop!D:D),'Job Hopping'!B:B,'Job Hopping'!F:F) -> N | P10: =_xlfn.XLOOKUP(_xlfn.XLOOKUP(TableIncome[[#This Row],[Year]],Loop!C:C,Loop!E:E),'Job Hopping'!B:B,'Job Hopping'!G:G) -> Y
B11: 2033 | C11: =(TableIncomeCalculations[[#This Row],[GrossMonthlySalaryP1]]*12) -> 688546.03 | D11: =(TableIncomeCalculations[[#This Row],[GrossMonthlySalaryP2]]*12) -> 1004482.1 | E11: =TableIncome[[#This Row],[SalaryP1]]*$I$6 -> 68854.603 | F11: =TableIncome[[#This Row],[SalaryP2]]*$I$6 -> 100448.21 | M11: =IF(_xlfn.XLOOKUP(TableIncome[[#This Row],[Year]],Loop!C:C,Loop!D:D)<70,(M10*(1+$I$4))+IF(TableIncomeCalculations[[#This Row],[SwitchP1]]="Y",M10*$I$5,0),0) -> 57378.836 | N11: =IF(_xlfn.XLOOKUP(TableIncome[[#This Row],[Year]],Loop!C:C,Loop!E:E)<70,(N10*(1+$I$4))+IF(TableIncomeCalculations[[#This Row],[SwitchP2]]="Y",N10*$I$5,0),0) -> 83706.842 | O11: =_xlfn.XLOOKUP(_xlfn.XLOOKUP(TableIncome[[#This Row],[Year]],Loop!C:C,Loop!D:D),'Job Hopping'!B:B,'Job Hopping'!F:F) -> N | P11: =_xlfn.XLOOKUP(_xlfn.XLOOKUP(TableIncome[[#This Row],[Year]],Loop!C:C,Loop!E:E),'Job Hopping'!B:B,'Job Hopping'!G:G) -> N
B12: 2034 | C12: =(TableIncomeCalculations[[#This Row],[GrossMonthlySalaryP1]]*12) -> 695431.49 | D12: =(TableIncomeCalculations[[#This Row],[GrossMonthlySalaryP2]]*12) -> 1014526.9 | E12: =TableIncome[[#This Row],[SalaryP1]]*$I$6 -> 69543.149 | F12: =TableIncome[[#This Row],[SalaryP2]]*$I$6 -> 101452.69 | M12: =IF(_xlfn.XLOOKUP(TableIncome[[#This Row],[Year]],Loop!C:C,Loop!D:D)<70,(M11*(1+$I$4))+IF(TableIncomeCalculations[[#This Row],[SwitchP1]]="Y",M11*$I$5,0),0) -> 57952.624 | N12: =IF(_xlfn.XLOOKUP(TableIncome[[#This Row],[Year]],Loop!C:C,Loop!E:E)<70,(N11*(1+$I$4))+IF(TableIncomeCalculations[[#This Row],[SwitchP2]]="Y",N11*$I$5,0),0) -> 84543.911 | O12: =_xlfn.XLOOKUP(_xlfn.XLOOKUP(TableIncome[[#This Row],[Year]],Loop!C:C,Loop!D:D),'Job Hopping'!B:B,'Job Hopping'!F:F) -> N | P12: =_xlfn.XLOOKUP(_xlfn.XLOOKUP(TableIncome[[#This Row],[Year]],Loop!C:C,Loop!E:E),'Job Hopping'!B:B,'Job Hopping'!G:G) -> N
B13: 2035 | C13: =(TableIncomeCalculations[[#This Row],[GrossMonthlySalaryP1]]*12) -> 771928.96 | D13: =(TableIncomeCalculations[[#This Row],[GrossMonthlySalaryP2]]*12) -> 1024672.2 | E13: =TableIncome[[#This Row],[SalaryP1]]*$I$6 -> 77192.896 | F13: =TableIncome[[#This Row],[SalaryP2]]*$I$6 -> 102467.22 | M13: =IF(_xlfn.XLOOKUP(TableIncome[[#This Row],[Year]],Loop!C:C,Loop!D:D)<70,(M12*(1+$I$4))+IF(TableIncomeCalculations[[#This Row],[SwitchP1]]="Y",M12*$I$5,0),0) -> 64327.413 | N13: =IF(_xlfn.XLOOKUP(TableIncome[[#This Row],[Year]],Loop!C:C,Loop!E:E)<70,(N12*(1+$I$4))+IF(TableIncomeCalculations[[#This Row],[SwitchP2]]="Y",N12*$I$5,0),0) -> 85389.35 | O13: =_xlfn.XLOOKUP(_xlfn.XLOOKUP(TableIncome[[#This Row],[Year]],Loop!C:C,Loop!D:D),'Job Hopping'!B:B,'Job Hopping'!F:F) -> Y | P13: =_xlfn.XLOOKUP(_xlfn.XLOOKUP(TableIncome[[#This Row],[Year]],Loop!C:C,Loop!E:E),'Job Hopping'!B:B,'Job Hopping'!G:G) -> N
B14: 2036 | C14: =(TableIncomeCalculations[[#This Row],[GrossMonthlySalaryP1]]*12) -> 779648.25 | D14: =(TableIncomeCalculations[[#This Row],[GrossMonthlySalaryP2]]*12) -> 1034918.9 | E14: =TableIncome[[#This Row],[SalaryP1]]*$I$6 -> 77964.825 | F14: =TableIncome[[#This Row],[SalaryP2]]*$I$6 -> 103491.89 | M14: =IF(_xlfn.XLOOKUP(TableIncome[[#This Row],[Year]],Loop!C:C,Loop!D:D)<70,(M13*(1+$I$4))+IF(TableIncomeCalculations[[#This Row],[SwitchP1]]="Y",M13*$I$5,0),0) -> 64970.687 | N14: =IF(_xlfn.XLOOKUP(TableIncome[[#This Row],[Year]],Loop!C:C,Loop!E:E)<70,(N13*(1+$I$4))+IF(TableIncomeCalculations[[#This Row],[SwitchP2]]="Y",N13*$I$5,0),0) -> 86243.243 | O14: =_xlfn.XLOOKUP(_xlfn.XLOOKUP(TableIncome[[#This Row],[Year]],Loop!C:C,Loop!D:D),'Job Hopping'!B:B,'Job Hopping'!F:F) -> N | P14: =_xlfn.XLOOKUP(_xlfn.XLOOKUP(TableIncome[[#This Row],[Year]],Loop!C:C,Loop!E:E),'Job Hopping'!B:B,'Job Hopping'!G:G) -> N
B15: 2037 | C15: =(TableIncomeCalculations[[#This Row],[GrossMonthlySalaryP1]]*12) -> 787444.73 | D15: =(TableIncomeCalculations[[#This Row],[GrossMonthlySalaryP2]]*12) -> 1045268.1 | E15: =TableIncome[[#This Row],[SalaryP1]]*$I$6 -> 78744.473 | F15: =TableIncome[[#This Row],[SalaryP2]]*$I$6 -> 104526.81 | M15: =IF(_xlfn.XLOOKUP(TableIncome[[#This Row],[Year]],Loop!C:C,Loop!D:D)<70,(M14*(1+$I$4))+IF(TableIncomeCalculations[[#This Row],[SwitchP1]]="Y",M14*$I$5,0),0) -> 65620.394 | N15: =IF(_xlfn.XLOOKUP(TableIncome[[#This Row],[Year]],Loop!C:C,Loop!E:E)<70,(N14*(1+$I$4))+IF(TableIncomeCalculations[[#This Row],[SwitchP2]]="Y",N14*$I$5,0),0) -> 87105.676 | O15: =_xlfn.XLOOKUP(_xlfn.XLOOKUP(TableIncome[[#This Row],[Year]],Loop!C:C,Loop!D:D),'Job Hopping'!B:B,'Job Hopping'!F:F) -> N | P15: =_xlfn.XLOOKUP(_xlfn.XLOOKUP(TableIncome[[#This Row],[Year]],Loop!C:C,Loop!E:E),'Job Hopping'!B:B,'Job Hopping'!G:G) -> N
B16: 2038 | C16: =(TableIncomeCalculations[[#This Row],[GrossMonthlySalaryP1]]*12) -> 795319.18 | D16: =(TableIncomeCalculations[[#This Row],[GrossMonthlySalaryP2]]*12) -> 1055720.8 | E16: =TableIncome[[#This Row],[SalaryP1]]*$I$6 -> 79531.918 | F16: =TableIncome[[#This Row],[SalaryP2]]*$I$6 -> 105572.08 | M16: =IF(_xlfn.XLOOKUP(TableIncome[[#This Row],[Year]],Loop!C:C,Loop!D:D)<70,(M15*(1+$I$4))+IF(TableIncomeCalculations[[#This Row],[SwitchP1]]="Y",M15*$I$5,0),0) -> 66276.598 | N16: =IF(_xlfn.XLOOKUP(TableIncome[[#This Row],[Year]],Loop!C:C,Loop!E:E)<70,(N15*(1+$I$4))+IF(TableIncomeCalculations[[#This Row],[SwitchP2]]="Y",N15*$I$5,0),0) -> 87976.733 | O16: =_xlfn.XLOOKUP(_xlfn.XLOOKUP(TableIncome[[#This Row],[Year]],Loop!C:C,Loop!D:D),'Job Hopping'!B:B,'Job Hopping'!F:F) -> N | P16: =_xlfn.XLOOKUP(_xlfn.XLOOKUP(TableIncome[[#This Row],[Year]],Loop!C:C,Loop!E:E),'Job Hopping'!B:B,'Job Hopping'!G:G) -> N
B17: 2039 | C17: =(TableIncomeCalculations[[#This Row],[GrossMonthlySalaryP1]]*12) -> 882804.29 | D17: =(TableIncomeCalculations[[#This Row],[GrossMonthlySalaryP2]]*12) -> 1066278 | E17: =TableIncome[[#This Row],[SalaryP1]]*$I$6 -> 88280.429 | F17: =TableIncome[[#This Row],[SalaryP2]]*$I$6 -> 106627.8 | M17: =IF(_xlfn.XLOOKUP(TableIncome[[#This Row],[Year]],Loop!C:C,Loop!D:D)<70,(M16*(1+$I$4))+IF(TableIncomeCalculations[[#This Row],[SwitchP1]]="Y",M16*$I$5,0),0) -> 73567.024 | N17: =IF(_xlfn.XLOOKUP(TableIncome[[#This Row],[Year]],Loop!C:C,Loop!E:E)<70,(N16*(1+$I$4))+IF(TableIncomeCalculations[[#This Row],[SwitchP2]]="Y",N16*$I$5,0),0) -> 88856.5 | O17: =_xlfn.XLOOKUP(_xlfn.XLOOKUP(TableIncome[[#This Row],[Year]],Loop!C:C,Loop!D:D),'Job Hopping'!B:B,'Job Hopping'!F:F) -> Y | P17: =_xlfn.XLOOKUP(_xlfn.XLOOKUP(TableIncome[[#This Row],[Year]],Loop!C:C,Loop!E:E),'Job Hopping'!B:B,'Job Hopping'!G:G) -> N
B18: 2040 | C18: =(TableIncomeCalculations[[#This Row],[GrossMonthlySalaryP1]]*12) -> 891632.33 | D18: =(TableIncomeCalculations[[#This Row],[GrossMonthlySalaryP2]]*12) -> 1076940.8 | E18: =TableIncome[[#This Row],[SalaryP1]]*$I$6 -> 89163.233 | F18: =TableIncome[[#This Row],[SalaryP2]]*$I$6 -> 107694.08 | M18: =IF(_xlfn.XLOOKUP(TableIncome[[#This Row],[Year]],Loop!C:C,Loop!D:D)<70,(M17*(1+$I$4))+IF(TableIncomeCalculations[[#This Row],[SwitchP1]]="Y",M17*$I$5,0),0) -> 74302.694 | N18: =IF(_xlfn.XLOOKUP(TableIncome[[#This Row],[Year]],Loop!C:C,Loop!E:E)<70,(N17*(1+$I$4))+IF(TableIncomeCalculations[[#This Row],[SwitchP2]]="Y",N17*$I$5,0),0) -> 89745.065 | O18: =_xlfn.XLOOKUP(_xlfn.XLOOKUP(TableIncome[[#This Row],[Year]],Loop!C:C,Loop!D:D),'Job Hopping'!B:B,'Job Hopping'!F:F) -> N | P18: =_xlfn.XLOOKUP(_xlfn.XLOOKUP(TableIncome[[#This Row],[Year]],Loop!C:C,Loop!E:E),'Job Hopping'!B:B,'Job Hopping'!G:G) -> N
... B48: 2070 | C48: =(TableIncomeCalculations[[#This Row],[GrossMonthlySalaryP1]]*12) -> 0 | D48: =(TableIncomeCalculations[[#This Row],[GrossMonthlySalaryP2]]*12) -> 0 | E48: =TableIncome[[#This Row],[SalaryP1]]*$I$6 -> 0 | F48: =TableIncome[[#This Row],[SalaryP2]]*$I$6 -> 0 | M48: =IF(_xlfn.XLOOKUP(TableIncome[[#This Row],[Year]],Loop!C:C,Loop!D:D)<70,(M47*(1+$I$4))+IF(TableIncomeCalculations[[#This Row],[SwitchP1]]="Y",M47*$I$5,0),0) -> 0 | N48: =IF(_xlfn.XLOOKUP(TableIncome[[#This Row],[Year]],Loop!C:C,Loop!E:E)<70,(N47*(1+$I$4))+IF(TableIncomeCalculations[[#This Row],[SwitchP2]]="Y",N47*$I$5,0),0) -> 0 | O48: =_xlfn.XLOOKUP(_xlfn.XLOOKUP(TableIncome[[#This Row],[Year]],Loop!C:C,Loop!D:D),'Job Hopping'!B:B,'Job Hopping'!F:F) -> N | P48: =_xlfn.XLOOKUP(_xlfn.XLOOKUP(TableIncome[[#This Row],[Year]],Loop!C:C,Loop!E:E),'Job Hopping'!B:B,'Job Hopping'!G:G) -> N

Sheet Job Hopping
B2: Age | C2: Age Group | D2: FH/FW | E2: Switch | F2: SwitchP1Static | G2: SwitchP2Static | M2: Year | N2: Age Group | O2: Finance Workers | P2: Finance Hoppers | Q2: FH/FW | S2: Age Group | T2: FH/FV
B3: 25 | C3: =IF(B3<30, "25-29 år", IF(B3<35, "30-34 år", IF(B3<40, "35-39 år", IF(B3<45, "40-44 år", IF(B3<50, "45-49 år", IF(B3<55, "50-54 år", IF(B3<60, "55-59 år", IF(B3<65, "60-64 år", "65+ år")))))))) -> 25-29 år | D3: =_xlfn.XLOOKUP(C3,S:S,T:T) -> 0.51651948 | E3: =IF(OR(JobHopping[[#This Row],[Age]]=25,JobHopping[[#This Row],[Age]]>69),"N",IF(AND(E1="N",E2="N", RAND()<=D3), "Y", "N")) -> N | F3: N | G3: =IF(JobHopping[[#This Row],[Age]]<40,"",JobHopping[[#This Row],[SwitchP1Static]]) | M3: 2013 | N3: 25-29 år | O3: =_xlfn.XLOOKUP(M3&"-"&N3,'Djøf Finance Workers'!D:D,'Djøf Finance Workers'!C:C,0,1) -> 6202 | P3: =_xlfn.XLOOKUP(M3&"-"&N3,'Djøf Finance Hoppers'!D:D,'Djøf Finance Hoppers'!C:C,0,1) -> 2524 | Q3: =IF(O3>0, P3/O3, 0) -> 0.4069655 | S3: 25-29 år | T3: =SUMIFS(Q:Q,N:N,S3)/(MAX($M$3:$M$101)-MIN($M$3:$M$101)) -> 0.51651948
B4: 26 | C4: =IF(B4<30, "25-29 år", IF(B4<35, "30-34 år", IF(B4<40, "35-39 år", IF(B4<45, "40-44 år", IF(B4<50, "45-49 år", IF(B4<55, "50-54 år", IF(B4<60, "55-59 år", IF(B4<65, "60-64 år", "65+ år")))))))) -> 25-29 år | D4: =_xlfn.XLOOKUP(C4,S:S,T:T) -> 0.51651948 | E4: =IF(OR(JobHopping[[#This Row],[Age]]=25,JobHopping[[#This Row],[Age]]>69),"N",IF(AND(E2="N",E3="N", RAND()<=D4), "Y", "N")) -> N | F4: N | G4: =IF(JobHopping[[#This Row],[Age]]<40,"",JobHopping[[#This Row],[SwitchP1Static]]) | M4: 2013 | N4: 30-34 år | O4: =_xlfn.XLOOKUP(M4&"-"&N4,'Djøf Finance Workers'!D:D,'Djøf Finance Workers'!C:C,0,1) -> 8560 | P4: =_xlfn.XLOOKUP(M4&"-"&N4,'Djøf Finance Hoppers'!D:D,'Djøf Finance Hoppers'!C:C,0,1) -> 2176 | Q4: =IF(O4>0, P4/O4, 0) -> 0.25420561 | S4: 30-34 år | T4: =SUMIFS(Q:Q,N:N,S4)/(MAX($M$3:$M$101)-MIN($M$3:$M$101)) -> 0.3390802
B5: 27 | C5: =IF(B5<30, "25-29 år", IF(B5<35, "30-34 år", IF(B5<40, "35-39 år", IF(B5<45, "40-44 år", IF(B5<50, "45-49 år", IF(B5<55, "50-54 år", IF(B5<60, "55-59 år", IF(B5<65, "60-64 år", "65+ år")))))))) -> 25-29 år | D5: =_xlfn.XLOOKUP(C5,S:S,T:T) -> 0.51651948 | E5: =IF(OR(JobHopping[[#This Row],[Age]]=25,JobHopping[[#This Row],[Age]]>69),"N",IF(AND(E3="N",E4="N", RAND()<=D5), "Y", "N")) -> N | F5: Y | G5: =IF(JobHopping[[#This Row],[Age]]<40,"",JobHopping[[#This Row],[SwitchP1Static]]) | M5: 2013 | N5: 35-39 år | O5: =_xlfn.XLOOKUP(M5&"-"&N5,'Djøf Finance Workers'!D:D,'Djøf Finance Workers'!C:C,0,1) -> 9790 | P5: =_xlfn.XLOOKUP(M5&"-"&N5,'Djøf Finance Hoppers'!D:D,'Djøf Finance Hoppers'!C:C,0,1) -> 1896 | Q5: =IF(O5>0, P5/O5, 0) -> 0.19366701 | S5: 35-39 år | T5: =SUMIFS(Q:Q,N:N,S5)/(MAX($M$3:$M$101)-MIN($M$3:$M$101)) -> 0.26240269
B6: 28 | C6: =IF(B6<30, "25-29 år", IF(B6<35, "30-34 år", IF(B6<40, "35-39 år", IF(B6<45, "40-44 år", IF(B6<50, "45-49 år", IF(B6<55, "50-54 år", IF(B6<60, "55-59 år", IF(B6<65, "60-64 år", "65+ år")))))))) -> 25-29 år | D6: =_xlfn.XLOOKUP(C6,S:S,T:T) -> 0.51651948 | E6: =IF(OR(JobHopping[[#This Row],[Age]]=25,JobHopping[[#This Row],[Age]]>69),"N",IF(AND(E4="N",E5="N", RAND()<=D6), "Y", "N")) -> N | F6: N | G6: =IF(JobHopping[[#This Row],[Age]]<40,"",JobHopping[[#This Row],[SwitchP1Static]]) | M6: 2013 | N6: 40-44 år | O6: =_xlfn.XLOOKUP(M6&"-"&N6,'Djøf Finance Workers'!D:D,'Djøf Finance Workers'!C:C,0,1) -> 9383 | P6: =_xlfn.XLOOKUP(M6&"-"&N6,'Djøf Finance Hoppers'!D:D,'Djøf Finance Hoppers'!C:C,0,1) -> 1579 | Q6: =IF(O6>0, P6/O6, 0) -> 0.16828307 | S6: 40-44 år | T6: =SUMIFS(Q:Q,N:N,S6)/(MAX($M$3:$M$101)-MIN($M$3:$M$101)) -> 0.22131873
B7: 29 | C7: =IF(B7<30, "25-29 år", IF(B7<35, "30-34 år", IF(B7<40, "35-39 år", IF(B7<45, "40-44 år", IF(B7<50, "45-49 år", IF(B7<55, "50-54 år", IF(B7<60, "55-59 år", IF(B7<65, "60-64 år", "65+ år")))))))) -> 25-29 år | D7: =_xlfn.XLOOKUP(C7,S:S,T:T) -> 0.51651948 | E7: =IF(OR(JobHopping[[#This Row],[Age]]=25,JobHopping[[#This Row],[Age]]>69),"N",IF(AND(E5="N",E6="N", RAND()<=D7), "Y", "N")) -> N | F7: N | G7: =IF(JobHopping[[#This Row],[Age]]<40,"",JobHopping[[#This Row],[SwitchP1Static]]) | M7: 2013 | N7: 45-49 år | O7: =_xlfn.XLOOKUP(M7&"-"&N7,'Djøf Finance Workers'!D:D,'Djøf Finance Workers'!C:C,0,1) -> 12762 | P7: =_xlfn.XLOOKUP(M7&"-"&N7,'Djøf Finance Hoppers'!D:D,'Djøf Finance Hoppers'!C:C,0,1) -> 1915 | Q7: =IF(O7>0, P7/O7, 0) -> 0.15005485 | S7: 45-49 år | T7: =SUMIFS(Q:Q,N:N,S7)/(MAX($M$3:$M$101)-MIN($M$3:$M$101)) -> 0.1992948
B8: 30 | C8: =IF(B8<30, "25-29 år", IF(B8<35, "30-34 år", IF(B8<40, "35-39 år", IF(B8<45, "40-44 år", IF(B8<50, "45-49 år", IF(B8<55, "50-54 år", IF(B8<60, "55-59 år", IF(B8<65, "60-64 år", "65+ år")))))))) -> 30-34 år | D8: =_xlfn.XLOOKUP(C8,S:S,T:T) -> 0.3390802 | E8: =IF(OR(JobHopping[[#This Row],[Age]]=25,JobHopping[[#This Row],[Age]]>69),"N",IF(AND(E6="N",E7="N", RAND()<=D8), "Y", "N")) -> Y | F8: N | G8: =IF(JobHopping[[#This Row],[Age]]<40,"",JobHopping[[#This Row],[SwitchP1Static]]) | M8: 2013 | N8: 50-54 år | O8: =_xlfn.XLOOKUP(M8&"-"&N8,'Djøf Finance Workers'!D:D,'Djøf Finance Workers'!C:C,0,1) -> 10587 | P8: =_xlfn.XLOOKUP(M8&"-"&N8,'Djøf Finance Hoppers'!D:D,'Djøf Finance Hoppers'!C:C,0,1) -> 1462 | Q8: =IF(O8>0, P8/O8, 0) -> 0.13809389 | S8: 50-54 år | T8: =SUMIFS(Q:Q,N:N,S8)/(MAX($M$3:$M$101)-MIN($M$3:$M$101)) -> 0.17668929
